Workbook

Sheet 01_23
A1: Tagesumsätze | H1: 44927
C3: Restaurant | E3: Terrasse | G3: Lounge | I3: Pavillon | K3: Bankett | M3: Seminar | Q3: Hotel | S3: TOTAL Gesamtbetrieb ohne Seebad | U3: Seebad | W3: TOTAL Gesamtbetrieb mit Seebad | Y3: Info's
C4: IST | D4: Budget | E4: IST | F4: Budget | G4: IST | H4: Budget | I4: IST | J4: Budget | K4: IST | L4: Budget | M4: IST/GN | N4: IST/ET | O4: TOTAL IST | P4: Budget | Q4: IST | R4: Budget | S4: IST | T4: Budget | U4: IST | V4: Budget | W4: IST | X4: Budget | Y4: Wetter | Z4: Temp. | AB4: Bemerkung
A5: 1 | B5: So | C5: 10468 | D5: 5161.2903 | E5: 2002 | F5: 32.25806 | G5: 244.9 | H5: 32.25806 | K5: 0 | L5: 1935.4839 | N5: 0 | O5: =M5+N5 -> 0 | P5: 967.74194 | Q5: 6009.5 | R5: 2638.7097 | S5: =SUM(C5+E5+G5+I5+K5+O5+Q5) -> 18724.4 | T5: =SUM(D5+F5+H5+J5+L5+P5+R5) -> 10767.742 | W5: =SUM(S5+U5) -> 18724.4 | X5: =SUM(T5+V5) -> 10767.742 | Y5: sonnig | Z5: 14 | AA5: °C
A6: KW | B6: 52 | C6: =SUM(C5:C5) -> 10468 | D6: =SUM(D5:D5) -> 5161.2903 | E6: =SUM(E5:E5) -> 2002 | F6: =SUM(F5:F5) -> 32.25806 | G6: =SUM(G5:G5) -> 244.9 | H6: =SUM(H5:H5) -> 32.25806 | I6: =SUM(I5:I5) -> 0 | J6: =SUM(J5:J5) -> 0 | ... X6: =SUM(X5:X5) -> 10767.742 | Y6: Ø Temp | Z6: =SUM(Z5:Z5)/5 -> 2.8 | AA6: °C
A7: =SUM(A5+1) -> 2 | B7: Mo | C7: 9440.6 | D7: 5161.2903 | E7: 76.7 | F7: 32.25806 | G7: 89 | H7: 32.25806 | K7: 0 | L7: 1935.4839 | N7: 0 | O7: =M7+N7 -> 0 | P7: 967.74194 | Q7: 2549.6 | R7: 2638.7097 | S7: =SUM(C7+E7+G7+I7+K7+O7+Q7) -> 12155.9 | T7: =SUM(D7+F7+H7+J7+L7+P7+R7) -> 10767.742 | W7: =SUM(S7+U7) -> 12155.9 | X7: =SUM(T7+V7) -> 10767.742 | Y7: sonnig | Z7: 12 | AA7: °C
A8: =SUM(A7+1) -> 3 | B8: Di | C8: 2919.1 | D8: 5161.2903 | E8: 0 | F8: 32.25806 | G8: 0 | H8: 32.25806 | K8: 3677.8 | L8: 1935.4839 | M8: 0 | N8: 0 | O8: =M8+N8 -> 0 | P8: 967.74194 | Q8: 1665.2 | R8: 2638.7097 | S8: =SUM(C8+E8+G8+I8+K8+O8+Q8) -> 8262.1 | T8: =SUM(D8+F8+H8+J8+L8+P8+R8) -> 10767.742 | W8: =SUM(S8+U8) -> 8262.1 | X8: =SUM(T8+V8) -> 10767.742 | AA8: °C
A9: =SUM(A8+1) -> 4 | B9: Mi | C9: 4070.3 | D9: 5161.2903 | E9: 0 | F9: 32.25806 | G9: 0 | H9: 32.25806 | K9: 0 | L9: 1935.4839 | M9: 0 | N9: 1200 | O9: =M9+N9 -> 1200 | P9: 967.74194 | Q9: 1678.5 | R9: 2638.7097 | S9: =SUM(C9+E9+G9+I9+K9+O9+Q9) -> 6948.8 | T9: =SUM(D9+F9+H9+J9+L9+P9+R9) -> 10767.742 | W9: =SUM(S9+U9) -> 6948.8 | X9: =SUM(T9+V9) -> 10767.742 | AA9: °C
A10: =SUM(A9+1) -> 5 | B10: Do | C10: 5371.7 | D10: 5161.2903 | E10: 0 | F10: 32.25806 | G10: 0 | H10: 32.25806 | K10: 0 | L10: 1935.4839 | M10: 0 | N10: 0 | O10: =M10+N10 -> 0 | P10: 967.74194 | Q10: 1582 | R10: 2638.7097 | S10: =SUM(C10+E10+G10+I10+K10+O10+Q10) -> 6953.7 | T10: =SUM(D10+F10+H10+J10+L10+P10+R10) -> 10767.742 | W10: =SUM(S10+U10) -> 6953.7 | X10: =SUM(T10+V10) -> 10767.742 | AA10: °C
A11: =SUM(A10+1) -> 6 | B11: Fr | C11: 7603.2 | D11: 5161.2903 | E11: 0 | F11: 32.25806 | G11: 0 | H11: 32.25806 | K11: 8659.1 | L11: 1935.4839 | M11: 0 | N11: 0 | O11: =M11+N11 -> 0 | P11: 967.74194 | Q11: 2527.85 | R11: 2638.7097 | S11: =SUM(C11+E11+G11+I11+K11+O11+Q11) -> 18790.15 | T11: =SUM(D11+F11+H11+J11+L11+P11+R11) -> 10767.742 | W11: =SUM(S11+U11) -> 18790.15 | X11: =SUM(T11+V11) -> 10767.742 | AA11: °C
A12: =SUM(A11+1) -> 7 | B12: Sa | C12: 13336 | D12: 5161.2903 | E12: 226 | F12: 32.25806 | G12: 339.6 | H12: 32.25806 | K12: 2906.5 | L12: 1935.4839 | M12: 0 | N12: 0 | O12: =M12+N12 -> 0 | P12: 967.74194 | Q12: 2890.4 | R12: 2638.7097 | S12: =SUM(C12+E12+G12+I12+K12+O12+Q12) -> 19698.5 | T12: =SUM(D12+F12+H12+J12+L12+P12+R12) -> 10767.742 | W12: =SUM(S12+U12) -> 19698.5 | X12: =SUM(T12+V12) -> 10767.742 | AA12: °C
A13: =SUM(A12+1) -> 8 | B13: So | C13: 5025.8 | D13: 5161.2903 | E13: 0 | F13: 32.25806 | G13: 0 | H13: 32.25806 | K13: 0 | L13: 1935.4839 | M13: 0 | N13: 0 | O13: =M13+N13 -> 0 | P13: 967.74194 | Q13: 496.4 | R13: 2638.7097 | S13: =SUM(C13+E13+G13+I13+K13+O13+Q13) -> 5522.2 | T13: =SUM(D13+F13+H13+J13+L13+P13+R13) -> 10767.742 | W13: =SUM(S13+U13) -> 5522.2 | X13: =SUM(T13+V13) -> 10767.742 | AA13: °C | AB13: MA Feier ab 16:00 geschlossen
A14: KW | B14: 1 | C14: =SUM(C7:C13) -> 47766.7 | D14: =SUM(D7:D13) -> 36129.032 | E14: =SUM(E7:E13) -> 302.7 | F14: =SUM(F7:F13) -> 225.80642 | G14: =SUM(G7:G13) -> 428.6 | H14: =SUM(H7:H13) -> 225.80642 | I14: =SUM(I7:I13) -> 0 | J14: 0 | K14: =SUM(K7:K13) -> 15243.4 | L14: =SUM(L7:L13) -> 13548.387 | M14: =SUM(M7:M13) -> 0 | N14: =SUM(N7:N13) -> 1200 | O14: =SUM(O7:O13) -> 1200 | P14: =SUM(P7:P13) -> 6774.1935 | Q14: =SUM(Q7:Q13) -> 13389.95 | R14: =SUM(R7:R13) -> 18470.968 | ... X14: =SUM(X7:X13) -> 75374.193 | Y14: Ø Temp | Z14: =SUM(Z7:Z13)/7 -> 1.7142857 | AA14: °C
A15: =SUM(A13+1) -> 9 | B15: Mo | C15: 5560.7 | D15: 5161.2903 | E15: 0 | F15: 32.25806 | G15: 0 | H15: 32.25806 | K15: 1866.8 | L15: 1935.4839 | M15: 0 | N15: 0 | O15: =M15+N15 -> 0 | P15: 967.74194 | Q15: 796.2 | R15: 2638.7097 | S15: =SUM(C15+E15+G15+I15+K15+O15+Q15) -> 8223.7 | T15: =SUM(D15+F15+H15+J15+L15+P15+R15) -> 10767.742 | W15: =SUM(S15+U15) -> 8223.7 | X15: =SUM(T15+V15) -> 10767.742 | AA15: °C
A16: =SUM(A15+1) -> 10 | B16: Di | C16: 2287.2 | D16: 5161.2903 | E16: 0 | F16: 32.25806 | G16: 0 | H16: 32.25806 | K16: 0 | L16: 1935.4839 | M16: 0 | N16: 0 | O16: =M16+N16 -> 0 | P16: 967.74194 | Q16: 1028 | R16: 2638.7097 | S16: =SUM(C16+E16+G16+I16+K16+O16+Q16) -> 3315.2 | T16: =SUM(D16+F16+H16+J16+L16+P16+R16) -> 10767.742 | W16: =SUM(S16+U16) -> 3315.2 | X16: =SUM(T16+V16) -> 10767.742 | AA16: °C
A17: =SUM(A16+1) -> 11 | B17: Mi | C17: 5738.8 | D17: 5161.2903 | E17: 0 | F17: 32.25806 | G17: 15 | H17: 32.25806 | K17: 0 | L17: 1935.4839 | M17: 749.6 | N17: 2064 | O17: =M17+N17 -> 2813.6 | P17: 967.74194 | Q17: 2189.4 | R17: 2638.7097 | S17: =SUM(C17+E17+G17+I17+K17+O17+Q17) -> 10756.8 | T17: =SUM(D17+F17+H17+J17+L17+P17+R17) -> 10767.742 | W17: =SUM(S17+U17) -> 10756.8 | X17: =SUM(T17+V17) -> 10767.742 | AA17: °C
A18: =SUM(A17+1) -> 12 | B18: Do | C18: 4954.8 | D18: 5161.2903 | E18: 0 | F18: 32.25806 | G18: 0 | H18: 32.25806 | K18: 0 | L18: 1935.4839 | M18: 1603.7 | N18: 6807 | O18: =M18+N18 -> 8410.7 | P18: 967.74194 | Q18: 5554.8 | R18: 2638.7097 | S18: =SUM(C18+E18+G18+I18+K18+O18+Q18) -> 18920.3 | T18: =SUM(D18+F18+H18+J18+L18+P18+R18) -> 10767.742 | W18: =SUM(S18+U18) -> 18920.3 | X18: =SUM(T18+V18) -> 10767.742 | AA18: °C
A19: =SUM(A18+1) -> 13 | B19: Fr | C19: 6164 | D19: 5161.2903 | E19: 0 | F19: 32.25806 | G19: 0 | H19: 32.25806 | K19: 17902.9 | L19: 1935.4839 | M19: 22.6 | N19: 1836 | O19: =M19+N19 -> 1858.6 | P19: 967.74194 | Q19: 2119.7 | R19: 2638.7097 | S19: =SUM(C19+E19+G19+I19+K19+O19+Q19) -> 28045.2 | T19: =SUM(D19+F19+H19+J19+L19+P19+R19) -> 10767.742 | W19: =SUM(S19+U19) -> 28045.2 | X19: =SUM(T19+V19) -> 10767.742 | AA19: °C
A20: =SUM(A19+1) -> 14 | B20: Sa | C20: 11289.9 | D20: 5161.2903 | E20: 0 | F20: 32.25806 | G20: 19.5 | H20: 32.25806 | K20: 5689.2 | L20: 1935.4839 | M20: 2757 | N20: 11124 | O20: =M20+N20 -> 13881 | P20: 967.74194 | Q20: 3269.6 | R20: 2638.7097 | S20: =SUM(C20+E20+G20+I20+K20+O20+Q20) -> 34149.2 | T20: =SUM(D20+F20+H20+J20+L20+P20+R20) -> 10767.742 | W20: =SUM(S20+U20) -> 34149.2 | X20: =SUM(T20+V20) -> 10767.742 | AA20: °C
A21: =SUM(A20+1) -> 15 | B21: So | C21: 7346.6 | D21: 5161.2903 | E21: 0 | F21: 32.25806 | G21: 0 | H21: 32.25806 | K21: 2815.7 | L21: 1935.4839 | M21: 0 | N21: 0 | O21: =M21+N21 -> 0 | P21: 967.74194 | Q21: 1431.4 | R21: 2638.7097 | S21: =SUM(C21+E21+G21+I21+K21+O21+Q21) -> 11593.7 | T21: =SUM(D21+F21+H21+J21+L21+P21+R21) -> 10767.742 | W21: =SUM(S21+U21) -> 11593.7 | X21: =SUM(T21+V21) -> 10767.742 | AA21: °C
A22: KW | B22: =SUM(B14+1) -> 2 | C22: =SUM(C15:C21) -> 43342 | D22: =SUM(D15:D21) -> 36129.032 | E22: =SUM(E15:E21) -> 0 | F22: =SUM(F15:F21) -> 225.80642 | G22: =SUM(G15:G21) -> 34.5 | H22: =SUM(H15:H21) -> 225.80642 | I22: =SUM(I15:I21) -> 0 | J22: 0 | K22: =SUM(K15:K21) -> 28274.6 | L22: =SUM(L15:L21) -> 13548.387 | M22: =SUM(M15:M21) -> 5132.9 | N22: =SUM(N15:N21) -> 21831 | O22: =SUM(O15:O21) -> 26963.9 | P22: =SUM(P15:P21) -> 6774.1935 | Q22: =SUM(Q15:Q21) -> 16389.1 | R22: =SUM(R15:R21) -> 18470.968 | ... X22: =SUM(X15:X21) -> 75374.193 | Y22: Ø Temp | Z22: =SUM(Z15:Z21)/7 -> 0 | AA22: °C
A23: =SUM(A21+1) -> 16 | B23: Mo | C23: 5932.5 | D23: 5161.2903 | E23: 0 | F23: 32.25806 | G23: 0 | H23: 32.25806 | K23: 0 | L23: 1935.4839 | M23: 993.6 | N23: 0 | O23: =M23+N23 -> 993.6 | P23: 967.74194 | Q23: 4802.6 | R23: 2638.7097 | S23: =SUM(C23+E23+G23+I23+K23+O23+Q23) -> 11728.7 | T23: =SUM(D23+F23+H23+J23+L23+P23+R23) -> 10767.742 | W23: =SUM(S23+U23) -> 11728.7 | X23: =SUM(T23+V23) -> 10767.742 | Y23: Schnee | Z23: 1 | AA23: °C
A24: =SUM(A23+1) -> 17 | B24: Di | C24: 4476.4 | D24: 5161.2903 | E24: 0 | F24: 32.25806 | G24: 0 | H24: 32.25806 | K24: 987 | L24: 1935.4839 | M24: 1556.7 | N24: 4401 | O24: =M24+N24 -> 5957.7 | P24: 967.74194 | Q24: 6459.1 | R24: 2638.7097 | S24: =SUM(C24+E24+G24+I24+K24+O24+Q24) -> 17880.2 | T24: =SUM(D24+F24+H24+J24+L24+P24+R24) -> 10767.742 | W24: =SUM(S24+U24) -> 17880.2 | X24: =SUM(T24+V24) -> 10767.742 | Y24: Schnee | Z24: 1 | AA24: °C
A25: =SUM(A24+1) -> 18 | B25: Mi | C25: 4486.6 | D25: 5161.2903 | E25: 0 | F25: 32.25806 | G25: 0 | H25: 32.25806 | K25: 0 | L25: 1935.4839 | M25: 1767 | N25: 5647 | O25: =M25+N25 -> 7414 | P25: 967.74194 | Q25: 6393.5 | R25: 2638.7097 | S25: =SUM(C25+E25+G25+I25+K25+O25+Q25) -> 18294.1 | T25: =SUM(D25+F25+H25+J25+L25+P25+R25) -> 10767.742 | W25: =SUM(S25+U25) -> 18294.1 | X25: =SUM(T25+V25) -> 10767.742 | Y25: Schnee | Z25: 1 | AA25: °C
A26: =SUM(A25+1) -> 19 | B26: Do | C26: 4113.4 | D26: 5161.2903 | E26: 0 | F26: 32.25806 | G26: 0 | H26: 32.25806 | K26: 0 | L26: 1935.4839 | M26: 696.1 | N26: 5024 | O26: =M26+N26 -> 5720.1 | P26: 967.74194 | Q26: 5233 | R26: 2638.7097 | S26: =SUM(C26+E26+G26+I26+K26+O26+Q26) -> 15066.5 | T26: =SUM(D26+F26+H26+J26+L26+P26+R26) -> 10767.742 | W26: =SUM(S26+U26) -> 15066.5 | X26: =SUM(T26+V26) -> 10767.742 | Y26: sonnig | Z26: 0.5 | AA26: °C
A27: =SUM(A26+1) -> 20 | B27: Fr | C27: 9020.1 | D27: 5161.2903 | E27: 0 | F27: 32.25806 | G27: 0 | H27: 32.25806 | K27: 5231.4 | L27: 1935.4839 | M27: 438.2 | N27: 3928 | O27: =M27+N27 -> 4366.2 | P27: 967.74194 | Q27: 3387.5 | R27: 2638.7097 | S27: =SUM(C27+E27+G27+I27+K27+O27+Q27) -> 22005.2 | T27: =SUM(D27+F27+H27+J27+L27+P27+R27) -> 10767.742 | W27: =SUM(S27+U27) -> 22005.2 | X27: =SUM(T27+V27) -> 10767.742 | Y27: sonnig | Z27: -2 | AA27: °C
A28: =SUM(A27+1) -> 21 | B28: Sa | C28: 10713 | D28: 5161.2903 | E28: 0 | F28: 32.25806 | G28: 0 | H28: 32.25806 | K28: 0 | L28: 1935.4839 | M28: 0 | N28: 2562 | O28: =M28+N28 -> 2562 | P28: 967.74194 | Q28: 2565.4 | R28: 2638.7097 | S28: =SUM(C28+E28+G28+I28+K28+O28+Q28) -> 15840.4 | T28: =SUM(D28+F28+H28+J28+L28+P28+R28) -> 10767.742 | W28: =SUM(S28+U28) -> 15840.4 | X28: =SUM(T28+V28) -> 10767.742 | Y28: bedeckt | Z28: -1 | AA28: °C
A29: =SUM(A28+1) -> 22 | B29: So | C29: 6541.7 | D29: 5161.2903 | E29: 0 | F29: 32.25806 | G29: 0 | H29: 32.25806 | K29: 0 | L29: 1935.4839 | M29: 0 | N29: 0 | O29: =M29+N29 -> 0 | P29: 967.74194 | Q29: 589.6 | R29: 2638.7097 | S29: =SUM(C29+E29+G29+I29+K29+O29+Q29) -> 7131.3 | T29: =SUM(D29+F29+H29+J29+L29+P29+R29) -> 10767.742 | W29: =SUM(S29+U29) -> 7131.3 | X29: =SUM(T29+V29) -> 10767.742 | Y29: bewölkt | Z29: -2 | AA29: °C
A30: KW | B30: =SUM(B22+1) -> 3 | C30: =SUM(C23:C29) -> 45283.7 | D30: =SUM(D23:D29) -> 36129.032 | E30: =SUM(E23:E29) -> 0 | F30: =SUM(F23:F29) -> 225.80642 | G30: =SUM(G23:G29) -> 0 | H30: =SUM(H23:H29) -> 225.80642 | I30: =SUM(I23:I29) -> 0 | J30: =SUM(J23:J29) -> 0 | ... X30: =SUM(X23:X29) -> 75374.193 | Y30: Ø Temp | Z30: =SUM(Z23:Z29)/7 -> -0.21428571 | AA30: °C
A31: =SUM(A29+1) -> 23 | B31: Mo | C31: 5875.1 | D31: 5161.2903 | E31: 0 | F31: 32.25806 | G31: 0 | H31: 32.25806 | K31: 0 | L31: 1935.4839 | M31: 1513 | N31: 824 | O31: =M31+N31 -> 2337 | P31: 967.74194 | Q31: 3650.4 | R31: 2638.7097 | S31: =SUM(C31+E31+G31+I31+K31+O31+Q31) -> 11862.5 | T31: =SUM(D31+F31+H31+J31+L31+P31+R31) -> 10767.742 | W31: =SUM(S31+U31) -> 11862.5 | X31: =SUM(T31+V31) -> 10767.742 | Y31: bewölkt | Z31: -1 | AA31: °C
A32: =SUM(A31+1) -> 24 | B32: Di | C32: 3346.1 | D32: 5161.2903 | E32: 0 | F32: 32.25806 | G32: 0 | H32: 32.25806 | K32: 2877.2 | L32: 1935.4839 | M32: 942.4 | N32: 3666 | O32: =M32+N32 -> 4608.4 | P32: 967.74194 | Q32: 6224.2 | R32: 2638.7097 | S32: =SUM(C32+E32+G32+I32+K32+O32+Q32) -> 17055.9 | T32: =SUM(D32+F32+H32+J32+L32+P32+R32) -> 10767.742 | W32: =SUM(S32+U32) -> 17055.9 | X32: =SUM(T32+V32) -> 10767.742 | Y32: bewölkt | Z32: -1 | AA32: °C
A33: =SUM(A32+1) -> 25 | B33: Mi | C33: 5612.4 | D33: 5161.2903 | E33: 0 | F33: 32.25806 | G33: 0 | H33: 32.25806 | K33: 0 | L33: 1935.4839 | M33: 17.8 | N33: 2648 | O33: =M33+N33 -> 2665.8 | P33: 967.74194 | Q33: 4509.3 | R33: 2638.7097 | S33: =SUM(C33+E33+G33+I33+K33+O33+Q33) -> 12787.5 | T33: =SUM(D33+F33+H33+J33+L33+P33+R33) -> 10767.742 | W33: =SUM(S33+U33) -> 12787.5 | X33: =SUM(T33+V33) -> 10767.742 | Y33: bewölkt | Z33: -1 | AA33: °C
A34: =SUM(A33+1) -> 26 | B34: Do | C34: 3191 | D34: 5161.2903 | E34: 0 | F34: 32.25806 | G34: 0 | H34: 32.25806 | K34: 0 | L34: 1935.4839 | M34: 115 | N34: 2412 | O34: =M34+N34 -> 2527 | P34: 967.74194 | Q34: 1709.8 | R34: 2638.7097 | S34: =SUM(C34+E34+G34+I34+K34+O34+Q34) -> 7427.8 | T34: =SUM(D34+F34+H34+J34+L34+P34+R34) -> 10767.742 | W34: =SUM(S34+U34) -> 7427.8 | X34: =SUM(T34+V34) -> 10767.742 | Y34: bewölkt | Z34: -1 | AA34: °C
A35: =SUM(A34+1) -> 27 | B35: Fr | C35: 6370.2 | D35: 5161.2903 | E35: 0 | F35: 32.25806 | G35: 0 | H35: 32.25806 | K35: 0 | L35: 1935.4839 | M35: 0 | N35: 0 | O35: =M35+N35 -> 0 | P35: 967.74194 | Q35: 967.8 | R35: 2638.7097 | S35: =SUM(C35+E35+G35+I35+K35+O35+Q35) -> 7338 | T35: =SUM(D35+F35+H35+J35+L35+P35+R35) -> 10767.742 | W35: =SUM(S35+U35) -> 7338 | X35: =SUM(T35+V35) -> 10767.742 | Y35: bewölkt | Z35: -1 | AA35: °C
A36: =SUM(A35+1) -> 28 | B36: Sa | C36: 10223.4 | D36: 5161.2903 | E36: 0 | F36: 32.25806 | G36: 0 | H36: 32.25806 | K36: 0 | L36: 1935.4839 | M36: 0 | N36: 0 | O36: =M36+N36 -> 0 | P36: 967.74194 | Q36: 4402.4 | R36: 2638.7097 | S36: =SUM(C36+E36+G36+I36+K36+O36+Q36) -> 14625.8 | T36: =SUM(D36+F36+H36+J36+L36+P36+R36) -> 10767.742 | W36: =SUM(S36+U36) -> 14625.8 | X36: =SUM(T36+V36) -> 10767.742 | Y36: bewölkt | Z36: 1 | AA36: °C
A37: =SUM(A36+1) -> 29 | B37: So | C37: 6056.3 | D37: 5161.2903 | E37: 0 | F37: 32.25806 | G37: 0 | H37: 32.25806 | K37: 3183 | L37: 1935.4839 | M37: 0 | N37: 0 | O37: =M37+N37 -> 0 | P37: 967.74194 | Q37: 1417.8 | R37: 2638.7097 | S37: =SUM(C37+E37+G37+I37+K37+O37+Q37) -> 10657.1 | T37: =SUM(D37+F37+H37+J37+L37+P37+R37) -> 10767.742 | W37: =SUM(S37+U37) -> 10657.1 | X37: =SUM(T37+V37) -> 10767.742 | Z37: 5 | AA37: °C
A38: KW | B38: =SUM(B30+1) -> 4 | C38: =SUM(C31:C37) -> 40674.5 | D38: =SUM(D31:D37) -> 36129.032 | E38: =SUM(E31:E37) -> 0 | F38: =SUM(F31:F37) -> 225.80642 | G38: =SUM(G31:G37) -> 0 | H38: =SUM(H31:H37) -> 225.80642 | I38: =SUM(I31:I37) -> 0 | J38: =SUM(J31:J37) -> 0 | ... X38: =SUM(X31:X37) -> 75374.193 | Y38: Ø Temp | Z38: =SUM(Z31:Z37)/7 -> 0.14285714 | AA38: °C
A39: 30 | B39: Mo | C39: 4215.2 | D39: 5161.2903 | E39: 0 | F39: 32.25806 | G39: 10.9 | H39: 32.25806 | K39: 0 | L39: 1935.4839 | M39: 218.6 | N39: 1439 | O39: =M39+N39 -> 1657.6 | P39: 967.74194 | Q39: 3178.6 | R39: 2638.7097 | S39: =SUM(C39+E39+G39+I39+K39+O39+Q39) -> 9062.3 | T39: =SUM(D39+F39+H39+J39+L39+P39+R39) -> 10767.742 | W39: =SUM(S39+U39) -> 9062.3 | X39: =SUM(T39+V39) -> 10767.742 | Z39: -1 | AA39: °C
A40: 31 | B40: Di | C40: 5874 | D40: 5161.2903 | E40: 0 | F40: 32.25806 | G40: 34.8 | H40: 32.25806 | K40: 1526.2 | L40: 1935.4839 | M40: 6 | N40: 1368 | O40: =M40+N40 -> 1374 | P40: 967.74194 | Q40: 2493.6 | R40: 2638.7097 | S40: =SUM(C40+E40+G40+I40+K40+O40+Q40) -> 11302.6 | T40: =SUM(D40+F40+H40+J40+L40+P40+R40) -> 10767.742 | W40: =SUM(S40+U40) -> 11302.6 | X40: =SUM(T40+V40) -> 10767.742 | Z40: 0 | AA40: °C
A41: KW | B41: 5 | C41: =SUM(C39:C40) -> 10089.2 | D41: =SUM(D39:D40) -> 10322.581 | E41: =SUM(E39:E40) -> 0 | F41: =SUM(F39:F40) -> 64.51612 | G41: =SUM(G39:G40) -> 45.7 | H41: =SUM(H39:H40) -> 64.51612 | I41: =SUM(I39:I40) -> 0 | J41: =SUM(J39:J40) -> 0 | ... X41: =SUM(X39:X40) -> 21535.484 | Y41: Ø Temp | Z41: =SUM(Z31:Z37)/7 -> 0.14285714 | AA41: °C
...

Sheet 02_23
A1: Tagesumsätze | H1: 44958
C3: Restaurant | E3: Terrasse | G3: Lounge | I3: Pavillon | K3: Bankett | M3: Seminar | Q3: Hotel | S3: TOTAL Gesamtbetrieb ohne Seebad | U3: Seebad | W3: TOTAL Gesamtbetrieb mit Seebad | Y3: Info's
C4: IST | D4: Budget | E4: IST | F4: Budget | G4: IST | H4: Budget | I4: IST | J4: Budget | K4: IST | L4: Budget | M4: IST/GN | N4: IST/ET | O4: TOTAL IST | P4: Budget | Q4: IST | R4: Budget | S4: IST | T4: Budget | U4: IST | V4: Budget | W4: IST | X4: Budget | Y4: Wetter | Z4: Temp. | AB4: Bemerkung
A5: 1 | B5: Mi | C5: 3024.7 | D5: 6428.5714 | E5: 0 | F5: 35.714285 | G5: 0 | H5: 35.714285 | K5: 0 | L5: 2142.8571 | M5: 1922.9 | N5: 2175 | O5: =M5+N5 -> 4097.9 | P5: 1071.4285 | Q5: 4747.5 | R5: 2925 | S5: =C5+E5+G5+I5+K5+O5+Q5 -> 11870.1 | T5: =D5+F5+H5+J5+L5+P5+R5 -> 12639.286 | W5: =SUM(S5+U5) -> 11870.1 | X5: =SUM(T5+V5) -> 12639.286 | Y5: sonnig | Z5: 5 | AA5: °C
A6: =SUM(A5+1) -> 2 | B6: Do | C6: 5466.8 | D6: 6428.5714 | E6: 0 | F6: 35.714285 | G6: 0 | H6: 35.714285 | K6: 0 | L6: 2142.8571 | M6: 1589 | N6: 7146 | O6: =M6+N6 -> 8735 | P6: 1071.4285 | Q6: 5383.1 | R6: 2925 | S6: =C6+E6+G6+I6+K6+O6+Q6 -> 19584.9 | T6: =D6+F6+H6+J6+L6+P6+R6 -> 12639.286 | W6: =SUM(S6+U6) -> 19584.9 | X6: =SUM(T6+V6) -> 12639.286 | Y6: sonnig | Z6: 5 | AA6: °C
A7: =SUM(A6+1) -> 3 | B7: Fr | C7: 12900.9 | D7: 6428.5714 | E7: 0 | F7: 35.714285 | G7: 16.1 | H7: 35.714285 | K7: 4454.4 | L7: 2142.8571 | M7: 0 | N7: 2694 | O7: =M7+N7 -> 2694 | P7: 1071.4285 | Q7: 3786.5 | R7: 2925 | S7: =C7+E7+G7+I7+K7+O7+Q7 -> 23851.9 | T7: =D7+F7+H7+J7+L7+P7+R7 -> 12639.286 | W7: =SUM(S7+U7) -> 23851.9 | X7: =SUM(T7+V7) -> 12639.286 | Y7: sonnig | Z7: 5 | AA7: °C
A8: =SUM(A7+1) -> 4 | B8: Sa | C8: 12493.6 | D8: 6428.5714 | E8: 0 | F8: 35.714285 | G8: 0 | H8: 35.714285 | K8: 4175.1 | L8: 2142.8571 | M8: 0 | N8: 0 | O8: =M8+N8 -> 0 | P8: 1071.4285 | Q8: 3721.8 | R8: 2925 | S8: =C8+E8+G8+I8+K8+O8+Q8 -> 20390.5 | T8: =D8+F8+H8+J8+L8+P8+R8 -> 12639.286 | W8: =SUM(S8+U8) -> 20390.5 | X8: =SUM(T8+V8) -> 12639.286 | Y8: bewölkt | Z8: 5 | AA8: °C
A9: =SUM(A8+1) -> 5 | B9: So | C9: 8255.1 | D9: 6428.5714 | E9: 0 | F9: 35.714285 | G9: 0 | H9: 35.714285 | K9: 1885 | L9: 2142.8571 | M9: 0 | N9: 150 | O9: =M9+N9 -> 150 | P9: 1071.4285 | Q9: 4817.3 | R9: 2925 | S9: =C9+E9+G9+I9+K9+O9+Q9 -> 15107.4 | T9: =D9+F9+H9+J9+L9+P9+R9 -> 12639.286 | W9: =SUM(S9+U9) -> 15107.4 | X9: =SUM(T9+V9) -> 12639.286 | Y9: Regen | Z9: 3 | AA9: °C | AB9: YB zu Gast
A10: KW | B10: 5 | C10: =SUM(C5:C9) -> 42141.1 | D10: =SUM(D5:D9) -> 32142.857 | E10: =SUM(E5:E9) -> 0 | F10: =SUM(F5:F9) -> 178.57142 | G10: =SUM(G5:G9) -> 16.1 | H10: =SUM(H5:H9) -> 178.57142 | I10: =SUM(I5:I9) -> 0 | J10: =SUM(J5:J9) -> 0 | ... X10: =SUM(X5:X9) -> 63196.428 | Y10: Ø Temp | Z10: =SUM(Z5:Z9)/7 -> 3.2857143 | AA10: °C | AB10: Winterferien
A11: =SUM(A9+1) -> 6 | B11: Mo | C11: 5038.8 | D11: 6428.5714 | E11: 0 | F11: 35.714285 | G11: 0 | H11: 35.714285 | K11: 0 | L11: 2142.8571 | M11: 0 | N11: 0 | O11: =M11+N11 -> 0 | P11: 1071.4285 | Q11: 1797 | R11: 2925 | S11: =C11+E11+G11+I11+K11+O11+Q11 -> 6835.8 | T11: =D11+F11+H11+J11+L11+P11+R11 -> 12639.286 | W11: =SUM(S11+U11) -> 6835.8 | X11: =SUM(T11+V11) -> 12639.286 | Y11: Hochnebel | Z11: 3 | AA11: °C
A12: =SUM(A11+1) -> 7 | B12: Di | C12: 4986.3 | D12: 6428.5714 | E12: 0 | F12: 35.714285 | G12: 0 | H12: 35.714285 | K12: 835 | L12: 2142.8571 | M12: 0 | N12: 0 | O12: =M12+N12 -> 0 | P12: 1071.4285 | Q12: 2677.4 | R12: 2925 | S12: =C12+E12+G12+I12+K12+O12+Q12 -> 8498.7 | T12: =D12+F12+H12+J12+L12+P12+R12 -> 12639.286 | W12: =SUM(S12+U12) -> 8498.7 | X12: =SUM(T12+V12) -> 12639.286 | Y12: sonnig | Z12: 0 | AA12: °C
A13: =SUM(A12+1) -> 8 | B13: Mi | C13: 2499.9 | D13: 6428.5714 | E13: 0 | F13: 35.714285 | G13: 4.6 | H13: 35.714285 | K13: 954 | L13: 2142.8571 | M13: 212.3 | N13: 1371 | O13: =M13+N13 -> 1583.3 | P13: 1071.4285 | Q13: 2436.4 | R13: 2925 | S13: =C13+E13+G13+I13+K13+O13+Q13 -> 7478.2 | T13: =D13+F13+H13+J13+L13+P13+R13 -> 12639.286 | W13: =SUM(S13+U13) -> 7478.2 | X13: =SUM(T13+V13) -> 12639.286 | Y13: Hochnebel | Z13: -3 | AA13: °C
A14: =SUM(A13+1) -> 9 | B14: Do | C14: 4906.6 | D14: 6428.5714 | E14: 93.3 | F14: 35.714285 | G14: 242.5 | H14: 35.714285 | K14: 0 | L14: 2142.8571 | M14: 0 | N14: 1076 | O14: =M14+N14 -> 1076 | P14: 1071.4285 | Q14: 717.8 | R14: 2925 | S14: =C14+E14+G14+I14+K14+O14+Q14 -> 7036.2 | T14: =D14+F14+H14+J14+L14+P14+R14 -> 12639.286 | W14: =SUM(S14+U14) -> 7036.2 | X14: =SUM(T14+V14) -> 12639.286 | Y14: Sonnig | Z14: 3 | AA14: °C
A15: =SUM(A14+1) -> 10 | B15: Fr | C15: 6361.3 | D15: 6428.5714 | E15: 114.7 | F15: 35.714285 | G15: 231.8 | H15: 35.714285 | K15: 0 | L15: 2142.8571 | M15: 0 | N15: 0 | O15: =M15+N15 -> 0 | P15: 1071.4285 | Q15: 1554.6 | R15: 2925 | S15: =C15+E15+G15+I15+K15+O15+Q15 -> 8262.4 | T15: =D15+F15+H15+J15+L15+P15+R15 -> 12639.286 | W15: =SUM(S15+U15) -> 8262.4 | X15: =SUM(T15+V15) -> 12639.286 | Y15: sonnig | Z15: 4 | AA15: °C
A16: =SUM(A15+1) -> 11 | B16: Sa | C16: 9368.3 | D16: 6428.5714 | E16: 628.7 | F16: 35.714285 | G16: 472.2 | H16: 35.714285 | K16: 5442.5 | L16: 2142.8571 | M16: 0 | N16: 0 | O16: =M16+N16 -> 0 | P16: 1071.4285 | Q16: 3900.6 | R16: 2925 | S16: =C16+E16+G16+I16+K16+O16+Q16 -> 19812.3 | T16: =D16+F16+H16+J16+L16+P16+R16 -> 12639.286 | W16: =SUM(S16+U16) -> 19812.3 | X16: =SUM(T16+V16) -> 12639.286 | Y16: sonnig | Z16: 5 | AA16: °C
A17: =SUM(A16+1) -> 12 | B17: So | C17: 12198.9 | D17: 6428.5714 | E17: 2066.5 | F17: 35.714285 | G17: 797.5 | H17: 35.714285 | K17: 2597.5 | L17: 2142.8571 | M17: 0 | N17: 0 | O17: =M17+N17 -> 0 | P17: 1071.4285 | Q17: 1581.9 | R17: 2925 | S17: =C17+E17+G17+I17+K17+O17+Q17 -> 19242.3 | T17: =D17+F17+H17+J17+L17+P17+R17 -> 12639.286 | W17: =SUM(S17+U17) -> 19242.3 | X17: =SUM(T17+V17) -> 12639.286 | Y17: sonnig | Z17: 6 | AA17: °C | AB17: Fasnachtferien
A18: KW | B18: =SUM(B10+1) -> 6 | C18: =SUM(C11:C17) -> 45360.1 | D18: =SUM(D11:D17) -> 45000 | E18: =SUM(E11:E17) -> 2903.2 | F18: =SUM(F11:F17) -> 249.99999 | G18: =SUM(G11:G17) -> 1748.6 | H18: =SUM(H11:H17) -> 249.99999 | I18: =SUM(I11:I17) -> 0 | J18: =SUM(J11:J17) -> 0 | ... X18: =SUM(X11:X17) -> 88474.999 | Y18: Ø Temp | Z18: =SUM(Z11:Z17)/7 -> 2.5714286 | AA18: °C
A19: =SUM(A17+1) -> 13 | B19: Mo | C19: 3211.4 | D19: 6428.5714 | E19: 13 | F19: 35.714285 | G19: 50 | H19: 35.714285 | K19: 0 | L19: 2142.8571 | M19: 899 | N19: 2330 | O19: =M19+N19 -> 3229 | P19: 1071.4285 | Q19: 3700.2 | R19: 2925 | S19: =C19+E19+G19+I19+K19+O19+Q19 -> 10203.6 | T19: =D19+F19+H19+J19+L19+P19+R19 -> 12639.286 | W19: =SUM(S19+U19) -> 10203.6 | X19: =SUM(T19+V19) -> 12639.286 | Y19: Hochnebel | Z19: 7 | AA19: °C
A20: =SUM(A19+1) -> 14 | B20: Di | C20: 15682 | D20: 6428.5714 | E20: 395.4 | F20: 35.714285 | G20: 201.3 | H20: 35.714285 | K20: 0 | L20: 2142.8571 | M20: 0 | N20: 2331 | O20: =M20+N20 -> 2331 | P20: 1071.4285 | Q20: 3014.2 | R20: 2925 | S20: =C20+E20+G20+I20+K20+O20+Q20 -> 21623.9 | T20: =D20+F20+H20+J20+L20+P20+R20 -> 12639.286 | W20: =SUM(S20+U20) -> 21623.9 | X20: =SUM(T20+V20) -> 12639.286 | Y20: sonnig | Z20: 7 | AA20: °C
A21: =SUM(A20+1) -> 15 | B21: Mi | C21: 5791.2 | D21: 6428.5714 | E21: 568.5 | F21: 35.714285 | G21: 360.1 | H21: 35.714285 | K21: 0 | L21: 2142.8571 | M21: 0 | N21: 0 | O21: =M21+N21 -> 0 | P21: 1071.4285 | Q21: 3009.3 | R21: 2925 | S21: =C21+E21+G21+I21+K21+O21+Q21 -> 9729.1 | T21: =D21+F21+H21+J21+L21+P21+R21 -> 12639.286 | W21: =SUM(S21+U21) -> 9729.1 | X21: =SUM(T21+V21) -> 12639.286 | Y21: sonnig | Z21: 9 | AA21: °C
A22: =SUM(A21+1) -> 16 | B22: Do | C22: 6554.5 | D22: 6428.5714 | E22: 1169.2 | F22: 35.714285 | G22: 301 | H22: 35.714285 | K22: 0 | L22: 2142.8571 | M22: 0 | N22: 0 | O22: =M22+N22 -> 0 | P22: 1071.4285 | Q22: 2841.7 | R22: 2925 | S22: =C22+E22+G22+I22+K22+O22+Q22 -> 10866.4 | T22: =D22+F22+H22+J22+L22+P22+R22 -> 12639.286 | W22: =SUM(S22+U22) -> 10866.4 | X22: =SUM(T22+V22) -> 12639.286 | Y22: sonnig | Z22: 10 | AA22: °C | AB22: Schmudo
A23: =SUM(A22+1) -> 17 | B23: Fr | C23: 10783.3 | D23: 6428.5714 | E23: 0 | F23: 35.714285 | G23: 11.8 | H23: 35.714285 | K23: 0 | L23: 2142.8571 | M23: 36 | N23: 1323 | O23: =M23+N23 -> 1359 | P23: 1071.4285 | Q23: 1341.8 | R23: 2925 | S23: =C23+E23+G23+I23+K23+O23+Q23 -> 13495.9 | T23: =D23+F23+H23+J23+L23+P23+R23 -> 12639.286 | W23: =SUM(S23+U23) -> 13495.9 | X23: =SUM(T23+V23) -> 12639.286 | Y23: bewölkt | Z23: 13 | AA23: °C
A24: =SUM(A23+1) -> 18 | B24: Sa | C24: 8761.5 | D24: 6428.5714 | E24: 1114.3 | F24: 35.714285 | G24: 687.2 | H24: 35.714285 | K24: 3141.7 | L24: 2142.8571 | M24: 0 | N24: 0 | O24: =M24+N24 -> 0 | P24: 1071.4285 | Q24: 5626.4 | R24: 2925 | S24: =C24+E24+G24+I24+K24+O24+Q24 -> 19331.1 | T24: =D24+F24+H24+J24+L24+P24+R24 -> 12639.286 | W24: =SUM(S24+U24) -> 19331.1 | X24: =SUM(T24+V24) -> 12639.286 | Y24: sonnig | Z24: 15 | AA24: °C
A25: =SUM(A24+1) -> 19 | B25: So | C25: 8841.5 | D25: 6428.5714 | E25: 427 | F25: 35.714285 | G25: 335.5 | H25: 35.714285 | K25: 6536.6 | L25: 2142.8571 | M25: 0 | N25: 0 | O25: =M25+N25 -> 0 | P25: 1071.4285 | Q25: 1394.2 | R25: 2925 | S25: =C25+E25+G25+I25+K25+O25+Q25 -> 17534.8 | T25: =D25+F25+H25+J25+L25+P25+R25 -> 12639.286 | W25: =SUM(S25+U25) -> 17534.8 | X25: =SUM(T25+V25) -> 12639.286 | Y25: sonnig | Z25: 13 | AA25: °C
A26: KW | B26: =SUM(B18+1) -> 7 | C26: =SUM(C19:C25) -> 59625.4 | D26: =SUM(D19:D25) -> 45000 | E26: =SUM(E19:E25) -> 3687.4 | F26: =SUM(F19:F25) -> 249.99999 | G26: =SUM(G19:G25) -> 1946.9 | H26: =SUM(H19:H25) -> 249.99999 | I26: =SUM(I19:I25) -> 0 | J26: =SUM(J19:J25) -> 0 | ... X26: =SUM(X19:X25) -> 88474.999 | Y26: Ø Temp | Z26: =SUM(Z19:Z25)/7 -> 10.571429 | AA26: °C
A27: =SUM(A25+1) -> 20 | B27: Mo | C27: 4309.8 | D27: 6428.5714 | E27: 1644.2 | F27: 35.714285 | G27: 370.9 | H27: 35.714285 | K27: 0 | L27: 2142.8571 | M27: 234.8 | N27: 742 | O27: =M27+N27 -> 976.8 | P27: 1071.4285 | Q27: 612.7 | R27: 2925 | S27: =C27+E27+G27+I27+K27+O27+Q27 -> 7914.4 | T27: =D27+F27+H27+J27+L27+P27+R27 -> 12639.286 | W27: =SUM(S27+U27) -> 7914.4 | X27: =SUM(T27+V27) -> 12639.286 | Y27: sonnig | Z27: 12 | AA27: °C | AB27: Güdismontag
A28: =SUM(A27+1) -> 21 | B28: Di | C28: 6787.15 | D28: 6428.5714 | E28: 3364.2 | F28: 35.714285 | G28: 402.2 | H28: 35.714285 | K28: 0 | L28: 2142.8571 | M28: 0 | N28: 0 | O28: =M28+N28 -> 0 | P28: 1071.4285 | Q28: 1015.8 | R28: 2925 | S28: =C28+E28+G28+I28+K28+O28+Q28 -> 11569.35 | T28: =D28+F28+H28+J28+L28+P28+R28 -> 12639.286 | W28: =SUM(S28+U28) -> 11569.35 | X28: =SUM(T28+V28) -> 12639.286 | Y28: sonnig | Z28: 14 | AA28: °C | AB28: Güdisdienstag
A29: =SUM(A28+1) -> 22 | B29: Mi | C29: 9379.9 | D29: 6428.5714 | E29: 308.8 | F29: 35.714285 | G29: 120.9 | H29: 35.714285 | K29: 0 | L29: 2142.8571 | M29: 0 | N29: 0 | O29: =M29+N29 -> 0 | P29: 1071.4285 | Q29: 1210.2 | R29: 2925 | S29: =C29+E29+G29+I29+K29+O29+Q29 -> 11019.8 | T29: =D29+F29+H29+J29+L29+P29+R29 -> 12639.286 | W29: =SUM(S29+U29) -> 11019.8 | X29: =SUM(T29+V29) -> 12639.286 | Y29: bewölkt | Z29: 13 | AA29: °C | AB29: Aschermittwoch
A30: =SUM(A29+1) -> 23 | B30: Do | C30: 7121.9 | D30: 6428.5714 | E30: 809.6 | F30: 35.714285 | G30: 114.3 | H30: 35.714285 | K30: 0 | L30: 2142.8571 | M30: 0 | N30: 0 | O30: =M30+N30 -> 0 | P30: 1071.4285 | Q30: 1401.6 | R30: 2925 | S30: =C30+E30+G30+I30+K30+O30+Q30 -> 9447.4 | T30: =D30+F30+H30+J30+L30+P30+R30 -> 12639.286 | W30: =SUM(S30+U30) -> 9447.4 | X30: =SUM(T30+V30) -> 12639.286 | Y30: sonne/wolke | Z30: 12 | AA30: °C
A31: =SUM(A30+1) -> 24 | B31: Fr | C31: 7362.9 | D31: 6428.5714 | E31: 919.6 | F31: 35.714285 | G31: 436.7 | H31: 35.714285 | K31: 0 | L31: 2142.8571 | M31: 679.3 | N31: 957 | O31: =M31+N31 -> 1636.3 | P31: 1071.4285 | Q31: 2942.4 | R31: 2925 | S31: =C31+E31+G31+I31+K31+O31+Q31 -> 13297.9 | T31: =D31+F31+H31+J31+L31+P31+R31 -> 12639.286 | W31: =SUM(S31+U31) -> 13297.9 | X31: =SUM(T31+V31) -> 12639.286 | Y31: sonne/wolke | Z31: 13 | AA31: °C
A32: =SUM(A31+1) -> 25 | B32: Sa | C32: 12490.6 | D32: 6428.5714 | E32: 0 | F32: 35.714285 | G32: 0 | H32: 35.714285 | K32: 0 | L32: 2142.8571 | M32: 11.8 | N32: 972 | O32: =M32+N32 -> 983.8 | P32: 1071.4285 | Q32: 4399.7 | R32: 2925 | S32: =C32+E32+G32+I32+K32+O32+Q32 -> 17874.1 | T32: =D32+F32+H32+J32+L32+P32+R32 -> 12639.286 | W32: =SUM(S32+U32) -> 17874.1 | X32: =SUM(T32+V32) -> 12639.286 | Y32: bewölkt | Z32: 5 | AA32: °C
A33: =SUM(A32+1) -> 26 | B33: So | C33: 13094.6 | D33: 6428.5714 | E33: 0 | F33: 35.714285 | G33: 23 | H33: 35.714285 | K33: 5116.6 | L33: 2142.8571 | M33: 0 | N33: 0 | O33: =M33+N33 -> 0 | P33: 1071.4285 | Q33: 2100.8 | R33: 2925 | S33: =C33+E33+G33+I33+K33+O33+Q33 -> 20335 | T33: =D33+F33+H33+J33+L33+P33+R33 -> 12639.286 | W33: =SUM(S33+U33) -> 20335 | X33: =SUM(T33+V33) -> 12639.286 | Y33: stürmisch | Z33: -2 | AA33: °C | AB33: Ende Fasnachtferien
A34: KW | B34: =SUM(B26+1) -> 8 | C34: =SUM(C27:C33) -> 60546.85 | D34: =SUM(D27:D33) -> 45000 | E34: =SUM(E27:E33) -> 7046.4 | F34: =SUM(F27:F33) -> 249.99999 | G34: =SUM(G27:G33) -> 1468 | H34: =SUM(H27:H33) -> 249.99999 | I34: =SUM(I27:I33) -> 0 | J34: =SUM(J27:J33) -> 0 | ... X34: =SUM(X27:X33) -> 88474.999 | Y34: Ø Temp | Z34: =SUM(Z27:Z33)/7 -> 9.5714286 | AA34: °C
A35: 27 | B35: Mo | C35: 7102.1 | D35: 6428.5714 | E35: 0 | F35: 35.714285 | G35: 0 | H35: 35.714285 | K35: 0 | L35: 2142.8571 | M35: 0 | N35: 0 | O35: =M35+N35 -> 0 | P35: 1071.4285 | Q35: 1358.8 | R35: 2925 | S35: =C35+E35+G35+I35+K35+O35+Q35 -> 8460.9 | T35: =D35+F35+H35+J35+L35+P35+R35 -> 12639.286 | W35: =SUM(S35+U35) -> 8460.9 | X35: =SUM(T35+V35) -> 12639.286 | Y35: bewölkt | Z35: 1 | AA35: °C
A36: 28 | B36: Di | C36: 5914.4 | D36: 6428.5714 | E36: 0 | F36: 35.714285 | G36: 0 | H36: 35.714285 | K36: 3346.2 | L36: 2142.8571 | M36: 536.7 | N36: 2337 | O36: =M36+N36 -> 2873.7 | P36: 1071.4285 | Q36: 1708.8 | R36: 2925 | S36: =C36+E36+G36+I36+K36+O36+Q36 -> 13843.1 | T36: =D36+F36+H36+J36+L36+P36+R36 -> 12639.286 | W36: =SUM(S36+U36) -> 13843.1 | X36: =SUM(T36+V36) -> 12639.286 | Y36: bewölkt | Z36: 3 | AA36: °C
A37: KW | B37: =SUM(B34+1) -> 9 | C37: =SUM(C35:C36) -> 13016.5 | D37: =SUM(D35:D36) -> 12857.143 | E37: =SUM(E35:E36) -> 0 | F37: =SUM(F35:F36) -> 71.42857 | G37: =SUM(G35:G36) -> 0 | H37: =SUM(H35:H36) -> 71.42857 | I37: =SUM(I35:I36) -> 0 | J37: =SUM(J35:J36) -> 0 | ... X37: =SUM(X35:X36) -> 25278.571 | Y37: Ø Temp | Z37: =SUM(Z27:Z33)/7 -> 9.5714286 | AA37: °C
A38: Umsatz kumuliert | C38: =SUM(C10+C18+C26+C34+C37) -> 220689.95 | D38: =SUM(D10+D18+D26+D34+D37) -> 180000 | E38: =SUM(E10+E18+E26+E34+E37) -> 13637 | F38: =SUM(F10+F18+F26+F34+F37) -> 999.99998 | G38: =SUM(G10+G18+G26+G34+G37) -> 5179.6 | H38: =SUM(H10+H18+H26+H34+H37) -> 999.99998 | I38: =SUM(I10+I18+I26+I34+I37) -> 0 | J38: =SUM(J10+J18+J26+J34+J37) -> 0 | ... X38: =SUM(X10+X18+X26+X34+X37) -> 353900 | Y38: Umsatz kumuliert
A39: Umsatz pro Tag | C39: =C38/28 -> 7881.7839 | D39: =D38/28 -> 6428.5714 | E39: =E38/28 -> 487.03571 | F39: =F38/28 -> 35.714285 | G39: =G38/28 -> 184.98571 | H39: =H38/28 -> 35.714285 | I39: =I38/28 -> 0 | J39: =J38/28 -> 0 | ... L39: =L38/28 -> 2142.8571 | M39: =M38/30 -> 204.06 | P39: =P38/30 -> 999.99993 | Q39: =Q38/28 -> 2671.4464 | R39: =R38/28 -> 2925 | S39: =S38/28 -> 13732.766 | T39: =T38/28 -> 12639.286 | U39: =U38/28 -> 0 | V39: =V38/28 -> 0 | W39: =W38/28 -> 13732.766 | X39: =X38/28 -> 12639.286 | Y39: Budget pro Tag
A40: Diff. zu Budget | C40: =SUM(C38-D38) -> 40689.95 | E40: =SUM(E38-F38) -> 12637 | G40: =SUM(G38-H38) -> 4179.6 | I40: =SUM(I38-J38) -> 0 | K40: =SUM(K38-L38) -> -21515.4 | P40: =SUM(O38-P38) -> 1725.802 | Q40: =SUM(Q38-R38) -> -7099.5 | S40: =SUM(S38-T38) -> 30617.452 | U40: =SUM(U38-V38) -> 0 | W40: =SUM(W38-X38) -> 30617.452
A41: Index | C41: =SUM(100/D38*C38) -> 122.60553 | E41: =SUM(100/F38*E38) -> 1363.7 | G41: =SUM(100/H38*G38) -> 517.96001 | I41: =SUM(100/J38*I38) -> #DIV/0! | K41: =SUM(100/L38*K38) -> 64.141 | O41: =SUM(100/P38*O38) -> 105.75267 | Q41: =SUM(100/R38*Q38) -> 91.331502 | S41: =SUM(100/T38*S38) -> 108.65144 | U41: =SUM(100/V38*U38) -> #DIV/0! | W41: =SUM(100/X38*W38) -> 108.65144

Sheet 03_23
A1: Tagesumsätze | H1: 44986
C3: Restaurant | E3: Terrasse | G3: Lounge | I3: Pavillon | K3: Bankett | M3: Seminar | Q3: Hotel | S3: TOTAL Gesamtbetrieb ohne Seebad | U3: Seebad | W3: TOTAL Gesamtbetrieb mit Seebad | Y3: Info's
C4: IST | D4: Budget | E4: IST | F4: Budget | G4: IST | H4: Budget | I4: IST | J4: Budget | K4: IST | L4: Budget | M4: IST/GN | N4: IST/ET | O4: TOTAL IST | P4: Budget | Q4: IST | R4: Budget | S4: IST | T4: Budget | U4: IST | V4: Budget | W4: IST | X4: Budget | Y4: Wetter | Z4: Temp. | AB4: Bemerkung
A5: 1 | B5: Mi | C5: 5871.1 | D5: 8064.5161 | E5: 0 | F5: 1290.3226 | G5: 0 | H5: 161.29032 | I5: 0 | K5: 0 | L5: 2580.6452 | M5: 12 | N5: 3741 | O5: =M5+N5 -> 3753 | P5: 1935.4839 | Q5: 1892.7 | R5: 2996.7742 | S5: =SUM(C5+E5+G5+I5+K5+O5+Q5) -> 11516.8 | T5: =SUM(D5+F5+H5+J5+L5+P5+R5) -> 17029.032 | W5: =SUM(S5+U5) -> 11516.8 | X5: =SUM(T5+V5) -> 17029.032 | Y5: hochnebel | Z5: 3 | AA5: °C
A6: =SUM(A5+1) -> 2 | B6: Do | C6: 7766.9 | D6: 8064.5161 | E6: 128.5 | F6: 1290.3226 | G6: 85 | H6: 161.29032 | I6: 0 | K6: 674.8 | L6: 2580.6452 | M6: 1415.4 | N6: 888 | O6: =M6+N6 -> 2303.4 | P6: 1935.4839 | Q6: 1197.5 | R6: 2996.7742 | S6: =SUM(C6+E6+G6+I6+K6+O6+Q6) -> 12156.1 | T6: =SUM(D6+F6+H6+J6+L6+P6+R6) -> 17029.032 | W6: =SUM(S6+U6) -> 12156.1 | X6: =SUM(T6+V6) -> 17029.032 | Y6: hochnebel | Z6: 6 | AA6: °C
A7: =SUM(A6+1) -> 3 | B7: Fr | C7: 5311.5 | D7: 8064.5161 | E7: 0 | F7: 1290.3226 | G7: 30.2 | H7: 161.29032 | I7: 0 | K7: 3591.1 | L7: 2580.6452 | M7: 297 | N7: 0 | O7: =M7+N7 -> 297 | P7: 1935.4839 | Q7: 609.7 | R7: 2996.7742 | S7: =SUM(C7+E7+G7+I7+K7+O7+Q7) -> 9839.5 | T7: =SUM(D7+F7+H7+J7+L7+P7+R7) -> 17029.032 | W7: =SUM(S7+U7) -> 9839.5 | X7: =SUM(T7+V7) -> 17029.032 | Y7: hochnebel | Z7: 7 | AA7: °C
A8: =SUM(A7+1) -> 4 | B8: Sa | C8: 11972.7 | D8: 8064.5161 | E8: 645.2 | F8: 1290.3226 | G8: 383.9 | H8: 161.29032 | I8: 0 | K8: 0 | L8: 2580.6452 | M8: 0 | N8: 0 | O8: =M8+N8 -> 0 | P8: 1935.4839 | Q8: 2276.8 | R8: 2996.7742 | S8: =SUM(C8+E8+G8+I8+K8+O8+Q8) -> 15278.6 | T8: =SUM(D8+F8+H8+J8+L8+P8+R8) -> 17029.032 | W8: =SUM(S8+U8) -> 15278.6 | X8: =SUM(T8+V8) -> 17029.032 | Y8: hochnebel/sonne | Z8: 8 | AA8: °C
A9: =SUM(A8+1) -> 5 | B9: So | C9: 11661.6 | D9: 8064.5161 | E9: 264.3 | F9: 1290.3226 | G9: 296.7 | H9: 161.29032 | I9: 0 | K9: 1319.4 | L9: 2580.6452 | M9: 0 | N9: 0 | O9: =M9+N9 -> 0 | P9: 1935.4839 | Q9: 939.7 | R9: 2996.7742 | S9: =SUM(C9+E9+G9+I9+K9+O9+Q9) -> 14481.7 | T9: =SUM(D9+F9+H9+J9+L9+P9+R9) -> 17029.032 | W9: =SUM(S9+U9) -> 14481.7 | X9: =SUM(T9+V9) -> 17029.032 | Y9: hochnebel/sonne | Z9: 8 | AA9: °C
A10: KW | B10: 9 | C10: =SUM(C5:C9) -> 42583.8 | D10: =SUM(D5:D9) -> 40322.58 | E10: =SUM(E5:E9) -> 1038 | F10: =SUM(F5:F9) -> 6451.6129 | G10: =SUM(G5:G9) -> 795.8 | H10: =SUM(H5:H9) -> 806.45161 | I10: =SUM(I5:I9) -> 0 | J10: =SUM(J5:J9) -> 0 | ... X10: =SUM(X5:X9) -> 85145.161 | Y10: Ø Temp | Z10: =SUM(Z5:Z9)/7 -> 4.5714286 | AA10: °C
A11: =SUM(A9+1) -> 6 | B11: Mo | C11: 2104.6 | D11: 8064.5161 | E11: 117.8 | F11: 1290.3226 | G11: 20 | H11: 161.29032 | I11: 0 | K11: 3000 | L11: 2580.6452 | M11: 6 | N11: 1342 | O11: =M11+N11 -> 1348 | P11: 1935.4839 | Q11: 3506.8 | R11: 2996.7742 | S11: =SUM(C11+E11+G11+I11+K11+O11+Q11) -> 10097.2 | T11: =SUM(D11+F11+H11+J11+L11+P11+R11) -> 17029.032 | W11: =SUM(S11+U11) -> 10097.2 | X11: =SUM(T11+V11) -> 17029.032 | Y11: hochnebel/sonne | Z11: 6 | AA11: °C
A12: =SUM(A11+1) -> 7 | B12: Di | C12: 3878.1 | D12: 8064.5161 | E12: 0 | F12: 1290.3226 | G12: 12.8 | H12: 161.29032 | I12: 0 | K12: 1410 | L12: 2580.6452 | M12: 1351.8 | N12: 1921 | O12: =M12+N12 -> 3272.8 | P12: 1935.4839 | Q12: 5846 | R12: 2996.7742 | S12: =SUM(C12+E12+G12+I12+K12+O12+Q12) -> 14419.7 | T12: =SUM(D12+F12+H12+J12+L12+P12+R12) -> 17029.032 | W12: =SUM(S12+U12) -> 14419.7 | X12: =SUM(T12+V12) -> 17029.032 | Y12: hochnebel/sonne | Z12: 8 | AA12: °C
A13: =SUM(A12+1) -> 8 | B13: Mi | C13: 7827.15 | D13: 8064.5161 | E13: 13 | F13: 1290.3226 | G13: 0 | H13: 161.29032 | I13: 0 | K13: 3215.5 | L13: 2580.6452 | M13: 283 | N13: 4772 | O13: =M13+N13 -> 5055 | P13: 1935.4839 | Q13: 3073.8 | R13: 2996.7742 | S13: =SUM(C13+E13+G13+I13+K13+O13+Q13) -> 19184.45 | T13: =SUM(D13+F13+H13+J13+L13+P13+R13) -> 17029.032 | W13: =SUM(S13+U13) -> 19184.45 | X13: =SUM(T13+V13) -> 17029.032 | Y13: hochnebel/sonne | Z13: 8 | AA13: °C
A14: =SUM(A13+1) -> 9 | B14: Do | C14: 5037.3 | D14: 8064.5161 | E14: 100.5 | F14: 1290.3226 | G14: 79.1 | H14: 161.29032 | I14: 0 | K14: 8769.7 | L14: 2580.6452 | M14: 180 | N14: 3477 | O14: =M14+N14 -> 3657 | P14: 1935.4839 | Q14: 4801.1 | R14: 2996.7742 | S14: =SUM(C14+E14+G14+I14+K14+O14+Q14) -> 22444.7 | T14: =SUM(D14+F14+H14+J14+L14+P14+R14) -> 17029.032 | W14: =SUM(S14+U14) -> 22444.7 | X14: =SUM(T14+V14) -> 17029.032 | Y14: teilweise sonnig | Z14: 14 | AA14: °C
A15: =SUM(A14+1) -> 10 | B15: Fr | C15: 8057.8 | D15: 8064.5161 | E15: 0 | F15: 1290.3226 | G15: 9 | H15: 161.29032 | I15: 0 | K15: 1434.5 | L15: 2580.6452 | M15: 881.2 | N15: 2048 | O15: =M15+N15 -> 2929.2 | P15: 1935.4839 | Q15: 1525.8 | R15: 2996.7742 | S15: =SUM(C15+E15+G15+I15+K15+O15+Q15) -> 13956.3 | T15: =SUM(D15+F15+H15+J15+L15+P15+R15) -> 17029.032 | W15: =SUM(S15+U15) -> 13956.3 | X15: =SUM(T15+V15) -> 17029.032 | Y15: Wind / bewölkt | Z15: 5 | AA15: °C
A16: =SUM(A15+1) -> 11 | B16: Sa | C16: 11455.6 | D16: 8064.5161 | E16: 0 | F16: 1290.3226 | G16: 0 | H16: 161.29032 | I16: 0 | K16: 12974.3 | L16: 2580.6452 | M16: 0 | N16: 400 | O16: =M16+N16 -> 400 | P16: 1935.4839 | Q16: 5392 | R16: 2996.7742 | S16: =SUM(C16+E16+G16+I16+K16+O16+Q16) -> 30221.9 | T16: =SUM(D16+F16+H16+J16+L16+P16+R16) -> 17029.032 | W16: =SUM(S16+U16) -> 30221.9 | X16: =SUM(T16+V16) -> 17029.032 | Y16: Wind / Schnee | Z16: 1 | AA16: °C
A17: =SUM(A16+1) -> 12 | B17: So | C17: 13329.1 | D17: 8064.5161 | E17: 17.7 | F17: 1290.3226 | G17: 31.8 | H17: 161.29032 | I17: 0 | K17: 6020.3 | L17: 2580.6452 | M17: -881.2 | N17: 0 | O17: =M17+N17 -> -881.2 | P17: 1935.4839 | Q17: 2121.6 | R17: 2996.7742 | S17: =SUM(C17+E17+G17+I17+K17+O17+Q17) -> 20639.3 | T17: =SUM(D17+F17+H17+J17+L17+P17+R17) -> 17029.032 | W17: =SUM(S17+U17) -> 20639.3 | X17: =SUM(T17+V17) -> 17029.032 | Y17: wechselhaft | Z17: 11 | AA17: °C
A18: KW | B18: =SUM(B10+1) -> 10 | C18: =SUM(C11:C17) -> 51689.65 | D18: =SUM(D11:D17) -> 56451.613 | E18: =SUM(E11:E17) -> 249 | F18: =SUM(F11:F17) -> 9032.2581 | G18: =SUM(G11:G17) -> 152.7 | H18: =SUM(H11:H17) -> 1129.0323 | I18: =SUM(I11:I17) -> 0 | J18: =SUM(J11:J17) -> 0 | ... X18: =SUM(X11:X17) -> 119203.23 | Y18: Ø Temp | Z18: =SUM(Z11:Z17)/7 -> 7.5714286 | AA18: °C
A19: =SUM(A17+1) -> 13 | B19: Mo | C19: 5071.4 | D19: 8064.5161 | E19: 743.6 | F19: 1290.3226 | G19: 428.9 | H19: 161.29032 | I19: 0 | K19: 0 | L19: 2580.6452 | M19: 0 | N19: 1450 | O19: =M19+N19 -> 1450 | P19: 1935.4839 | Q19: 660.4 | R19: 2996.7742 | S19: =SUM(C19+E19+G19+I19+K19+O19+Q19) -> 8354.3 | T19: =SUM(D19+F19+H19+J19+L19+P19+R19) -> 17029.032 | W19: =SUM(S19+U19) -> 8354.3 | X19: =SUM(T19+V19) -> 17029.032 | Y19: sonnig | Z19: 22 | AA19: °C
A20: =SUM(A19+1) -> 14 | B20: Di | C20: 5115.6 | D20: 8064.5161 | E20: 0 | F20: 1290.3226 | G20: 0 | H20: 161.29032 | I20: 0 | K20: 0 | L20: 2580.6452 | M20: 357.6 | N20: 3289 | O20: =M20+N20 -> 3646.6 | P20: 1935.4839 | Q20: 6616.6 | R20: 2996.7742 | S20: =SUM(C20+E20+G20+I20+K20+O20+Q20) -> 15378.8 | T20: =SUM(D20+F20+H20+J20+L20+P20+R20) -> 17029.032 | W20: =SUM(S20+U20) -> 15378.8 | X20: =SUM(T20+V20) -> 17029.032 | Y20: bewölkt | Z20: 9 | AA20: °C
A21: =SUM(A20+1) -> 15 | B21: Mi | C21: 4807.3 | D21: 8064.5161 | E21: 7 | F21: 1290.3226 | G21: 211 | H21: 161.29032 | I21: 0 | K21: 0 | L21: 2580.6452 | M21: 924.5 | N21: 6887 | O21: =M21+N21 -> 7811.5 | P21: 1935.4839 | Q21: 4944.7 | R21: 2996.7742 | S21: =SUM(C21+E21+G21+I21+K21+O21+Q21) -> 17781.5 | T21: =SUM(D21+F21+H21+J21+L21+P21+R21) -> 17029.032 | W21: =SUM(S21+U21) -> 17781.5 | X21: =SUM(T21+V21) -> 17029.032 | Y21: teilweise sonnig | Z21: 8 | AA21: °C
A22: =SUM(A21+1) -> 16 | B22: Do | C22: =5366.35+347.1 -> 5713.45 | D22: 8064.5161 | E22: 465.1 | F22: 1290.3226 | G22: 256.8 | H22: 161.29032 | I22: 0 | K22: 0 | L22: 2580.6452 | M22: 1470.1 | N22: 9536 | O22: =M22+N22 -> 11006.1 | P22: 1935.4839 | Q22: 7632 | R22: 2996.7742 | S22: =SUM(C22+E22+G22+I22+K22+O22+Q22) -> 25073.45 | T22: =SUM(D22+F22+H22+J22+L22+P22+R22) -> 17029.032 | W22: =SUM(S22+U22) -> 25073.45 | X22: =SUM(T22+V22) -> 17029.032 | Y22: sonnig/wolkenfelder | Z22: 12 | AA22: °C
A23: =SUM(A22+1) -> 17 | B23: Fr | C23: 10407 | D23: 8064.5161 | E23: 488.6 | F23: 1290.3226 | G23: 355.8 | H23: 161.29032 | I23: 0 | K23: 0 | L23: 2580.6452 | M23: 109 | N23: 4177 | O23: =M23+N23 -> 4286 | P23: 1935.4839 | Q23: 3595.6 | R23: 2996.7742 | S23: =SUM(C23+E23+G23+I23+K23+O23+Q23) -> 19133 | T23: =SUM(D23+F23+H23+J23+L23+P23+R23) -> 17029.032 | W23: =SUM(S23+U23) -> 19133 | X23: =SUM(T23+V23) -> 17029.032 | Y23: sonnig | Z23: 15 | AA23: °C
A24: =SUM(A23+1) -> 18 | B24: Sa | C24: 13775.2 | D24: 8064.5161 | E24: 5549.5 | F24: 1290.3226 | G24: 956.6 | H24: 161.29032 | I24: 0 | K24: 3652 | L24: 2580.6452 | M24: 0 | N24: 0 | O24: =M24+N24 -> 0 | P24: 1935.4839 | Q24: 4988.6 | R24: 2996.7742 | S24: =SUM(C24+E24+G24+I24+K24+O24+Q24) -> 28921.9 | T24: =SUM(D24+F24+H24+J24+L24+P24+R24) -> 17029.032 | W24: =SUM(S24+U24) -> 28921.9 | X24: =SUM(T24+V24) -> 17029.032 | Y24: sonnig/bedeckt | Z24: 16 | AA24: °C
A25: =SUM(A24+1) -> 19 | B25: So | C25: 12494.9 | D25: 8064.5161 | E25: 11.3 | F25: 1290.3226 | G25: 196 | H25: 161.29032 | I25: 0 | K25: 0 | L25: 2580.6452 | N25: 0 | O25: =M25+N25 -> 0 | P25: 1935.4839 | Q25: 1935.8 | R25: 2996.7742 | S25: =SUM(C25+E25+G25+I25+K25+O25+Q25) -> 14638 | T25: =SUM(D25+F25+H25+J25+L25+P25+R25) -> 17029.032 | W25: =SUM(S25+U25) -> 14638 | X25: =SUM(T25+V25) -> 17029.032 | Y25: Regenschauer | Z25: 12 | AA25: °C
A26: KW | B26: =SUM(B18+1) -> 11 | C26: =SUM(C19:C25) -> 57384.85 | D26: =SUM(D19:D25) -> 56451.613 | E26: =SUM(E19:E25) -> 7265.1 | F26: =SUM(F19:F25) -> 9032.2581 | G26: =SUM(G19:G25) -> 2405.1 | H26: =SUM(H19:H25) -> 1129.0323 | I26: =SUM(I19:I25) -> 0 | J26: =SUM(J19:J25) -> 0 | ... X26: =SUM(X19:X25) -> 119203.23 | Y26: Ø Temp | Z26: =SUM(Z19:Z25)/7 -> 13.428571 | AA26: °C
A27: =SUM(A25+1) -> 20 | B27: Mo | C27: 6177.2 | D27: 8064.5161 | E27: 365 | F27: 1290.3226 | G27: 172.6 | H27: 161.29032 | I27: 0 | K27: 61 | L27: 2580.6452 | M27: 0 | N27: 0 | O27: =M27+N27 -> 0 | P27: 1935.4839 | Q27: 4527.2 | R27: 2996.7742 | S27: =SUM(C27+E27+G27+I27+K27+O27+Q27) -> 11303 | T27: =SUM(D27+F27+H27+J27+L27+P27+R27) -> 17029.032 | W27: =SUM(S27+U27) -> 11303 | X27: =SUM(T27+V27) -> 17029.032 | Y27: zemlich sonnig | Z27: 12 | AA27: °C
A28: =SUM(A27+1) -> 21 | B28: Di | C28: 6835 | D28: 8064.5161 | E28: 430.7 | F28: 1290.3226 | G28: 205.5 | H28: 161.29032 | I28: 0 | K28: 0 | L28: 2580.6452 | M28: 1252.2 | N28: 2071 | O28: =M28+N28 -> 3323.2 | P28: 1935.4839 | Q28: 3743.7 | R28: 2996.7742 | S28: =SUM(C28+E28+G28+I28+K28+O28+Q28) -> 14538.1 | T28: =SUM(D28+F28+H28+J28+L28+P28+R28) -> 17029.032 | W28: =SUM(S28+U28) -> 14538.1 | X28: =SUM(T28+V28) -> 17029.032 | Y28: sonnig/wolkenfelder | Z28: 15 | AA28: °C
A29: =SUM(A28+1) -> 22 | B29: Mi | C29: 6288.5 | D29: 8064.5161 | E29: 3829.7 | F29: 1290.3226 | G29: 488.2 | H29: 161.29032 | I29: 0 | K29: 850 | L29: 2580.6452 | M29: 207.6 | N29: 827.5 | O29: =M29+N29 -> 1035.1 | P29: 1935.4839 | Q29: 4644.5 | R29: 2996.7742 | S29: =SUM(C29+E29+G29+I29+K29+O29+Q29) -> 17136 | T29: =SUM(D29+F29+H29+J29+L29+P29+R29) -> 17029.032 | W29: =SUM(S29+U29) -> 17136 | X29: =SUM(T29+V29) -> 17029.032 | Y29: sonnig | Z29: 18 | AA29: °C
A30: =SUM(A29+1) -> 23 | B30: Do | C30: 5932.8 | D30: 8064.5161 | E30: 37 | F30: 1290.3226 | G30: 154.1 | H30: 161.29032 | I30: 0 | K30: 0 | L30: 2580.6452 | M30: 509.5 | N30: 9968 | O30: =M30+N30 -> 10477.5 | P30: 1935.4839 | Q30: 3039.9 | R30: 2996.7742 | S30: =SUM(C30+E30+G30+I30+K30+O30+Q30) -> 19641.3 | T30: =SUM(D30+F30+H30+J30+L30+P30+R30) -> 17029.032 | W30: =SUM(S30+U30) -> 19641.3 | X30: =SUM(T30+V30) -> 17029.032 | Y30: etwas Regenschauer | Z30: 17 | AA30: °C
A31: =SUM(A30+1) -> 24 | B31: Fr | C31: 8752.9 | D31: 8064.5161 | E31: 10.4 | F31: 1290.3226 | G31: 20 | H31: 161.29032 | I31: 0 | K31: 0 | L31: 2580.6452 | M31: 789.1 | N31: 8904.8 | O31: =M31+N31 -> 9693.9 | P31: 1935.4839 | Q31: 6862.7 | R31: 2996.7742 | S31: =SUM(C31+E31+G31+I31+K31+O31+Q31) -> 25339.9 | T31: =SUM(D31+F31+H31+J31+L31+P31+R31) -> 17029.032 | W31: =SUM(S31+U31) -> 25339.9 | X31: =SUM(T31+V31) -> 17029.032 | Y31: Regenschauer | Z31: 10 | AA31: °C
A32: =SUM(A31+1) -> 25 | B32: Sa | C32: 13218.7 | D32: 8064.5161 | E32: 0 | F32: 1290.3226 | G32: 17.3 | H32: 161.29032 | I32: 0 | K32: 2202.7 | L32: 2580.6452 | M32: -72.5 | N32: 2858 | O32: =M32+N32 -> 2785.5 | P32: 1935.4839 | Q32: 3436.8 | R32: 2996.7742 | S32: =SUM(C32+E32+G32+I32+K32+O32+Q32) -> 21661 | T32: =SUM(D32+F32+H32+J32+L32+P32+R32) -> 17029.032 | W32: =SUM(S32+U32) -> 21661 | X32: =SUM(T32+V32) -> 17029.032 | Y32: bewölkt/ wenig Regen | Z32: 10 | AA32: °C
A33: =SUM(A32+1) -> 26 | B33: So | C33: 13502.1 | D33: 8064.5161 | E33: 0 | F33: 1290.3226 | G33: 35.3 | H33: 161.29032 | I33: 0 | K33: 2552 | L33: 2580.6452 | M33: 0 | N33: 0 | O33: =M33+N33 -> 0 | P33: 1935.4839 | Q33: 1534.2 | R33: 2996.7742 | S33: =SUM(C33+E33+G33+I33+K33+O33+Q33) -> 17623.6 | T33: =SUM(D33+F33+H33+J33+L33+P33+R33) -> 17029.032 | W33: =SUM(S33+U33) -> 17623.6 | X33: =SUM(T33+V33) -> 17029.032 | Y33: bedeckt/stark Regen | Z33: 8 | AA33: °C
A34: KW | B34: =SUM(B26+1) -> 12 | C34: =SUM(C27:C33) -> 60707.2 | D34: =SUM(D27:D33) -> 56451.613 | E34: =SUM(E27:E33) -> 4672.8 | F34: =SUM(F27:F33) -> 9032.2581 | G34: =SUM(G27:G33) -> 1093 | H34: =SUM(H27:H33) -> 1129.0323 | I34: =SUM(I27:I33) -> 0 | J34: =SUM(J27:J33) -> 0 | ... X34: =SUM(X27:X33) -> 119203.23 | Y34: Ø Temp | Z34: =SUM(Z27:Z33)/7 -> 12.857143 | AA34: °C
A35: =SUM(A33+1) -> 27 | B35: Mo | C35: 3672.6 | D35: 8064.5161 | E35: 0 | F35: 1290.3226 | G35: 10.4 | H35: 161.29032 | I35: 0 | K35: 0 | L35: 2580.6452 | M35: 744.7 | N35: 1316 | O35: =M35+N35 -> 2060.7 | P35: 1935.4839 | Q35: 1999.5 | R35: 2996.7742 | S35: =SUM(C35+E35+G35+I35+K35+O35+Q35) -> 7743.2 | T35: =SUM(D35+F35+H35+J35+L35+P35+R35) -> 17029.032 | W35: =SUM(S35+U35) -> 7743.2 | X35: =SUM(T35+V35) -> 17029.032 | Y35: bedeckt/leicht Regen | Z35: 5 | AA35: °C
A36: =SUM(A35+1) -> 28 | B36: Di | C36: 6079.9 | D36: 8064.5161 | E36: 63.5 | F36: 1290.3226 | G36: 14.1 | H36: 161.29032 | I36: 0 | K36: 2335 | L36: 2580.6452 | M36: 916.4 | N36: 9266 | O36: =M36+N36 -> 10182.4 | P36: 1935.4839 | Q36: 5950.9 | R36: 2996.7742 | S36: =SUM(C36+E36+G36+I36+K36+O36+Q36) -> 24625.8 | T36: =SUM(D36+F36+H36+J36+L36+P36+R36) -> 17029.032 | W36: =SUM(S36+U36) -> 24625.8 | X36: =SUM(T36+V36) -> 17029.032 | Y36: bewölkt | Z36: 9 | AA36: °C
A37: =SUM(A36+1) -> 29 | B37: Mi | C37: 5560.5 | D37: 8064.5161 | E37: 17.8 | F37: 1290.3226 | G37: 241.3 | H37: 161.29032 | I37: 0 | K37: 0 | L37: 2580.6452 | M37: 0 | N37: 5350 | O37: =M37+N37 -> 5350 | P37: 1935.4839 | Q37: 7696.9 | R37: 2996.7742 | S37: =SUM(C37+E37+G37+I37+K37+O37+Q37) -> 18866.5 | T37: =SUM(D37+F37+H37+J37+L37+P37+R37) -> 17029.032 | W37: =SUM(S37+U37) -> 18866.5 | X37: =SUM(T37+V37) -> 17029.032 | Y37: bedeckt | Z37: 17 | AA37: °C
A38: =SUM(A37+1) -> 30 | B38: Do | C38: 5075 | D38: 8064.5161 | E38: 27.2 | F38: 1290.3226 | G38: 18.5 | H38: 161.29032 | I38: 0 | K38: 0 | L38: 2580.6452 | M38: 73 | N38: 5197 | O38: =M38+N38 -> 5270 | P38: 1935.4839 | Q38: 2910.8 | R38: 2996.7742 | S38: =SUM(C38+E38+G38+I38+K38+O38+Q38) -> 13301.5 | T38: =SUM(D38+F38+H38+J38+L38+P38+R38) -> 17029.032 | W38: =SUM(S38+U38) -> 13301.5 | X38: =SUM(T38+V38) -> 17029.032 | Y38: bedekt / regen / wind | Z38: 13 | AA38: °C
A39: =SUM(A38+1) -> 31 | B39: Fr | C39: 8517.6 | D39: 8064.5161 | E39: 0 | F39: 1290.3226 | G39: 0 | H39: 161.29032 | I39: 0 | K39: 0 | L39: 2580.6452 | M39: 371.4 | N39: 2948 | O39: =M39+N39 -> 3319.4 | P39: 1935.4839 | Q39: 1794.7 | R39: 2996.7742 | S39: =SUM(C39+E39+G39+I39+K39+O39+Q39) -> 13631.7 | T39: =SUM(D39+F39+H39+J39+L39+P39+R39) -> 17029.032 | W39: =SUM(S39+U39) -> 13631.7 | X39: =SUM(T39+V39) -> 17029.032 | Y39: bewölkt/regen | Z39: 14 | AA39: °C
A40: KW | B40: =SUM(B34+1) -> 13 | C40: =SUM(C35:C39) -> 28905.6 | D40: =SUM(D35:D39) -> 40322.58 | E40: =SUM(E35:E39) -> 108.5 | F40: =SUM(F35:F39) -> 6451.6129 | G40: =SUM(G35:G39) -> 284.3 | H40: =SUM(H35:H39) -> 806.45161 | I40: =SUM(I35:I39) -> 0 | J40: =SUM(J35:J39) -> 0 | ... X40: =SUM(X35:X39) -> 85145.161 | Y40: Ø Temp | Z40: =SUM(Z35:Z39)/4 -> 14.5 | AA40: °C
A41: Umsatz kumuliert | C41: =SUM(C10+C18+C26+C34+C40) -> 241271.1 | D41: =SUM(D10+D18+D26+D34+D40) -> 250000 | E41: =SUM(E10+E18+E26+E34+E40) -> 13333.4 | F41: =SUM(F10+F18+F26+F34+F40) -> 40000 | G41: =SUM(G10+G18+G26+G34+G40) -> 4730.9 | H41: =SUM(H10+H18+H26+H34+H40) -> 5000 | I41: =SUM(I10+I18+I26+I40) -> 0 | J41: =SUM(J10+J18+J26+J40) -> 0 | K41: =SUM(K10+K18+K26+K34+K40) -> 54062.3 | L41: =SUM(L10+L18+L26+L34+L40) -> 80000 | M41: =SUM(M10+M18+M26+M34+M40) -> 11197.8 | N41: =SUM(N10+N18+N26+N34+N40) -> 92634.3 | O41: =SUM(O10+O18+O26+O34+O40) -> 103832.1 | P41: =P10+P18+P26+P34+P40 -> 60000 | Q41: =SUM(Q10+Q18+Q26+Q34+Q40) -> 111699 | R41: =SUM(R10+R18+R26+R34+R40) -> 92900 | S41: =SUM(S10+S18+S26+S34+S40) -> 528928.8 | T41: =SUM(T10+T18+T26+T34+T40) -> 527900 | U41: =SUM(U10+U18+U26+U34+U40) -> 0 | V41: =SUM(V10+V18+V26+V34+V40) -> 0 | W41: =SUM(W10+W18+W26+W34+W40) -> 528928.8 | X41: =SUM(X10+X18+X26+X34+X40) -> 527900 | Y41: Umsatz kumuliert
...

Sheet 04_23
A1: Tagesumsätze | H1: 45017
C3: Restaurant | E3: Terrasse | G3: Lounge | I3: Pavillon | K3: Bankett | M3: Seminar | Q3: Hotel | S3: TOTAL Gesamtbetrieb ohne Seebad | U3: Seebad | W3: TOTAL Gesamtbetrieb mit Seebad | Y3: Info's
C4: IST | D4: Budget | E4: IST | F4: Budget | G4: IST | H4: Budget | I4: IST | J4: Budget | K4: IST | L4: Budget | M4: IST/GN | N4: IST/ET | O4: TOTAL IST | P4: Budget | Q4: IST | R4: Budget | S4: IST | T4: Budget | U4: IST | V4: Budget | W4: IST | X4: Budget | Y4: Wetter | Z4: Temp. | AB4: Bemerkung
A5: 1 | B5: Sa | C5: 9737.2 | D5: 8333.3333 | E5: 0 | F5: 2666.6667 | G5: 22.9 | H5: 333.33333 | I5: 0 | K5: 12270.5 | L5: 3000 | M5: 0 | N5: 0 | O5: =M5+N5 -> 0 | P5: 2000 | Q5: 7355.6 | R5: 3096.6667 | S5: =C5+E5+G5+I5+K5+O5+Q5 -> 29386.2 | T5: =D5+F5+H5+J5+L5+P5+R5 -> 19430 | V5: 66.66666 | W5: =SUM(S5+U5) -> 29386.2 | X5: =SUM(T5+V5) -> 19496.667 | Y5: teils Regenschauer | Z5: 10 | AA5: °C
A6: =SUM(A5+1) -> 2 | B6: So | C6: 11726.5 | D6: 8333.3333 | E6: 478.5 | F6: 2666.6667 | G6: 519.5 | H6: 333.33333 | I6: 0 | K6: 8983.6 | L6: 3000 | M6: 227.3 | N6: 0 | O6: =M6+N6 -> 227.3 | P6: 2000 | Q6: 2523.42 | R6: 3096.6667 | S6: =C6+E6+G6+I6+K6+O6+Q6 -> 24458.82 | T6: =D6+F6+H6+J6+L6+P6+R6 -> 19430 | V6: 66.66666 | W6: =SUM(S6+U6) -> 24458.82 | X6: =SUM(T6+V6) -> 19496.667 | Y6: teils Regenschauer | Z6: 11 | AA6: °C
A7: KW | B7: 14 | C7: =SUM(C5:C6) -> 21463.7 | D7: =SUM(D5:D6) -> 16666.667 | E7: =SUM(E5:E6) -> 478.5 | F7: =SUM(F5:F6) -> 5333.3333 | G7: =SUM(G5:G6) -> 542.4 | H7: =SUM(H5:H6) -> 666.66666 | I7: =SUM(I5:I6) -> 0 | J7: =SUM(J5:J6) -> 0 | ... X7: =SUM(X5:X6) -> 38993.333 | Y7: Ø Temp | Z7: =SUM(Z5:Z6)/4 -> 5.25 | AA7: °C
A8: =SUM(A6+1) -> 3 | B8: Mo | C8: =5682.1+13.6 -> 5695.7 | D8: 8333.3333 | E8: 0 | F8: 2666.6667 | G8: 0 | H8: 333.33333 | I8: 0 | K8: 0 | L8: 3000 | M8: 568.5 | N8: 5329.8 | O8: =M8+N8 -> 5898.3 | P8: 2000 | Q8: 4366.2 | R8: 3096.6667 | S8: =C8+E8+G8+I8+K8+O8+Q8 -> 15960.2 | T8: =D8+F8+H8+J8+L8+P8+R8 -> 19430 | V8: 66.66666 | W8: =SUM(S8+U8) -> 15960.2 | X8: =SUM(T8+V8) -> 19496.667 | Y8: Hochnebel | Z8: 7 | AA8: °C
A9: =SUM(A8+1) -> 4 | B9: Di | C9: =6387-13.6 -> 6373.4 | D9: 8333.3333 | E9: 53.8 | F9: 2666.6667 | G9: 173.7 | H9: 333.33333 | I9: 0 | K9: 0 | L9: 3000 | M9: 141.7 | N9: 4190 | O9: =M9+N9 -> 4331.7 | P9: 2000 | Q9: 3300.2 | R9: 3096.6667 | S9: =C9+E9+G9+I9+K9+O9+Q9 -> 14232.8 | T9: =D9+F9+H9+J9+L9+P9+R9 -> 19430 | V9: 66.66666 | W9: =SUM(S9+U9) -> 14232.8 | X9: =SUM(T9+V9) -> 19496.667 | Y9: sonnig | Z9: 7 | AA9: °C
A10: =SUM(A9+1) -> 5 | B10: Mi | C10: 5715.8 | D10: 8333.3333 | E10: 302 | F10: 2666.6667 | G10: 396 | H10: 333.33333 | I10: 0 | K10: 0 | L10: 3000 | M10: 36.1 | N10: 3150 | O10: =M10+N10 -> 3186.1 | P10: 2000 | Q10: 1553 | R10: 3096.6667 | S10: =C10+E10+G10+I10+K10+O10+Q10 -> 11152.9 | T10: =D10+F10+H10+J10+L10+P10+R10 -> 19430 | V10: 66.66666 | W10: =SUM(S10+U10) -> 11152.9 | X10: =SUM(T10+V10) -> 19496.667 | Y10: sonnig | Z10: 8 | AA10: °C
A11: =SUM(A10+1) -> 6 | B11: Do | C11: 6371 | D11: 8333.3333 | E11: 0 | F11: 2666.6667 | G11: 185.9 | H11: 333.33333 | I11: 0 | K11: 0 | L11: 3000 | M11: 40.4 | N11: 100 | O11: =M11+N11 -> 140.4 | P11: 2000 | Q11: 3929.7 | R11: 3096.6667 | S11: =C11+E11+G11+I11+K11+O11+Q11 -> 10627 | T11: =D11+F11+H11+J11+L11+P11+R11 -> 19430 | V11: 66.66666 | W11: =SUM(S11+U11) -> 10627 | X11: =SUM(T11+V11) -> 19496.667 | Y11: Regenschauer/trocken | Z11: 11 | AA11: °C
A12: =SUM(A11+1) -> 7 | B12: Fr | C12: 16490.4 | D12: 8333.3333 | E12: 0 | F12: 2666.6667 | G12: 0 | H12: 333.33333 | I12: 0 | K12: 0 | L12: 3000 | M12: 0 | N12: 0 | O12: =M12+N12 -> 0 | P12: 2000 | Q12: 10362.2 | R12: 3096.6667 | S12: =C12+E12+G12+I12+K12+O12+Q12 -> 26852.6 | T12: =D12+F12+H12+J12+L12+P12+R12 -> 19430 | V12: 66.66666 | W12: =SUM(S12+U12) -> 26852.6 | X12: =SUM(T12+V12) -> 19496.667 | Y12: starke Regenschauer/Schneeregen | Z12: 5 | AA12: °C | AB12: Karfreitag
A13: =SUM(A12+1) -> 8 | B13: Sa | C13: 17023.3 | D13: 8333.3333 | E13: 77.4 | F13: 2666.6667 | G13: 112.8 | H13: 333.33333 | I13: 0 | K13: 1600 | L13: 3000 | M13: 0 | N13: 0 | O13: =M13+N13 -> 0 | P13: 2000 | Q13: 8919.2 | R13: 3096.6667 | S13: =C13+E13+G13+I13+K13+O13+Q13 -> 27732.7 | T13: =D13+F13+H13+J13+L13+P13+R13 -> 19430 | V13: 66.66666 | W13: =SUM(S13+U13) -> 27732.7 | X13: =SUM(T13+V13) -> 19496.667 | Y13: bewölkt / teils Regen | Z13: 8 | AA13: °C
A14: =SUM(A13+1) -> 9 | B14: So | C14: 20628.2 | D14: 8333.3333 | E14: 2062.3 | F14: 2666.6667 | G14: 1045.1 | H14: 333.33333 | I14: 0 | K14: 4669.1 | L14: 3000 | M14: 0 | N14: 0 | O14: =M14+N14 -> 0 | P14: 2000 | Q14: 8066.3 | R14: 3096.6667 | S14: =C14+E14+G14+I14+K14+O14+Q14 -> 36471 | T14: =D14+F14+H14+J14+L14+P14+R14 -> 19430 | V14: 66.66666 | W14: =SUM(S14+U14) -> 36471 | X14: =SUM(T14+V14) -> 19496.667 | Y14: ziemlich sonnig | Z14: 13 | AA14: °C | AB14: Ostersonntag
A15: KW | B15: =SUM(B7+1) -> 15 | C15: =SUM(C8:C14) -> 78297.8 | D15: =SUM(D8:D14) -> 58333.333 | E15: =SUM(E8:E14) -> 2495.5 | F15: =SUM(F8:F14) -> 18666.667 | G15: =SUM(G8:G14) -> 1913.5 | H15: =SUM(H8:H14) -> 2333.3333 | I15: =SUM(I8:I14) -> 0 | J15: =SUM(J8:J14) -> 0 | ... X15: =SUM(X8:X14) -> 136476.67 | Y15: Ø Temp | Z15: =SUM(Z8:Z14)/7 -> 8.4285714 | AA15: °C
A16: =SUM(A14+1) -> 10 | B16: Mo | C16: 13572 | D16: 8333.3333 | E16: 4225.8 | F16: 2666.6667 | G16: 719.3 | H16: 333.33333 | I16: 0 | K16: 5024 | L16: 3000 | M16: 0 | N16: 0 | O16: =M16+N16 -> 0 | P16: 2000 | Q16: 3569.1 | R16: 3096.6667 | S16: =C16+E16+G16+I16+K16+O16+Q16 -> 27110.2 | T16: =D16+F16+H16+J16+L16+P16+R16 -> 19430 | V16: 66.66666 | W16: =SUM(S16+U16) -> 27110.2 | X16: =SUM(T16+V16) -> 19496.667 | Y16: sonnig / bedeckt | Z16: 17 | AA16: °C | AB16: Ostermontag
A17: =SUM(A16+1) -> 11 | B17: Di | C17: 6530.6 | D17: 8333.3333 | E17: 0 | F17: 2666.6667 | G17: 0 | H17: 333.33333 | I17: 0 | K17: 0 | L17: 3000 | M17: 0 | N17: 0 | O17: =M17+N17 -> 0 | P17: 2000 | Q17: 3911.5 | R17: 3096.6667 | S17: =C17+E17+G17+I17+K17+O17+Q17 -> 10442.1 | T17: =D17+F17+H17+J17+L17+P17+R17 -> 19430 | V17: 66.66666 | W17: =SUM(S17+U17) -> 10442.1 | X17: =SUM(T17+V17) -> 19496.667 | Y17: regnerisch | Z17: 15 | AA17: °C
A18: =SUM(A17+1) -> 12 | B18: Mi | C18: 5186.9 | D18: 8333.3333 | E18: 10.2 | F18: 2666.6667 | G18: 0 | H18: 333.33333 | I18: 0 | K18: 1625.9 | L18: 3000 | M18: 0 | N18: 0 | O18: =M18+N18 -> 0 | P18: 2000 | Q18: 2828.04 | R18: 3096.6667 | S18: =C18+E18+G18+I18+K18+O18+Q18 -> 9651.04 | T18: =D18+F18+H18+J18+L18+P18+R18 -> 19430 | V18: 66.66666 | W18: =SUM(S18+U18) -> 9651.04 | X18: =SUM(T18+V18) -> 19496.667 | Y18: bedeckt, etwas Regen | Z18: 13 | AA18: °C
A19: =SUM(A18+1) -> 13 | B19: Do | C19: 8008.9 | D19: 8333.3333 | E19: 0 | F19: 2666.6667 | G19: 0 | H19: 333.33333 | I19: 0 | K19: 0 | L19: 3000 | M19: 0 | N19: 0 | O19: =M19+N19 -> 0 | P19: 2000 | Q19: 3645 | R19: 3096.6667 | S19: =C19+E19+G19+I19+K19+O19+Q19 -> 11653.9 | T19: =D19+F19+H19+J19+L19+P19+R19 -> 19430 | V19: 66.66666 | W19: =SUM(S19+U19) -> 11653.9 | X19: =SUM(T19+V19) -> 19496.667 | Y19: bedeckt, Regen | Z19: 5 | AA19: °C
A20: =SUM(A19+1) -> 14 | B20: Fr | C20: 8369.8 | D20: 8333.3333 | E20: 358 | F20: 2666.6667 | G20: 394.5 | H20: 333.33333 | I20: 0 | K20: 0 | L20: 3000 | M20: 830 | N20: 1335 | O20: =M20+N20 -> 2165 | P20: 2000 | Q20: 4963.2 | R20: 3096.6667 | S20: =C20+E20+G20+I20+K20+O20+Q20 -> 16250.5 | T20: =D20+F20+H20+J20+L20+P20+R20 -> 19430 | V20: 66.66666 | W20: =SUM(S20+U20) -> 16250.5 | X20: =SUM(T20+V20) -> 19496.667 | Y20: teilweise sonnig | Z20: 11 | AA20: °C
A21: =SUM(A20+1) -> 15 | B21: Sa | C21: 12740.7 | D21: 8333.3333 | E21: 0 | F21: 2666.6667 | G21: 75.3 | H21: 333.33333 | I21: 0 | K21: 6416.2 | L21: 3000 | M21: 0 | N21: 0 | O21: =M21+N21 -> 0 | P21: 2000 | Q21: 5849.8 | R21: 3096.6667 | S21: =C21+E21+G21+I21+K21+O21+Q21 -> 25082 | T21: =D21+F21+H21+J21+L21+P21+R21 -> 19430 | V21: 66.66666 | W21: =SUM(S21+U21) -> 25082 | X21: =SUM(T21+V21) -> 19496.667 | Y21: teils starker Regen | Z21: 8 | AA21: °C
A22: =SUM(A21+1) -> 16 | B22: So | C22: 12742.8 | D22: 8333.3333 | E22: 0 | F22: 2666.6667 | G22: 20.8 | H22: 333.33333 | I22: 0 | K22: 18989.3 | L22: 3000 | M22: 0 | N22: 0 | O22: =M22+N22 -> 0 | P22: 2000 | Q22: 2355.4 | R22: 3096.6667 | S22: =C22+E22+G22+I22+K22+O22+Q22 -> 34108.3 | T22: =D22+F22+H22+J22+L22+P22+R22 -> 19430 | V22: 66.66666 | W22: =SUM(S22+U22) -> 34108.3 | X22: =SUM(T22+V22) -> 19496.667 | Y22: regnerisch | Z22: 8 | AA22: °C
A23: KW | B23: =SUM(B15+1) -> 16 | C23: =SUM(C16:C22) -> 67151.7 | D23: =SUM(D16:D22) -> 58333.333 | E23: =SUM(E16:E22) -> 4594 | F23: =SUM(F16:F22) -> 18666.667 | G23: =SUM(G16:G22) -> 1209.9 | H23: =SUM(H16:H22) -> 2333.3333 | I23: =SUM(I16:I22) -> 0 | J23: =SUM(J16:J22) -> 0 | ... X23: =SUM(X16:X22) -> 136476.67 | Y23: Ø Temp | Z23: =SUM(Z16:Z22)/7 -> 11 | AA23: °C
A24: =SUM(A22+1) -> 17 | B24: Mo | C24: 4347.2 | D24: 8333.3333 | E24: 227.5 | F24: 2666.6667 | G24: 194.7 | H24: 333.33333 | I24: 0 | K24: 2663.2 | L24: 3000 | M24: 24 | N24: 480 | O24: =M24+N24 -> 504 | P24: 2000 | Q24: 5118.8 | R24: 3096.6667 | S24: =C24+E24+G24+I24+K24+O24+Q24 -> 13055.4 | T24: =D24+F24+H24+J24+L24+P24+R24 -> 19430 | V24: 66.66666 | W24: =SUM(S24+U24) -> 13055.4 | X24: =SUM(T24+V24) -> 19496.667 | Y24: ziemlich sonnig | Z24: 14 | AA24: °C
A25: =SUM(A24+1) -> 18 | B25: Di | C25: 5728.9 | D25: 8333.3333 | E25: 352.6 | F25: 2666.6667 | G25: 150.5 | H25: 333.33333 | I25: 0 | K25: 0 | L25: 3000 | M25: 1162.8 | N25: 7622 | O25: =M25+N25 -> 8784.8 | P25: 2000 | Q25: 7514.8 | R25: 3096.6667 | S25: =C25+E25+G25+I25+K25+O25+Q25 -> 22531.6 | T25: =D25+F25+H25+J25+L25+P25+R25 -> 19430 | V25: 66.66666 | W25: =SUM(S25+U25) -> 22531.6 | X25: =SUM(T25+V25) -> 19496.667 | Y25: bedeckt, leicht Regen | Z25: 12 | AA25: °C
