Workbook

Sheet 01_22
A1: Tagesumsätze | H1: 44562
C3: Restaurant | E3: Terrasse | G3: Lounge | I3: Pavillon | K3: Bankett | M3: Seminar | O3: Hotel | Q3: TOTAL Gesamtbetrieb ohne Seebad | S3: Seebad | U3: TOTAL Gesamtbetrieb mit Seebad | W3: Info's
C4: IST | D4: Budget | E4: IST | F4: Budget | G4: IST | H4: Budget | I4: IST | J4: Budget | K4: IST | L4: Budget | M4: IST | N4: Budget | O4: IST | P4: Budget | Q4: IST | R4: Budget | S4: IST | T4: Budget | U4: IST | V4: Budget | W4: Wetter | X4: Temp. | Z4: Bemerkung
A5: 1 | B5: Sa | C5: 5675.8 | D5: 2096.7742 | E5: 1793.6 | F5: 29.03225 | G5: 480 | H5: 56.4516 | I5: 0 | J5: 0 | K5: 735.6 | L5: 0 | M5: 0 | N5: 0 | O5: 290.6 | P5: 385.80645 | Q5: =SUM(C5+E5+G5+I5+K5+M5+O5) -> 8975.6 | R5: =SUM(D5+F5+H5+J5+L5+N5+P5) -> 2568.0645 | U5: =SUM(Q5+S5) -> 8975.6 | V5: =SUM(R5+T5) -> 2568.0645 | W5: sonnig | X5: 12 | Y5: °C
A6: 2 | B6: So | C6: 4336.6 | D6: 2096.7742 | E6: 34.6 | F6: 29.03225 | G6: 70.2 | H6: 56.4516 | I6: 0 | J6: 0 | K6: 564.7 | L6: 0 | M6: 0 | N6: 0 | O6: 0 | P6: 385.80645 | Q6: =SUM(C6+E6+G6+I6+K6+M6+O6) -> 5006.1 | R6: =SUM(D6+F6+H6+J6+L6+N6+P6) -> 2568.0645 | U6: =SUM(Q6+S6) -> 5006.1 | V6: =SUM(R6+T6) -> 2568.0645 | W6: bewölkt | X6: 8 | Y6: °C
A7: KW | B7: 52 | C7: =SUM(C5:C6) -> 10012.4 | D7: =SUM(D5:D6) -> 4193.5484 | E7: =SUM(E5:E6) -> 1828.2 | F7: =SUM(F5:F6) -> 58.0645 | G7: =SUM(G5:G6) -> 550.2 | H7: =SUM(H5:H6) -> 112.9032 | I7: =SUM(I5:I6) -> 0 | J7: =SUM(J5:J6) -> 0 | ... V7: =SUM(V5:V6) -> 5136.129 | W7: Ø Temp | X7: =SUM(X5:X6)/5 -> 4 | Y7: °C
A8: =SUM(A6+1) -> 3 | B8: Mo | C8: 1757.7 | D8: 2096.7742 | E8: 0 | F8: 29.03225 | G8: 0 | H8: 56.4516 | I8: 0 | J8: 0 | K8: 28.2 | L8: 0 | M8: 0 | N8: 0 | O8: 1152.4 | P8: 385.80645 | Q8: =SUM(C8+E8+G8+I8+K8+M8+O8) -> 2938.3 | R8: =SUM(D8+F8+H8+J8+L8+N8+P8) -> 2568.0645 | U8: =SUM(Q8+S8) -> 2938.3 | V8: =SUM(R8+T8) -> 2568.0645 | W8: bewölkt | X8: 8 | Y8: °C
A9: =SUM(A8+1) -> 4 | B9: Di | C9: 1929.3 | D9: 2096.7742 | E9: 0 | F9: 29.03225 | G9: 11 | H9: 56.4516 | I9: 0 | J9: 0 | K9: 0 | L9: 0 | M9: 0 | N9: 0 | O9: 1152.4 | P9: 385.80645 | Q9: =SUM(C9+E9+G9+I9+K9+M9+O9) -> 3092.7 | R9: =SUM(D9+F9+H9+J9+L9+N9+P9) -> 2568.0645 | U9: =SUM(Q9+S9) -> 3092.7 | V9: =SUM(R9+T9) -> 2568.0645 | W9: bewölkt | X9: 8 | Y9: °C
A10: =SUM(A9+1) -> 5 | B10: Mi | C10: 1901.1 | D10: 2096.7742 | E10: 0 | F10: 29.03225 | G10: 0 | H10: 56.4516 | I10: 0 | J10: 0 | K10: 0 | L10: 0 | M10: 0 | N10: 0 | O10: 1667.05 | P10: 385.80645 | Q10: =SUM(C10+E10+G10+I10+K10+M10+O10) -> 3568.15 | R10: =SUM(D10+F10+H10+J10+L10+N10+P10) -> 2568.0645 | U10: =SUM(Q10+S10) -> 3568.15 | V10: =SUM(R10+T10) -> 2568.0645 | W10: bewölkt | X10: 5 | Y10: °C
A11: =SUM(A10+1) -> 6 | B11: Do | C11: 2142.1 | D11: 2096.7742 | E11: 0 | F11: 29.03225 | G11: 0 | H11: 56.4516 | I11: 0 | J11: 0 | K11: 20 | L11: 0 | M11: 0 | N11: 0 | O11: 982.4 | P11: 385.80645 | Q11: =SUM(C11+E11+G11+I11+K11+M11+O11) -> 3144.5 | R11: =SUM(D11+F11+H11+J11+L11+N11+P11) -> 2568.0645 | U11: =SUM(Q11+S11) -> 3144.5 | V11: =SUM(R11+T11) -> 2568.0645 | W11: bewölkt | X11: 5 | Y11: °C
A12: =SUM(A11+1) -> 7 | B12: Fr | C12: 3547.2 | D12: 2096.7742 | E12: 0 | F12: 29.03225 | G12: 0 | H12: 56.4516 | I12: 0 | J12: 0 | K12: 0 | L12: 0 | M12: 0 | N12: 0 | O12: 635.4 | P12: 385.80645 | Q12: =SUM(C12+E12+G12+I12+K12+M12+O12) -> 4182.6 | R12: =SUM(D12+F12+H12+J12+L12+N12+P12) -> 2568.0645 | U12: =SUM(Q12+S12) -> 4182.6 | V12: =SUM(R12+T12) -> 2568.0645 | W12: bewölkt | X12: 3 | Y12: °C
A13: =SUM(A12+1) -> 8 | B13: Sa | C13: 4447.5 | D13: 2096.7742 | E13: 0 | F13: 29.03225 | G13: 9.6 | H13: 56.4516 | I13: 0 | J13: 0 | K13: 0 | L13: 0 | M13: 0 | N13: 0 | O13: 777.5 | P13: 385.80645 | Q13: =SUM(C13+E13+G13+I13+K13+M13+O13) -> 5234.6 | R13: =SUM(D13+F13+H13+J13+L13+N13+P13) -> 2568.0645 | U13: =SUM(Q13+S13) -> 5234.6 | V13: =SUM(R13+T13) -> 2568.0645 | W13: Schneeschauer | X13: 0 | Y13: °C
A14: =SUM(A13+1) -> 9 | B14: So | C14: 5743.1 | D14: 2096.7742 | E14: 0 | F14: 29.03225 | G14: 0 | H14: 56.4516 | I14: 0 | J14: 0 | K14: 1335.7 | L14: 0 | M14: 0 | N14: 0 | O14: 705.4 | P14: 385.80645 | Q14: =SUM(C14+E14+G14+I14+K14+M14+O14) -> 7784.2 | R14: =SUM(D14+F14+H14+J14+L14+N14+P14) -> 2568.0645 | U14: =SUM(Q14+S14) -> 7784.2 | V14: =SUM(R14+T14) -> 2568.0645 | W14: Schneeschauer | X14: 0 | Y14: °C
A15: KW | B15: 1 | C15: =SUM(C8:C14) -> 21468 | D15: =SUM(D8:D14) -> 14677.419 | E15: =SUM(E8:E14) -> 0 | F15: =SUM(F8:F14) -> 203.22575 | G15: =SUM(G8:G14) -> 20.6 | H15: =SUM(H8:H14) -> 395.1612 | I15: =SUM(I8:I14) -> 0 | J15: 0 | K15: =SUM(K8:K14) -> 1383.9 | L15: =SUM(L8:L14) -> 0 | M15: =SUM(M8:M14) -> 0 | N15: =SUM(N8:N14) -> 0 | O15: =SUM(O8:O14) -> 7072.55 | P15: =SUM(P8:P14) -> 2700.6451 | Q15: =SUM(Q8:Q14) -> 29945.05 | R15: =SUM(R8:R14) -> 17976.451 | ... V15: =SUM(V8:V14) -> 17976.451 | W15: Ø Temp | X15: =SUM(X8:X14)/7 -> 4.1428571 | Y15: °C
A16: =SUM(A14+1) -> 10 | B16: Mo | C16: 2036.6 | D16: 2096.7742 | E16: 33 | F16: 29.03225 | G16: 0 | H16: 56.4516 | I16: 0 | J16: 0 | K16: 60.4 | L16: 0 | M16: 0 | N16: 0 | O16: 1121.8 | P16: 385.80645 | Q16: =SUM(C16+E16+G16+I16+K16+M16+O16) -> 3251.8 | R16: =SUM(D16+F16+H16+J16+L16+N16+P16) -> 2568.0645 | U16: =SUM(Q16+S16) -> 3251.8 | V16: =SUM(R16+T16) -> 2568.0645 | W16: bewölkt | X16: 3 | Y16: °C
A17: =SUM(A16+1) -> 11 | B17: Di | C17: 3490.4 | D17: 2096.7742 | E17: 0 | F17: 29.03225 | G17: 0 | H17: 56.4516 | I17: 0 | J17: 0 | K17: 0 | L17: 0 | M17: 0 | N17: 0 | O17: 442.2 | P17: 385.80645 | Q17: =SUM(C17+E17+G17+I17+K17+M17+O17) -> 3932.6 | R17: =SUM(D17+F17+H17+J17+L17+N17+P17) -> 2568.0645 | U17: =SUM(Q17+S17) -> 3932.6 | V17: =SUM(R17+T17) -> 2568.0645 | W17: bewölkt | X17: 3 | Y17: °C
A18: =SUM(A17+1) -> 12 | B18: Mi | C18: 2537.6 | D18: 2096.7742 | E18: 97.1 | F18: 29.03225 | G18: 28.2 | H18: 56.4516 | I18: 0 | J18: 0 | K18: 0 | L18: 0 | M18: 0 | N18: 0 | O18: 841.3 | P18: 385.80645 | Q18: =SUM(C18+E18+G18+I18+K18+M18+O18) -> 3504.2 | R18: =SUM(D18+F18+H18+J18+L18+N18+P18) -> 2568.0645 | U18: =SUM(Q18+S18) -> 3504.2 | V18: =SUM(R18+T18) -> 2568.0645 | W18: sonnig | X18: 5 | Y18: °C
A19: =SUM(A18+1) -> 13 | B19: Do | C19: 2515.8 | D19: 2096.7742 | E19: 0 | F19: 29.03225 | G19: 0 | H19: 56.4516 | I19: 0 | J19: 0 | K19: 45.7 | L19: 0 | M19: 0 | N19: 0 | O19: 1597.1 | P19: 385.80645 | Q19: =SUM(C19+E19+G19+I19+K19+M19+O19) -> 4158.6 | R19: =SUM(D19+F19+H19+J19+L19+N19+P19) -> 2568.0645 | U19: =SUM(Q19+S19) -> 4158.6 | V19: =SUM(R19+T19) -> 2568.0645 | W19: sonnig | X19: 5 | Y19: °C
A20: =SUM(A19+1) -> 14 | B20: Fr | C20: 4667.5 | D20: 2096.7742 | E20: 0 | F20: 29.03225 | G20: 75.1 | H20: 56.4516 | I20: 0 | J20: 0 | K20: 0 | L20: 0 | M20: 0 | N20: 0 | O20: 1386.4 | P20: 385.80645 | Q20: =SUM(C20+E20+G20+I20+K20+M20+O20) -> 6129 | R20: =SUM(D20+F20+H20+J20+L20+N20+P20) -> 2568.0645 | U20: =SUM(Q20+S20) -> 6129 | V20: =SUM(R20+T20) -> 2568.0645 | W20: sonnig | X20: 5 | Y20: °C
A21: =SUM(A20+1) -> 15 | B21: Sa | C21: 6598.5 | D21: 2096.7742 | E21: 0 | F21: 29.03225 | G21: 10 | H21: 56.4516 | I21: 0 | J21: 0 | K21: 788.9 | L21: 0 | M21: 0 | N21: 0 | O21: 732.3 | P21: 385.80645 | Q21: =SUM(C21+E21+G21+I21+K21+M21+O21) -> 8129.7 | R21: =SUM(D21+F21+H21+J21+L21+N21+P21) -> 2568.0645 | U21: =SUM(Q21+S21) -> 8129.7 | V21: =SUM(R21+T21) -> 2568.0645 | W21: Frühnebel, sonnig | X21: 2 | Y21: °C
A22: =SUM(A21+1) -> 16 | B22: So | C22: 6427.8 | D22: 2096.7742 | E22: 32.6 | F22: 29.03225 | G22: 135.3 | H22: 56.4516 | I22: 0 | J22: 0 | K22: 81 | L22: 0 | M22: 261.4 | N22: 0 | O22: 10 | P22: 385.80645 | Q22: =SUM(C22+E22+G22+I22+K22+M22+O22) -> 6948.1 | R22: =SUM(D22+F22+H22+J22+L22+N22+P22) -> 2568.0645 | U22: =SUM(Q22+S22) -> 6948.1 | V22: =SUM(R22+T22) -> 2568.0645 | W22: Frühnebel, sonnig | X22: 4 | Y22: °C
A23: KW | B23: =SUM(B15+1) -> 2 | C23: =SUM(C16:C22) -> 28274.2 | D23: =SUM(D16:D22) -> 14677.419 | E23: =SUM(E16:E22) -> 162.7 | F23: =SUM(F16:F22) -> 203.22575 | G23: =SUM(G16:G22) -> 248.6 | H23: =SUM(H16:H22) -> 395.1612 | I23: =SUM(I16:I22) -> 0 | J23: 0 | K23: =SUM(K16:K22) -> 976 | L23: =SUM(L16:L22) -> 0 | M23: =SUM(M16:M22) -> 261.4 | N23: =SUM(N16:N22) -> 0 | O23: =SUM(O16:O22) -> 6131.1 | P23: =SUM(P16:P22) -> 2700.6451 | Q23: =SUM(Q16:Q22) -> 36054 | R23: =SUM(R16:R22) -> 17976.451 | ... V23: =SUM(V16:V22) -> 17976.451 | W23: Ø Temp | X23: =SUM(X16:X22)/7 -> 3.8571429 | Y23: °C
A24: =SUM(A22+1) -> 17 | B24: Mo | C24: 2116.6 | D24: 2096.7742 | E24: 126.3 | F24: 29.03225 | G24: 34.3 | H24: 56.4516 | I24: 0 | J24: 0 | K24: 37.4 | L24: 0 | M24: 513.3 | N24: 0 | O24: 0 | P24: 385.80645 | Q24: =SUM(C24+E24+G24+I24+K24+M24+O24) -> 2827.9 | R24: =SUM(D24+F24+H24+J24+L24+N24+P24) -> 2568.0645 | U24: =SUM(Q24+S24) -> 2827.9 | V24: =SUM(R24+T24) -> 2568.0645 | W24: sonnig | X24: 5 | Y24: °C | Z24: Zimmer geschlossen
A25: =SUM(A24+1) -> 18 | B25: Di | C25: 2343.6 | D25: 2096.7742 | E25: 0 | F25: 29.03225 | G25: 0 | H25: 56.4516 | I25: 0 | J25: 0 | K25: 0 | L25: 0 | M25: 23 | N25: 0 | O25: 0 | P25: 385.80645 | Q25: =SUM(C25+E25+G25+I25+K25+M25+O25) -> 2366.6 | R25: =SUM(D25+F25+H25+J25+L25+N25+P25) -> 2568.0645 | U25: =SUM(Q25+S25) -> 2366.6 | V25: =SUM(R25+T25) -> 2568.0645 | W25: sonnig | X25: 5 | Y25: °C | Z25: Zimmer geschlossen
A26: =SUM(A25+1) -> 19 | B26: Mi | C26: 2087.2 | D26: 2096.7742 | E26: 28.4 | F26: 29.03225 | G26: 13.1 | H26: 56.4516 | I26: 0 | J26: 0 | K26: 0 | L26: 0 | M26: 0 | N26: 0 | O26: 0 | P26: 385.80645 | Q26: =SUM(C26+E26+G26+I26+K26+M26+O26) -> 2128.7 | R26: =SUM(D26+F26+H26+J26+L26+N26+P26) -> 2568.0645 | U26: =SUM(Q26+S26) -> 2128.7 | V26: =SUM(R26+T26) -> 2568.0645 | W26: sonnig | X26: 3 | Y26: °C | Z26: Zimmer geschlossen
A27: =SUM(A26+1) -> 20 | B27: Do | C27: 926.6 | D27: 2096.7742 | E27: 28.4 | F27: 29.03225 | G27: 0 | H27: 56.4516 | I27: 0 | J27: 0 | K27: 0 | L27: 0 | M27: 0 | N27: 0 | O27: 0 | P27: 385.80645 | Q27: =SUM(C27+E27+G27+I27+K27+M27+O27) -> 955 | R27: =SUM(D27+F27+H27+J27+L27+N27+P27) -> 2568.0645 | U27: =SUM(Q27+S27) -> 955 | V27: =SUM(R27+T27) -> 2568.0645 | W27: bewölkt | X27: 3 | Y27: °C | Z27: Zimmer geschlossen
A28: =SUM(A27+1) -> 21 | B28: Fr | C28: 3886.3 | D28: 2096.7742 | E28: 38.1 | F28: 29.03225 | G28: 62.1 | H28: 56.4516 | I28: 0 | J28: 0 | K28: 0 | L28: 0 | M28: 0 | N28: 0 | O28: 0 | P28: 385.80645 | Q28: =SUM(C28+E28+G28+I28+K28+M28+O28) -> 3986.5 | R28: =SUM(D28+F28+H28+J28+L28+N28+P28) -> 2568.0645 | U28: =SUM(Q28+S28) -> 3986.5 | V28: =SUM(R28+T28) -> 2568.0645 | W28: bewölkt | X28: 5 | Y28: °C | Z28: Zimmer geschlossen
A29: =SUM(A28+1) -> 22 | B29: Sa | C29: 5765.1 | D29: 2096.7742 | E29: 167.2 | F29: 29.03225 | G29: 211.5 | H29: 56.4516 | I29: 0 | J29: 0 | K29: 0 | L29: 0 | M29: 0 | N29: 0 | O29: 0 | P29: 385.80645 | Q29: =SUM(C29+E29+G29+I29+K29+M29+O29) -> 6143.8 | R29: =SUM(D29+F29+H29+J29+L29+N29+P29) -> 2568.0645 | U29: =SUM(Q29+S29) -> 6143.8 | V29: =SUM(R29+T29) -> 2568.0645 | W29: sonnig | X29: 5 | Y29: °C | Z29: Zimmer geschlossen
A30: =SUM(A29+1) -> 23 | B30: So | C30: 4212 | D30: 2096.7742 | E30: 50.2 | F30: 29.03225 | G30: 25.4 | H30: 56.4516 | I30: 0 | J30: 0 | K30: 0 | L30: 0 | M30: 0 | N30: 0 | O30: 0 | P30: 385.80645 | Q30: =SUM(C30+E30+G30+I30+K30+M30+O30) -> 4287.6 | R30: =SUM(D30+F30+H30+J30+L30+N30+P30) -> 2568.0645 | U30: =SUM(Q30+S30) -> 4287.6 | V30: =SUM(R30+T30) -> 2568.0645 | W30: sonnig | X30: 5 | Y30: °C | Z30: Zimmer geschlossen
A31: KW | B31: =SUM(B23+1) -> 3 | C31: =SUM(C24:C30) -> 21337.4 | D31: =SUM(D24:D30) -> 14677.419 | E31: =SUM(E24:E30) -> 438.6 | F31: =SUM(F24:F30) -> 203.22575 | G31: =SUM(G24:G30) -> 346.4 | H31: =SUM(H24:H30) -> 395.1612 | I31: =SUM(I24:I30) -> 0 | J31: =SUM(J24:J30) -> 0 | ... V31: =SUM(V24:V30) -> 17976.451 | W31: Ø Temp | X31: =SUM(X24:X30)/7 -> 4.4285714 | Y31: °C
A32: =SUM(A30+1) -> 24 | B32: Mo | C32: 3382.6 | D32: 2096.7742 | E32: 33 | F32: 29.03225 | G32: 0 | H32: 56.4516 | I32: 0 | J32: 0 | K32: 0 | L32: 0 | M32: 0 | N32: 0 | O32: 0 | P32: 385.80645 | Q32: =SUM(C32+E32+G32+I32+K32+M32+O32) -> 3415.6 | R32: =SUM(D32+F32+H32+J32+L32+N32+P32) -> 2568.0645 | U32: =SUM(Q32+S32) -> 3415.6 | V32: =SUM(R32+T32) -> 2568.0645 | W32: bewölkt | X32: 5 | Y32: °C | Z32: Zimmer geschlossen
A33: =SUM(A32+1) -> 25 | B33: Di | C33: 707 | D33: 2096.7742 | E33: 99.9 | F33: 29.03225 | G33: 0 | H33: 56.4516 | I33: 0 | J33: 0 | K33: 0 | L33: 0 | M33: 0 | N33: 0 | O33: 0 | P33: 385.80645 | Q33: =SUM(C33+E33+G33+I33+K33+M33+O33) -> 806.9 | R33: =SUM(D33+F33+H33+J33+L33+N33+P33) -> 2568.0645 | U33: =SUM(Q33+S33) -> 806.9 | V33: =SUM(R33+T33) -> 2568.0645 | W33: bewölkt | X33: 5 | Y33: °C | Z33: Zimmer geschlossen
A34: =SUM(A33+1) -> 26 | B34: Mi | C34: 1460.6 | D34: 2096.7742 | E34: 16.5 | F34: 29.03225 | G34: 0 | H34: 56.4516 | I34: 0 | J34: 0 | K34: 0 | L34: 0 | M34: 0 | N34: 0 | O34: 0 | P34: 385.80645 | Q34: =SUM(C34+E34+G34+I34+K34+M34+O34) -> 1477.1 | R34: =SUM(D34+F34+H34+J34+L34+N34+P34) -> 2568.0645 | U34: =SUM(Q34+S34) -> 1477.1 | V34: =SUM(R34+T34) -> 2568.0645 | W34: sonnig | X34: 5 | Y34: °C | Z34: Zimmer geschlossen
A35: =SUM(A34+1) -> 27 | B35: Do | C35: 4097.7 | D35: 2096.7742 | E35: 84 | F35: 29.03225 | G35: 0 | H35: 56.4516 | I35: 0 | J35: 0 | K35: 0 | L35: 0 | M35: 0 | N35: 0 | O35: 0 | P35: 385.80645 | Q35: =SUM(C35+E35+G35+I35+K35+M35+O35) -> 4181.7 | R35: =SUM(D35+F35+H35+J35+L35+N35+P35) -> 2568.0645 | U35: =SUM(Q35+S35) -> 4181.7 | V35: =SUM(R35+T35) -> 2568.0645 | W35: sonnig | X35: 5 | Y35: °C | Z35: Zimmer geschlossen
A36: =SUM(A35+1) -> 28 | B36: Fr | C36: 3983.3 | D36: 2096.7742 | E36: 130.6 | F36: 29.03225 | G36: 0 | H36: 56.4516 | I36: 0 | J36: 0 | K36: 0 | L36: 0 | M36: 0 | N36: 0 | O36: 0 | P36: 385.80645 | Q36: =SUM(C36+E36+G36+I36+K36+M36+O36) -> 4113.9 | R36: =SUM(D36+F36+H36+J36+L36+N36+P36) -> 2568.0645 | U36: =SUM(Q36+S36) -> 4113.9 | V36: =SUM(R36+T36) -> 2568.0645 | W36: sonnig | X36: 5 | Y36: °C | Z36: Zimmer geschlossen
A37: =SUM(A36+1) -> 29 | B37: Sa | C37: 3804.5 | D37: 2096.7742 | E37: 679.3 | F37: 29.03225 | G37: 0 | H37: 56.4516 | I37: 0 | J37: 0 | K37: 0 | L37: 0 | M37: 0 | N37: 0 | O37: 0 | P37: 385.80645 | Q37: =SUM(C37+E37+G37+I37+K37+M37+O37) -> 4483.8 | R37: =SUM(D37+F37+H37+J37+L37+N37+P37) -> 2568.0645 | U37: =SUM(Q37+S37) -> 4483.8 | V37: =SUM(R37+T37) -> 2568.0645 | W37: sonnig | X37: 5 | Y37: °C | Z37: Zimmer geschlossen
A38: =SUM(A37+1) -> 30 | B38: So | C38: 4893.6 | D38: 2096.7742 | E38: 226.9 | F38: 29.03225 | G38: 0 | H38: 56.4516 | I38: 0 | J38: 0 | K38: 0 | L38: 0 | M38: 0 | N38: 0 | O38: 0 | P38: 385.80645 | Q38: =SUM(C38+E38+G38+I38+K38+M38+O38) -> 5120.5 | R38: =SUM(D38+F38+H38+J38+L38+N38+P38) -> 2568.0645 | U38: =SUM(Q38+S38) -> 5120.5 | V38: =SUM(R38+T38) -> 2568.0645 | W38: sonnig | X38: 5 | Y38: °C | Z38: Zimmer geschlossen
A39: KW | B39: =SUM(B31+1) -> 4 | C39: =SUM(C32:C38) -> 22329.3 | D39: =SUM(D32:D38) -> 14677.419 | E39: =SUM(E32:E38) -> 1270.2 | F39: =SUM(F32:F38) -> 203.22575 | G39: =SUM(G32:G38) -> 0 | H39: =SUM(H32:H38) -> 395.1612 | I39: =SUM(I32:I38) -> 0 | J39: =SUM(J32:J38) -> 0 | ... V39: =SUM(V32:V38) -> 17976.451 | W39: Ø Temp | X39: =SUM(X32:X38)/7 -> 5 | Y39: °C
A40: =SUM(A38+1) -> 31 | B40: Mo | C40: 0 | D40: 2096.7742 | E40: 0 | F40: 29.03225 | G40: 0 | H40: 56.4516 | I40: 0 | J40: 0 | K40: 0 | L40: 0 | M40: 0 | N40: 0 | O40: -263.55 | P40: 385.80645 | Q40: =SUM(C40+E40+G40+I40+K40+M40+O40) -> -263.55 | R40: =SUM(D40+F40+H40+J40+L40+N40+P40) -> 2568.0645 | U40: =SUM(Q40+S40) -> -263.55 | V40: =SUM(R40+T40) -> 2568.0645 | W40: Schneeschauer | X40: 0 | Y40: °C | Z40: Hotel geschlossen
A41: KW | B41: 5 | C41: =SUM(C40) -> 0 | D41: =SUM(D40) -> 2096.7742 | E41: =SUM(E40) -> 0 | F41: =SUM(F40) -> 29.03225 | G41: =SUM(G40) -> 0 | H41: =SUM(H40) -> 56.4516 | I41: =SUM(I40) -> 0 | J41: =SUM(J40) -> 0 | ... V41: =SUM(V40) -> 2568.0645 | W41: Ø Temp | X41: =SUM(X32:X38)/7 -> 5 | Y41: °C
...

Sheet 02_22
A1: Tagesumsätze | H1: 44593
C3: Restaurant | E3: Terrasse | G3: Lounge | I3: Pavillon | K3: Bankett | M3: Seminar | O3: Hotel | Q3: TOTAL Gesamtbetrieb ohne Seebad | S3: Seebad | U3: TOTAL Gesamtbetrieb mit Seebad | W3: Info's
C4: IST | D4: Budget | E4: IST | F4: Budget | G4: IST | H4: Budget | I4: IST | J4: Budget | K4: IST | L4: Budget | M4: IST | N4: Budget | O4: IST | P4: Budget | Q4: IST | R4: Budget | S4: IST | T4: Budget | U4: IST | V4: Budget | W4: Wetter | X4: Temp. | Z4: Bemerkung
A5: 1 | B5: Di | U5: =SUM(Q5+S5) -> 0 | V5: =SUM(R5+T5) -> 0 | Y5: °C | Z5: Hotel geschlossen
A6: =SUM(A5+1) -> 2 | B6: Mi | U6: =SUM(Q6+S6) -> 0 | V6: =SUM(R6+T6) -> 0 | Y6: °C | Z6: Hotel geschlossen
A7: =SUM(A6+1) -> 3 | B7: Do | U7: =SUM(Q7+S7) -> 0 | V7: =SUM(R7+T7) -> 0 | Y7: °C | Z7: Hotel geschlossen
A8: =SUM(A7+1) -> 4 | B8: Fr | U8: =SUM(Q8+S8) -> 0 | V8: =SUM(R8+T8) -> 0 | Y8: °C | Z8: Hotel geschlossen
A9: =SUM(A8+1) -> 5 | B9: Sa | U9: =SUM(Q9+S9) -> 0 | V9: =SUM(R9+T9) -> 0 | Y9: °C | Z9: Hotel geschlossen
A10: =SUM(A9+1) -> 6 | B10: So | U10: =SUM(Q10+S10) -> 0 | V10: =SUM(R10+T10) -> 0 | Y10: °C | Z10: Hotel geschlossen
A11: KW | B11: 5 | C11: =SUM(C5:C10) -> 0 | D11: =SUM(D5:D10) -> 0 | E11: =SUM(E5:E10) -> 0 | F11: =SUM(F5:F10) -> 0 | G11: =SUM(G5:G10) -> 0 | H11: =SUM(H5:H10) -> 0 | I11: =SUM(I5:I10) -> 0 | J11: =SUM(J5:J10) -> 0 | ... V11: =SUM(V5:V10) -> 0 | W11: Ø Temp | X11: =SUM(X5:X10)/7 -> 0 | Y11: °C | Z11: Hotel geschlossen
A12: =SUM(A10+1) -> 7 | B12: Mo | Q12: =SUM(C12+E12+G12+I12+K12+M12+O12) -> 0 | R12: =SUM(D12+F12+H12+J12+L12+N12+P12) -> 0 | U12: =SUM(Q12+S12) -> 0 | V12: =SUM(R12+T12) -> 0 | Y12: °C | Z12: Hotel geschlossen
A13: =SUM(A12+1) -> 8 | B13: Di | Q13: =SUM(C13+E13+G13+I13+K13+M13+O13) -> 0 | R13: =SUM(D13+F13+H13+J13+L13+N13+P13) -> 0 | U13: =SUM(Q13+S13) -> 0 | V13: =SUM(R13+T13) -> 0 | Y13: °C | Z13: Hotel geschlossen
A14: =SUM(A13+1) -> 9 | B14: Mi | Q14: =SUM(C14+E14+G14+I14+K14+M14+O14) -> 0 | R14: =SUM(D14+F14+H14+J14+L14+N14+P14) -> 0 | U14: =SUM(Q14+S14) -> 0 | V14: =SUM(R14+T14) -> 0 | Y14: °C | Z14: Hotel geschlossen
A15: =SUM(A14+1) -> 10 | B15: Do | Q15: =SUM(C15+E15+G15+I15+K15+M15+O15) -> 0 | R15: =SUM(D15+F15+H15+J15+L15+N15+P15) -> 0 | U15: =SUM(Q15+S15) -> 0 | V15: =SUM(R15+T15) -> 0 | Y15: °C | Z15: Hotel geschlossen
A16: =SUM(A15+1) -> 11 | B16: Fr | Q16: =SUM(C16+E16+G16+I16+K16+M16+O16) -> 0 | R16: =SUM(D16+F16+H16+J16+L16+N16+P16) -> 0 | U16: =SUM(Q16+S16) -> 0 | V16: =SUM(R16+T16) -> 0 | Y16: °C | Z16: Hotel geschlossen
A17: =SUM(A16+1) -> 12 | B17: Sa | Q17: =SUM(C17+E17+G17+I17+K17+M17+O17) -> 0 | R17: =SUM(D17+F17+H17+J17+L17+N17+P17) -> 0 | U17: =SUM(Q17+S17) -> 0 | V17: =SUM(R17+T17) -> 0 | Y17: °C | Z17: Hotel geschlossen
A18: =SUM(A17+1) -> 13 | B18: So | Q18: =SUM(C18+E18+G18+I18+K18+M18+O18) -> 0 | R18: =SUM(D18+F18+H18+J18+L18+N18+P18) -> 0 | U18: =SUM(Q18+S18) -> 0 | V18: =SUM(R18+T18) -> 0 | Y18: °C | Z18: Hotel geschlossen
A19: KW | B19: =SUM(B11+1) -> 6 | C19: =SUM(C12:C18) -> 0 | D19: =SUM(D12:D18) -> 0 | E19: =SUM(E12:E18) -> 0 | F19: =SUM(F12:F18) -> 0 | G19: =SUM(G12:G18) -> 0 | H19: =SUM(H12:H18) -> 0 | I19: =SUM(I12:I18) -> 0 | J19: =SUM(J12:J18) -> 0 | ... V19: =SUM(V12:V18) -> 0 | W19: Ø Temp | X19: =SUM(X12:X18)/7 -> 0 | Y19: °C | Z19: Hotel geschlossen
A20: =SUM(A18+1) -> 14 | B20: Mo | Q20: =SUM(C20+E20+G20+I20+K20+M20+O20) -> 0 | R20: =SUM(D20+F20+H20+J20+L20+N20+P20) -> 0 | U20: =SUM(Q20+S20) -> 0 | V20: =SUM(R20+T20) -> 0 | Y20: °C | Z20: Hotel geschlossen
A21: =SUM(A20+1) -> 15 | B21: Di | Q21: =SUM(C21+E21+G21+I21+K21+M21+O21) -> 0 | R21: =SUM(D21+F21+H21+J21+L21+N21+P21) -> 0 | U21: =SUM(Q21+S21) -> 0 | V21: =SUM(R21+T21) -> 0 | Y21: °C | Z21: Hotel geschlossen
A22: =SUM(A21+1) -> 16 | B22: Mi | Q22: =SUM(C22+E22+G22+I22+K22+M22+O22) -> 0 | R22: =SUM(D22+F22+H22+J22+L22+N22+P22) -> 0 | U22: =SUM(Q22+S22) -> 0 | V22: =SUM(R22+T22) -> 0 | Y22: °C | Z22: Hotel geschlossen
A23: =SUM(A22+1) -> 17 | B23: Do | Q23: =SUM(C23+E23+G23+I23+K23+M23+O23) -> 0 | R23: =SUM(D23+F23+H23+J23+L23+N23+P23) -> 0 | U23: =SUM(Q23+S23) -> 0 | V23: =SUM(R23+T23) -> 0 | Y23: °C | Z23: Hotel geschlossen
A24: =SUM(A23+1) -> 18 | B24: Fr | Q24: =SUM(C24+E24+G24+I24+K24+M24+O24) -> 0 | R24: =SUM(D24+F24+H24+J24+L24+N24+P24) -> 0 | U24: =SUM(Q24+S24) -> 0 | V24: =SUM(R24+T24) -> 0 | Y24: °C | Z24: Hotel geschlossen
A25: =SUM(A24+1) -> 19 | B25: Sa | Q25: =SUM(C25+E25+G25+I25+K25+M25+O25) -> 0 | R25: =SUM(D25+F25+H25+J25+L25+N25+P25) -> 0 | U25: =SUM(Q25+S25) -> 0 | V25: =SUM(R25+T25) -> 0 | Y25: °C | Z25: Hotel geschlossen
A26: =SUM(A25+1) -> 20 | B26: So | Q26: =SUM(C26+E26+G26+I26+K26+M26+O26) -> 0 | R26: =SUM(D26+F26+H26+J26+L26+N26+P26) -> 0 | U26: =SUM(Q26+S26) -> 0 | V26: =SUM(R26+T26) -> 0 | Y26: °C | Z26: Hotel geschlossen
A27: KW | B27: =SUM(B19+1) -> 7 | C27: =SUM(C20:C26) -> 0 | D27: =SUM(D20:D26) -> 0 | E27: =SUM(E20:E26) -> 0 | F27: =SUM(F20:F26) -> 0 | G27: =SUM(G20:G26) -> 0 | H27: =SUM(H20:H26) -> 0 | I27: =SUM(I20:I26) -> 0 | J27: =SUM(J20:J26) -> 0 | ... V27: =SUM(V20:V26) -> 0 | W27: Ø Temp | X27: =SUM(X20:X26)/7 -> 0 | Y27: °C | Z27: Hotel geschlossen
A28: =SUM(A26+1) -> 21 | B28: Mo | Q28: =SUM(C28+E28+G28+I28+K28+M28+O28) -> 0 | R28: =SUM(D28+F28+H28+J28+L28+N28+P28) -> 0 | U28: =SUM(Q28+S28) -> 0 | V28: =SUM(R28+T28) -> 0 | Y28: °C | Z28: Hotel geschlossen
A29: =SUM(A28+1) -> 22 | B29: Di | Q29: =SUM(C29+E29+G29+I29+K29+M29+O29) -> 0 | R29: =SUM(D29+F29+H29+J29+L29+N29+P29) -> 0 | U29: =SUM(Q29+S29) -> 0 | V29: =SUM(R29+T29) -> 0 | Y29: °C | Z29: Hotel geschlossen
A30: =SUM(A29+1) -> 23 | B30: Mi | Q30: =SUM(C30+E30+G30+I30+K30+M30+O30) -> 0 | R30: =SUM(D30+F30+H30+J30+L30+N30+P30) -> 0 | U30: =SUM(Q30+S30) -> 0 | V30: =SUM(R30+T30) -> 0 | Y30: °C | Z30: Hotel geschlossen
A31: =SUM(A30+1) -> 24 | B31: Do | Q31: =SUM(C31+E31+G31+I31+K31+M31+O31) -> 0 | R31: =SUM(D31+F31+H31+J31+L31+N31+P31) -> 0 | U31: =SUM(Q31+S31) -> 0 | V31: =SUM(R31+T31) -> 0 | Y31: °C | Z31: Hotel geschlossen
A32: =SUM(A31+1) -> 25 | B32: Fr | Q32: =SUM(C32+E32+G32+I32+K32+M32+O32) -> 0 | R32: =SUM(D32+F32+H32+J32+L32+N32+P32) -> 0 | U32: =SUM(Q32+S32) -> 0 | V32: =SUM(R32+T32) -> 0 | Y32: °C | Z32: Hotel geschlossen
A33: =SUM(A32+1) -> 26 | B33: Sa | Q33: =SUM(C33+E33+G33+I33+K33+M33+O33) -> 0 | R33: =SUM(D33+F33+H33+J33+L33+N33+P33) -> 0 | U33: =SUM(Q33+S33) -> 0 | V33: =SUM(R33+T33) -> 0 | Y33: °C | Z33: Hotel geschlossen
A34: =SUM(A33+1) -> 27 | B34: So | Q34: =SUM(C34+E34+G34+I34+K34+M34+O34) -> 0 | R34: =SUM(D34+F34+H34+J34+L34+N34+P34) -> 0 | U34: =SUM(Q34+S34) -> 0 | V34: =SUM(R34+T34) -> 0 | Y34: °C | Z34: Hotel geschlossen
A35: =SUM(A34+1) -> 28 | B35: So | Q35: =SUM(C35+E35+G35+I35+K35+M35+O35) -> 0 | R35: =SUM(D35+F35+H35+J35+L35+N35+P35) -> 0 | U35: =SUM(Q35+S35) -> 0 | V35: =SUM(R35+T35) -> 0 | Y35: °C | Z35: Hotel geschlossen
A36: KW | B36: =SUM(B27+1) -> 8 | C36: =SUM(C32:C34) -> 0 | D36: =SUM(D32:D34) -> 0 | E36: =SUM(E32:E34) -> 0 | F36: =SUM(F32:F34) -> 0 | G36: =SUM(G32:G34) -> 0 | H36: =SUM(H32:H34) -> 0 | I36: =SUM(I32:I34) -> 0 | J36: =SUM(J32:J34) -> 0 | ... V36: =SUM(V32:V34) -> 0 | W36: Ø Temp | X36: =SUM(X28:X34)/7 -> 0 | Y36: °C | Z36: Hotel geschlossen
A37: Umsatz kumuliert | C37: =SUM(C11+C19+C27+C36) -> 0 | D37: =SUM(D11+D19+D27+D36) -> 0 | E37: =SUM(E11+E19+E27+E36) -> 0 | F37: =SUM(F11+F19+F27+F36) -> 0 | G37: =SUM(G11+G19+G27+G36) -> 0 | H37: =SUM(H11+H19+H27+H36) -> 0 | I37: =SUM(I11+I19+I27+I36) -> 0 | J37: =SUM(J11+J19+J27+J36) -> 0 | ... V37: =SUM(V11+V19+V27+V36) -> 0 | W37: Umsatz kumuliert
A38: Umsatz pro Tag | C38: =C37/28 -> 0 | D38: =D37/28 -> 0 | E38: =E37/28 -> 0 | F38: =F37/28 -> 0 | G38: =G37/28 -> 0 | H38: =H37/28 -> 0 | I38: =I37/28 -> 0 | J38: =J37/28 -> 0 | ... V38: =V37/28 -> 0 | W38: Budget pro Tag
A39: Diff. zu Budget | C39: =SUM(C37-D37) -> 0 | E39: =SUM(E37-F37) -> 0 | G39: =SUM(G37-H37) -> 0 | I39: =SUM(I37-J37) -> 0 | K39: =SUM(K37-L37) -> 0 | M39: =SUM(M37-N37) -> 0 | O39: =SUM(O37-P37) -> 0 | Q39: =SUM(Q37-R37) -> 0 | S39: =SUM(S37-T37) -> 0 | U39: =SUM(U37-V37) -> 0
A40: Index | C40: =SUM(100/D37*C37) -> #DIV/0! | E40: =SUM(100/F37*E37) -> #DIV/0! | G40: =SUM(100/H37*G37) -> #DIV/0! | I40: =SUM(100/J37*I37) -> #DIV/0! | K40: =SUM(100/L37*K37) -> #DIV/0! | M40: =SUM(100/N37*M37) -> #DIV/0! | O40: =SUM(100/P37*O37) -> #DIV/0! | Q40: =SUM(100/R37*Q37) -> #DIV/0! | S40: =SUM(100/T37*S37) -> #DIV/0! | U40: =SUM(100/V37*U37) -> #DIV/0!

Sheet 03_22
A1: Tagesumsätze | H1: 44621
C3: Restaurant | E3: Terrasse | G3: Lounge | I3: Pavillon | K3: Bankett | M3: Seminar | O3: Hotel | Q3: TOTAL Gesamtbetrieb ohne Seebad | S3: Seebad | U3: TOTAL Gesamtbetrieb mit Seebad | W3: Info's
C4: IST | D4: Budget | E4: IST | F4: Budget | G4: IST | H4: Budget | I4: IST | J4: Budget | K4: IST | L4: Budget | M4: IST | N4: Budget | O4: IST | P4: Budget | Q4: IST | R4: Budget | S4: IST | T4: Budget | U4: IST | V4: Budget | W4: Wetter | X4: Temp. | Z4: Bemerkung
A5: 1 | B5: Di | D5: 4193.5484 | F5: 322.58065 | H5: 161.29032 | P5: 1285.4839 | Q5: =SUM(C5+E5+G5+I5+K5+M5+O5) -> 0 | R5: =SUM(D5+F5+H5+J5+L5+N5+P5) -> 5962.9032 | U5: =SUM(Q5+S5) -> 0 | V5: =SUM(R5+T5) -> 5962.9032 | Y5: °C | Z5: Hotel geschlossen
A6: =SUM(A5+1) -> 2 | B6: Mi | D6: 4193.5484 | F6: 322.58065 | H6: 161.29032 | P6: 1285.4839 | Q6: =SUM(C6+E6+G6+I6+K6+M6+O6) -> 0 | R6: =SUM(D6+F6+H6+J6+L6+N6+P6) -> 5962.9032 | U6: =SUM(Q6+S6) -> 0 | V6: =SUM(R6+T6) -> 5962.9032 | Y6: °C | Z6: Hotel geschlossen
A7: =SUM(A6+1) -> 3 | B7: Do | D7: 4193.5484 | F7: 322.58065 | H7: 161.29032 | P7: 1285.4839 | Q7: =SUM(C7+E7+G7+I7+K7+M7+O7) -> 0 | R7: =SUM(D7+F7+H7+J7+L7+N7+P7) -> 5962.9032 | U7: =SUM(Q7+S7) -> 0 | V7: =SUM(R7+T7) -> 5962.9032 | Y7: °C | Z7: Hotel geschlossen
A8: =SUM(A7+1) -> 4 | B8: Fr | D8: 4193.5484 | F8: 322.58065 | H8: 161.29032 | P8: 1285.4839 | Q8: =SUM(C8+E8+G8+I8+K8+M8+O8) -> 0 | R8: =SUM(D8+F8+H8+J8+L8+N8+P8) -> 5962.9032 | U8: =SUM(Q8+S8) -> 0 | V8: =SUM(R8+T8) -> 5962.9032 | Y8: °C | Z8: Hotel geschlossen
A9: =SUM(A8+1) -> 5 | B9: Sa | D9: 4193.5484 | F9: 322.58065 | H9: 161.29032 | P9: 1285.4839 | Q9: =SUM(C9+E9+G9+I9+K9+M9+O9) -> 0 | R9: =SUM(D9+F9+H9+J9+L9+N9+P9) -> 5962.9032 | U9: =SUM(Q9+S9) -> 0 | V9: =SUM(R9+T9) -> 5962.9032 | Y9: °C | Z9: Hotel geschlossen
A10: =SUM(A9+1) -> 6 | B10: So | D10: 4193.5484 | F10: 322.58065 | H10: 161.29032 | P10: 1285.4839 | Q10: =SUM(C10+E10+G10+I10+K10+M10+O10) -> 0 | R10: =SUM(D10+F10+H10+J10+L10+N10+P10) -> 5962.9032 | U10: =SUM(Q10+S10) -> 0 | V10: =SUM(R10+T10) -> 5962.9032 | Y10: °C | Z10: Hotel geschlossen
A11: KW | B11: 9 | C11: =SUM(C5:C10) -> 0 | D11: =SUM(D5:D10) -> 25161.29 | E11: =SUM(E5:E10) -> 0 | F11: =SUM(F5:F10) -> 1935.4839 | G11: =SUM(G5:G10) -> 0 | H11: =SUM(H5:H10) -> 967.74192 | I11: =SUM(I5:I10) -> 0 | J11: =SUM(J5:J10) -> 0 | ... V11: =SUM(V5:V10) -> 35777.419 | W11: Ø Temp | X11: =SUM(X5:X10)/7 -> 0 | Y11: °C
A12: =SUM(A10+1) -> 7 | B12: Mo | D12: 4193.5484 | F12: 322.58065 | H12: 161.29032 | P12: 1285.4839 | Q12: =SUM(C12+E12+G12+I12+K12+M12+O12) -> 0 | R12: =SUM(D12+F12+H12+J12+L12+N12+P12) -> 5962.9032 | U12: =SUM(Q12+S12) -> 0 | V12: =SUM(R12+T12) -> 5962.9032 | Y12: °C | Z12: Hotel geschlossen
A13: =SUM(A12+1) -> 8 | B13: Di | D13: 4193.5484 | F13: 322.58065 | H13: 161.29032 | P13: 1285.4839 | Q13: =SUM(C13+E13+G13+I13+K13+M13+O13) -> 0 | R13: =SUM(D13+F13+H13+J13+L13+N13+P13) -> 5962.9032 | U13: =SUM(Q13+S13) -> 0 | V13: =SUM(R13+T13) -> 5962.9032 | Y13: °C | Z13: Hotel geschlossen
A14: =SUM(A13+1) -> 9 | B14: Mi | D14: 4193.5484 | F14: 322.58065 | H14: 161.29032 | P14: 1285.4839 | Q14: =SUM(C14+E14+G14+I14+K14+M14+O14) -> 0 | R14: =SUM(D14+F14+H14+J14+L14+N14+P14) -> 5962.9032 | U14: =SUM(Q14+S14) -> 0 | V14: =SUM(R14+T14) -> 5962.9032 | Y14: °C | Z14: Hotel geschlossen
A15: =SUM(A14+1) -> 10 | B15: Do | D15: 4193.5484 | F15: 322.58065 | H15: 161.29032 | P15: 1285.4839 | Q15: =SUM(C15+E15+G15+I15+K15+M15+O15) -> 0 | R15: =SUM(D15+F15+H15+J15+L15+N15+P15) -> 5962.9032 | U15: =SUM(Q15+S15) -> 0 | V15: =SUM(R15+T15) -> 5962.9032 | Y15: °C | Z15: Hotel geschlossen
A16: =SUM(A15+1) -> 11 | B16: Fr | C16: 4864.3 | D16: 4193.5484 | E16: 0 | F16: 322.58065 | G16: 0 | H16: 161.29032 | I16: 0 | K16: 0 | M16: 0 | O16: 1084.4 | P16: 1285.4839 | Q16: =SUM(C16+E16+G16+I16+K16+M16+O16) -> 5948.7 | R16: =SUM(D16+F16+H16+J16+L16+N16+P16) -> 5962.9032 | U16: =SUM(Q16+S16) -> 5948.7 | V16: =SUM(R16+T16) -> 5962.9032 | W16: bewölkt | X16: 7 | Y16: °C | Z16: Wasserschaden
A17: =SUM(A16+1) -> 12 | B17: Sa | C17: 6615.4 | D17: 4193.5484 | E17: 688.1 | F17: 322.58065 | G17: 293.5 | H17: 161.29032 | I17: 0 | K17: 0 | M17: 0 | O17: 1501.8 | P17: 1285.4839 | Q17: =SUM(C17+E17+G17+I17+K17+M17+O17) -> 9098.8 | R17: =SUM(D17+F17+H17+J17+L17+N17+P17) -> 5962.9032 | U17: =SUM(Q17+S17) -> 9098.8 | V17: =SUM(R17+T17) -> 5962.9032 | W17: sonnig | X17: 10 | Y17: °C | Z17: Wasserschaden
A18: =SUM(A17+1) -> 13 | B18: So | C18: 7683.8 | D18: 4193.5484 | E18: 5167.7 | F18: 322.58065 | G18: 488.1 | H18: 161.29032 | I18: 0 | K18: 0 | M18: 0 | O18: 724 | P18: 1285.4839 | Q18: =SUM(C18+E18+G18+I18+K18+M18+O18) -> 14063.6 | R18: =SUM(D18+F18+H18+J18+L18+N18+P18) -> 5962.9032 | U18: =SUM(Q18+S18) -> 14063.6 | V18: =SUM(R18+T18) -> 5962.9032 | W18: sonnig | X18: 15 | Y18: °C | Z18: Wasserschaden
A19: KW | B19: =SUM(B11+1) -> 10 | C19: =SUM(C12:C18) -> 19163.5 | D19: =SUM(D12:D18) -> 29354.839 | E19: =SUM(E12:E18) -> 5855.8 | F19: =SUM(F12:F18) -> 2258.0645 | G19: =SUM(G12:G18) -> 781.6 | H19: =SUM(H12:H18) -> 1129.0322 | I19: =SUM(I12:I18) -> 0 | J19: =SUM(J12:J18) -> 0 | ... V19: =SUM(V12:V18) -> 41740.323 | W19: Ø Temp | X19: =SUM(X12:X18)/7 -> 4.5714286 | Y19: °C
A20: =SUM(A18+1) -> 14 | B20: Mo | C20: 3890.2 | D20: 4193.5484 | E20: 417.6 | F20: 322.58065 | G20: 69.8 | H20: 161.29032 | I20: 0 | K20: 0 | M20: 0 | O20: 517.2 | P20: 1285.4839 | Q20: =SUM(C20+E20+G20+I20+K20+M20+O20) -> 4894.8 | R20: =SUM(D20+F20+H20+J20+L20+N20+P20) -> 5962.9032 | U20: =SUM(Q20+S20) -> 4894.8 | V20: =SUM(R20+T20) -> 5962.9032 | W20: sonnig | X20: 12 | Y20: °C
A21: =SUM(A20+1) -> 15 | B21: Di | C21: 3512.1 | D21: 4193.5484 | E21: 0 | F21: 322.58065 | G21: 0 | H21: 161.29032 | I21: 0 | K21: 0 | M21: 0 | O21: 927.6 | P21: 1285.4839 | Q21: =SUM(C21+E21+G21+I21+K21+M21+O21) -> 4439.7 | R21: =SUM(D21+F21+H21+J21+L21+N21+P21) -> 5962.9032 | U21: =SUM(Q21+S21) -> 4439.7 | V21: =SUM(R21+T21) -> 5962.9032 | W21: bewölkt | X21: 7 | Y21: °C
A22: =SUM(A21+1) -> 16 | B22: Mi | C22: 3855.3 | D22: 4193.5484 | E22: 635 | F22: 322.58065 | G22: 42.4 | H22: 161.29032 | I22: 0 | K22: 0 | M22: 0 | O22: 1534.8 | P22: 1285.4839 | Q22: =SUM(C22+E22+G22+I22+K22+M22+O22) -> 6067.5 | R22: =SUM(D22+F22+H22+J22+L22+N22+P22) -> 5962.9032 | U22: =SUM(Q22+S22) -> 6067.5 | V22: =SUM(R22+T22) -> 5962.9032 | W22: sonnig | X22: 12 | Y22: °C
A23: =SUM(A22+1) -> 17 | B23: Do | C23: 5326.5 | D23: 4193.5484 | E23: 97.5 | F23: 322.58065 | G23: 31.5 | H23: 161.29032 | I23: 0 | K23: 0 | M23: 0 | O23: 1682.5 | P23: 1285.4839 | Q23: =SUM(C23+E23+G23+I23+K23+M23+O23) -> 7138 | R23: =SUM(D23+F23+H23+J23+L23+N23+P23) -> 5962.9032 | U23: =SUM(Q23+S23) -> 7138 | V23: =SUM(R23+T23) -> 5962.9032 | W23: sonnig | X23: 15 | Y23: °C
A24: =SUM(A23+1) -> 18 | B24: Fr | C24: 4905.7 | D24: 4193.5484 | E24: 0 | F24: 322.58065 | G24: 0 | H24: 161.29032 | I24: 0 | K24: 0 | M24: 0 | O24: 0 | P24: 1285.4839 | Q24: =SUM(C24+E24+G24+I24+K24+M24+O24) -> 4905.7 | R24: =SUM(D24+F24+H24+J24+L24+N24+P24) -> 5962.9032 | U24: =SUM(Q24+S24) -> 4905.7 | V24: =SUM(R24+T24) -> 5962.9032 | W24: bewölkt | X24: 8 | Y24: °C
A25: =SUM(A24+1) -> 19 | B25: Sa | C25: 5407.5 | D25: 4193.5484 | E25: 361 | F25: 322.58065 | G25: 312.5 | H25: 161.29032 | I25: 0 | K25: 0 | M25: 0 | O25: 950.8 | P25: 1285.4839 | Q25: =SUM(C25+E25+G25+I25+K25+M25+O25) -> 7031.8 | R25: =SUM(D25+F25+H25+J25+L25+N25+P25) -> 5962.9032 | U25: =SUM(Q25+S25) -> 7031.8 | V25: =SUM(R25+T25) -> 5962.9032 | W25: sonnig | X25: 12 | Y25: °C
A26: =SUM(A25+1) -> 20 | B26: So | C26: 5775.1 | D26: 4193.5484 | E26: 5248.7 | F26: 322.58065 | G26: 438.6 | H26: 161.29032 | I26: 0 | K26: 0 | M26: 0 | O26: 4.5 | P26: 1285.4839 | Q26: =SUM(C26+E26+G26+I26+K26+M26+O26) -> 11466.9 | R26: =SUM(D26+F26+H26+J26+L26+N26+P26) -> 5962.9032 | U26: =SUM(Q26+S26) -> 11466.9 | V26: =SUM(R26+T26) -> 5962.9032 | W26: sonnig | X26: 15 | Y26: °C
A27: KW | B27: =SUM(B19+1) -> 11 | C27: =SUM(C20:C26) -> 32672.4 | D27: =SUM(D20:D26) -> 29354.839 | E27: =SUM(E20:E26) -> 6759.8 | F27: =SUM(F20:F26) -> 2258.0645 | G27: =SUM(G20:G26) -> 894.8 | H27: =SUM(H20:H26) -> 1129.0322 | I27: =SUM(I20:I26) -> 0 | J27: =SUM(J20:J26) -> 0 | ... V27: =SUM(V20:V26) -> 41740.323 | W27: Ø Temp | X27: =SUM(X20:X26)/7 -> 11.571429 | Y27: °C
A28: =SUM(A26+1) -> 21 | B28: Mo | C28: 2626.3 | D28: 4193.5484 | E28: 748.8 | F28: 322.58065 | G28: 52.7 | H28: 161.29032 | I28: 0 | K28: 0 | M28: 0 | O28: 161.8 | P28: 1285.4839 | Q28: =SUM(C28+E28+G28+I28+K28+M28+O28) -> 3589.6 | R28: =SUM(D28+F28+H28+J28+L28+N28+P28) -> 5962.9032 | U28: =SUM(Q28+S28) -> 3589.6 | V28: =SUM(R28+T28) -> 5962.9032 | W28: sonnig | X28: 15 | Y28: °C
A29: =SUM(A28+1) -> 22 | B29: Di | C29: 4726.2 | D29: 4193.5484 | E29: 2011 | F29: 322.58065 | G29: 199.6 | H29: 161.29032 | I29: 0 | K29: 0 | M29: 0 | O29: 2259.2 | P29: 1285.4839 | Q29: =SUM(C29+E29+G29+I29+K29+M29+O29) -> 9196 | R29: =SUM(D29+F29+H29+J29+L29+N29+P29) -> 5962.9032 | U29: =SUM(Q29+S29) -> 9196 | V29: =SUM(R29+T29) -> 5962.9032 | W29: sonnig | X29: 17 | Y29: °C
A30: =SUM(A29+1) -> 23 | B30: Mi | C30: 4498.9 | D30: 4193.5484 | E30: 2995.2 | F30: 322.58065 | G30: 163.9 | H30: 161.29032 | I30: 0 | K30: 0 | M30: 0 | O30: 2641.6 | P30: 1285.4839 | Q30: =SUM(C30+E30+G30+I30+K30+M30+O30) -> 10299.6 | R30: =SUM(D30+F30+H30+J30+L30+N30+P30) -> 5962.9032 | U30: =SUM(Q30+S30) -> 10299.6 | V30: =SUM(R30+T30) -> 5962.9032 | W30: sonnig | X30: 17 | Y30: °C
A31: =SUM(A30+1) -> 24 | B31: Do | C31: 3989.4 | D31: 4193.5484 | E31: 1615.4 | F31: 322.58065 | G31: 368 | H31: 161.29032 | I31: 0 | K31: 0 | M31: 726.9 | O31: 1550.8 | P31: 1285.4839 | Q31: =SUM(C31+E31+G31+I31+K31+M31+O31) -> 8250.5 | R31: =SUM(D31+F31+H31+J31+L31+N31+P31) -> 5962.9032 | U31: =SUM(Q31+S31) -> 8250.5 | V31: =SUM(R31+T31) -> 5962.9032 | W31: sonnig | X31: 17 | Y31: °C
A32: =SUM(A31+1) -> 25 | B32: Fr | C32: 5606.4 | D32: 4193.5484 | E32: 3633.9 | F32: 322.58065 | G32: 148.5 | H32: 161.29032 | I32: 0 | K32: 0 | M32: 0 | O32: 2091.8 | P32: 1285.4839 | Q32: =SUM(C32+E32+G32+I32+K32+M32+O32) -> 11480.6 | R32: =SUM(D32+F32+H32+J32+L32+N32+P32) -> 5962.9032 | U32: =SUM(Q32+S32) -> 11480.6 | V32: =SUM(R32+T32) -> 5962.9032 | W32: sonnig | X32: 18 | Y32: °C
A33: =SUM(A32+1) -> 26 | B33: Sa | C33: 7382 | D33: 4193.5484 | E33: 6179.5 | F33: 322.58065 | G33: 258.5 | H33: 161.29032 | I33: 0 | K33: 262.9 | M33: 0 | O33: 3534.3 | P33: 1285.4839 | Q33: =SUM(C33+E33+G33+I33+K33+M33+O33) -> 17617.2 | R33: =SUM(D33+F33+H33+J33+L33+N33+P33) -> 5962.9032 | U33: =SUM(Q33+S33) -> 17617.2 | V33: =SUM(R33+T33) -> 5962.9032 | W33: sonnig | X33: 19 | Y33: °C
A34: =SUM(A33+1) -> 27 | B34: So | C34: 6886.7 | D34: 4193.5484 | E34: 10386.6 | F34: 322.58065 | G34: 1028.9 | H34: 161.29032 | I34: 0 | K34: 0 | M34: 0 | O34: 51.5 | P34: 1285.4839 | Q34: =SUM(C34+E34+G34+I34+K34+M34+O34) -> 18353.7 | R34: =SUM(D34+F34+H34+J34+L34+N34+P34) -> 5962.9032 | U34: =SUM(Q34+S34) -> 18353.7 | V34: =SUM(R34+T34) -> 5962.9032 | W34: sonnig | X34: 19 | Y34: °C
A35: KW | B35: =SUM(B27+1) -> 12 | C35: =SUM(C28:C34) -> 35715.9 | D35: =SUM(D28:D34) -> 29354.839 | E35: =SUM(E28:E34) -> 27570.4 | F35: =SUM(F28:F34) -> 2258.0645 | G35: =SUM(G28:G34) -> 2220.1 | H35: =SUM(H28:H34) -> 1129.0322 | I35: =SUM(I28:I34) -> 0 | J35: =SUM(J28:J34) -> 0 | ... V35: =SUM(V28:V34) -> 41740.323 | W35: Ø Temp | X35: =SUM(X28:X34)/7 -> 17.428571 | Y35: °C
A36: =SUM(A34+1) -> 28 | B36: Mo | C36: 2960.6 | D36: 4193.5484 | E36: 3826.4 | F36: 322.58065 | G36: 131.7 | H36: 161.29032 | I36: 0 | K36: 0 | M36: 0 | O36: 759 | P36: 1285.4839 | Q36: =SUM(C36+E36+G36+I36+K36+M36+O36) -> 7677.7 | R36: =SUM(D36+F36+H36+J36+L36+N36+P36) -> 5962.9032 | U36: =SUM(Q36+S36) -> 7677.7 | V36: =SUM(R36+T36) -> 5962.9032 | W36: sonnig | X36: 20 | Y36: °C
A37: =SUM(A36+1) -> 29 | B37: Di | C37: 3240.5 | D37: 4193.5484 | E37: 1457.7 | F37: 322.58065 | G37: 19.3 | H37: 161.29032 | I37: 0 | K37: 0 | M37: 0 | O37: 1138.1 | P37: 1285.4839 | Q37: =SUM(C37+E37+G37+I37+K37+M37+O37) -> 5855.6 | R37: =SUM(D37+F37+H37+J37+L37+N37+P37) -> 5962.9032 | U37: =SUM(Q37+S37) -> 5855.6 | V37: =SUM(R37+T37) -> 5962.9032 | W37: bewölkt | X37: 15 | Y37: °C
A38: =SUM(A37+1) -> 30 | B38: Mi | C38: 3146.3 | D38: 4193.5484 | E38: 20.8 | F38: 322.58065 | G38: 29 | H38: 161.29032 | I38: 0 | K38: 0 | M38: 0 | O38: 1084.8 | P38: 1285.4839 | Q38: =SUM(C38+E38+G38+I38+K38+M38+O38) -> 4280.9 | R38: =SUM(D38+F38+H38+J38+L38+N38+P38) -> 5962.9032 | U38: =SUM(Q38+S38) -> 4280.9 | V38: =SUM(R38+T38) -> 5962.9032 | W38: bewölkt | X38: 11 | Y38: °C
A39: =SUM(A38+1) -> 31 | B39: Do | C39: 4391.2 | D39: 4193.5484 | E39: 0 | F39: 322.58065 | G39: 0 | H39: 161.29032 | I39: 0 | K39: 0 | M39: 0 | O39: 95.75 | P39: 1285.4839 | Q39: =SUM(C39+E39+G39+I39+K39+M39+O39) -> 4486.95 | R39: =SUM(D39+F39+H39+J39+L39+N39+P39) -> 5962.9032 | U39: =SUM(Q39+S39) -> 4486.95 | V39: =SUM(R39+T39) -> 5962.9032 | W39: Regen | X39: 8 | Y39: °C
A40: KW | B40: =SUM(B35+1) -> 13 | C40: =SUM(C36:C39) -> 13738.6 | D40: =SUM(D36:D39) -> 16774.194 | E40: =SUM(E36:E39) -> 5304.9 | F40: =SUM(F36:F39) -> 1290.3226 | G40: =SUM(G36:G39) -> 180 | H40: =SUM(H36:H39) -> 645.16128 | I40: =SUM(I36:I39) -> 0 | J40: =SUM(J36:J39) -> 0 | ... V40: =SUM(V36:V39) -> 23851.613 | W40: Ø Temp | X40: =SUM(X36:X39)/4 -> 13.5 | Y40: °C
A41: Umsatz kumuliert | C41: =SUM(C11+C19+C27+C35+C40) -> 101290.4 | D41: =SUM(D11+D19+D27+D35+D40) -> 130000 | E41: =SUM(E11+E19+E27+E35+E40) -> 45490.9 | F41: =SUM(F11+F19+F27+F35+F40) -> 10000 | G41: =SUM(G11+G19+G27+G35+G40) -> 4076.5 | H41: =SUM(H11+H19+H27+H35+H40) -> 4999.9999 | I41: =SUM(I11+I19+I27+I40) -> 0 | J41: =SUM(J11+J19+J27+J40) -> 0 | K41: =SUM(K11+K19+K27+K35+K40) -> 262.9 | L41: =SUM(L11+L19+L27+L35+L40) -> 0 | M41: =SUM(M11+M19+M27+M35+M40) -> 726.9 | N41: =SUM(N11+N19+N27+N35+N40) -> 0 | O41: =SUM(O11+O19+O27+O35+O40) -> 24296.25 | P41: =SUM(P11+P19+P27+P35+P40) -> 39850 | Q41: =SUM(Q11+Q19+Q27+Q35+Q40) -> 176143.85 | R41: =SUM(R11+R19+R27+R35+R40) -> 184850 | ... V41: =SUM(V11+V19+V27+V35+V40) -> 184850 | W41: Umsatz kumuliert
...

Sheet 04_22
A1: Tagesumsätze | H1: 44652
C3: Restaurant | E3: Terrasse | G3: Lounge | I3: Pavillon | K3: Bankett | M3: Seminar | O3: Hotel | Q3: TOTAL Gesamtbetrieb ohne Seebad | S3: Seebad | U3: TOTAL Gesamtbetrieb mit Seebad | W3: Info's
C4: IST | D4: Budget | E4: IST | F4: Budget | G4: IST | H4: Budget | I4: IST | J4: Budget | K4: IST | L4: Budget | M4: IST | N4: Budget | O4: IST | P4: Budget | Q4: IST | R4: Budget | S4: IST | T4: Budget | U4: IST | V4: Budget | W4: Wetter | X4: Temp. | Z4: Bemerkung
A5: 1 | B5: Fr | C5: 5721.2 | D5: 5000 | E5: 0 | F5: 2666.6666 | G5: 0 | H5: 833.33333 | I5: 0 | K5: 0 | M5: 0 | O5: 840.8 | P5: 2656.6667 | Q5: =C5+E5+G5+I5+K5+M5+O5 -> 6562 | R5: =D5+F5+H5+J5+L5+N5+P5 -> 11156.667 | T5: 66.66666 | U5: =Q5+S5 -> 6562 | V5: =SUM(R5+T5) -> 11223.333 | W5: Schnee | X5: 0 | Y5: °C
A6: =SUM(A5+1) -> 2 | B6: Sa | C6: 8844.8 | D6: 5000 | E6: 0 | F6: 2666.6666 | G6: 0 | H6: 833.33333 | I6: 0 | K6: 0 | M6: 0 | O6: 1751.35 | P6: 2656.6667 | Q6: =C6+E6+G6+I6+K6+M6+O6 -> 10596.15 | R6: =D6+F6+H6+J6+L6+N6+P6 -> 11156.667 | T6: 66.66666 | U6: =SUM(Q6+S6) -> 10596.15 | V6: =SUM(R6+T6) -> 11223.333 | W6: Schnee | X6: 0 | Y6: °C
A7: =SUM(A6+1) -> 3 | B7: So | C7: 8688.4 | D7: 5000 | E7: 0 | F7: 2666.6666 | G7: 0 | H7: 833.33333 | I7: 0 | K7: 0 | M7: 0 | O7: 467.1 | P7: 2656.6667 | Q7: =C7+E7+G7+I7+K7+M7+O7 -> 9155.5 | R7: =D7+F7+H7+J7+L7+N7+P7 -> 11156.667 | T7: 66.66666 | U7: =SUM(Q7+S7) -> 9155.5 | V7: =SUM(R7+T7) -> 11223.333 | W7: Schnee | X7: 0 | Y7: °C
A8: KW | B8: 14 | C8: =SUM(C5:C7) -> 23254.4 | D8: =SUM(D5:D7) -> 15000 | E8: =SUM(E5:E7) -> 0 | F8: =SUM(F5:F7) -> 7999.9998 | G8: =SUM(G5:G7) -> 0 | H8: =SUM(H5:H7) -> 2500 | I8: =SUM(I5:I7) -> 0 | J8: =SUM(J5:J7) -> 0 | ... V8: =SUM(V5:V7) -> 33670 | W8: Ø Temp | X8: =SUM(X5:X7)/4 -> 0 | Y8: °C
A9: =SUM(A7+1) -> 4 | B9: Mo | C9: 3380.6 | D9: 5000 | E9: 0 | F9: 2666.6666 | G9: 0 | H9: 833.33333 | I9: 0 | K9: 0 | M9: 1048 | O9: 1469.2 | P9: 2656.6667 | Q9: =C9+E9+G9+I9+K9+M9+O9 -> 5897.8 | R9: =D9+F9+H9+J9+L9+N9+P9 -> 11156.667 | T9: 66.66666 | U9: =SUM(Q9+S9) -> 5897.8 | V9: =SUM(R9+T9) -> 11223.333 | W9: teilweise sonnig | X9: 11 | Y9: °C
A10: =SUM(A9+1) -> 5 | B10: Di | C10: 4103.8 | D10: 5000 | E10: 0 | F10: 2666.6666 | G10: 0 | H10: 833.33333 | I10: 0 | K10: 0 | M10: 0 | O10: 2738.4 | P10: 2656.6667 | Q10: =C10+E10+G10+I10+K10+M10+O10 -> 6842.2 | R10: =D10+F10+H10+J10+L10+N10+P10 -> 11156.667 | T10: 66.66666 | U10: =SUM(Q10+S10) -> 6842.2 | V10: =SUM(R10+T10) -> 11223.333 | W10: teilweise sonnig | X10: 12 | Y10: °C
A11: =SUM(A10+1) -> 6 | B11: Mi | C11: 4878.9 | D11: 5000 | E11: 9.8 | F11: 2666.6666 | G11: 0 | H11: 833.33333 | I11: 0 | K11: 0 | M11: 0 | O11: 3070 | P11: 2656.6667 | Q11: =C11+E11+G11+I11+K11+M11+O11 -> 7958.7 | R11: =D11+F11+H11+J11+L11+N11+P11 -> 11156.667 | T11: 66.66666 | U11: =SUM(Q11+S11) -> 7958.7 | V11: =SUM(R11+T11) -> 11223.333 | W11: teilweise sonnig | X11: 12 | Y11: °C
A12: =SUM(A11+1) -> 7 | B12: Do | C12: 2857.7 | D12: 5000 | E12: 0 | F12: 2666.6666 | G12: 0 | H12: 833.33333 | I12: 0 | K12: 0 | M12: 0 | O12: 1599 | P12: 2656.6667 | Q12: =C12+E12+G12+I12+K12+M12+O12 -> 4456.7 | R12: =D12+F12+H12+J12+L12+N12+P12 -> 11156.667 | T12: 66.66666 | U12: =SUM(Q12+S12) -> 4456.7 | V12: =SUM(R12+T12) -> 11223.333 | W12: Regen | X12: 8 | Y12: °C
A13: =SUM(A12+1) -> 8 | B13: Fr | C13: 5736.1 | D13: 5000 | E13: 0 | F13: 2666.6666 | G13: 0 | H13: 833.33333 | I13: 0 | K13: 0 | M13: 64.4 | O13: 2192 | P13: 2656.6667 | Q13: =C13+E13+G13+I13+K13+M13+O13 -> 7992.5 | R13: =D13+F13+H13+J13+L13+N13+P13 -> 11156.667 | T13: 66.66666 | U13: =SUM(Q13+S13) -> 7992.5 | V13: =SUM(R13+T13) -> 11223.333 | W13: Regen | X13: 8 | Y13: °C
A14: =SUM(A13+1) -> 9 | B14: Sa | C14: 6441.3 | D14: 5000 | E14: 47.2 | F14: 2666.6666 | G14: 153.8 | H14: 833.33333 | I14: 0 | K14: 0 | M14: 1955.3 | O14: 3765.9 | P14: 2656.6667 | Q14: =C14+E14+G14+I14+K14+M14+O14 -> 12363.5 | R14: =D14+F14+H14+J14+L14+N14+P14 -> 11156.667 | T14: 66.66666 | U14: =SUM(Q14+S14) -> 12363.5 | V14: =SUM(R14+T14) -> 11223.333 | W14: Schneeschauer | X14: 1 | Y14: °C
A15: =SUM(A14+1) -> 10 | B15: So | C15: 7217.4 | D15: 5000 | E15: 1849 | F15: 2666.6666 | G15: 586.5 | H15: 833.33333 | I15: 0 | K15: 0 | M15: 1766.8 | O15: 1073.9 | P15: 2656.6667 | Q15: =C15+E15+G15+I15+K15+M15+O15 -> 12493.6 | R15: =D15+F15+H15+J15+L15+N15+P15 -> 11156.667 | T15: 66.66666 | U15: =SUM(Q15+S15) -> 12493.6 | V15: =SUM(R15+T15) -> 11223.333 | W15: sonnig | X15: 11 | Y15: °C
A16: KW | B16: =SUM(B8+1) -> 15 | C16: =SUM(C9:C15) -> 34615.8 | D16: =SUM(D9:D15) -> 35000 | E16: =SUM(E9:E15) -> 1906 | F16: =SUM(F9:F15) -> 18666.666 | G16: =SUM(G9:G15) -> 740.3 | H16: =SUM(H9:H15) -> 5833.3333 | I16: =SUM(I9:I15) -> 0 | J16: =SUM(J9:J15) -> 0 | ... V16: =SUM(V9:V15) -> 78563.333 | W16: Ø Temp | X16: =SUM(X9:X15)/7 -> 9 | Y16: °C
A17: =SUM(A15+1) -> 11 | B17: Mo | C17: 3798.9 | D17: 5000 | E17: 737.8 | F17: 2666.6666 | G17: 275.4 | H17: 833.33333 | I17: 0 | K17: 0 | M17: 0 | O17: 2460 | P17: 2656.6667 | Q17: =C17+E17+G17+I17+K17+M17+O17 -> 7272.1 | R17: =D17+F17+H17+J17+L17+N17+P17 -> 11156.667 | T17: 66.66666 | U17: =SUM(Q17+S17) -> 7272.1 | V17: =SUM(R17+T17) -> 11223.333 | W17: sonnig | X17: 16 | Y17: °C
A18: =SUM(A17+1) -> 12 | B18: Di | C18: 4242.2 | D18: 5000 | E18: 1796.2 | F18: 2666.6666 | G18: 248.8 | H18: 833.33333 | I18: 0 | K18: 0 | M18: 0 | O18: 2303.3 | P18: 2656.6667 | Q18: =C18+E18+G18+I18+K18+M18+O18 -> 8590.5 | R18: =D18+F18+H18+J18+L18+N18+P18 -> 11156.667 | T18: 66.66666 | U18: =SUM(Q18+S18) -> 8590.5 | V18: =SUM(R18+T18) -> 11223.333 | W18: sonnig | X18: 20 | Y18: °C
A19: =SUM(A18+1) -> 13 | B19: Mi | C19: 3282.5 | D19: 5000 | E19: 4568.5 | F19: 2666.6666 | G19: 354.7 | H19: 833.33333 | I19: 0 | K19: 0 | M19: 0 | O19: 1041.6 | P19: 2656.6667 | Q19: =C19+E19+G19+I19+K19+M19+O19 -> 9247.3 | R19: =D19+F19+H19+J19+L19+N19+P19 -> 11156.667 | T19: 66.66666 | U19: =SUM(Q19+S19) -> 9247.3 | V19: =SUM(R19+T19) -> 11223.333 | W19: sonnig | X19: 17 | Y19: °C
A20: =SUM(A19+1) -> 14 | B20: Do | C20: 4782.5 | D20: 5000 | E20: 3972.6 | F20: 2666.6666 | G20: 433.6 | H20: 833.33333 | I20: 0 | K20: 0 | M20: 0 | O20: 1795.4 | P20: 2656.6667 | Q20: =C20+E20+G20+I20+K20+M20+O20 -> 10984.1 | R20: =D20+F20+H20+J20+L20+N20+P20 -> 11156.667 | T20: 66.66666 | U20: =SUM(Q20+S20) -> 10984.1 | V20: =SUM(R20+T20) -> 11223.333 | W20: sonnig | X20: 18 | Y20: °C
A21: =SUM(A20+1) -> 15 | B21: Fr | C21: 6682.4 | D21: 5000 | E21: 8108.3 | F21: 2666.6666 | G21: 786.6 | H21: 833.33333 | I21: 0 | K21: 0 | M21: 0 | O21: 4370.5 | P21: 2656.6667 | Q21: =C21+E21+G21+I21+K21+M21+O21 -> 19947.8 | R21: =D21+F21+H21+J21+L21+N21+P21 -> 11156.667 | T21: 66.66666 | U21: =SUM(Q21+S21) -> 19947.8 | V21: =SUM(R21+T21) -> 11223.333 | W21: sonnig | X21: 18 | Y21: °C | Z21: Karfreitag
A22: =SUM(A21+1) -> 16 | B22: Sa | C22: 7779.9 | D22: 5000 | E22: 1195.1 | F22: 2666.6666 | G22: 558.3 | H22: 833.33333 | I22: 0 | K22: 0 | M22: 0 | O22: 4730.1 | P22: 2656.6667 | Q22: =C22+E22+G22+I22+K22+M22+O22 -> 14263.4 | R22: =D22+F22+H22+J22+L22+N22+P22 -> 11156.667 | T22: 66.66666 | U22: =SUM(Q22+S22) -> 14263.4 | V22: =SUM(R22+T22) -> 11223.333 | W22: sonnig | X22: 18 | Y22: °C
A23: =SUM(A22+1) -> 17 | B23: So | C23: 8826.4 | D23: 5000 | E23: 7067.9 | F23: 2666.6666 | G23: 598.1 | H23: 833.33333 | I23: 0 | K23: 0 | M23: 0 | O23: 4352.8 | P23: 2656.6667 | Q23: =C23+E23+G23+I23+K23+M23+O23 -> 20845.2 | R23: =D23+F23+H23+J23+L23+N23+P23 -> 11156.667 | T23: 66.66666 | U23: =SUM(Q23+S23) -> 20845.2 | V23: =SUM(R23+T23) -> 11223.333 | W23: sonnig | X23: 13 | Y23: °C | Z23: Ostersonntag
A24: KW | B24: =SUM(B16+1) -> 16 | C24: =SUM(C17:C23) -> 39394.8 | D24: =SUM(D17:D23) -> 35000 | E24: =SUM(E17:E23) -> 27446.4 | F24: =SUM(F17:F23) -> 18666.666 | G24: =SUM(G17:G23) -> 3255.5 | H24: =SUM(H17:H23) -> 5833.3333 | I24: =SUM(I17:I23) -> 0 | J24: =SUM(J17:J23) -> 0 | ... V24: =SUM(V17:V23) -> 78563.333 | W24: Ø Temp | X24: =SUM(X17:X23)/7 -> 17.142857 | Y24: °C
A25: =SUM(A23+1) -> 18 | B25: Mo | C25: 6729.3 | D25: 5000 | E25: 11959.9 | F25: 2666.6666 | G25: 1068.1 | H25: 833.33333 | I25: 0 | K25: 0 | M25: 0 | O25: 1089.6 | P25: 2656.6667 | Q25: =C25+E25+G25+I25+K25+M25+O25 -> 20846.9 | R25: =D25+F25+H25+J25+L25+N25+P25 -> 11156.667 | T25: 66.66666 | U25: =SUM(Q25+S25) -> 20846.9 | V25: =SUM(R25+T25) -> 11223.333 | W25: sonnig | X25: 18 | Y25: °C | Z25: Ostermontag
A26: =SUM(A25+1) -> 19 | B26: Di | C26: 3541 | D26: 5000 | E26: 3420.3 | F26: 2666.6666 | G26: 353 | H26: 833.33333 | I26: 0 | K26: 0 | M26: 0 | O26: 1531.6 | P26: 2656.6667 | Q26: =C26+E26+G26+I26+K26+M26+O26 -> 8845.9 | R26: =D26+F26+H26+J26+L26+N26+P26 -> 11156.667 | T26: 66.66666 | U26: =SUM(Q26+S26) -> 8845.9 | V26: =SUM(R26+T26) -> 11223.333 | W26: sonnig | X26: 13 | Y26: °C
A27: =SUM(A26+1) -> 20 | B27: Mi | C27: 3465.7 | D27: 5000 | E27: 2729.3 | F27: 2666.6666 | G27: 554.6 | H27: 833.33333 | I27: 0 | K27: 0 | M27: 0 | O27: 1582.1 | P27: 2656.6667 | Q27: =C27+E27+G27+I27+K27+M27+O27 -> 8331.7 | R27: =D27+F27+H27+J27+L27+N27+P27 -> 11156.667 | T27: 66.66666 | U27: =SUM(Q27+S27) -> 8331.7 | V27: =SUM(R27+T27) -> 11223.333 | W27: sonnig | X27: 17 | Y27: °C
A28: =SUM(A27+1) -> 21 | B28: Do | C28: 2449.6 | D28: 5000 | E28: 4599.7 | F28: 2666.6666 | G28: 326.9 | H28: 833.33333 | I28: 0 | K28: 0 | M28: 0 | O28: 1072.6 | P28: 2656.6667 | Q28: =C28+E28+G28+I28+K28+M28+O28 -> 8448.8 | R28: =D28+F28+H28+J28+L28+N28+P28 -> 11156.667 | T28: 66.66666 | U28: =SUM(Q28+S28) -> 8448.8 | V28: =SUM(R28+T28) -> 11223.333 | W28: sonnig | X28: 17 | Y28: °C
A29: =SUM(A28+1) -> 22 | B29: Fr | C29: 5631.8 | D29: 5000 | E29: 4924 | F29: 2666.6666 | G29: 457.8 | H29: 833.33333 | I29: 0 | K29: 0 | M29: 0 | O29: 1854.5 | P29: 2656.6667 | Q29: =C29+E29+G29+I29+K29+M29+O29 -> 12868.1 | R29: =D29+F29+H29+J29+L29+N29+P29 -> 11156.667 | T29: 66.66666 | U29: =SUM(Q29+S29) -> 12868.1 | V29: =SUM(R29+T29) -> 11223.333 | W29: sonnig | X29: 16 | Y29: °C
A30: =SUM(A29+1) -> 23 | B30: Sa | C30: 7316.5 | D30: 5000 | E30: 1069.4 | F30: 2666.6666 | G30: 172.6 | H30: 833.33333 | I30: 0 | K30: 0 | M30: 0 | O30: 2248.6 | P30: 2656.6667 | Q30: =C30+E30+G30+I30+K30+M30+O30 -> 10807.1 | R30: =D30+F30+H30+J30+L30+N30+P30 -> 11156.667 | T30: 66.66666 | U30: =SUM(Q30+S30) -> 10807.1 | V30: =SUM(R30+T30) -> 11223.333 | W30: bewölkt | X30: 15 | Y30: °C
A31: =SUM(A30+1) -> 24 | B31: So | C31: 7882.4 | D31: 5000 | E31: 0 | F31: 2666.6666 | G31: 33.9 | H31: 833.33333 | I31: 0 | K31: 0 | M31: 0 | O31: 1788.4 | P31: 2656.6667 | Q31: =C31+E31+G31+I31+K31+M31+O31 -> 9704.7 | R31: =D31+F31+H31+J31+L31+N31+P31 -> 11156.667 | T31: 66.66666 | U31: =SUM(Q31+S31) -> 9704.7 | V31: =SUM(R31+T31) -> 11223.333 | W31: bewölkt | X31: 13 | Y31: °C
A32: KW | B32: =SUM(B24+1) -> 17 | C32: =SUM(C25:C31) -> 37016.3 | D32: =SUM(D25:D31) -> 35000 | E32: =SUM(E25:E31) -> 28702.6 | F32: =SUM(F25:F31) -> 18666.666 | G32: =SUM(G25:G31) -> 2966.9 | H32: =SUM(H25:H31) -> 5833.3333 | I32: =SUM(I25:I31) -> 0 | J32: =SUM(J25:J31) -> 0 | ... V32: =SUM(V25:V31) -> 78563.333 | W32: Ø Temp | X32: =SUM(X25:X31)/7 -> 15.571429 | Y32: °C
A33: =SUM(A31+1) -> 25 | B33: Mo | C33: 5437.2 | D33: 5000 | E33: 197.5 | F33: 2666.6666 | G33: 0 | H33: 833.33333 | I33: 0 | K33: 0 | M33: 0 | O33: 2531.3 | P33: 2656.6667 | Q33: =C33+E33+G33+I33+K33+M33+O33 -> 8166 | R33: =D33+F33+H33+J33+L33+N33+P33 -> 11156.667 | T33: 66.66666 | U33: =SUM(Q33+S33) -> 8166 | V33: =SUM(R33+T33) -> 11223.333 | W33: bewölkt | X33: 13 | Y33: °C | Z33: Gastronovi/Mews
A34: =SUM(A33+1) -> 26 | B34: Di | C34: 5564.5 | D34: 5000 | E34: 4.8 | F34: 2666.6666 | G34: 15 | H34: 833.33333 | I34: 0 | K34: 12 | M34: 0 | O34: 2546.5 | P34: 2656.6667 | Q34: =C34+E34+G34+I34+K34+M34+O34 -> 8142.8 | R34: =D34+F34+H34+J34+L34+N34+P34 -> 11156.667 | T34: 66.66666 | U34: =SUM(Q34+S34) -> 8142.8 | V34: =SUM(R34+T34) -> 11223.333 | W34: bewölkt | X34: 13 | Y34: °C | Z34: Gastronovi/Mews
A35: =SUM(A34+1) -> 27 | B35: Mi | C35: 5217.7 | D35: 5000 | E35: 1951 | F35: 2666.6666 | G35: 116.5 | H35: 833.33333 | I35: 0 | K35: 0 | M35: 0 | O35: 2898.8 | P35: 2656.6667 | Q35: =C35+E35+G35+I35+K35+M35+O35 -> 10184 | R35: =D35+F35+H35+J35+L35+N35+P35 -> 11156.667 | T35: 66.66666 | U35: =SUM(Q35+S35) -> 10184 | V35: =SUM(R35+T35) -> 11223.333 | W35: teilweise sonnig | X35: 16 | Y35: °C | Z35: Gastronovi/Mews
A36: =SUM(A35+1) -> 28 | B36: Do | C36: 4153.7 | D36: 5000 | E36: 7937.6 | F36: 2666.6666 | G36: 303.5 | H36: 833.33333 | I36: 0 | K36: 0 | M36: 13 | O36: 2568.9 | P36: 2656.6667 | Q36: =C36+E36+G36+I36+K36+M36+O36 -> 14976.7 | R36: =D36+F36+H36+J36+L36+N36+P36 -> 11156.667 | T36: 66.66666 | U36: =SUM(Q36+S36) -> 14976.7 | V36: =SUM(R36+T36) -> 11223.333 | W36: sonnig | X36: 18 | Y36: °C | Z36: Gastronovi/Mews
A37: =SUM(A36+1) -> 29 | B37: Fr | C37: 4157.3 | D37: 5000 | E37: 4163.1 | F37: 2666.6666 | G37: 571.3 | H37: 833.33333 | I37: 0 | K37: 0 | M37: 0 | O37: 2790.2 | P37: 2656.6667 | Q37: =C37+E37+G37+I37+K37+M37+O37 -> 11681.9 | R37: =D37+F37+H37+J37+L37+N37+P37 -> 11156.667 | T37: 66.66666 | U37: =SUM(Q37+S37) -> 11681.9 | V37: =SUM(R37+T37) -> 11223.333 | W37: sonnig | X37: 20 | Y37: °C | Z37: Gastronovi/Mews
A38: 30 | B38: Sa | C38: 6759.7 | D38: 5000 | E38: 2477.7 | F38: 2666.6666 | G38: 381.9 | H38: 833.33333 | I38: 0 | K38: 1642.3 | M38: 0 | O38: 3644.7 | P38: 2656.6667 | Q38: =C38+E38+G38+I38+K38+M38+O38 -> 14906.3 | R38: =D38+F38+H38+J38+L38+N38+P38 -> 11156.667 | T38: 66.66666 | U38: =SUM(Q38+S38) -> 14906.3 | V38: =SUM(R38+T38) -> 11223.333 | W38: veränderlich | X38: 15 | Y38: °C | Z38: Gastronovi/Mews
A39: KW | B39: =SUM(B32+1) -> 18 | C39: =SUM(C33:C38) -> 31290.1 | D39: =SUM(D33:D38) -> 30000 | E39: =SUM(E33:E38) -> 16731.7 | F39: =SUM(F33:F38) -> 16000 | G39: =SUM(G33:G38) -> 1388.2 | H39: =SUM(H33:H38) -> 5000 | I39: =SUM(I33:I38) -> 0 | J39: =SUM(J33:J38) -> 0 | ... V39: =SUM(V33:V38) -> 67340 | W39: Ø Temp | X39: =SUM(X33:X38)/5 -> 19 | Y39: °C
A40: Umsatz kumuliert | C40: =SUM(C8+C16+C24+C32+C39) -> 165571.4 | D40: =SUM(D8+D16+D24+D32+D39) -> 150000 | E40: =SUM(E8+E16+E24+E32+E39) -> 74786.7 | F40: =SUM(F8+F16+F24+F32+F39) -> 79999.998 | G40: =SUM(G8+G16+G24+G32+G39) -> 8350.9 | H40: =SUM(H8+H16+H24+H32+H39) -> 25000 | I40: =SUM(I8+I16+I24+I32+I39) -> 0 | J40: =SUM(J8+J16+J24+J32+J39) -> 0 | ... V40: =SUM(V8+V16+V24+V32+V39) -> 336700 | W40: Umsatz kumuliert
A41: Umsatz pro Tag | C41: =C40/30 -> 5519.0467 | D41: =D40/30 -> 5000 | E41: =E40/30 -> 2492.89 | F41: =F40/30 -> 2666.6666 | G41: =G40/30 -> 278.36333 | H41: =H40/30 -> 833.33333 | I41: =I40/30 -> 0 | J41: =J40/30 -> 0 | ... V41: =V40/30 -> 11223.333 | W41: Budget pro Tag
...

Sheet 05_22
A1: Tagesumsätze | H1: 44682
C3: Restaurant | E3: Terrasse | G3: Lounge | I3: Pavillon | K3: Bankett | M3: Seminar | O3: Hotel | Q3: TOTAL Gesamtbetrieb ohne Seebad | S3: Seebad | U3: TOTAL Gesamtbetrieb mit Seebad | W3: Info's
C4: IST | D4: Budget | E4: IST | F4: Budget | G4: IST | H4: Budget | I4: IST | J4: Budget | K4: IST | L4: Budget | M4: IST | N4: Budget | O4: IST | P4: Budget | Q4: IST | R4: Budget | S4: IST | T4: Budget | U4: IST | V4: Budget | W4: Wetter | X4: Temp. | Z4: Bemerkung
A5: 1 | B5: So | C5: 7708.4 | D5: 3709.6774 | E5: 4619.5 | F5: 6129.0323 | G5: 822 | H5: 1129.0322 | I5: 0 | J5: 387.09677 | K5: 0 | L5: 3548.3871 | M5: 0 | N5: 1354.8387 | O5: 1910.1 | P5: 5366.9355 | Q5: =SUM(C5+E5+G5+I5+K5+M5+O5) -> 15060 | R5: =SUM(D5+F5+H5+J5+L5+N5+P5) -> 21625 | T5: 967.74194 | U5: =SUM(Q5+S5) -> 15060 | V5: =SUM(R5+T5) -> 22592.742 | W5: sonnig | X5: 18 | Y5: °C
A6: KW | B6: 18 | C6: =SUM(C5:C5) -> 7708.4 | D6: =SUM(D5:D5) -> 3709.6774 | E6: =SUM(E5:E5) -> 4619.5 | F6: =SUM(F5:F5) -> 6129.0323 | G6: =SUM(G5:G5) -> 822 | H6: =SUM(H5:H5) -> 1129.0322 | I6: =SUM(I5:I5) -> 0 | J6: =SUM(J5:J5) -> 387.09677 | ... V6: =SUM(V5:V5) -> 22592.742 | W6: Ø Temp | X6: =SUM(X5:X5)/2 -> 9 | Y6: °C
A7: =SUM(A5+1) -> 2 | B7: Mo | C7: 1826.7 | D7: 3709.6774 | E7: 2752.5 | F7: 6129.0323 | G7: 265.6 | H7: 1129.0322 | I7: 0 | J7: 387.09677 | K7: 0 | L7: 3548.3871 | M7: 0 | N7: 1354.8387 | O7: 2316.8 | P7: 5366.9355 | Q7: =SUM(C7+E7+G7+I7+K7+M7+O7) -> 7161.6 | R7: =SUM(D7+F7+H7+J7+L7+N7+P7) -> 21625 | S7: 0 | T7: 967.74194 | U7: =SUM(Q7+S7) -> 7161.6 | V7: =SUM(R7+T7) -> 22592.742 | W7: sonnig | X7: 18 | Y7: °C
A8: =SUM(A7+1) -> 3 | B8: Di | C8: 4973.8 | D8: 3709.6774 | E8: 1579.1 | F8: 6129.0323 | G8: 132.1 | H8: 1129.0322 | I8: 0 | J8: 387.09677 | K8: 0 | L8: 3548.3871 | M8: 0 | N8: 1354.8387 | O8: 1846.9 | P8: 5366.9355 | Q8: =SUM(C8+E8+G8+I8+K8+M8+O8) -> 8531.9 | R8: =SUM(D8+F8+H8+J8+L8+N8+P8) -> 21625 | S8: 0 | T8: 967.74194 | U8: =SUM(Q8+S8) -> 8531.9 | V8: =SUM(R8+T8) -> 22592.742 | W8: bewölkt | X8: 18 | Y8: °C
A9: =SUM(A8+1) -> 4 | B9: Mi | C9: 4779.5 | D9: 3709.6774 | E9: 1125.1 | F9: 6129.0323 | G9: 250.8 | H9: 1129.0322 | I9: 0 | J9: 387.09677 | K9: 0 | L9: 3548.3871 | M9: 290.1 | N9: 1354.8387 | O9: 2325.9 | P9: 5366.9355 | Q9: =SUM(C9+E9+G9+I9+K9+M9+O9) -> 8771.4 | R9: =SUM(D9+F9+H9+J9+L9+N9+P9) -> 21625 | S9: 0 | T9: 967.74194 | U9: =SUM(Q9+S9) -> 8771.4 | V9: =SUM(R9+T9) -> 22592.742 | Y9: °C
A10: =SUM(A9+1) -> 5 | B10: Do | C10: 4150.9 | D10: 3709.6774 | E10: 0 | F10: 6129.0323 | G10: 0 | H10: 1129.0322 | I10: 0 | J10: 387.09677 | K10: 1560.5 | L10: 3548.3871 | M10: 152.5 | N10: 1354.8387 | O10: 3327.6 | P10: 5366.9355 | Q10: =SUM(C10+E10+G10+I10+K10+M10+O10) -> 9191.5 | R10: =SUM(D10+F10+H10+J10+L10+N10+P10) -> 21625 | S10: 0 | T10: 967.74194 | U10: =SUM(Q10+S10) -> 9191.5 | V10: =SUM(R10+T10) -> 22592.742 | Y10: °C
A11: =SUM(A10+1) -> 6 | B11: Fr | C11: 6448.6 | D11: 3709.6774 | E11: 187.4 | F11: 6129.0323 | G11: 64 | H11: 1129.0322 | I11: 0 | J11: 387.09677 | K11: 20779.5 | L11: 3548.3871 | M11: 2319.9 | N11: 1354.8387 | O11: 5834.2 | P11: 5366.9355 | Q11: =SUM(C11+E11+G11+I11+K11+M11+O11) -> 35633.6 | R11: =SUM(D11+F11+H11+J11+L11+N11+P11) -> 21625 | S11: 0 | T11: 967.74194 | U11: =SUM(Q11+S11) -> 35633.6 | V11: =SUM(R11+T11) -> 22592.742 | Y11: °C | Z11: Inbetriebnahme Erweiterungsbau
A12: =SUM(A11+1) -> 7 | B12: Sa | C12: 11008.5 | D12: 3709.6774 | E12: 325.7 | F12: 6129.0323 | G12: 534.1 | H12: 1129.0322 | I12: 2876 | J12: 387.09677 | K12: 6598.7 | L12: 3548.3871 | M12: 0 | N12: 1354.8387 | O12: 3884.8 | P12: 5366.9355 | Q12: =SUM(C12+E12+G12+I12+K12+M12+O12) -> 25227.8 | R12: =SUM(D12+F12+H12+J12+L12+N12+P12) -> 21625 | S12: 0 | T12: 967.74194 | U12: =SUM(Q12+S12) -> 25227.8 | V12: =SUM(R12+T12) -> 22592.742 | Y12: °C
A13: =SUM(A12+1) -> 8 | B13: So | C13: 18314.8 | D13: 3709.6774 | E13: 1889.7 | F13: 6129.0323 | G13: 283.6 | H13: 1129.0322 | I13: 0 | J13: 387.09677 | K13: 5559.7 | L13: 3548.3871 | M13: 0 | N13: 1354.8387 | O13: 1165.8 | P13: 5366.9355 | Q13: =SUM(C13+E13+G13+I13+K13+M13+O13) -> 27213.6 | R13: =SUM(D13+F13+H13+J13+L13+N13+P13) -> 21625 | S13: 1110.6 | T13: 967.74194 | U13: =SUM(Q13+S13) -> 28324.2 | V13: =SUM(R13+T13) -> 22592.742 | Y13: °C | Z13: Muttertag
A14: KW | B14: =SUM(B6+1) -> 19 | C14: =SUM(C7:C13) -> 51502.8 | D14: =SUM(D7:D13) -> 25967.742 | E14: =SUM(E7:E13) -> 7859.5 | F14: =SUM(F7:F13) -> 42903.226 | G14: =SUM(G7:G13) -> 1530.2 | H14: =SUM(H7:H13) -> 7903.2258 | I14: =SUM(I7:I13) -> 2876 | J14: =SUM(J7:J13) -> 2709.6774 | ... V14: =SUM(V7:V13) -> 158149.19 | W14: Ø Temp | X14: =SUM(X7:X13)/7 -> 5.1428571 | Y14: °C
A15: =SUM(A13+1) -> 9 | B15: Mo | C15: 2654.5 | D15: 3709.6774 | E15: 5141.6 | F15: 6129.0323 | G15: 568.4 | H15: 1129.0322 | I15: 0 | J15: 387.09677 | K15: 0 | L15: 3548.3871 | M15: 0 | N15: 1354.8387 | O15: 4006.8 | P15: 5366.9355 | Q15: =SUM(C15+E15+G15+I15+K15+M15+O15) -> 12371.3 | R15: =SUM(D15+F15+H15+J15+L15+N15+P15) -> 21625 | S15: 474.5 | T15: 967.74194 | U15: =SUM(Q15+S15) -> 12845.8 | V15: =SUM(R15+T15) -> 22592.742 | Y15: °C
A16: =SUM(A15+1) -> 10 | B16: Di | C16: 2660 | D16: 3709.6774 | E16: 6834.9 | F16: 6129.0323 | G16: 591.5 | H16: 1129.0322 | I16: 0 | J16: 387.09677 | K16: 0 | L16: 3548.3871 | M16: 6252.6 | N16: 1354.8387 | O16: 3392 | P16: 5366.9355 | Q16: =SUM(C16+E16+G16+I16+K16+M16+O16) -> 19731 | R16: =SUM(D16+F16+H16+J16+L16+N16+P16) -> 21625 | S16: 1081 | T16: 967.74194 | U16: =SUM(Q16+S16) -> 20812 | V16: =SUM(R16+T16) -> 22592.742 | Y16: °C
A17: =SUM(A16+1) -> 11 | B17: Mi | C17: 679.5 | D17: 3709.6774 | E17: 10241 | F17: 6129.0323 | G17: 698.9 | H17: 1129.0322 | I17: 0 | J17: 387.09677 | K17: 7181.4 | L17: 3548.3871 | M17: 2267.1 | N17: 1354.8387 | O17: 3802.5 | P17: 5366.9355 | Q17: =SUM(C17+E17+G17+I17+K17+M17+O17) -> 24870.4 | R17: =SUM(D17+F17+H17+J17+L17+N17+P17) -> 21625 | S17: 2963.5 | T17: 967.74194 | U17: =SUM(Q17+S17) -> 27833.9 | V17: =SUM(R17+T17) -> 22592.742 | Y17: °C
A18: =SUM(A17+1) -> 12 | B18: Do | C18: 2936.1 | D18: 3709.6774 | E18: 5912.2 | F18: 6129.0323 | G18: 326.7 | H18: 1129.0322 | I18: 0 | J18: 387.09677 | K18: 0 | L18: 3548.3871 | M18: 2429.8 | N18: 1354.8387 | O18: 2881 | P18: 5366.9355 | Q18: =SUM(C18+E18+G18+I18+K18+M18+O18) -> 14485.8 | R18: =SUM(D18+F18+H18+J18+L18+N18+P18) -> 21625 | S18: 699.6 | T18: 967.74194 | U18: =SUM(Q18+S18) -> 15185.4 | V18: =SUM(R18+T18) -> 22592.742 | Y18: °C
A19: =SUM(A18+1) -> 13 | B19: Fr | C19: 7230.7 | D19: 3709.6774 | E19: 4108 | F19: 6129.0323 | G19: 322.5 | H19: 1129.0322 | I19: 1132 | J19: 387.09677 | K19: 12807.2 | L19: 3548.3871 | M19: 0 | N19: 1354.8387 | O19: 3821.1 | P19: 5366.9355 | Q19: =SUM(C19+E19+G19+I19+K19+M19+O19) -> 29421.5 | R19: =SUM(D19+F19+H19+J19+L19+N19+P19) -> 21625 | S19: 0 | T19: 967.74194 | U19: =SUM(Q19+S19) -> 29421.5 | V19: =SUM(R19+T19) -> 22592.742 | Y19: °C
