Workbook

Sheet 01_24
A1: Tagesumsätze | H1: 45292
C3: Restaurant | E3: Terrasse | G3: Lounge | I3: Pavillon | M3: Bankett | Q3: Seminar | U3: Hotel | W3: TOTAL Gesamtbetrieb ohne Seebad | Y3: Seebad | AA3: TOTAL Gesamtbetrieb mit Seebad | AC3: Info's | AH3: Gegenkontrolle Gastronovi
C4: IST | D4: Budget | E4: IST | F4: Budget | G4: IST | H4: Budget | I4: IST/GN | J4: IST/ET | K4: TOTAL IST | L4: Budget | M4: IST/GN | N4: IST/ET | O4: TOTAL IST | P4: Budget | Q4: IST/GN | R4: IST/ET | S4: TOTAL IST | T4: Budget | U4: TOTAL IST | V4: Budget | W4: IST | X4: Budget | Y4: IST | Z4: Budget | AA4: IST | AB4: Budget | AC4: Wetter | AD4: Temp. | AF4: Bemerkung
A5: 1 | B5: Mo | C5: 9138.9 | D5: 6451.6129 | E5: 0 | F5: 80.64516 | G5: 0 | H5: 32.25806 | I5: 0 | J5: 0 | K5: =I5+J5 -> 0 | M5: =0 -> 0 | N5: 0 | O5: =M5+N5 -> 0 | P5: 1935.4839 | Q5: 0 | R5: 0 | S5: =Q5+R5 -> 0 | T5: 2258.0645 | U5: 3768.51 | V5: 3116.129 | W5: =SUM(C5+E5+G5+K5+O5+S5+U5) -> 12907.41 | X5: =SUM(D5+F5+H5+L5+P5+T5+V5) -> 13874.194 | Y5: 0 | AA5: =SUM(W5+Y5) -> 12907.41 | AB5: =SUM(X5+Z5) -> 13874.194 | AC5: bedeckt, teilweise sonnig | AD5: 8 | AE5: °C | AF5: Neujahr | AH5: =C5+E5+G5+I5+M5+Q5+Y5 -> 9138.9
A6: =SUM(A5+1) -> 2 | B6: Di | C6: 11308.66 | D6: 6451.6129 | E6: 0 | F6: 80.64516 | G6: 0 | H6: 32.25806 | I6: 0 | K6: =I6+J6 -> 0 | M6: 0 | N6: 0 | O6: =M6+N6 -> 0 | P6: 1935.4839 | Q6: 0 | R6: 0 | S6: =Q6+R6 -> 0 | T6: 2258.0645 | U6: 1885.4 | V6: 3116.129 | W6: =SUM(C6+E6+G6+K6+O6+S6+U6) -> 13194.06 | X6: =SUM(D6+F6+H6+L6+P6+T6+V6) -> 13874.194 | Y6: 0 | AA6: =SUM(W6+Y6) -> 13194.06 | AB6: =SUM(X6+Z6) -> 13874.194 | AC6: leichter Regenschauer | AD6: 7 | AE6: °C | AF6: Berchtoldstag | AH6: =C6+E6+G6+I6+M6+Q6+Y6 -> 11308.66
A7: =SUM(A6+1) -> 3 | B7: Mi | C7: 4284.8 | D7: 6451.6129 | E7: 30 | F7: 80.64516 | G7: 77.8 | H7: 32.25806 | I7: 0 | K7: =I7+J7 -> 0 | M7: 0 | N7: 0 | O7: =M7+N7 -> 0 | P7: 1935.4839 | Q7: 0 | R7: 0 | S7: =Q7+R7 -> 0 | T7: 2258.0645 | U7: 1433.8 | V7: 3116.129 | W7: =SUM(C7+E7+G7+K7+O7+S7+U7) -> 5826.4 | X7: =SUM(D7+F7+H7+L7+P7+T7+V7) -> 13874.194 | Y7: 0 | AA7: =SUM(W7+Y7) -> 5826.4 | AB7: =SUM(X7+Z7) -> 13874.194 | AC7: bedeckt, windig | AD7: 12 | AE7: °C | AH7: =C7+E7+G7+I7+M7+Q7+Y7 -> 4392.6
A8: =SUM(A7+1) -> 4 | B8: Do | C8: 6025 | D8: 6451.6129 | E8: 177.9 | F8: 80.64516 | G8: 155.5 | H8: 32.25806 | I8: 0 | K8: =I8+J8 -> 0 | M8: 7642.8 | N8: 0 | O8: =M8+N8 -> 7642.8 | P8: 1935.4839 | Q8: 1095.9 | R8: 1664 | S8: =Q8+R8 -> 2759.9 | T8: 2258.0645 | U8: 2334.5 | V8: 3116.129 | W8: =SUM(C8+E8+G8+K8+O8+S8+U8) -> 19095.6 | X8: =SUM(D8+F8+H8+L8+P8+T8+V8) -> 13874.194 | Y8: 0 | AA8: =SUM(W8+Y8) -> 19095.6 | AB8: =SUM(X8+Z8) -> 13874.194 | AC8: bewölkt, Regenschauer | AD8: 9 | AE8: °C | AH8: =C8+E8+G8+I8+M8+Q8+Y8 -> 15097.1
A9: =SUM(A8+1) -> 5 | B9: Fr | C9: 6459.9 | D9: 6451.6129 | E9: 0 | F9: 80.64516 | G9: 0 | H9: 32.25806 | I9: 0 | K9: =I9+J9 -> 0 | M9: 2093.3 | N9: 0 | O9: =M9+N9 -> 2093.3 | P9: 1935.4839 | Q9: 46.6 | R9: 1140 | S9: =Q9+R9 -> 1186.6 | T9: 2258.0645 | U9: 2787.9 | V9: 3116.129 | W9: =SUM(C9+E9+G9+K9+O9+S9+U9) -> 12527.7 | X9: =SUM(D9+F9+H9+L9+P9+T9+V9) -> 13874.194 | Y9: 0 | AA9: =SUM(W9+Y9) -> 12527.7 | AB9: =SUM(X9+Z9) -> 13874.194 | AC9: leichter Regenschauer | AD9: 6 | AE9: °C | AH9: =C9+E9+G9+I9+M9+Q9+Y9 -> 8599.8
A10: =SUM(A9+1) -> 6 | B10: Sa | C10: 10408.6 | D10: 6451.6129 | E10: 0 | F10: 80.64516 | G10: 0 | H10: 32.25806 | I10: 0 | K10: =I10+J10 -> 0 | M10: 0 | N10: 0 | O10: =M10+N10 -> 0 | P10: 1935.4839 | Q10: 4319.6 | R10: 0 | S10: =Q10+R10 -> 4319.6 | T10: 2258.0645 | U10: 3488.2 | V10: 3116.129 | W10: =SUM(C10+E10+G10+K10+O10+S10+U10) -> 18216.4 | X10: =SUM(D10+F10+H10+L10+P10+T10+V10) -> 13874.194 | Y10: 0 | AA10: =SUM(W10+Y10) -> 18216.4 | AB10: =SUM(X10+Z10) -> 13874.194 | AC10: leichter Regenschauer | AD10: 2 | AE10: °C | AH10: =C10+E10+G10+I10+M10+Q10+Y10 -> 14728.2
A11: =SUM(A10+1) -> 7 | B11: So | C11: 3362 | D11: 6451.6129 | E11: 0 | F11: 80.64516 | G11: 0 | H11: 32.25806 | I11: 0 | K11: =I11+J11 -> 0 | M11: 0 | N11: 0 | O11: =M11+N11 -> 0 | P11: 1935.4839 | Q11: 0 | R11: 0 | S11: =Q11+R11 -> 0 | T11: 2258.0645 | U11: 1239.6 | V11: 3116.129 | W11: =SUM(C11+E11+G11+K11+O11+S11+U11) -> 4601.6 | X11: =SUM(D11+F11+H11+L11+P11+T11+V11) -> 13874.194 | Y11: 0 | AA11: =SUM(W11+Y11) -> 4601.6 | AB11: =SUM(X11+Z11) -> 13874.194 | AC11: Regen | AD11: 1 | AE11: °C | AF11: MA Feier ab 15:00 geschlossen | AH11: =C11+E11+G11+I11+M11+Q11+Y11 -> 3362
A12: KW | B12: 1 | C12: =SUM(C5:C11) -> 50987.86 | D12: =SUM(D5:D11) -> 45161.29 | E12: =SUM(E5:E11) -> 207.9 | F12: =SUM(F5:F11) -> 564.51612 | G12: =SUM(G5:G11) -> 233.3 | H12: =SUM(H5:H11) -> 225.80642 | I12: =SUM(I5:I11) -> 0 | J12: =SUM(J5:J11) -> 0 | K12: =SUM(K5:K11) -> 0 | L12: 0 | M12: =SUM(M5:M11) -> 9736.1 | N12: =SUM(N5:N11) -> 0 | O12: =SUM(O5:O11) -> 9736.1 | P12: =SUM(P5:P11) -> 13548.387 | Q12: =SUM(Q5:Q11) -> 5462.1 | R12: =SUM(R5:R11) -> 2804 | S12: =SUM(S5:S11) -> 8266.1 | T12: =SUM(T5:T11) -> 15806.452 | ... AB12: =SUM(AB5:AB11) -> 97119.355 | AC12: Ø Temp | AD12: =SUM(AD5:AD11)/7 -> 6.4285714 | AE12: °C
A13: =SUM(A11+1) -> 8 | B13: Mo | C13: 2627.5 | D13: 6451.6129 | E13: 0 | F13: 80.64516 | G13: 0 | H13: 32.25806 | I13: 0 | K13: =I13+J13 -> 0 | M13: 1264.8 | N13: 0 | O13: =M13+N13 -> 1264.8 | P13: 1935.4839 | Q13: 10.6 | R13: 1351 | S13: =Q13+R13 -> 1361.6 | T13: 2258.0645 | U13: 1568.85 | V13: 3116.129 | W13: =SUM(C13+E13+G13+K13+O13+S13+U13) -> 6822.75 | X13: =SUM(D13+F13+H13+L13+P13+T13+V13) -> 13874.194 | Y13: 0 | AA13: =SUM(W13+Y13) -> 6822.75 | AB13: =SUM(X13+Z13) -> 13874.194 | AC13: bedeckt | AD13: -3 | AE13: °C | AH13: =C13+E13+G13+I13+M13+Q13+Y13 -> 3902.9
A14: =SUM(A13+1) -> 9 | B14: Di | C14: 4714.4 | D14: 6451.6129 | E14: 0 | F14: 80.64516 | G14: 0 | H14: 32.25806 | I14: 0 | K14: =I14+J14 -> 0 | M14: 3202.6 | N14: 0 | O14: =M14+N14 -> 3202.6 | P14: 1935.4839 | Q14: 279.8 | R14: 2387 | S14: =Q14+R14 -> 2666.8 | T14: 2258.0645 | U14: 6112.1 | V14: 3116.129 | W14: =SUM(C14+E14+G14+K14+O14+S14+U14) -> 16695.9 | X14: =SUM(D14+F14+H14+L14+P14+T14+V14) -> 13874.194 | Y14: 0 | AA14: =SUM(W14+Y14) -> 16695.9 | AB14: =SUM(X14+Z14) -> 13874.194 | AC14: bedeckt, leichter Schneeschauer | AD14: -4 | AE14: °C | AH14: =C14+E14+G14+I14+M14+Q14+Y14 -> 8196.8
A15: =SUM(A14+1) -> 10 | B15: Mi | C15: 1590 | D15: 6451.6129 | E15: 0 | F15: 80.64516 | G15: 0 | H15: 32.25806 | I15: 0 | K15: =I15+J15 -> 0 | M15: 0 | N15: 0 | O15: =M15+N15 -> 0 | P15: 1935.4839 | Q15: 1260.5 | R15: 7157 | S15: =Q15+R15 -> 8417.5 | T15: 2258.0645 | U15: 8677.3 | V15: 3116.129 | W15: =SUM(C15+E15+G15+K15+O15+S15+U15) -> 18684.8 | X15: =SUM(D15+F15+H15+L15+P15+T15+V15) -> 13874.194 | Y15: 0 | AA15: =SUM(W15+Y15) -> 18684.8 | AB15: =SUM(X15+Z15) -> 13874.194 | AC15: bedeckt | AD15: -3 | AE15: °C | AH15: =C15+E15+G15+I15+M15+Q15+Y15 -> 2850.5
A16: =SUM(A15+1) -> 11 | B16: Do | C16: 2525 | D16: 6451.6129 | E16: 0 | F16: 80.64516 | G16: 0 | H16: 32.25806 | I16: 0 | K16: =I16+J16 -> 0 | M16: 0 | N16: 0 | O16: =M16+N16 -> 0 | P16: 1935.4839 | Q16: 394.1 | R16: 10945 | S16: =Q16+R16 -> 11339.1 | T16: 2258.0645 | U16: 10778.3 | V16: 3116.129 | W16: =SUM(C16+E16+G16+K16+O16+S16+U16) -> 24642.4 | X16: =SUM(D16+F16+H16+L16+P16+T16+V16) -> 13874.194 | Y16: 0 | AA16: =SUM(W16+Y16) -> 24642.4 | AB16: =SUM(X16+Z16) -> 13874.194 | AC16: Hochnebel | AD16: -2 | AE16: °C | AH16: =C16+E16+G16+I16+M16+Q16+Y16 -> 2919.1
A17: =SUM(A16+1) -> 12 | B17: Fr | C17: 7664.2 | D17: 6451.6129 | E17: 0 | F17: 80.64516 | G17: 0 | H17: 32.25806 | I17: 0 | K17: =I17+J17 -> 0 | M17: 0 | N17: 0 | O17: =M17+N17 -> 0 | P17: 1935.4839 | Q17: 36 | R17: 8690 | S17: =Q17+R17 -> 8726 | T17: 2258.0645 | U17: 3417.1 | V17: 3116.129 | W17: =SUM(C17+E17+G17+K17+O17+S17+U17) -> 19807.3 | X17: =SUM(D17+F17+H17+L17+P17+T17+V17) -> 13874.194 | Y17: 0 | AA17: =SUM(W17+Y17) -> 19807.3 | AB17: =SUM(X17+Z17) -> 13874.194 | AC17: bedeckt, ziemlich sonnig | AD17: -3 | AE17: °C | AH17: =C17+E17+G17+I17+M17+Q17+Y17 -> 7700.2
A18: =SUM(A17+1) -> 13 | B18: Sa | C18: 9747.5 | D18: 6451.6129 | E18: 0 | F18: 80.64516 | G18: 0 | H18: 32.25806 | I18: 0 | K18: =I18+J18 -> 0 | M18: 1946.2 | N18: 0 | O18: =M18+N18 -> 1946.2 | P18: 1935.4839 | Q18: 2829 | R18: 12367 | S18: =Q18+R18 -> 15196 | T18: 2258.0645 | U18: 3456.2 | V18: 3116.129 | W18: =SUM(C18+E18+G18+K18+O18+S18+U18) -> 30345.9 | X18: =SUM(D18+F18+H18+L18+P18+T18+V18) -> 13874.194 | Y18: 0 | AA18: =SUM(W18+Y18) -> 30345.9 | AB18: =SUM(X18+Z18) -> 13874.194 | AC18: bedeckt, hochnebel | AD18: -3.5 | AE18: °C | AH18: =C18+E18+G18+I18+M18+Q18+Y18 -> 14522.7
A19: =SUM(A18+1) -> 14 | B19: So | C19: 11725.2 | D19: 6451.6129 | E19: 0 | F19: 80.64516 | G19: 214.4 | H19: 32.25806 | I19: 0 | K19: =I19+J19 -> 0 | M19: 8649.7 | N19: 0 | O19: =M19+N19 -> 8649.7 | P19: 1935.4839 | Q19: 0 | R19: 0 | S19: =Q19+R19 -> 0 | T19: 2258.0645 | U19: 1913.3 | V19: 3116.129 | W19: =SUM(C19+E19+G19+K19+O19+S19+U19) -> 22502.6 | X19: =SUM(D19+F19+H19+L19+P19+T19+V19) -> 13874.194 | Y19: 0 | AA19: =SUM(W19+Y19) -> 22502.6 | AB19: =SUM(X19+Z19) -> 13874.194 | AC19: bedeckt, hochnebel | AD19: -5 | AE19: °C | AH19: =C19+E19+G19+I19+M19+Q19+Y19 -> 20589.3
A20: KW | B20: =SUM(B12+1) -> 2 | C20: =SUM(C13:C19) -> 40593.8 | D20: =SUM(D13:D19) -> 45161.29 | E20: =SUM(E13:E19) -> 0 | F20: =SUM(F13:F19) -> 564.51612 | G20: =SUM(G13:G19) -> 214.4 | H20: =SUM(H13:H19) -> 225.80642 | I20: =SUM(I13:I19) -> 0 | J20: =SUM(J13:J19) -> 0 | K20: =SUM(K13:K19) -> 0 | L20: 0 | M20: =SUM(M13:M19) -> 15063.3 | N20: =SUM(N13:N19) -> 0 | O20: =SUM(O13:O19) -> 15063.3 | P20: =SUM(P13:P19) -> 13548.387 | Q20: =SUM(Q13:Q19) -> 4810 | R20: =SUM(R13:R19) -> 42897 | S20: =SUM(S13:S19) -> 47707 | T20: =SUM(T13:T19) -> 15806.452 | ... AB20: =SUM(AB13:AB19) -> 97119.355 | AC20: Ø Temp | AD20: =SUM(AD13:AD19)/7 -> -3.3571429 | AE20: °C
A21: =SUM(A19+1) -> 15 | B21: Mo | C21: 3748.1 | D21: 6451.6129 | E21: 0 | F21: 80.64516 | G21: 0 | H21: 32.25806 | I21: 0 | K21: =I21+J21 -> 0 | M21: 0 | N21: 0 | O21: =M21+N21 -> 0 | P21: 1935.4839 | Q21: 1114.9 | R21: 4231.8 | S21: =Q21+R21 -> 5346.7 | T21: 2258.0645 | U21: 3253.6 | V21: 3116.129 | W21: =SUM(C21+E21+G21+K21+O21+S21+U21) -> 12348.4 | X21: =SUM(D21+F21+H21+L21+P21+T21+V21) -> 13874.194 | Y21: 0 | AA21: =SUM(W21+Y21) -> 12348.4 | AB21: =SUM(X21+Z21) -> 13874.194 | AC21: leichter Regen- oder Schneeschauer | AD21: -2 | AE21: °C | AH21: =C21+E21+G21+I21+M21+Q21+Y21 -> 4863
A22: =SUM(A21+1) -> 16 | B22: Di | C22: 2709.1 | D22: 6451.6129 | E22: 0 | F22: 80.64516 | G22: 0 | H22: 32.25806 | I22: 0 | K22: =I22+J22 -> 0 | M22: 2326 | N22: 0 | O22: =M22+N22 -> 2326 | P22: 1935.4839 | Q22: 1224.2 | R22: 2962 | S22: =Q22+R22 -> 4186.2 | T22: 2258.0645 | U22: 3537.8 | V22: 3116.129 | W22: =SUM(C22+E22+G22+K22+O22+S22+U22) -> 12759.1 | X22: =SUM(D22+F22+H22+L22+P22+T22+V22) -> 13874.194 | Y22: 0 | AA22: =SUM(W22+Y22) -> 12759.1 | AB22: =SUM(X22+Z22) -> 13874.194 | AC22: bewölkt | AD22: -4 | AE22: °C | AH22: =C22+E22+G22+I22+M22+Q22+Y22 -> 6259.3
A23: =SUM(A22+1) -> 17 | B23: Mi | C23: 3009 | D23: 6451.6129 | E23: 0 | F23: 80.64516 | G23: 0 | H23: 32.25806 | I23: 0 | K23: =I23+J23 -> 0 | M23: 1842.1 | N23: 0 | O23: =M23+N23 -> 1842.1 | P23: 1935.4839 | Q23: 972 | R23: 4182 | S23: =Q23+R23 -> 5154 | T23: 2258.0645 | U23: 3292.3 | V23: 3116.129 | W23: =SUM(C23+E23+G23+K23+O23+S23+U23) -> 13297.4 | X23: =SUM(D23+F23+H23+L23+P23+T23+V23) -> 13874.194 | Y23: 0 | AA23: =SUM(W23+Y23) -> 13297.4 | AB23: =SUM(X23+Z23) -> 13874.194 | AC23: Regenschauer | AD23: 4 | AE23: °C | AH23: =C23+E23+G23+I23+M23+Q23+Y23 -> 5823.1
A24: =SUM(A23+1) -> 18 | B24: Do | C24: 4199 | D24: 6451.6129 | E24: 0 | F24: 80.64516 | G24: 0 | H24: 32.25806 | I24: 0 | K24: =I24+J24 -> 0 | M24: 0 | N24: 0 | O24: =M24+N24 -> 0 | P24: 1935.4839 | Q24: 930.5 | R24: 5481 | S24: =Q24+R24 -> 6411.5 | T24: 2258.0645 | U24: 7615.1 | V24: 3116.129 | W24: =SUM(C24+E24+G24+K24+O24+S24+U24) -> 18225.6 | X24: =SUM(D24+F24+H24+L24+P24+T24+V24) -> 13874.194 | Y24: 0 | AA24: =SUM(W24+Y24) -> 18225.6 | AB24: =SUM(X24+Z24) -> 13874.194 | AC24: bedeckt, Regenschauer | AD24: 6 | AE24: °C | AH24: =C24+E24+G24+I24+M24+Q24+Y24 -> 5129.5
A25: =SUM(A24+1) -> 19 | B25: Fr | C25: 5441.1 | D25: 6451.6129 | E25: 71 | F25: 80.64516 | G25: 128.2 | H25: 32.25806 | I25: 0 | K25: =I25+J25 -> 0 | M25: 5362.9 | N25: 0 | O25: =M25+N25 -> 5362.9 | P25: 1935.4839 | Q25: 45.2 | R25: 3627 | S25: =Q25+R25 -> 3672.2 | T25: 2258.0645 | U25: 2413 | V25: 3116.129 | W25: =SUM(C25+E25+G25+K25+O25+S25+U25) -> 17088.4 | X25: =SUM(D25+F25+H25+L25+P25+T25+V25) -> 13874.194 | Y25: 0 | AA25: =SUM(W25+Y25) -> 17088.4 | AB25: =SUM(X25+Z25) -> 13874.194 | AC25: sonnig | AD25: -5 | AE25: °C | AH25: =C25+E25+G25+I25+M25+Q25+Y25 -> 11048.4
A26: =SUM(A25+1) -> 20 | B26: Sa | C26: 9412.1 | D26: 6451.6129 | E26: 67 | F26: 80.64516 | G26: 261.6 | H26: 32.25806 | I26: 0 | K26: =I26+J26 -> 0 | M26: 6224.9 | N26: 0 | O26: =M26+N26 -> 6224.9 | P26: 1935.4839 | Q26: 3374.7 | R26: 0 | S26: =Q26+R26 -> 3374.7 | T26: 2258.0645 | U26: 2807.7 | V26: 3116.129 | W26: =SUM(C26+E26+G26+K26+O26+S26+U26) -> 22148 | X26: =SUM(D26+F26+H26+L26+P26+T26+V26) -> 13874.194 | Y26: 0 | AA26: =SUM(W26+Y26) -> 22148 | AB26: =SUM(X26+Z26) -> 13874.194 | AC26: sonnig | AD26: -10 | AE26: °C | AH26: =C26+E26+G26+I26+M26+Q26+Y26 -> 19340.3
A27: =SUM(A26+1) -> 21 | B27: So | C27: 9349.3 | D27: 6451.6129 | E27: 238.3 | F27: 80.64516 | G27: 99.8 | H27: 32.25806 | I27: 0 | K27: =I27+J27 -> 0 | M27: 7437.1 | N27: 0 | O27: =M27+N27 -> 7437.1 | P27: 1935.4839 | Q27: 0 | R27: 0 | S27: =Q27+R27 -> 0 | T27: 2258.0645 | U27: 1085.6 | V27: 3116.129 | W27: =SUM(C27+E27+G27+K27+O27+S27+U27) -> 18210.1 | X27: =SUM(D27+F27+H27+L27+P27+T27+V27) -> 13874.194 | Y27: 0 | AA27: =SUM(W27+Y27) -> 18210.1 | AB27: =SUM(X27+Z27) -> 13874.194 | AC27: sonnig | AD27: 2 | AE27: °C | AH27: =C27+E27+G27+I27+M27+Q27+Y27 -> 17124.5
A28: KW | B28: =SUM(B20+1) -> 3 | C28: =SUM(C21:C27) -> 37867.7 | D28: =SUM(D21:D27) -> 45161.29 | E28: =SUM(E21:E27) -> 376.3 | F28: =SUM(F21:F27) -> 564.51612 | G28: =SUM(G21:G27) -> 489.6 | H28: =SUM(H21:H27) -> 225.80642 | I28: =SUM(I21:I27) -> 0 | J28: =SUM(J21:J27) -> 0 | ... AB28: =SUM(AB21:AB27) -> 97119.355 | AC28: Ø Temp | AD28: =SUM(AD21:AD27)/7 -> -1.2857143 | AE28: °C
A29: =SUM(A27+1) -> 22 | B29: Mo | C29: 4548.3 | D29: 6451.6129 | E29: 0 | F29: 80.64516 | G29: 0 | H29: 32.25806 | I29: 0 | K29: =I29+J29 -> 0 | M29: 0 | N29: 0 | O29: =M29+N29 -> 0 | P29: 1935.4839 | Q29: 152.3 | R29: 1283 | S29: =Q29+R29 -> 1435.3 | T29: 2258.0645 | U29: 4028.1 | V29: 3116.129 | W29: =SUM(C29+E29+G29+K29+O29+S29+U29) -> 10011.7 | X29: =SUM(D29+F29+H29+L29+P29+T29+V29) -> 13874.194 | Y29: 0 | AA29: =SUM(W29+Y29) -> 10011.7 | AB29: =SUM(X29+Z29) -> 13874.194 | AC29: bedeckt, Regenschauer | AD29: 5 | AE29: °C | AH29: =C29+E29+G29+I29+M29+Q29+Y29 -> 4700.6
A30: =SUM(A29+1) -> 23 | B30: Di | C30: 5567.5 | D30: 6451.6129 | E30: 0 | F30: 80.64516 | G30: 0 | H30: 32.25806 | I30: 0 | K30: =I30+J30 -> 0 | M30: 1329.1 | N30: 0 | O30: =M30+N30 -> 1329.1 | P30: 1935.4839 | Q30: 1339.9 | R30: 1277.5 | S30: =Q30+R30 -> 2617.4 | T30: 2258.0645 | U30: 5306.9 | V30: 3116.129 | W30: =SUM(C30+E30+G30+K30+O30+S30+U30) -> 14820.9 | X30: =SUM(D30+F30+H30+L30+P30+T30+V30) -> 13874.194 | Y30: 0 | AA30: =SUM(W30+Y30) -> 14820.9 | AB30: =SUM(X30+Z30) -> 13874.194 | AC30: bedeckt, Regenschauer | AD30: 10 | AE30: °C | AH30: =C30+E30+G30+I30+M30+Q30+Y30 -> 8236.5
A31: =SUM(A30+1) -> 24 | B31: Mi | C31: 4937.9 | D31: 6451.6129 | E31: 0 | F31: 80.64516 | G31: 0 | H31: 32.25806 | I31: 0 | K31: =I31+J31 -> 0 | M31: 0 | N31: 0 | O31: =M31+N31 -> 0 | P31: 1935.4839 | Q31: 596.2 | R31: 6604.6 | S31: =Q31+R31 -> 7200.8 | T31: 2258.0645 | U31: 5428.4 | V31: 3116.129 | W31: =SUM(C31+E31+G31+K31+O31+S31+U31) -> 17567.1 | X31: =SUM(D31+F31+H31+L31+P31+T31+V31) -> 13874.194 | Y31: 0 | AA31: =SUM(W31+Y31) -> 17567.1 | AB31: =SUM(X31+Z31) -> 13874.194 | AC31: leicht Regenschauer | AD31: 13 | AE31: °C | AH31: =C31+E31+G31+I31+M31+Q31+Y31 -> 5534.1
A32: =SUM(A31+1) -> 25 | B32: Do | C32: 5924.2 | D32: 6451.6129 | E32: 0 | F32: 80.64516 | G32: 0 | H32: 32.25806 | I32: 0 | K32: =I32+J32 -> 0 | M32: 3547.7 | N32: 0 | O32: =M32+N32 -> 3547.7 | P32: 1935.4839 | Q32: 1712.1 | R32: 5577 | S32: =Q32+R32 -> 7289.1 | T32: 2258.0645 | U32: 4583.9 | V32: 3116.129 | W32: =SUM(C32+E32+G32+K32+O32+S32+U32) -> 21344.9 | X32: =SUM(D32+F32+H32+L32+P32+T32+V32) -> 13874.194 | Y32: 0 | AA32: =SUM(W32+Y32) -> 21344.9 | AB32: =SUM(X32+Z32) -> 13874.194 | AC32: bedeckt, Regenschauer | AD32: 10 | AE32: °C | AH32: =C32+E32+G32+I32+M32+Q32+Y32 -> 11184
A33: =SUM(A32+1) -> 26 | B33: Fr | C33: 8017.6 | D33: 6451.6129 | E33: 0 | F33: 80.64516 | G33: 0 | H33: 32.25806 | I33: 0 | K33: =I33+J33 -> 0 | M33: 8158.8 | N33: 0 | O33: =M33+N33 -> 8158.8 | P33: 1935.4839 | Q33: 18 | R33: 888 | S33: =Q33+R33 -> 906 | T33: 2258.0645 | U33: 4716.3 | V33: 3116.129 | W33: =SUM(C33+E33+G33+K33+O33+S33+U33) -> 21798.7 | X33: =SUM(D33+F33+H33+L33+P33+T33+V33) -> 13874.194 | Y33: 0 | AA33: =SUM(W33+Y33) -> 21798.7 | AB33: =SUM(X33+Z33) -> 13874.194 | AC33: Regenschauer mit trockenen Abschnitten | AD33: 10 | AE33: °C | AH33: =C33+E33+G33+I33+M33+Q33+Y33 -> 16194.4
A34: =SUM(A33+1) -> 27 | B34: Sa | C34: 13013.6 | D34: 6451.6129 | E34: 543.9 | F34: 80.64516 | G34: 290.8 | H34: 32.25806 | I34: 0 | K34: =I34+J34 -> 0 | M34: 0 | N34: 0 | O34: =M34+N34 -> 0 | P34: 1935.4839 | Q34: 25.5 | R34: 0 | S34: =Q34+R34 -> 25.5 | T34: 2258.0645 | U34: 8339.1 | V34: 3116.129 | W34: =SUM(C34+E34+G34+K34+O34+S34+U34) -> 22212.9 | X34: =SUM(D34+F34+H34+L34+P34+T34+V34) -> 13874.194 | Y34: 0 | AA34: =SUM(W34+Y34) -> 22212.9 | AB34: =SUM(X34+Z34) -> 13874.194 | AC34: leicht bewölkt | AD34: 7 | AE34: °C | AH34: =C34+E34+G34+I34+M34+Q34+Y34 -> 13873.8
A35: =SUM(A34+1) -> 28 | B35: So | C35: 7672.1 | D35: 6451.6129 | E35: 757.5 | F35: 80.64516 | G35: 522.6 | H35: 32.25806 | I35: 0 | K35: =I35+J35 -> 0 | M35: 1350 | N35: 0 | O35: =M35+N35 -> 1350 | P35: 1935.4839 | Q35: 0 | R35: 0 | S35: =Q35+R35 -> 0 | T35: 2258.0645 | U35: 2884.8 | V35: 3116.129 | W35: =SUM(C35+E35+G35+K35+O35+S35+U35) -> 13187 | X35: =SUM(D35+F35+H35+L35+P35+T35+V35) -> 13874.194 | Y35: 0 | AA35: =SUM(W35+Y35) -> 13187 | AB35: =SUM(X35+Z35) -> 13874.194 | AC35: sonnig, bedeckt | AD35: 10 | AE35: °C | AH35: =C35+E35+G35+I35+M35+Q35+Y35 -> 10302.2
A36: KW | B36: =SUM(B28+1) -> 4 | C36: =SUM(C29:C35) -> 49681.2 | D36: =SUM(D29:D35) -> 45161.29 | E36: =SUM(E29:E35) -> 1301.4 | F36: =SUM(F29:F35) -> 564.51612 | G36: =SUM(G29:G35) -> 813.4 | H36: =SUM(H29:H35) -> 225.80642 | I36: =SUM(I29:I35) -> 0 | J36: =SUM(J29:J35) -> 0 | ... AB36: =SUM(AB29:AB35) -> 97119.355 | AC36: Ø Temp | AD36: =SUM(AD29:AD35)/7 -> 9.2857143 | AE36: °C
A37: 29 | B37: Mo | C37: 6192.5 | D37: 6451.6129 | E37: 140.4 | F37: 80.64516 | G37: 164.6 | H37: 32.25806 | I37: 0 | K37: =I37+J37 -> 0 | M37: 0 | N37: 0 | O37: =M37+N37 -> 0 | P37: 1935.4839 | Q37: 1432.8 | R37: 3641 | S37: =Q37+R37 -> 5073.8 | T37: 2258.0645 | U37: 4459.5 | V37: 3116.129 | W37: =SUM(C37+E37+G37+K37+O37+S37+U37) -> 16030.8 | X37: =SUM(D37+F37+H37+L37+P37+T37+V37) -> 13874.194 | Y37: 0 | AA37: =SUM(W37+Y37) -> 16030.8 | AB37: =SUM(X37+Z37) -> 13874.194 | AC37: sonnig, bedeckt | AD37: 8 | AE37: °C | AH37: =C37+E37+G37+I37+M37+Q37+Y37 -> 7930.3
A38: 30 | B38: Di | C38: 5645.1 | D38: 6451.6129 | E38: 20 | F38: 80.64516 | G38: 115.7 | H38: 32.25806 | I38: 0 | K38: =I38+J38 -> 0 | M38: 50 | N38: 0 | O38: =M38+N38 -> 50 | P38: 1935.4839 | Q38: 143.1 | R38: 3180 | S38: =Q38+R38 -> 3323.1 | T38: 2258.0645 | U38: 5839.2 | V38: 3116.129 | W38: =SUM(C38+E38+G38+K38+O38+S38+U38) -> 14993.1 | X38: =SUM(D38+F38+H38+L38+P38+T38+V38) -> 13874.194 | Y38: 0 | AA38: =SUM(W38+Y38) -> 14993.1 | AB38: =SUM(X38+Z38) -> 13874.194 | AC38: sonnig, bedeckt | AD38: 7 | AE38: °C | AH38: =C38+E38+G38+I38+M38+Q38+Y38 -> 5973.9
A39: 31 | B39: Mi | C39: 5460.4 | D39: 6451.6129 | E39: 120.9 | F39: 80.64516 | G39: 270.4 | H39: 32.25806 | I39: 0 | K39: =I39+J39 -> 0 | M39: 1077.4 | N39: 0 | O39: =M39+N39 -> 1077.4 | P39: 1935.4839 | Q39: 847.7 | R39: 3082 | S39: =Q39+R39 -> 3929.7 | T39: 2258.0645 | U39: 2143.3 | V39: 3116.129 | W39: =SUM(C39+E39+G39+K39+O39+S39+U39) -> 13002.1 | X39: =SUM(D39+F39+H39+L39+P39+T39+V39) -> 13874.194 | Y39: 0 | AA39: =SUM(W39+Y39) -> 13002.1 | AB39: =SUM(X39+Z39) -> 13874.194 | AC39: teilweise sonnig | AD39: 8 | AE39: °C | AH39: =C39+E39+G39+I39+M39+Q39+Y39 -> 7776.8
A40: KW | B40: 5 | C40: =SUM(C37:C39) -> 17298 | D40: =SUM(D37:D39) -> 19354.839 | E40: =SUM(E37:E39) -> 281.3 | F40: =SUM(F37:F39) -> 241.93548 | G40: =SUM(G37:G39) -> 550.7 | H40: =SUM(H37:H39) -> 96.77418 | I40: =SUM(I37:I39) -> 0 | J40: =SUM(J37:J39) -> 0 | ... AB40: =SUM(AB37:AB39) -> 41622.581 | AC40: Ø Temp | AD40: =SUM(AD29:AD35)/7 -> 9.2857143 | AE40: °C
A41: Umsatz kumuliert | C41: =SUM(C12+C20+C28+C40+C36) -> 196428.56 | D41: =SUM(D12+D20+D28+D36+D40) -> 200000 | E41: =SUM(E12+E20+E28+E40+E36) -> 2166.9 | F41: =SUM(F12+F20+F28+F40+F36) -> 2500 | G41: =SUM(G12+G20+G28+G40+G36) -> 2301.4 | H41: =SUM(H12+H20+H28+H40+H36) -> 999.99986 | I41: =SUM(I12+I20+I28+I40+I36) -> 0 | J41: =SUM(J12+J20+J28+J40+J36) -> 0 | K41: =SUM(K12+K20+K28+K40+K36) -> 0 | L41: =SUM(L12+L20+L28+L40+L36) -> 0 | ... AB41: =SUM(AB12+AB20+AB28+AB40+AB36) -> 430100 | AC41: Umsatz kumuliert
...

Sheet 02_24
A1: Tagesumsätze | H1: 45323
C3: Restaurant | E3: Terrasse | G3: Lounge | I3: Pavillon | K3: Bankett | O3: Seminar | S3: Hotel | U3: TOTAL Gesamtbetrieb ohne Seebad | W3: Seebad | Y3: TOTAL Gesamtbetrieb mit Seebad | AA3: Info's | AF3: Gegenkontrolle Gastronovi
C4: IST | D4: Budget | E4: IST | F4: Budget | G4: IST | H4: Budget | I4: IST | J4: Budget | K4: IST/GN | L4: IST/ET | M4: TOTAL IST | N4: Budget | O4: IST/GN | P4: IST/ET | Q4: TOTAL IST | R4: Budget | S4: IST | T4: Budget | U4: IST | V4: Budget | W4: IST | X4: Budget | Y4: IST | Z4: Budget | AA4: Wetter | AB4: Temp. | AD4: Bemerkung
A5: 1 | B5: Do | C5: 3848.2 | D5: 7655.1724 | E5: 0 | F5: 344.82759 | G5: 0 | H5: 172.41379 | I5: 0 | K5: 0 | M5: =K5+L5 -> 0 | N5: 1379.3103 | O5: 1485.7 | P5: 2336 | Q5: =SUM(O5:P5) -> 3821.7 | R5: 1034.4828 | S5: 2985.4 | T5: 2827.5862 | U5: =C5+E5+G5+I5+M5+Q5+S5 -> 10655.3 | V5: =D5+F5+H5+J5+N5+R5+T5 -> 13413.793 | W5: 0 | Y5: =SUM(U5+W5) -> 10655.3 | Z5: =SUM(V5+X5) -> 13413.793 | AA5: leicht Regenschauer | AB5: 5 | AC5: °C | AF5: =+C5+E5+G5+K5+O5+W5 -> 5333.9
A6: =SUM(A5+1) -> 2 | B6: Fr | C6: 6229 | D6: 7655.1724 | E6: 0 | F6: 344.82759 | G6: 18 | H6: 172.41379 | I6: 0 | K6: 0 | M6: 0 | N6: 1379.3103 | O6: 1004.9 | P6: 4460 | Q6: =SUM(O6:P6) -> 5464.9 | R6: 1034.4828 | S6: 3728.5 | T6: 2827.5862 | U6: =C6+E6+G6+I6+M6+Q6+S6 -> 15440.4 | V6: =D6+F6+H6+J6+N6+R6+T6 -> 13413.793 | W6: 0 | Y6: =SUM(U6+W6) -> 15440.4 | Z6: =SUM(V6+X6) -> 13413.793 | AA6: bedeckt, Regenschauer | AB6: 5 | AC6: °C | AF6: =+C6+E6+G6+K6+O6+W6 -> 7251.9
A7: =SUM(A6+1) -> 3 | B7: Sa | C7: 10263.2 | D7: 7655.1724 | E7: 1810.9 | F7: 344.82759 | G7: 673.3 | H7: 172.41379 | I7: 0 | K7: 0 | M7: 0 | N7: 1379.3103 | O7: 0 | P7: 1498 | Q7: =SUM(O7:P7) -> 1498 | R7: 1034.4828 | S7: 2515.2 | T7: 2827.5862 | U7: =C7+E7+G7+I7+M7+Q7+S7 -> 16760.6 | V7: =D7+F7+H7+J7+N7+R7+T7 -> 13413.793 | W7: 0 | Y7: =SUM(U7+W7) -> 16760.6 | Z7: =SUM(V7+X7) -> 13413.793 | AA7: sonnig | AB7: 9 | AC7: °C | AF7: =+C7+E7+G7+K7+O7+W7 -> 12747.4
A8: =SUM(A7+1) -> 4 | B8: So | C8: 9293.1 | D8: 7655.1724 | E8: 606.2 | F8: 344.82759 | G8: 380.4 | H8: 172.41379 | I8: 0 | K8: 0 | M8: 0 | N8: 1379.3103 | O8: 64.6 | P8: 0 | Q8: =SUM(O8:P8) -> 64.6 | R8: 1034.4828 | S8: 1009.3 | T8: 2827.5862 | U8: =C8+E8+G8+I8+M8+Q8+S8 -> 11353.6 | V8: =D8+F8+H8+J8+N8+R8+T8 -> 13413.793 | W8: 0 | Y8: =SUM(U8+W8) -> 11353.6 | Z8: =SUM(V8+X8) -> 13413.793 | AA8: Tageshälfte sonnig | AB8: 9 | AC8: °C | AF8: =+C8+E8+G8+K8+O8+W8 -> 10344.3
A9: KW | B9: 5 | C9: =SUM(C5:C8) -> 29633.5 | D9: =SUM(D5:D8) -> 30620.69 | E9: =SUM(E5:E8) -> 2417.1 | F9: =SUM(F5:F8) -> 1379.3103 | G9: =SUM(G5:G8) -> 1071.7 | H9: =SUM(H5:H8) -> 689.65517 | I9: =SUM(I5:I8) -> 0 | J9: =SUM(J5:J8) -> 0 | ... Z9: =SUM(Z5:Z8) -> 53655.172 | AA9: Ø Temp | AB9: =SUM(AB5:AB8)/7 -> 4 | AC9: °C
A10: =SUM(A8+1) -> 5 | B10: Mo | C10: 4527.1 | D10: 7655.1724 | E10: 349.9 | F10: 344.82759 | G10: 159 | H10: 172.41379 | I10: 0 | K10: 0 | M10: =K10+L10 -> 0 | N10: 1379.3103 | O10: 944.2 | P10: 3402 | Q10: =SUM(O10:P10) -> 4346.2 | R10: 1034.4828 | S10: 3724.3 | T10: 2827.5862 | U10: =C10+E10+G10+I10+M10+Q10+S10 -> 13106.5 | V10: =D10+F10+H10+J10+N10+R10+T10 -> 13413.793 | W10: 0 | Y10: =SUM(U10+W10) -> 13106.5 | Z10: =SUM(V10+X10) -> 13413.793 | AA10: hohe Wolkenfelder | AB10: 8 | AC10: °C | AF10: =+C10+E10+G10+K10+O10+W10 -> 5980.2
A11: =SUM(A10+1) -> 6 | B11: Di | C11: 7518.95 | D11: 7655.1724 | E11: 765.7 | F11: 344.82759 | G11: 609.9 | H11: 172.41379 | I11: 0 | K11: 0 | M11: =K11+L11 -> 0 | N11: 1379.3103 | O11: 176.7 | P11: 4017 | Q11: =SUM(O11:P11) -> 4193.7 | R11: 1034.4828 | S11: 2270.8 | T11: 2827.5862 | U11: =C11+E11+G11+I11+M11+Q11+S11 -> 15359.05 | V11: =D11+F11+H11+J11+N11+R11+T11 -> 13413.793 | W11: 0 | Y11: =SUM(U11+W11) -> 15359.05 | Z11: =SUM(V11+X11) -> 13413.793 | AA11: Wolkenfelder | AB11: 8 | AC11: °C | AF11: =+C11+E11+G11+K11+O11+W11 -> 9071.25
A12: =SUM(A11+1) -> 7 | B12: Mi | C12: 6631 | D12: 7655.1724 | E12: 154.3 | F12: 344.82759 | G12: 49.1 | H12: 172.41379 | I12: 0 | K12: 0 | M12: =K12+L12 -> 0 | N12: 1379.3103 | O12: 33 | P12: 1440 | Q12: =SUM(O12:P12) -> 1473 | R12: 1034.4828 | S12: 2146.8 | T12: 2827.5862 | U12: =C12+E12+G12+I12+M12+Q12+S12 -> 10454.2 | V12: =D12+F12+H12+J12+N12+R12+T12 -> 13413.793 | W12: 0 | Y12: =SUM(U12+W12) -> 10454.2 | Z12: =SUM(V12+X12) -> 13413.793 | AA12: bedeckt | AB12: 8 | AC12: °C | AF12: =+C12+E12+G12+K12+O12+W12 -> 6867.4
A13: =SUM(A12+1) -> 8 | B13: Do | C13: 6494.3 | D13: 7655.1724 | E13: 0 | F13: 344.82759 | G13: 54 | H13: 172.41379 | I13: 0 | K13: 0 | M13: =K13+L13 -> 0 | N13: 1379.3103 | O13: 0 | P13: 0 | Q13: =SUM(O13:P13) -> 0 | R13: 1034.4828 | S13: 2057 | T13: 2827.5862 | U13: =C13+E13+G13+I13+M13+Q13+S13 -> 8605.3 | V13: =D13+F13+H13+J13+N13+R13+T13 -> 13413.793 | W13: 0 | Y13: =SUM(U13+W13) -> 8605.3 | Z13: =SUM(V13+X13) -> 13413.793 | AA13: bedeckt, Regenschauer | AB13: 9 | AC13: °C | AF13: =+C13+E13+G13+K13+O13+W13 -> 6548.3
A14: =SUM(A13+1) -> 9 | B14: Fr | C14: 8614.8 | D14: 7655.1724 | E14: 7 | F14: 344.82759 | G14: 24.8 | H14: 172.41379 | I14: 0 | K14: 0 | M14: =K14+L14 -> 0 | N14: 1379.3103 | O14: 0 | P14: 0 | Q14: =SUM(O14:P14) -> 0 | R14: 1034.4828 | S14: 1246 | T14: 2827.5862 | U14: =C14+E14+G14+I14+M14+Q14+S14 -> 9892.6 | V14: =D14+F14+H14+J14+N14+R14+T14 -> 13413.793 | W14: 0 | Y14: =SUM(U14+W14) -> 9892.6 | Z14: =SUM(V14+X14) -> 13413.793 | AA14: Regenschauer | AB14: 10 | AC14: °C | AF14: =+C14+E14+G14+K14+O14+W14 -> 8646.6
A15: =SUM(A14+1) -> 10 | B15: Sa | C15: 10635.1 | D15: 7655.1724 | E15: 0 | F15: 344.82759 | G15: 159.8 | H15: 172.41379 | I15: 0 | K15: 4689.6 | M15: =K15+L15 -> 4689.6 | N15: 1379.3103 | O15: 0 | P15: 0 | Q15: =SUM(O15:P15) -> 0 | R15: 1034.4828 | S15: 2969 | T15: 2827.5862 | U15: =C15+E15+G15+I15+M15+Q15+S15 -> 18453.5 | V15: =D15+F15+H15+J15+N15+R15+T15 -> 13413.793 | W15: 0 | Y15: =SUM(U15+W15) -> 18453.5 | Z15: =SUM(V15+X15) -> 13413.793 | AA15: bedeckt, Regenschauer | AB15: 8 | AC15: °C | AF15: =+C15+E15+G15+K15+O15+W15 -> 15484.5
A16: =SUM(A15+1) -> 11 | B16: So | C16: 8745.9 | D16: 7655.1724 | E16: 0 | F16: 344.82759 | G16: 23.4 | H16: 172.41379 | I16: 0 | K16: 2544 | M16: =K16+L16 -> 2544 | N16: 1379.3103 | O16: 0 | P16: 0 | Q16: =SUM(O16:P16) -> 0 | R16: 1034.4828 | S16: 1641.9 | T16: 2827.5862 | U16: =C16+E16+G16+I16+M16+Q16+S16 -> 12955.2 | V16: =D16+F16+H16+J16+N16+R16+T16 -> 13413.793 | W16: 0 | Y16: =SUM(U16+W16) -> 12955.2 | Z16: =SUM(V16+X16) -> 13413.793 | AA16: Regenschauer | AB16: 8 | AC16: °C | AF16: =+C16+E16+G16+K16+O16+W16 -> 11313.3
A17: KW | B17: =SUM(B9+1) -> 6 | C17: =SUM(C10:C16) -> 53167.15 | D17: =SUM(D10:D16) -> 53586.207 | E17: =SUM(E10:E16) -> 1276.9 | F17: =SUM(F10:F16) -> 2413.7931 | G17: =SUM(G10:G16) -> 1080 | H17: =SUM(H10:H16) -> 1206.8966 | I17: =SUM(I10:I16) -> 0 | J17: =SUM(J10:J16) -> 0 | ... Z17: =SUM(Z10:Z16) -> 93896.552 | AA17: Ø Temp | AB17: =SUM(AB10:AB16)/7 -> 8.4285714 | AC17: °C
A18: =SUM(A16+1) -> 12 | B18: Mo | C18: 6132.1 | D18: 7655.1724 | E18: 9.5 | F18: 344.82759 | G18: 0 | H18: 172.41379 | I18: 0 | K18: 0 | M18: =K18+L18 -> 0 | N18: 1379.3103 | O18: 0 | P18: 1344 | Q18: =SUM(O18:P18) -> 1344 | R18: 1034.4828 | S18: 2322.1 | T18: 2827.5862 | U18: =C18+E18+G18+I18+M18+Q18+S18 -> 9807.7 | V18: =D18+F18+H18+J18+N18+R18+T18 -> 13413.793 | W18: 0 | Y18: =SUM(U18+W18) -> 9807.7 | Z18: =SUM(V18+X18) -> 13413.793 | AA18: bewölkt | AB18: 9 | AC18: °C | AF18: =+C18+E18+G18+K18+O18+W18 -> 6141.6
A19: =SUM(A18+1) -> 13 | B19: Di | C19: 10156.5 | D19: 7655.1724 | E19: 1018.8 | F19: 344.82759 | G19: 356.8 | H19: 172.41379 | I19: 0 | K19: 0 | M19: =K19+L19 -> 0 | N19: 1379.3103 | O19: 1292.2 | P19: 2372 | Q19: =SUM(O19:P19) -> 3664.2 | R19: 1034.4828 | S19: 5211.1 | T19: 2827.5862 | U19: =C19+E19+G19+I19+M19+Q19+S19 -> 20407.4 | V19: =D19+F19+H19+J19+N19+R19+T19 -> 13413.793 | W19: 0 | Y19: =SUM(U19+W19) -> 20407.4 | Z19: =SUM(V19+X19) -> 13413.793 | AA19: bewölkt | AB19: 9 | AC19: °C | AF19: =+C19+E19+G19+K19+O19+W19 -> 12824.3
A20: =SUM(A19+1) -> 14 | B20: Mi | C20: 15532.7 | D20: 7655.1724 | E20: 29 | F20: 344.82759 | G20: 160.3 | H20: 172.41379 | I20: 0 | K20: 670 | M20: =K20+L20 -> 670 | N20: 1379.3103 | O20: 828.9 | P20: 1948 | Q20: =SUM(O20:P20) -> 2776.9 | R20: 1034.4828 | S20: 3285.2 | T20: 2827.5862 | U20: =C20+E20+G20+I20+M20+Q20+S20 -> 22454.1 | V20: =D20+F20+H20+J20+N20+R20+T20 -> 13413.793 | W20: 0 | Y20: =SUM(U20+W20) -> 22454.1 | Z20: =SUM(V20+X20) -> 13413.793 | AA20: Tageshälfte bewölkt | AB20: 11 | AC20: °C | AD20: Valentinstag | AF20: =+C20+E20+G20+K20+O20+W20 -> 17220.9
A21: =SUM(A20+1) -> 15 | B21: Do | C21: 8861 | D21: 7655.1724 | E21: 0 | F21: 344.82759 | G21: 105.5 | H21: 172.41379 | I21: 0 | K21: 0 | M21: =K21+L21 -> 0 | N21: 1379.3103 | O21: 0 | P21: 999 | Q21: =SUM(O21:P21) -> 999 | R21: 1034.4828 | S21: 1059 | T21: 2827.5862 | U21: =C21+E21+G21+I21+M21+Q21+S21 -> 11024.5 | V21: =D21+F21+H21+J21+N21+R21+T21 -> 13413.793 | W21: 0 | Y21: =SUM(U21+W21) -> 11024.5 | Z21: =SUM(V21+X21) -> 13413.793 | AA21: bedeckt, Regenschauer | AB21: 9 | AC21: °C | AF21: =+C21+E21+G21+K21+O21+W21 -> 8966.5
A22: =SUM(A21+1) -> 16 | B22: Fr | C22: 11537.95 | D22: 7655.1724 | E22: 159.4 | F22: 344.82759 | G22: 196.3 | H22: 172.41379 | I22: 0 | K22: 0 | M22: =K22+L22 -> 0 | N22: 1379.3103 | O22: 0 | P22: 0 | Q22: =SUM(O22:P22) -> 0 | R22: 1034.4828 | S22: 1156.2 | T22: 2827.5862 | U22: =C22+E22+G22+I22+M22+Q22+S22 -> 13049.85 | V22: =D22+F22+H22+J22+N22+R22+T22 -> 13413.793 | W22: 0 | Y22: =SUM(U22+W22) -> 13049.85 | Z22: =SUM(V22+X22) -> 13413.793 | AA22: bedeckt | AB22: 13 | AC22: °C | AF22: =+C22+E22+G22+K22+O22+W22 -> 11893.65
A23: =SUM(A22+1) -> 17 | B23: Sa | C23: 14138.5 | D23: 7655.1724 | E23: 0 | F23: 344.82759 | G23: 198.6 | H23: 172.41379 | I23: 0 | K23: 3249.5 | M23: =K23+L23 -> 3249.5 | N23: 1379.3103 | O23: 0 | P23: 0 | Q23: =SUM(O23:P23) -> 0 | R23: 1034.4828 | S23: 3418.6 | T23: 2827.5862 | U23: =C23+E23+G23+I23+M23+Q23+S23 -> 21005.2 | V23: =D23+F23+H23+J23+N23+R23+T23 -> 13413.793 | W23: 0 | Y23: =SUM(U23+W23) -> 21005.2 | Z23: =SUM(V23+X23) -> 13413.793 | AA23: bedeckt, Regenschauer | AB23: 9 | AC23: °C | AF23: =+C23+E23+G23+K23+O23+W23 -> 17586.6
A24: =SUM(A23+1) -> 18 | B24: So | C24: 14312 | D24: 7655.1724 | E24: 280.1 | F24: 344.82759 | G24: 356.3 | H24: 172.41379 | I24: 0 | K24: 5182 | M24: =K24+L24 -> 5182 | N24: 1379.3103 | O24: 0 | P24: 0 | Q24: =SUM(O24:P24) -> 0 | R24: 1034.4828 | S24: 775.4 | T24: 2827.5862 | U24: =C24+E24+G24+I24+M24+Q24+S24 -> 20905.8 | V24: =D24+F24+H24+J24+N24+R24+T24 -> 13413.793 | W24: 0 | Y24: =SUM(U24+W24) -> 20905.8 | Z24: =SUM(V24+X24) -> 13413.793 | AA24: bedeckt, Regenschauer | AB24: 12 | AC24: °C | AF24: =+C24+E24+G24+K24+O24+W24 -> 20130.4
A25: KW | B25: =SUM(B17+1) -> 7 | C25: =SUM(C18:C24) -> 80670.75 | D25: =SUM(D18:D24) -> 53586.207 | E25: =SUM(E18:E24) -> 1496.8 | F25: =SUM(F18:F24) -> 2413.7931 | G25: =SUM(G18:G24) -> 1373.8 | H25: =SUM(H18:H24) -> 1206.8966 | I25: =SUM(I18:I24) -> 0 | J25: =SUM(J18:J24) -> 0 | ... Z25: =SUM(Z18:Z24) -> 93896.552 | AA25: Ø Temp | AB25: =SUM(AB18:AB24)/7 -> 10.285714 | AC25: °C
A26: =SUM(A24+1) -> 19 | B26: Mo | C26: 7152.1 | D26: 7655.1724 | E26: 0 | F26: 344.82759 | G26: 19.5 | H26: 172.41379 | I26: 0 | K26: 0 | M26: =K26+L26 -> 0 | N26: 1379.3103 | O26: 0 | P26: 0 | Q26: =SUM(O26:P26) -> 0 | R26: 1034.4828 | S26: 2130.6 | T26: 2827.5862 | U26: =C26+E26+G26+I26+M26+Q26+S26 -> 9302.2 | V26: =D26+F26+H26+J26+N26+R26+T26 -> 13413.793 | W26: 0 | Y26: =SUM(U26+W26) -> 9302.2 | Z26: =SUM(V26+X26) -> 13413.793 | AA26: trocken, Regenschauer | AB26: 11 | AC26: °C | AF26: =+C26+E26+G26+K26+O26+W26 -> 7171.6
A27: =SUM(A26+1) -> 20 | B27: Di | C27: 4628.9 | D27: 7655.1724 | E27: 29.5 | F27: 344.82759 | G27: 39.7 | H27: 172.41379 | I27: 0 | K27: 0 | M27: =K27+L27 -> 0 | N27: 1379.3103 | O27: 393.8 | P27: 1728 | Q27: =SUM(O27:P27) -> 2121.8 | R27: 1034.4828 | S27: 3270.7 | T27: 2827.5862 | U27: =C27+E27+G27+I27+M27+Q27+S27 -> 10090.6 | V27: =D27+F27+H27+J27+N27+R27+T27 -> 13413.793 | W27: 0 | Y27: =SUM(U27+W27) -> 10090.6 | Z27: =SUM(V27+X27) -> 13413.793 | AA27: bedeckt | AB27: 9 | AC27: °C | AF27: =+C27+E27+G27+K27+O27+W27 -> 5091.9
A28: =SUM(A27+1) -> 21 | B28: Mi | C28: 4970.6 | D28: 7655.1724 | E28: 12 | F28: 344.82759 | G28: 165.8 | H28: 172.41379 | I28: 0 | K28: 0 | M28: =K28+L28 -> 0 | N28: 1379.3103 | O28: 0 | P28: 3413 | Q28: =SUM(O28:P28) -> 3413 | R28: 1034.4828 | S28: 1990.5 | T28: 2827.5862 | U28: =C28+E28+G28+I28+M28+Q28+S28 -> 10551.9 | V28: =D28+F28+H28+J28+N28+R28+T28 -> 13413.793 | W28: 0 | Y28: =SUM(U28+W28) -> 10551.9 | Z28: =SUM(V28+X28) -> 13413.793 | AA28: bedeckt, Regenschauer | AB28: 10 | AC28: °C | AF28: =+C28+E28+G28+K28+O28+W28 -> 5148.4
A29: =SUM(A28+1) -> 22 | B29: Do | C29: 7805.2 | D29: 7655.1724 | E29: 0 | F29: 344.82759 | G29: 0 | H29: 172.41379 | I29: 0 | K29: 0 | M29: =K29+L29 -> 0 | N29: 1379.3103 | O29: 0 | P29: 0 | Q29: =SUM(O29:P29) -> 0 | R29: 1034.4828 | S29: 868.5 | T29: 2827.5862 | U29: =C29+E29+G29+I29+M29+Q29+S29 -> 8673.7 | V29: =D29+F29+H29+J29+N29+R29+T29 -> 13413.793 | W29: 0 | Y29: =SUM(U29+W29) -> 8673.7 | Z29: =SUM(V29+X29) -> 13413.793 | AA29: Regen, Gewitter | AB29: 11 | AC29: °C | AF29: =+C29+E29+G29+K29+O29+W29 -> 7805.2
A30: =SUM(A29+1) -> 23 | B30: Fr | C30: 9963.3 | D30: 7655.1724 | E30: 73.5 | F30: 344.82759 | G30: 172.3 | H30: 172.41379 | I30: 0 | K30: 0 | M30: =K30+L30 -> 0 | N30: 1379.3103 | O30: 492.7 | P30: 3743 | Q30: =SUM(O30:P30) -> 4235.7 | R30: 1034.4828 | S30: 3133.9 | T30: 2827.5862 | U30: =C30+E30+G30+I30+M30+Q30+S30 -> 17578.7 | V30: =D30+F30+H30+J30+N30+R30+T30 -> 13413.793 | W30: 0 | Y30: =SUM(U30+W30) -> 17578.7 | Z30: =SUM(V30+X30) -> 13413.793 | AA30: sonnig, leichter Regenschauer | AB30: 8 | AC30: °C | AF30: =+C30+E30+G30+K30+O30+W30 -> 10701.8
A31: =SUM(A30+1) -> 24 | B31: Sa | C31: 12923.6 | D31: 7655.1724 | E31: 48.1 | F31: 344.82759 | G31: 368.5 | H31: 172.41379 | I31: 0 | K31: 3530.7 | M31: =K31+L31 -> 3530.7 | N31: 1379.3103 | O31: 111 | P31: 1560 | Q31: =SUM(O31:P31) -> 1671 | R31: 1034.4828 | S31: 3472.4 | T31: 2827.5862 | U31: =C31+E31+G31+I31+M31+Q31+S31 -> 22014.3 | V31: =D31+F31+H31+J31+N31+R31+T31 -> 13413.793 | W31: 0 | Y31: =SUM(U31+W31) -> 22014.3 | Z31: =SUM(V31+X31) -> 13413.793 | AA31: bedeckt, Regenschauer | AB31: 8 | AC31: °C | AF31: =+C31+E31+G31+K31+O31+W31 -> 16981.9
A32: =SUM(A31+1) -> 25 | B32: So | C32: 10113.6 | D32: 7655.1724 | E32: 3458.7 | F32: 344.82759 | G32: 823.3 | H32: 172.41379 | I32: 0 | K32: 4098.5 | M32: =K32+L32 -> 4098.5 | N32: 1379.3103 | O32: 0 | P32: 0 | Q32: =SUM(O32:P32) -> 0 | R32: 1034.4828 | S32: 2600 | T32: 2827.5862 | U32: =C32+E32+G32+I32+M32+Q32+S32 -> 21094.1 | V32: =D32+F32+H32+J32+N32+R32+T32 -> 13413.793 | W32: 0 | Y32: =SUM(U32+W32) -> 21094.1 | Z32: =SUM(V32+X32) -> 13413.793 | AA32: sonnig | AB32: 9 | AC32: °C | AF32: =+C32+E32+G32+K32+O32+W32 -> 18494.1
A33: KW | B33: =SUM(B25+1) -> 8 | C33: =SUM(C26:C32) -> 57557.3 | D33: =SUM(D26:D32) -> 53586.207 | E33: =SUM(E26:E32) -> 3621.8 | F33: =SUM(F26:F32) -> 2413.7931 | G33: =SUM(G26:G32) -> 1589.1 | H33: =SUM(H26:H32) -> 1206.8966 | I33: =SUM(I26:I32) -> 0 | J33: =SUM(J26:J32) -> 0 | ... Z33: =SUM(Z26:Z32) -> 93896.552 | AA33: Ø Temp | AB33: =SUM(AB26:AB32)/7 -> 9.4285714 | AC33: °C
A34: =SUM(A32+1) -> 26 | B34: Mo | C34: 4841.7 | D34: 7655.1724 | E34: 0 | F34: 344.82759 | G34: 5.1 | H34: 172.41379 | I34: 0 | K34: 533 | M34: =K34+L34 -> 533 | N34: 1379.3103 | O34: 31.6 | P34: 2749 | Q34: =SUM(O34:P34) -> 2780.6 | R34: 1034.4828 | S34: 3556.2 | T34: 2827.5862 | U34: =C34+E34+G34+I34+M34+Q34+S34 -> 11716.6 | V34: =D34+F34+H34+J34+N34+R34+T34 -> 13413.793 | W34: 0 | Y34: =SUM(U34+W34) -> 11716.6 | Z34: =SUM(V34+X34) -> 13413.793 | AA34: bedeckt, sonnig | AB34: 10 | AC34: °C | AF34: =+C34+E34+G34+K34+O34+W34 -> 5411.4
A35: =SUM(A34+1) -> 27 | B35: Di. | C35: 4364.3 | D35: 7655.1724 | E35: 0 | F35: 344.82759 | G35: 20.9 | H35: 172.41379 | I35: 0 | K35: 207.7 | M35: =K35+L35 -> 207.7 | N35: 1379.3103 | O35: 79 | P35: 3316 | Q35: =SUM(O35:P35) -> 3395 | R35: 1034.4828 | S35: 4156.7 | T35: 2827.5862 | U35: =C35+E35+G35+I35+M35+Q35+S35 -> 12144.6 | V35: =D35+F35+H35+J35+N35+R35+T35 -> 13413.793 | W35: 0 | Y35: =SUM(U35+W35) -> 12144.6 | Z35: =SUM(V35+X35) -> 13413.793 | AA35: bedeckt, sonnig | AB35: 8 | AC35: °C | AF35: =+C35+E35+G35+K35+O35+W35 -> 4671.9
A36: =SUM(A35+1) -> 28 | B36: Mi. | C36: 3779.7 | D36: 7655.1724 | E36: 0 | F36: 344.82759 | G36: 0 | H36: 172.41379 | I36: 0 | K36: 0 | M36: =K36+L36 -> 0 | N36: 1379.3103 | O36: 564.6 | P36: 4794 | Q36: =SUM(O36:P36) -> 5358.6 | R36: 1034.4828 | S36: 4194.3 | T36: 2827.5862 | U36: =C36+E36+G36+I36+M36+Q36+S36 -> 13332.6 | V36: =D36+F36+H36+J36+N36+R36+T36 -> 13413.793 | W36: 0 | Y36: =SUM(U36+W36) -> 13332.6 | Z36: =SUM(V36+X36) -> 13413.793 | AA36: Hochnebel | AB36: 7 | AC36: °C | AF36: =+C36+E36+G36+K36+O36+W36 -> 4344.3
A37: =SUM(A36+1) -> 29 | B37: Do. | C37: 5340 | D37: 7655.1724 | E37: 24.5 | F37: 344.82759 | G37: 146.6 | H37: 172.41379 | I37: 0 | K37: -740.7 | M37: =K37+L37 -> -740.7 | N37: 1379.3103 | O37: 959.5 | P37: 4798 | Q37: =SUM(O37:P37) -> 5757.5 | R37: 1034.4828 | S37: 3193.5 | T37: 2827.5862 | U37: =C37+E37+G37+I37+M37+Q37+S37 -> 13721.4 | V37: =D37+F37+H37+J37+N37+R37+T37 -> 13413.793 | W37: 0 | Y37: =SUM(U37+W37) -> 13721.4 | Z37: =SUM(V37+X37) -> 13413.793 | AA37: teilweise sonnig | AB37: 11 | AC37: °C | AF37: =+C37+E37+G37+K37+O37+W37 -> 5729.9
A38: KW | B38: =SUM(B33+1) -> 9 | C38: =SUM(C34:C37) -> 18325.7 | D38: =SUM(D34:D37) -> 30620.69 | E38: =SUM(E34:E37) -> 24.5 | F38: =SUM(F34:F37) -> 1379.3103 | G38: =SUM(G34:G37) -> 172.6 | H38: =SUM(H34:H37) -> 689.65517 | I38: =SUM(I34:I37) -> 0 | J38: =SUM(J34:J37) -> 0 | ... Z38: =SUM(Z34:Z37) -> 53655.172 | AA38: Ø Temp | AB38: =SUM(AB26:AB32)/7 -> 9.4285714 | AC38: °C
A39: Umsatz kumuliert | C39: =SUM(C9+C17+C25+C33+C38) -> 239354.4 | D39: =SUM(D9+D17+D25+D33+D38) -> 222000 | E39: =SUM(E9+E17+E25+E33+E38) -> 8837.1 | F39: =SUM(F9+F17+F25+F33+F38) -> 10000 | G39: =SUM(G9+G17+G25+G33+G38) -> 5287.2 | H39: =SUM(H9+H17+H25+H33+H38) -> 5000 | I39: =SUM(I9+I17+I25+I33+I38) -> 0 | J39: =SUM(J9+J17+J25+J33+J38) -> 0 | ... Z39: =SUM(Z9+Z17+Z25+Z33+Z38) -> 389000 | AA39: Umsatz kumuliert | AF39: =SUM(AF5:AF38) -> 285905.4
A40: Umsatz pro Tag | C40: =C39/28 -> 8548.3714 | D40: =D39/28 -> 7928.5714 | E40: =E39/28 -> 315.61071 | F40: =F39/28 -> 357.14286 | G40: =G39/28 -> 188.82857 | H40: =H39/28 -> 178.57143 | I40: =I39/28 -> 0 | J40: =J39/28 -> 0 | K40: =K39/28 -> 855.86786 | N40: =N39/28 -> 1428.5714 | O40: =O39/30 -> 282.08 | R40: =R39/30 -> 1000 | S40: =S39/28 -> 2717.4679 | T40: =T39/28 -> 2928.5714 | U40: =U39/28 -> 14711.125 | V40: =V39/28 -> 13892.857 | W40: =W39/28 -> 0 | X40: =X39/28 -> 0 | Y40: =Y39/28 -> 14711.125 | Z40: =Z39/28 -> 13892.857 | AA40: Budget pro Tag
A41: Diff. zu Budget | C41: =SUM(C39-D39) -> 17354.4 | E41: =SUM(E39-F39) -> -1162.9 | G41: =SUM(G39-H39) -> 287.2 | I41: =SUM(I39-J39) -> 0 | K41: =SUM(K39-N39) -> -16035.7 | R41: =SUM(Q39-R39) -> 28379.4 | S41: =SUM(S39-T39) -> -5910.9 | U41: =SUM(U39-V39) -> 22911.5 | W41: =SUM(W39-X39) -> 0 | Y41: =SUM(Y39-Z39) -> 22911.5
...

Sheet 03_24
A1: Tagesumsätze | H1: 45352
C3: Restaurant | E3: Terrasse | G3: Lounge | I3: Pavillon | K3: Bankett | O3: Seminar | S3: Hotel | U3: TOTAL Gesamtbetrieb ohne Seebad | W3: Seebad | Y3: TOTAL Gesamtbetrieb mit Seebad | AA3: Info's | AF3: Gegenkontrolle Gastronovi
C4: IST | D4: Budget | E4: IST | F4: Budget | G4: IST | H4: Budget | I4: IST | J4: Budget | K4: IST/GN | L4: IST/ET | M4: TOTAL IST | N4: Budget | O4: IST/GN | P4: IST/ET | Q4: TOTAL IST | R4: Budget | S4: IST | T4: Budget | U4: IST | V4: Budget | W4: IST | X4: Budget | Y4: IST | Z4: Budget | AA4: Wetter | AB4: Temp. | AD4: Bemerkung
A5: 1 | B5: Fr | C5: 9673.9 | D5: 8064.5161 | E5: 0 | F5: 645.16129 | G5: 0 | H5: 161.29032 | I5: 0 | J5: 0 | K5: 4219 | M5: =K5+L5 -> 4219 | N5: 1935.4839 | O5: -3 | P5: 0 | Q5: =SUM(O5:P5) -> -3 | R5: 3225.8065 | S5: 2780.1 | T5: 3735.4839 | U5: =SUM(C5+E5+G5+I5+M5+Q5+S5) -> 16670 | V5: =SUM(D5+F5+H5+J5+N5+R5+T5) -> 17767.742 | W5: 0 | Y5: =SUM(U5+W5) -> 16670 | Z5: =SUM(V5+X5) -> 17767.742 | AA5: Regenschauer, trockene Abschnitte | AB5: 9 | AC5: °C | AE5: OK/SN | AF5: =C5+E5+G5+K5+O5+W5 -> 13889.9
A6: =SUM(A5+1) -> 2 | B6: Sa | C6: 11755.6 | D6: 8064.5161 | E6: 1211.2 | F6: 645.16129 | G6: 912.7 | H6: 161.29032 | I6: 0 | J6: 0 | K6: 0 | M6: =K6+L6 -> 0 | N6: 1935.4839 | O6: 0 | P6: 0 | Q6: =SUM(O6:P6) -> 0 | R6: 3225.8065 | S6: 5473 | T6: 3735.4839 | U6: =SUM(C6+E6+G6+I6+K6+Q6+S6) -> 19352.5 | V6: =SUM(D6+F6+H6+J6+N6+R6+T6) -> 17767.742 | W6: 0 | Y6: =SUM(U6+W6) -> 19352.5 | Z6: =SUM(V6+X6) -> 17767.742 | AA6: bewölkt, sonnig | AB6: 11 | AC6: °C | AE6: OK/SN | AF6: =C6+E6+G6+K6+O6+W6 -> 13879.5
A7: =SUM(A6+1) -> 3 | B7: So | C7: 9719.7 | D7: 8064.5161 | E7: 1746.2 | F7: 645.16129 | G7: 463.5 | H7: 161.29032 | I7: 0 | J7: 0 | K7: 5500 | M7: =K7+L7 -> 5500 | N7: 1935.4839 | O7: 0 | P7: 0 | Q7: =SUM(O7:P7) -> 0 | R7: 3225.8065 | S7: 1323.3 | T7: 3735.4839 | U7: =SUM(C7+E7+G7+I7+K7+Q7+S7) -> 18752.7 | V7: =SUM(D7+F7+H7+J7+N7+R7+T7) -> 17767.742 | W7: 0 | Y7: =SUM(U7+W7) -> 18752.7 | Z7: =SUM(V7+X7) -> 17767.742 | AA7: ziemlich sonnig | AB7: 14 | AC7: °C | AE7: OK/SN | AF7: =C7+E7+G7+K7+O7+W7 -> 17429.4
A8: KW | B8: 9 | C8: =SUM(C5:C7) -> 31149.2 | D8: =SUM(D5:D7) -> 24193.548 | E8: =SUM(E5:E7) -> 2957.4 | F8: =SUM(F5:F7) -> 1935.4839 | G8: =SUM(G5:G7) -> 1376.2 | H8: =SUM(H5:H7) -> 483.87097 | I8: =SUM(I5:I7) -> 0 | J8: =SUM(J5:J7) -> 0 | ... Z8: =SUM(Z5:Z7) -> 53303.226 | AA8: Ø Temp | AB8: =SUM(AB5:AB7)/7 -> 4.8571429 | AC8: °C
A9: =SUM(A7+1) -> 4 | B9: Mo | C9: 3732.3 | D9: 8064.5161 | E9: 0 | F9: 645.16129 | G9: 334 | H9: 161.29032 | I9: 0 | J9: 0 | K9: 0 | M9: =K9+L9 -> 0 | N9: 1935.4839 | O9: 580.7 | P9: 3090 | Q9: =SUM(O9:P9) -> 3670.7 | R9: 3225.8065 | S9: 1328.7 | T9: 3735.4839 | U9: =SUM(C9+E9+G9+I9+K9+Q9+S9) -> 9065.7 | V9: =SUM(D9+F9+H9+J9+N9+R9+T9) -> 17767.742 | W9: 0 | Y9: =SUM(U9+W9) -> 9065.7 | Z9: =SUM(V9+X9) -> 17767.742 | AA9: bedeckt | AB9: 8 | AC9: °C | AE9: OK/SN | AF9: =C9+E9+G9+K9+O9+W9 -> 4647
A10: =SUM(A9+1) -> 5 | B10: Di | C10: 6198.5 | D10: 8064.5161 | E10: 0 | F10: 645.16129 | G10: 0 | H10: 161.29032 | I10: 0 | J10: 0 | K10: 1000 | M10: =K10+L10 -> 1000 | N10: 1935.4839 | O10: 0 | P10: 2266 | Q10: =SUM(O10:P10) -> 2266 | R10: 3225.8065 | S10: 1370.5 | T10: 3735.4839 | U10: =SUM(C10+E10+G10+I10+K10+Q10+S10) -> 10835 | V10: =SUM(D10+F10+H10+J10+N10+R10+T10) -> 17767.742 | W10: 0 | Y10: =SUM(U10+W10) -> 10835 | Z10: =SUM(V10+X10) -> 17767.742 | AA10: regenschauer, bedeckt | AB10: 6 | AC10: °C | AE10: OK/SN | AF10: =C10+E10+G10+K10+O10+W10 -> 7198.5
A11: =SUM(A10+1) -> 6 | B11: Mi | C11: 3697.2 | D11: 8064.5161 | E11: 0 | F11: 645.16129 | G11: 0 | H11: 161.29032 | I11: 0 | J11: 0 | K11: 0 | M11: =K11+L11 -> 0 | N11: 1935.4839 | O11: 891.7 | P11: 896 | Q11: =SUM(O11:P11) -> 1787.7 | R11: 3225.8065 | S11: 3995 | T11: 3735.4839 | U11: =SUM(C11+E11+G11+I11+K11+Q11+S11) -> 9479.9 | V11: =SUM(D11+F11+H11+J11+N11+R11+T11) -> 17767.742 | W11: 0 | Y11: =SUM(U11+W11) -> 9479.9 | Z11: =SUM(V11+X11) -> 17767.742 | AA11: Schnee, Regen | AB11: 4 | AC11: °C | AE11: OK/SN | AF11: =C11+E11+G11+K11+O11+W11 -> 4588.9
A12: =SUM(A11+1) -> 7 | B12: Do | C12: 6109.6 | D12: 8064.5161 | E12: 0 | F12: 645.16129 | G12: 0 | H12: 161.29032 | I12: 0 | J12: 0 | K12: 2325.3 | M12: =K12+L12 -> 2325.3 | N12: 1935.4839 | O12: 60 | P12: 2251 | Q12: =SUM(O12:P12) -> 2311 | R12: 3225.8065 | S12: 1688.6 | T12: 3735.4839 | U12: =SUM(C12+E12+G12+I12+K12+Q12+S12) -> 12434.5 | V12: =SUM(D12+F12+H12+J12+N12+R12+T12) -> 17767.742 | W12: 0 | Y12: =SUM(U12+W12) -> 12434.5 | Z12: =SUM(V12+X12) -> 17767.742 | AA12: ziemlich sonnig | AB12: 8 | AC12: °C | AF12: =C12+E12+G12+K12+O12+W12 -> 8494.9
A13: =SUM(A12+1) -> 8 | B13: Fr | C13: 9738.3 | D13: 8064.5161 | E13: 0 | F13: 645.16129 | G13: 192.8 | H13: 161.29032 | I13: 0 | J13: 0 | K13: 1111.7 | M13: =K13+L13 -> 1111.7 | N13: 1935.4839 | O13: 0 | P13: 0 | Q13: =SUM(O13:P13) -> 0 | R13: 3225.8065 | S13: 2551.3 | T13: 3735.4839 | U13: =SUM(C13+E13+G13+I13+K13+Q13+S13) -> 13594.1 | V13: =SUM(D13+F13+H13+J13+N13+R13+T13) -> 17767.742 | W13: 0 | Y13: =SUM(U13+W13) -> 13594.1 | Z13: =SUM(V13+X13) -> 17767.742 | AA13: bedeckt, teilweise sonnig | AB13: 10 | AC13: °C | AF13: =C13+E13+G13+K13+O13+W13 -> 11042.8
A14: =SUM(A13+1) -> 9 | B14: Sa | C14: 10815.2 | D14: 8064.5161 | E14: 556.9 | F14: 645.16129 | G14: 464.4 | H14: 161.29032 | I14: 0 | J14: 0 | K14: 8866.1 | M14: =K14+L14 -> 8866.1 | N14: 1935.4839 | O14: 0 | P14: 0 | Q14: =SUM(O14:P14) -> 0 | R14: 3225.8065 | S14: 5314.8 | T14: 3735.4839 | U14: =SUM(C14+E14+G14+I14+K14+Q14+S14) -> 26017.4 | V14: =SUM(D14+F14+H14+J14+N14+R14+T14) -> 17767.742 | W14: 0 | Y14: =SUM(U14+W14) -> 26017.4 | Z14: =SUM(V14+X14) -> 17767.742 | AA14: bewölkt, sonnig | AB14: 13 | AC14: °C | AF14: =C14+E14+G14+K14+O14+W14 -> 20702.6
A15: =SUM(A14+1) -> 10 | B15: So | C15: 12581.2 | D15: 8064.5161 | E15: 0 | F15: 645.16129 | G15: 23 | H15: 161.29032 | I15: 0 | J15: 0 | K15: 7885.6 | M15: =K15+L15 -> 7885.6 | N15: 1935.4839 | O15: 2009.8 | P15: 0 | Q15: =SUM(O15:P15) -> 2009.8 | R15: 3225.8065 | S15: 3651 | T15: 3735.4839 | U15: =SUM(C15+E15+G15+I15+K15+Q15+S15) -> 26150.6 | V15: =SUM(D15+F15+H15+J15+N15+R15+T15) -> 17767.742 | W15: 0 | Y15: =SUM(U15+W15) -> 26150.6 | Z15: =SUM(V15+X15) -> 17767.742 | AA15: Zunächst bedeckt | AB15: 12 | AC15: °C | AF15: =C15+E15+G15+K15+O15+W15 -> 22499.6
A16: KW | B16: =SUM(B8+1) -> 10 | C16: =SUM(C9:C15) -> 52872.3 | D16: =SUM(D9:D15) -> 56451.613 | E16: =SUM(E9:E15) -> 556.9 | F16: =SUM(F9:F15) -> 4516.129 | G16: =SUM(G9:G15) -> 1014.2 | H16: =SUM(H9:H15) -> 1129.0323 | I16: =SUM(I9:I15) -> 0 | J16: =SUM(J9:J15) -> 0 | ... Z16: =SUM(Z9:Z15) -> 124374.19 | AA16: Ø Temp | AB16: =SUM(AB9:AB15)/7 -> 8.7142857 | AC16: °C
A17: =SUM(A15+1) -> 11 | B17: Mo | C17: 7727.6 | D17: 8064.5161 | E17: 24 | F17: 645.16129 | G17: 97.8 | H17: 161.29032 | I17: 0 | J17: 0 | K17: 0 | M17: =K17+L17 -> 0 | N17: 1935.4839 | O17: 1115.9 | P17: 1177 | Q17: =SUM(O17:P17) -> 2292.9 | R17: 3225.8065 | S17: 5667.4 | T17: 3735.4839 | U17: =SUM(C17+E17+G17+I17+K17+Q17+S17) -> 15809.7 | V17: =SUM(D17+F17+H17+J17+N17+R17+T17) -> 17767.742 | W17: 0 | Y17: =SUM(U17+W17) -> 15809.7 | Z17: =SUM(V17+X17) -> 17767.742 | AA17: Tageshälfte bewölkt | AB17: 10 | AC17: °C | AF17: =C17+E17+G17+K17+O17+W17 -> 8965.3
A18: =SUM(A17+1) -> 12 | B18: Di | C18: 2757.8 | D18: 8064.5161 | E18: 0 | F18: 645.16129 | G18: 9.5 | H18: 161.29032 | I18: 0 | J18: 0 | K18: 1668.8 | M18: =K18+L18 -> 1668.8 | N18: 1935.4839 | O18: 1361 | P18: 7456 | Q18: =SUM(O18:P18) -> 8817 | R18: 3225.8065 | S18: 6985.7 | T18: 3735.4839 | U18: =SUM(C18+E18+G18+I18+K18+Q18+S18) -> 20238.8 | V18: =SUM(D18+F18+H18+J18+N18+R18+T18) -> 17767.742 | W18: 0 | Y18: =SUM(U18+W18) -> 20238.8 | Z18: =SUM(V18+X18) -> 17767.742 | AA18: bedeckt, Regenschauer | AB18: 9 | AC18: °C | AF18: =C18+E18+G18+K18+O18+W18 -> 5797.1
A19: =SUM(A18+1) -> 13 | B19: Mi | C19: 5438.8 | D19: 8064.5161 | E19: 0 | F19: 645.16129 | G19: 0 | H19: 161.29032 | I19: 0 | J19: 0 | K19: 0 | M19: =K19+L19 -> 0 | N19: 1935.4839 | O19: 1085.2 | P19: 4503 | Q19: =SUM(O19:P19) -> 5588.2 | R19: 3225.8065 | S19: 6786.4 | T19: 3735.4839 | U19: =SUM(C19+E19+G19+I19+K19+Q19+S19) -> 17813.4 | V19: =SUM(D19+F19+H19+J19+N19+R19+T19) -> 17767.742 | W19: 0 | Y19: =SUM(U19+W19) -> 17813.4 | Z19: =SUM(V19+X19) -> 17767.742 | AA19: teilweise sonnig | AB19: 9 | AC19: °C | AF19: =C19+E19+G19+K19+O19+W19 -> 6524
A20: =SUM(A19+1) -> 14 | B20: Do | C20: 8425.9 | D20: 8064.5161 | E20: 1019.2 | F20: 645.16129 | G20: 374.1 | H20: 161.29032 | I20: 0 | J20: 0 | K20: 175.5 | M20: =K20+L20 -> 175.5 | N20: 1935.4839 | O20: 1967.8 | P20: 2953 | Q20: =SUM(O20:P20) -> 4920.8 | R20: 3225.8065 | S20: 6778.5 | T20: 3735.4839 | U20: =SUM(C20+E20+G20+I20+K20+Q20+S20) -> 21694 | V20: =SUM(D20+F20+H20+J20+N20+R20+T20) -> 17767.742 | W20: 0 | Y20: =SUM(U20+W20) -> 21694 | Z20: =SUM(V20+X20) -> 17767.742 | AA20: neblig, bedeckt | AB20: 15 | AC20: °C | AF20: =C20+E20+G20+K20+O20+W20 -> 11962.5
A21: =SUM(A20+1) -> 15 | B21: Fr | C21: 8266 | D21: 8064.5161 | E21: 0 | F21: 645.16129 | G21: 249.5 | H21: 161.29032 | I21: 0 | J21: 0 | K21: 0 | M21: =K21+L21 -> 0 | N21: 1935.4839 | O21: 1228.9 | P21: 7423 | Q21: =SUM(O21:P21) -> 8651.9 | R21: 3225.8065 | S21: 4334.1 | T21: 3735.4839 | U21: =SUM(C21+E21+G21+I21+K21+Q21+S21) -> 21501.5 | V21: =SUM(D21+F21+H21+J21+N21+R21+T21) -> 17767.742 | W21: 0 | Y21: =SUM(U21+W21) -> 21501.5 | Z21: =SUM(V21+X21) -> 17767.742 | AA21: bedeckt, Regenschauer | AB21: 16 | AC21: °C | AF21: =C21+E21+G21+K21+O21+W21 -> 9744.4
A22: =SUM(A21+1) -> 16 | B22: Sa | C22: 14353.6 | D22: 8064.5161 | E22: 24 | F22: 645.16129 | G22: 184.6 | H22: 161.29032 | I22: 0 | J22: 0 | K22: 0 | M22: =K22+L22 -> 0 | N22: 1935.4839 | O22: 8 | P22: 1494 | Q22: =SUM(O22:P22) -> 1502 | R22: 3225.8065 | S22: 4017.6 | T22: 3735.4839 | U22: =SUM(C22+E22+G22+I22+K22+Q22+S22) -> 20081.8 | V22: =SUM(D22+F22+H22+J22+N22+R22+T22) -> 17767.742 | W22: 0 | Y22: =SUM(U22+W22) -> 20081.8 | Z22: =SUM(V22+X22) -> 17767.742 | AA22: bedeckt, Regenschauer | AB22: 11 | AC22: °C | AF22: =C22+E22+G22+K22+O22+W22 -> 14570.2
A23: =SUM(A22+1) -> 17 | B23: So | C23: 12780.6 | D23: 8064.5161 | E23: 0 | F23: 645.16129 | G23: 0 | H23: 161.29032 | I23: 0 | J23: 0 | K23: 9436.5 | M23: =K23+L23 -> 9436.5 | N23: 1935.4839 | O23: 0 | P23: 0 | Q23: =SUM(O23:P23) -> 0 | R23: 3225.8065 | S23: 2084.2 | T23: 3735.4839 | U23: =SUM(C23+E23+G23+I23+K23+Q23+S23) -> 24301.3 | V23: =SUM(D23+F23+H23+J23+N23+R23+T23) -> 17767.742 | W23: 0 | Y23: =SUM(U23+W23) -> 24301.3 | Z23: =SUM(V23+X23) -> 17767.742 | AA23: trockene Abschnitte, Regenschauer | AB23: 11 | AC23: °C | AF23: =C23+E23+G23+K23+O23+W23 -> 22217.1
A24: KW | B24: =SUM(B16+1) -> 11 | C24: =SUM(C17:C23) -> 59750.3 | D24: =SUM(D17:D23) -> 56451.613 | E24: =SUM(E17:E23) -> 1067.2 | F24: =SUM(F17:F23) -> 4516.129 | G24: =SUM(G17:G23) -> 915.5 | H24: =SUM(H17:H23) -> 1129.0323 | I24: =SUM(I17:I23) -> 0 | J24: =SUM(J17:J23) -> 0 | ... Z24: =SUM(Z17:Z23) -> 124374.19 | AA24: Ø Temp | AB24: =SUM(AB17:AB23)/7 -> 11.571429 | AC24: °C
A25: =SUM(A23+1) -> 18 | B25: Mo | C25: 5532.6 | D25: 8064.5161 | E25: 0 | F25: 645.16129 | G25: 0 | H25: 161.29032 | I25: 0 | J25: 0 | K25: 0 | M25: =K25+L25 -> 0 | N25: 1935.4839 | O25: 0 | P25: 0 | Q25: =SUM(O25:P25) -> 0 | R25: 3225.8065 | S25: 2000.3 | T25: 3735.4839 | U25: =SUM(C25+E25+G25+I25+K25+Q25+S25) -> 7532.9 | V25: =SUM(D25+F25+H25+J25+N25+R25+T25) -> 17767.742 | W25: 0 | Y25: =SUM(U25+W25) -> 7532.9 | Z25: =SUM(V25+X25) -> 17767.742 | AA25: Regen, Gewitter | AB25: 10 | AC25: °C | AF25: =C25+E25+G25+K25+O25+W25 -> 5532.6
A26: =SUM(A25+1) -> 19 | B26: Di | C26: 5510.2 | D26: 8064.5161 | E26: 520 | F26: 645.16129 | G26: 538.6 | H26: 161.29032 | I26: 0 | J26: 0 | K26: 760 | M26: =K26+L26 -> 760 | N26: 1935.4839 | O26: 692 | P26: 4374 | Q26: =SUM(O26:P26) -> 5066 | R26: 3225.8065 | S26: 5557.3 | T26: 3735.4839 | U26: =SUM(C26+E26+G26+I26+K26+Q26+S26) -> 17952.1 | V26: =SUM(D26+F26+H26+J26+N26+R26+T26) -> 17767.742 | W26: 0 | Y26: =SUM(U26+W26) -> 17952.1 | Z26: =SUM(V26+X26) -> 17767.742 | AA26: hohe Wolkenfelder | AB26: 15 | AC26: °C | AF26: =C26+E26+G26+K26+O26+W26 -> 8020.8
A27: =SUM(A26+1) -> 20 | B27: Mi | C27: 5881.2 | D27: 8064.5161 | E27: 1955.1 | F27: 645.16129 | G27: 684.3 | H27: 161.29032 | I27: 0 | J27: 0 | K27: 0 | M27: =K27+L27 -> 0 | N27: 1935.4839 | O27: 1471.1 | P27: 4400 | Q27: =SUM(O27:P27) -> 5871.1 | R27: 3225.8065 | S27: 6574.1 | T27: 3735.4839 | U27: =SUM(C27+E27+G27+I27+K27+Q27+S27) -> 20965.8 | V27: =SUM(D27+F27+H27+J27+N27+R27+T27) -> 17767.742 | W27: 0 | Y27: =SUM(U27+W27) -> 20965.8 | Z27: =SUM(V27+X27) -> 17767.742 | AA27: Sonnig | AB27: 17 | AC27: °C | AF27: =C27+E27+G27+K27+O27+W27 -> 9991.7
A28: =SUM(A27+1) -> 21 | B28: Do | C28: 6205.1 | D28: 8064.5161 | E28: 200.5 | F28: 645.16129 | G28: 173.8 | H28: 161.29032 | I28: 0 | J28: 0 | K28: 2014.4 | M28: =K28+L28 -> 2014.4 | N28: 1935.4839 | O28: 1557.3 | P28: 5633 | Q28: =SUM(O28:P28) -> 7190.3 | R28: 3225.8065 | S28: 6598.3 | T28: 3735.4839 | U28: =SUM(C28+E28+G28+I28+K28+Q28+S28) -> 22382.4 | V28: =SUM(D28+F28+H28+J28+N28+R28+T28) -> 17767.742 | W28: 0 | Y28: =SUM(U28+W28) -> 22382.4 | Z28: =SUM(V28+X28) -> 17767.742 | AA28: Regenschauer | AB28: 12 | AC28: °C | AF28: =C28+E28+G28+K28+O28+W28 -> 10151.1
A29: =SUM(A28+1) -> 22 | B29: Fr | C29: 9918.2 | D29: 8064.5161 | E29: 3193.6 | F29: 645.16129 | G29: 294.5 | H29: 161.29032 | I29: 0 | J29: 0 | K29: 5898.7 | M29: =K29+L29 -> 5898.7 | N29: 1935.4839 | O29: 124.6 | P29: 6275 | Q29: =SUM(O29:P29) -> 6399.6 | R29: 3225.8065 | S29: 3930.7 | T29: 3735.4839 | U29: =SUM(C29+E29+G29+I29+K29+Q29+S29) -> 29635.3 | V29: =SUM(D29+F29+H29+J29+N29+R29+T29) -> 17767.742 | W29: 0 | Y29: =SUM(U29+W29) -> 29635.3 | Z29: =SUM(V29+X29) -> 17767.742 | AA29: Sonnig | AB29: 18 | AC29: °C | AF29: =C29+E29+G29+K29+O29+W29 -> 19429.6
A30: =SUM(A29+1) -> 23 | B30: Sa | C30: 10442.7 | D30: 8064.5161 | E30: 0 | F30: 645.16129 | G30: 40.7 | H30: 161.29032 | I30: 0 | J30: 0 | K30: 15255.6 | M30: =K30+L30 -> 15255.6 | N30: 1935.4839 | O30: 0 | P30: 1452 | Q30: =SUM(O30:P30) -> 1452 | R30: 3225.8065 | S30: 5632.5 | T30: 3735.4839 | U30: =SUM(C30+E30+G30+I30+K30+Q30+S30) -> 32823.5 | V30: =SUM(D30+F30+H30+J30+N30+R30+T30) -> 17767.742 | W30: 0 | Y30: =SUM(U30+W30) -> 32823.5 | Z30: =SUM(V30+X30) -> 17767.742 | AA30: Regenschauer, trockene Abschnitte | AB30: 12 | AC30: °C | AF30: =C30+E30+G30+K30+O30+W30 -> 25739
A31: =SUM(A30+1) -> 24 | B31: So | C31: 12537.6 | D31: 8064.5161 | E31: 0 | F31: 645.16129 | G31: 10.4 | H31: 161.29032 | I31: 0 | J31: 0 | K31: 8561.2 | M31: =K31+L31 -> 8561.2 | N31: 1935.4839 | O31: 1531.2 | P31: 400 | Q31: =SUM(O31:P31) -> 1931.2 | R31: 3225.8065 | S31: 3376.3 | T31: 3735.4839 | U31: =SUM(C31+E31+G31+I31+K31+Q31+S31) -> 26416.7 | V31: =SUM(D31+F31+H31+J31+N31+R31+T31) -> 17767.742 | W31: 0 | Y31: =SUM(U31+W31) -> 26416.7 | Z31: =SUM(V31+X31) -> 17767.742 | AA31: Regenschauer, Wind | AB31: 5 | AC31: °C | AF31: =C31+E31+G31+K31+O31+W31 -> 22640.4
A32: KW | B32: =SUM(B24+1) -> 12 | C32: =SUM(C25:C31) -> 56027.6 | D32: =SUM(D25:D31) -> 56451.613 | E32: =SUM(E25:E31) -> 5869.2 | F32: =SUM(F25:F31) -> 4516.129 | G32: =SUM(G25:G31) -> 1742.3 | H32: =SUM(H25:H31) -> 1129.0323 | I32: =SUM(I25:I31) -> 0 | J32: =SUM(J25:J31) -> 0 | ... Z32: =SUM(Z25:Z31) -> 124374.19 | AA32: Ø Temp | AB32: =SUM(AB25:AB31)/7 -> 12.714286 | AC32: °C
A33: =SUM(A31+1) -> 25 | B33: Mo | C33: 5773.4 | D33: 8064.5161 | E33: 509.7 | F33: 645.16129 | G33: 352.5 | H33: 161.29032 | I33: 0 | J33: 0 | K33: 0 | M33: =K33+L33 -> 0 | N33: 1935.4839 | O33: 1541.6 | P33: 3679.5 | Q33: =SUM(O33:P33) -> 5221.1 | R33: 3225.8065 | S33: 5861.4 | T33: 3735.4839 | U33: =SUM(C33+E33+G33+I33+K33+Q33+S33) -> 17718.1 | V33: =SUM(D33+F33+H33+J33+N33+R33+T33) -> 17767.742 | W33: 0 | Y33: =SUM(U33+W33) -> 17718.1 | Z33: =SUM(V33+X33) -> 17767.742 | AA33: sonnig | AB33: 11 | AC33: °C | AF33: =C33+E33+G33+K33+O33+W33 -> 8177.2
A34: =SUM(A33+1) -> 26 | B34: Di | C34: 5609.3 | D34: 8064.5161 | E34: 926.9 | F34: 645.16129 | G34: 502.3 | H34: 161.29032 | I34: 0 | J34: 0 | K34: 4230.2 | M34: =K34+L34 -> 4230.2 | N34: 1935.4839 | O34: 1010.4 | P34: 4878 | Q34: =SUM(O34:P34) -> 5888.4 | R34: 3225.8065 | S34: 6279.5 | T34: 3735.4839 | U34: =SUM(C34+E34+G34+I34+K34+Q34+S34) -> 23436.6 | V34: =SUM(D34+F34+H34+J34+N34+R34+T34) -> 17767.742 | W34: 0 | Y34: =SUM(U34+W34) -> 23436.6 | Z34: =SUM(V34+X34) -> 17767.742 | AA34: bedeckt | AB34: 15 | AC34: °C | AF34: =C34+E34+G34+K34+O34+W34 -> 12279.1
A35: =SUM(A34+1) -> 27 | B35: Mi | C35: 4074.2 | D35: 8064.5161 | E35: 0 | F35: 645.16129 | G35: 54.1 | H35: 161.29032 | I35: 0 | J35: 0 | K35: 0 | M35: =K35+L35 -> 0 | N35: 1935.4839 | O35: 3919.2 | P35: 9876 | Q35: =SUM(O35:P35) -> 13795.2 | R35: 3225.8065 | S35: 7729.8 | T35: 3735.4839 | U35: =SUM(C35+E35+G35+I35+K35+Q35+S35) -> 25653.3 | V35: =SUM(D35+F35+H35+J35+N35+R35+T35) -> 17767.742 | W35: 0 | Y35: =SUM(U35+W35) -> 25653.3 | Z35: =SUM(V35+X35) -> 17767.742 | AA35: wechselhaft | AB35: 7 | AC35: °C | AF35: =C35+E35+G35+K35+O35+W35 -> 8047.5
A36: =SUM(A35+1) -> 28 | B36: Do | C36: 8647.3 | D36: 8064.5161 | E36: 0 | F36: 645.16129 | G36: 56.5 | H36: 161.29032 | I36: 0 | J36: 0 | K36: 300 | M36: =K36+L36 -> 300 | N36: 1935.4839 | O36: 95.1 | P36: 4475 | Q36: =SUM(O36:P36) -> 4570.1 | R36: 3225.8065 | S36: 3256.7 | T36: 3735.4839 | U36: =SUM(C36+E36+G36+I36+K36+Q36+S36) -> 16830.6 | V36: =SUM(D36+F36+H36+J36+N36+R36+T36) -> 17767.742 | W36: 0 | Y36: =SUM(U36+W36) -> 16830.6 | Z36: =SUM(V36+X36) -> 17767.742 | AA36: Regenschauner, sonnig | AB36: 11 | AC36: °C | AF36: =C36+E36+G36+K36+O36+W36 -> 9098.9
A37: =SUM(A36+1) -> 29 | B37: Fr | C37: 26778.2 | D37: 8064.5161 | E37: 1555.3 | F37: 645.16129 | G37: 779.6 | H37: 161.29032 | I37: 0 | J37: 0 | K37: 0 | M37: =K37+L37 -> 0 | N37: 1935.4839 | O37: 0 | P37: 0 | Q37: =SUM(O37:P37) -> 0 | R37: 3225.8065 | S37: 7998.6 | T37: 3735.4839 | U37: =SUM(C37+E37+G37+I37+K37+Q37+S37) -> 37111.7 | V37: =SUM(D37+F37+H37+J37+N37+R37+T37) -> 17767.742 | W37: 0 | Y37: =SUM(U37+W37) -> 37111.7 | Z37: =SUM(V37+X37) -> 17767.742 | AA37: Sonnig, hohe Wolkenfelder | AB37: 18 | AC37: °C | AD37: Karfreitag | AF37: =C37+E37+G37+K37+O37+W37 -> 29113.1
A38: =SUM(A37+1) -> 30 | B38: Sa | C38: 15624 | D38: 8064.5161 | E38: 284.7 | F38: 645.16129 | G38: 572.4 | H38: 161.29032 | I38: 0 | J38: 0 | K38: 0 | M38: =K38+L38 -> 0 | N38: 1935.4839 | O38: 0 | P38: 0 | Q38: =SUM(O38:P38) -> 0 | R38: 3225.8065 | S38: 10294.9 | T38: 3735.4839 | U38: =SUM(C38+E38+G38+I38+K38+Q38+S38) -> 26776 | V38: =SUM(D38+F38+H38+J38+N38+R38+T38) -> 17767.742 | W38: 0 | Y38: =SUM(U38+W38) -> 26776 | Z38: =SUM(V38+X38) -> 17767.742 | AA38: bedeckt, straker Regen | AB38: 18 | AC38: °C | AD38: Ostersamstag | AF38: =C38+E38+G38+K38+O38+W38 -> 16481.1
A39: =SUM(A38+1) -> 31 | B39: So | C39: 24421.6 | D39: 8064.5161 | E39: 1299.4 | F39: 645.16129 | G39: 771.1 | H39: 161.29032 | I39: 0 | J39: 0 | K39: 4293.1 | M39: =K39+L39 -> 4293.1 | N39: 1935.4839 | O39: 0 | P39: 0 | Q39: =SUM(O39:P39) -> 0 | R39: 3225.8065 | S39: 5238.6 | T39: 3735.4839 | U39: =SUM(C39+E39+G39+I39+K39+Q39+S39) -> 36023.8 | V39: =SUM(D39+F39+H39+J39+N39+R39+T39) -> 17767.742 | W39: 0 | Y39: =SUM(U39+W39) -> 36023.8 | Z39: =SUM(V39+X39) -> 17767.742 | AA39: bedeckt, Regenschauer | AB39: 16 | AC39: °C | AD39: Ostersonntag | AF39: =C39+E39+G39+K39+O39+W39 -> 30785.2
