Workbook

Sheet 01_25
A1: Tagesumsätze | H1: 45658
C3: Restaurant | E3: Terrasse | G3: Lounge | I3: Pavillon | M3: Bankett | Q3: Seminar | U3: Hotel | W3: TOTAL Gesamtbetrieb ohne Seebad | Y3: Seebad | AA3: TOTAL Gesamtbetrieb mit Seebad | AC3: Info's | AH3: Gegenkontrolle Gastronovi
C4: IST | D4: Budget | E4: IST | F4: Budget | G4: IST | H4: Budget | I4: IST/GN | J4: IST/ET | K4: TOTAL IST | L4: Budget | M4: IST/GN | N4: IST/ET | O4: TOTAL IST | P4: Budget | Q4: IST/GN | R4: IST/ET | S4: TOTAL IST | T4: Budget | U4: TOTAL IST | V4: Budget | W4: IST | X4: Budget | Y4: IST | Z4: Budget | AA4: IST | AB4: Budget | AC4: Wetter | AD4: Temp. | AF4: Bemerkung
A5: 1 | B5: Mi | C5: 8678.4 | D5: 6451.6129 | E5: 366 | F5: 80.645161 | G5: 319.3 | H5: 80.645161 | I5: 0 | K5: =I5+J5 -> 0 | L5: 0 | M5: 0 | N5: 0 | O5: =M5+N5 -> 0 | P5: 2022.5806 | Q5: 0 | R5: 0 | S5: =Q5+R5 -> 0 | T5: 3709.6774 | U5: 5468.5 | V5: 3945.1613 | W5: =SUM(C5+E5+G5+K5+O5+S5+U5) -> 14832.2 | X5: =SUM(D5+F5+H5+L5+P5+T5+V5) -> 16290.323 | Y5: 0 | AA5: =SUM(W5+Y5) -> 14832.2 | AB5: =SUM(X5+Z5) -> 16290.323 | AC5: bedeckt | AD5: 1 | AE5: °C | AH5: =C5+E5+G5+I5+M5+Q5+Y5 -> 9363.7
A6: =SUM(A5+1) -> 2 | B6: Do | C6: 7072 | D6: 6451.6129 | E6: 0 | F6: 80.645161 | G6: 5.1 | H6: 80.645161 | I6: 0 | K6: =I6+J6 -> 0 | L6: 0 | M6: 0 | N6: 0 | O6: =M6+N6 -> 0 | P6: 2022.5806 | Q6: 0 | R6: 0 | S6: =Q6+R6 -> 0 | T6: 3709.6774 | U6: 3246.62 | V6: 3945.1613 | W6: =SUM(C6+E6+G6+K6+O6+S6+U6) -> 10323.72 | X6: =SUM(D6+F6+H6+L6+P6+T6+V6) -> 16290.323 | Y6: 0 | AA6: =SUM(W6+Y6) -> 10323.72 | AB6: =SUM(X6+Z6) -> 16290.323 | AC6: Schneeregen | AD6: 1 | AE6: °C | AH6: =C6+E6+G6+I6+M6+Q6+Y6 -> 7077.1
A7: =SUM(A6+1) -> 3 | B7: Fr | C7: 5737.6 | D7: 6451.6129 | E7: 0 | F7: 80.645161 | G7: 41.8 | H7: 80.645161 | I7: 0 | K7: =I7+J7 -> 0 | L7: 0 | M7: 0 | O7: =M7+N7 -> 0 | P7: 2022.5806 | Q7: 0 | R7: 0 | S7: =Q7+R7 -> 0 | T7: 3709.6774 | U7: 3224.04 | V7: 3945.1613 | W7: =SUM(C7+E7+G7+K7+O7+S7+U7) -> 9003.44 | X7: =SUM(D7+F7+H7+L7+P7+T7+V7) -> 16290.323 | Y7: 0 | AA7: =SUM(W7+Y7) -> 9003.44 | AB7: =SUM(X7+Z7) -> 16290.323 | AC7: sonnig am NA | AD7: 2 | AE7: °C | AH7: =C7+E7+G7+I7+M7+Q7+Y7 -> 5779.4
A8: =SUM(A7+1) -> 4 | B8: Sa | C8: 12210 | D8: 6451.6129 | E8: 0 | F8: 80.645161 | G8: 39.1 | H8: 80.645161 | I8: 0 | K8: =I8+J8 -> 0 | L8: 0 | M8: 2755.5 | O8: =M8+N8 -> 2755.5 | P8: 2022.5806 | Q8: 0 | R8: 0 | S8: =Q8+R8 -> 0 | T8: 3709.6774 | U8: 3647.34 | V8: 3945.1613 | W8: =SUM(C8+E8+G8+K8+O8+S8+U8) -> 18651.94 | X8: =SUM(D8+F8+H8+L8+P8+T8+V8) -> 16290.323 | Y8: 0 | AA8: =SUM(W8+Y8) -> 18651.94 | AB8: =SUM(X8+Z8) -> 16290.323 | AC8: Schneeregen | AD8: -1 | AE8: °C | AH8: =C8+E8+G8+I8+M8+Q8+Y8 -> 15004.6
A9: =SUM(A8+1) -> 5 | B9: So | C9: 5389.9 | D9: 6451.6129 | E9: 0 | F9: 80.645161 | G9: 40.2 | H9: 80.645161 | I9: 0 | K9: =I9+J9 -> 0 | L9: 0 | M9: 314.6 | O9: =M9+N9 -> 314.6 | P9: 2022.5806 | Q9: 0 | R9: 0 | S9: =Q9+R9 -> 0 | T9: 3709.6774 | U9: 2144.1 | V9: 3945.1613 | W9: =SUM(C9+E9+G9+K9+O9+S9+U9) -> 7888.8 | X9: =SUM(D9+F9+H9+L9+P9+T9+V9) -> 16290.323 | Y9: 0 | AA9: =SUM(W9+Y9) -> 7888.8 | AB9: =SUM(X9+Z9) -> 16290.323 | AC9: bewölkt | AD9: 3 | AE9: °C | AF9: MA Feier ab 15:00 geschlossen | AH9: =C9+E9+G9+I9+M9+Q9+Y9 -> 5744.7
A10: KW | B10: 1 | C10: =SUM(C5:C9) -> 39087.9 | D10: =SUM(D5:D9) -> 32258.065 | E10: =SUM(E5:E9) -> 366 | F10: =SUM(F5:F9) -> 403.22581 | G10: =SUM(G5:G9) -> 445.5 | H10: =SUM(H5:H9) -> 403.22581 | I10: =SUM(I5:I9) -> 0 | J10: =SUM(J5:J9) -> 0 | K10: =SUM(K5:K9) -> 0 | L10: 0 | M10: =SUM(M5:M9) -> 3070.1 | N10: =SUM(N5:N9) -> 0 | O10: =SUM(O5:O9) -> 3070.1 | P10: =SUM(P5:P9) -> 10112.903 | Q10: =SUM(Q5:Q9) -> 0 | R10: =SUM(R5:R9) -> 0 | S10: =SUM(S5:S9) -> 0 | T10: =SUM(T5:T9) -> 18548.387 | ... AB10: =SUM(AB5:AB9) -> 81451.613 | AC10: Ø Temp | AD10: =SUM(AD5:AD9)/7 -> 0.85714286 | AE10: °C
A11: =SUM(A9+1) -> 6 | B11: Mo | C11: 5189.4 | D11: 6451.6129 | E11: 0 | F11: 80.645161 | G11: 0 | H11: 80.645161 | I11: 0 | K11: =I11+J11 -> 0 | L11: 0 | M11: 1737.4 | O11: =M11+N11 -> 1737.4 | P11: 2022.5806 | Q11: 1225 | R11: 2338 | S11: =Q11+R11 -> 3563 | T11: 3709.6774 | U11: 3658.7 | V11: 3945.1613 | W11: =SUM(C11+E11+G11+K11+O11+S11+U11) -> 14148.5 | X11: =SUM(D11+F11+H11+L11+P11+T11+V11) -> 16290.323 | Y11: 0 | AA11: =SUM(W11+Y11) -> 14148.5 | AB11: =SUM(X11+Z11) -> 16290.323 | AC11: regen | AD11: 5 | AE11: °C | AH11: =C11+E11+G11+I11+M11+Q11+Y11 -> 8151.8
A12: =SUM(A11+1) -> 7 | B12: Di | C12: 3482 | D12: 6451.6129 | E12: 0 | F12: 80.645161 | G12: 0 | H12: 80.645161 | I12: 0 | K12: =I12+J12 -> 0 | L12: 0 | M12: 820 | O12: =M12+N12 -> 820 | P12: 2022.5806 | Q12: 176.2 | R12: 1896 | S12: =Q12+R12 -> 2072.2 | T12: 3709.6774 | U12: 1776.9 | V12: 3945.1613 | W12: =SUM(C12+E12+G12+K12+O12+S12+U12) -> 8151.1 | X12: =SUM(D12+F12+H12+L12+P12+T12+V12) -> 16290.323 | Y12: 0 | AA12: =SUM(W12+Y12) -> 8151.1 | AB12: =SUM(X12+Z12) -> 16290.323 | AC12: sonnig am NA | AD12: 8 | AE12: °C | AH12: =C12+E12+G12+I12+M12+Q12+Y12 -> 4478.2
A13: =SUM(A12+1) -> 8 | B13: Mi | C13: 3186.7 | D13: 6451.6129 | E13: 0 | F13: 80.645161 | G13: 0 | H13: 80.645161 | I13: 0 | K13: =I13+J13 -> 0 | L13: 0 | M13: 0 | O13: =M13+N13 -> 0 | P13: 2022.5806 | Q13: 504.5 | R13: 275 | S13: =Q13+R13 -> 779.5 | T13: 3709.6774 | U13: 1065.95 | V13: 3945.1613 | W13: =SUM(C13+E13+G13+K13+O13+S13+U13) -> 5032.15 | X13: =SUM(D13+F13+H13+L13+P13+T13+V13) -> 16290.323 | Y13: 0 | AA13: =SUM(W13+Y13) -> 5032.15 | AB13: =SUM(X13+Z13) -> 16290.323 | AC13: bedeckt | AD13: 5 | AE13: °C | AH13: =C13+E13+G13+I13+M13+Q13+Y13 -> 3691.2
A14: =SUM(A13+1) -> 9 | B14: Do | C14: 5361.6 | D14: 6451.6129 | E14: 0 | F14: 80.645161 | G14: 0 | H14: 80.645161 | I14: 0 | K14: =I14+J14 -> 0 | L14: 0 | M14: 0 | O14: =M14+N14 -> 0 | P14: 2022.5806 | Q14: 0 | R14: 0 | S14: =Q14+R14 -> 0 | T14: 3709.6774 | U14: 1684.6 | V14: 3945.1613 | W14: =SUM(C14+E14+G14+K14+O14+S14+U14) -> 7046.2 | X14: =SUM(D14+F14+H14+L14+P14+T14+V14) -> 16290.323 | Y14: 0 | AA14: =SUM(W14+Y14) -> 7046.2 | AB14: =SUM(X14+Z14) -> 16290.323 | AC14: regenschauer | AD14: 8 | AE14: °C | AH14: =C14+E14+G14+I14+M14+Q14+Y14 -> 5361.6
A15: =SUM(A14+1) -> 10 | B15: Fr | C15: 7683.8 | D15: 6451.6129 | E15: 0 | F15: 80.645161 | G15: 0 | H15: 80.645161 | I15: 0 | K15: =I15+J15 -> 0 | L15: 0 | M15: 1876.5 | O15: =M15+N15 -> 1876.5 | P15: 2022.5806 | Q15: 811.7 | R15: 2672 | S15: =Q15+R15 -> 3483.7 | T15: 3709.6774 | U15: 1950.6 | V15: 3945.1613 | W15: =SUM(C15+E15+G15+K15+O15+S15+U15) -> 14994.6 | X15: =SUM(D15+F15+H15+L15+P15+T15+V15) -> 16290.323 | Y15: 0 | AA15: =SUM(W15+Y15) -> 14994.6 | AB15: =SUM(X15+Z15) -> 16290.323 | AC15: Regen-Schneeschauer | AD15: 1 | AE15: °C | AH15: =C15+E15+G15+I15+M15+Q15+Y15 -> 10372
A16: =SUM(A15+1) -> 11 | B16: Sa | C16: 10294 | D16: 6451.6129 | E16: 48.3 | F16: 80.645161 | G16: 389.8 | H16: 80.645161 | I16: 0 | K16: =I16+J16 -> 0 | L16: 0 | M16: 6580.2 | O16: =M16+N16 -> 6580.2 | P16: 2022.5806 | Q16: 0 | R16: 0 | S16: =Q16+R16 -> 0 | T16: 3709.6774 | U16: 3057.6 | V16: 3945.1613 | W16: =SUM(C16+E16+G16+K16+O16+S16+U16) -> 20369.9 | X16: =SUM(D16+F16+H16+L16+P16+T16+V16) -> 16290.323 | Y16: 0 | AA16: =SUM(W16+Y16) -> 20369.9 | AB16: =SUM(X16+Z16) -> 16290.323 | AC16: sonnig am NA | AD16: -3 | AE16: °C | AH16: =C16+E16+G16+I16+M16+Q16+Y16 -> 17312.3
A17: =SUM(A16+1) -> 12 | B17: So | C17: 10291.8 | D17: 6451.6129 | E17: 195.1 | F17: 80.645161 | G17: 293.9 | H17: 80.645161 | I17: 0 | K17: =I17+J17 -> 0 | L17: 0 | M17: 1300 | O17: =M17+N17 -> 1300 | P17: 2022.5806 | Q17: 0 | R17: 280 | S17: =Q17+R17 -> 280 | T17: 3709.6774 | U17: 2146 | V17: 3945.1613 | W17: =SUM(C17+E17+G17+K17+O17+S17+U17) -> 14506.8 | X17: =SUM(D17+F17+H17+L17+P17+T17+V17) -> 16290.323 | Y17: 0 | AA17: =SUM(W17+Y17) -> 14506.8 | AB17: =SUM(X17+Z17) -> 16290.323 | AC17: sonnig am NA | AD17: -4 | AE17: °C | AH17: =C17+E17+G17+I17+M17+Q17+Y17 -> 12080.8
A18: KW | B18: =SUM(B10+1) -> 2 | C18: =SUM(C11:C17) -> 45489.3 | D18: =SUM(D11:D17) -> 45161.29 | E18: =SUM(E11:E17) -> 243.4 | F18: =SUM(F11:F17) -> 564.51613 | G18: =SUM(G11:G17) -> 683.7 | H18: =SUM(H11:H17) -> 564.51613 | I18: =SUM(I11:I17) -> 0 | J18: =SUM(J11:J17) -> 0 | K18: =SUM(K11:K17) -> 0 | L18: 0 | M18: =SUM(M11:M17) -> 12314.1 | N18: =SUM(N11:N17) -> 0 | O18: =SUM(O11:O17) -> 12314.1 | P18: =SUM(P11:P17) -> 14158.065 | Q18: =SUM(Q11:Q17) -> 2717.4 | R18: =SUM(R11:R17) -> 7461 | S18: =SUM(S11:S17) -> 10178.4 | T18: =SUM(T11:T17) -> 25967.742 | ... AB18: =SUM(AB11:AB17) -> 114032.26 | AC18: Ø Temp | AD18: =SUM(AD11:AD17)/7 -> 2.8571429 | AE18: °C
A19: =SUM(A17+1) -> 13 | B19: Mo | C19: 3503.1 | D19: 6451.6129 | E19: 0 | F19: 80.645161 | G19: 0 | H19: 80.645161 | I19: 0 | K19: =I19+J19 -> 0 | L19: 0 | M19: 0 | O19: =M19+N19 -> 0 | P19: 2022.5806 | Q19: 115 | R19: 585 | S19: =Q19+R19 -> 700 | T19: 3709.6774 | U19: 4151.8 | V19: 3945.1613 | W19: =SUM(C19+E19+G19+K19+O19+S19+U19) -> 8354.9 | X19: =SUM(D19+F19+H19+L19+P19+T19+V19) -> 16290.323 | Y19: 0 | AA19: =SUM(W19+Y19) -> 8354.9 | AB19: =SUM(X19+Z19) -> 16290.323 | AC19: sonnig am NA | AD19: -4 | AE19: °C | AH19: =C19+E19+G19+I19+M19+Q19+Y19 -> 3618.1
A20: =SUM(A19+1) -> 14 | B20: Di | C20: 4733 | D20: 6451.6129 | E20: 0 | F20: 80.645161 | G20: 0 | H20: 80.645161 | I20: 0 | K20: =I20+J20 -> 0 | L20: 0 | M20: 0 | O20: =M20+N20 -> 0 | P20: 2022.5806 | Q20: 771.3 | R20: 545 | S20: =Q20+R20 -> 1316.3 | T20: 3709.6774 | U20: 4183.6 | V20: 3945.1613 | W20: =SUM(C20+E20+G20+K20+O20+S20+U20) -> 10232.9 | X20: =SUM(D20+F20+H20+L20+P20+T20+V20) -> 16290.323 | Y20: 0 | AA20: =SUM(W20+Y20) -> 10232.9 | AB20: =SUM(X20+Z20) -> 16290.323 | AC20: sonnig am NA | AD20: -5 | AE20: °C | AH20: =C20+E20+G20+I20+M20+Q20+Y20 -> 5504.3
A21: =SUM(A20+1) -> 15 | B21: Mi | C21: 4421.1 | D21: 6451.6129 | E21: 0 | F21: 80.645161 | G21: 0 | H21: 80.645161 | I21: 0 | K21: =I21+J21 -> 0 | L21: 0 | M21: 674.2 | O21: =M21+N21 -> 674.2 | P21: 2022.5806 | Q21: 1430.9 | R21: 460 | S21: =Q21+R21 -> 1890.9 | T21: 3709.6774 | U21: 5961.4 | V21: 3945.1613 | W21: =SUM(C21+E21+G21+K21+O21+S21+U21) -> 12947.6 | X21: =SUM(D21+F21+H21+L21+P21+T21+V21) -> 16290.323 | Y21: 0 | AA21: =SUM(W21+Y21) -> 12947.6 | AB21: =SUM(X21+Z21) -> 16290.323 | AC21: teilweise sonnig | AD21: -2 | AE21: °C | AH21: =C21+E21+G21+I21+M21+Q21+Y21 -> 6526.2
A22: =SUM(A21+1) -> 16 | B22: Do | C22: 5663 | D22: 6451.6129 | E22: 0 | F22: 80.645161 | G22: 0 | H22: 80.645161 | I22: 0 | K22: =I22+J22 -> 0 | L22: 0 | M22: 1000 | O22: =M22+N22 -> 1000 | P22: 2022.5806 | Q22: 796.3 | R22: 4362 | S22: =Q22+R22 -> 5158.3 | T22: 3709.6774 | U22: 4752.45 | V22: 3945.1613 | W22: =SUM(C22+E22+G22+K22+O22+S22+U22) -> 16573.75 | X22: =SUM(D22+F22+H22+L22+P22+T22+V22) -> 16290.323 | Y22: 0 | AA22: =SUM(W22+Y22) -> 16573.75 | AB22: =SUM(X22+Z22) -> 16290.323 | AC22: teilweise sonnig | AD22: 1 | AE22: °C | AH22: =C22+E22+G22+I22+M22+Q22+Y22 -> 7459.3
A23: =SUM(A22+1) -> 17 | B23: Fr | C23: 8229 | D23: 6451.6129 | E23: 0 | F23: 80.645161 | G23: 0 | H23: 80.645161 | I23: 0 | K23: =I23+J23 -> 0 | L23: 0 | M23: 0 | O23: =M23+N23 -> 0 | P23: 2022.5806 | Q23: 18 | R23: 3521 | S23: =Q23+R23 -> 3539 | T23: 3709.6774 | U23: 1787.8 | V23: 3945.1613 | W23: =SUM(C23+E23+G23+K23+O23+S23+U23) -> 13555.8 | X23: =SUM(D23+F23+H23+L23+P23+T23+V23) -> 16290.323 | Y23: 0 | AA23: =SUM(W23+Y23) -> 13555.8 | AB23: =SUM(X23+Z23) -> 16290.323 | AC23: teilweise sonnig | AD23: 2 | AE23: °C | AH23: =C23+E23+G23+I23+M23+Q23+Y23 -> 8247
A24: =SUM(A23+1) -> 18 | B24: Sa | C24: 10307.7 | D24: 6451.6129 | E24: 0 | F24: 80.645161 | G24: 0 | H24: 80.645161 | I24: 0 | K24: =I24+J24 -> 0 | L24: 0 | M24: 3227.9 | O24: =M24+N24 -> 3227.9 | P24: 2022.5806 | Q24: 2452 | R24: 11576 | S24: =Q24+R24 -> 14028 | T24: 3709.6774 | U24: 4332.9 | V24: 3945.1613 | W24: =SUM(C24+E24+G24+K24+O24+S24+U24) -> 31896.5 | X24: =SUM(D24+F24+H24+L24+P24+T24+V24) -> 16290.323 | Y24: 0 | AA24: =SUM(W24+Y24) -> 31896.5 | AB24: =SUM(X24+Z24) -> 16290.323 | AC24: teilweise sonnig | AD24: 2 | AE24: °C | AH24: =C24+E24+G24+I24+M24+Q24+Y24 -> 15987.6
A25: =SUM(A24+1) -> 19 | B25: So | C25: 7956.3 | D25: 6451.6129 | E25: 0 | F25: 80.645161 | G25: 65 | H25: 80.645161 | I25: 0 | K25: =I25+J25 -> 0 | L25: 0 | M25: 5851.3 | O25: =M25+N25 -> 5851.3 | P25: 2022.5806 | Q25: 0 | R25: 0 | S25: =Q25+R25 -> 0 | T25: 3709.6774 | U25: 1128.9 | V25: 3945.1613 | W25: =SUM(C25+E25+G25+K25+O25+S25+U25) -> 15001.5 | X25: =SUM(D25+F25+H25+L25+P25+T25+V25) -> 16290.323 | Y25: 0 | AA25: =SUM(W25+Y25) -> 15001.5 | AB25: =SUM(X25+Z25) -> 16290.323 | AC25: teilweise sonnig | AD25: 1 | AE25: °C | AH25: =C25+E25+G25+I25+M25+Q25+Y25 -> 13872.6
A26: KW | B26: =SUM(B18+1) -> 3 | C26: =SUM(C19:C25) -> 44813.2 | D26: =SUM(D19:D25) -> 45161.29 | E26: =SUM(E19:E25) -> 0 | F26: =SUM(F19:F25) -> 564.51613 | G26: =SUM(G19:G25) -> 65 | H26: =SUM(H19:H25) -> 564.51613 | I26: =SUM(I19:I25) -> 0 | J26: =SUM(J19:J25) -> 0 | ... AB26: =SUM(AB19:AB25) -> 114032.26 | AC26: Ø Temp | AD26: =SUM(AD19:AD25)/7 -> -0.71428571 | AE26: °C
A27: =SUM(A25+1) -> 20 | B27: Mo | C27: 6007.4 | D27: 6451.6129 | E27: 0 | F27: 80.645161 | G27: 0 | H27: 80.645161 | I27: 0 | K27: =I27+J27 -> 0 | L27: 0 | M27: 0 | O27: =M27+N27 -> 0 | P27: 2022.5806 | Q27: 130 | R27: 2833 | S27: =Q27+R27 -> 2963 | T27: 3709.6774 | U27: 1846.5 | V27: 3945.1613 | W27: =SUM(C27+E27+G27+K27+O27+S27+U27) -> 10816.9 | X27: =SUM(D27+F27+H27+L27+P27+T27+V27) -> 16290.323 | Y27: 0 | AA27: =SUM(W27+Y27) -> 10816.9 | AB27: =SUM(X27+Z27) -> 16290.323 | AC27: nebel | AD27: -2 | AE27: °C | AH27: =C27+E27+G27+I27+M27+Q27+Y27 -> 6137.4
A28: =SUM(A27+1) -> 21 | B28: Di | C28: 5744.95 | D28: 6451.6129 | E28: 0 | F28: 80.645161 | G28: 0 | H28: 80.645161 | I28: 0 | K28: =I28+J28 -> 0 | L28: 0 | M28: 1606.9 | O28: =M28+N28 -> 1606.9 | P28: 2022.5806 | Q28: 7516.1 | R28: 1907 | S28: =Q28+R28 -> 9423.1 | T28: 3709.6774 | U28: 6841.7 | V28: 3945.1613 | W28: =SUM(C28+E28+G28+K28+O28+S28+U28) -> 23616.65 | X28: =SUM(D28+F28+H28+L28+P28+T28+V28) -> 16290.323 | Y28: 0 | AA28: =SUM(W28+Y28) -> 23616.65 | AB28: =SUM(X28+Z28) -> 16290.323 | AC28: nebel | AD28: -2 | AE28: °C | AH28: =C28+E28+G28+I28+M28+Q28+Y28 -> 14867.95
A29: =SUM(A28+1) -> 22 | B29: Mi | C29: 6388.2 | D29: 6451.6129 | E29: 0 | F29: 80.645161 | G29: 36 | H29: 80.645161 | I29: 0 | K29: =I29+J29 -> 0 | L29: 0 | M29: 0 | O29: =M29+N29 -> 0 | P29: 2022.5806 | Q29: 398.5 | R29: 4100 | S29: =Q29+R29 -> 4498.5 | T29: 3709.6774 | U29: 4506.9 | V29: 3945.1613 | W29: =SUM(C29+E29+G29+K29+O29+S29+U29) -> 15429.6 | X29: =SUM(D29+F29+H29+L29+P29+T29+V29) -> 16290.323 | Y29: 0 | AA29: =SUM(W29+Y29) -> 15429.6 | AB29: =SUM(X29+Z29) -> 16290.323 | AC29: regenschauer | AD29: 1 | AE29: °C | AH29: =C29+E29+G29+I29+M29+Q29+Y29 -> 6822.7
A30: =SUM(A29+1) -> 23 | B30: Do | C30: 4353.6 | D30: 6451.6129 | E30: 0 | F30: 80.645161 | G30: 5.1 | H30: 80.645161 | I30: 0 | K30: =I30+J30 -> 0 | L30: 0 | O30: =M30+N30 -> 0 | P30: 2022.5806 | Q30: 1446.2 | R30: 4448 | S30: =Q30+R30 -> 5894.2 | T30: 3709.6774 | U30: 5324.4 | V30: 3945.1613 | W30: =SUM(C30+E30+G30+K30+O30+S30+U30) -> 15577.3 | X30: =SUM(D30+F30+H30+L30+P30+T30+V30) -> 16290.323 | Y30: 0 | AA30: =SUM(W30+Y30) -> 15577.3 | AB30: =SUM(X30+Z30) -> 16290.323 | AC30: regenschauer | AD30: 4 | AE30: °C | AH30: =C30+E30+G30+I30+M30+Q30+Y30 -> 5804.9
A31: =SUM(A30+1) -> 24 | B31: Fr | C31: 9150.9 | D31: 6451.6129 | E31: 5.2 | F31: 80.645161 | G31: 92.3 | H31: 80.645161 | I31: 0 | K31: =I31+J31 -> 0 | L31: 0 | M31: 9144.9 | O31: =M31+N31 -> 9144.9 | P31: 2022.5806 | Q31: 0 | R31: 2817 | S31: =Q31+R31 -> 2817 | T31: 3709.6774 | U31: 3082.2 | V31: 3945.1613 | W31: =SUM(C31+E31+G31+K31+O31+S31+U31) -> 24292.5 | X31: =SUM(D31+F31+H31+L31+P31+T31+V31) -> 16290.323 | Y31: 0 | AA31: =SUM(W31+Y31) -> 24292.5 | AB31: =SUM(X31+Z31) -> 16290.323 | AC31: sonnig am NA | AD31: 5 | AE31: °C | AH31: =C31+E31+G31+I31+M31+Q31+Y31 -> 18393.3
A32: =SUM(A31+1) -> 25 | B32: Sa | C32: 10929.9 | D32: 6451.6129 | E32: 892.1 | F32: 80.645161 | G32: 377.5 | H32: 80.645161 | I32: 0 | K32: =I32+J32 -> 0 | L32: 0 | M32: 19186 | O32: =M32+N32 -> 19186 | P32: 2022.5806 | Q32: 0 | R32: 0 | S32: =Q32+R32 -> 0 | T32: 3709.6774 | U32: 6170.2 | V32: 3945.1613 | W32: =SUM(C32+E32+G32+K32+O32+S32+U32) -> 37555.7 | X32: =SUM(D32+F32+H32+L32+P32+T32+V32) -> 16290.323 | Y32: 0 | AA32: =SUM(W32+Y32) -> 37555.7 | AB32: =SUM(X32+Z32) -> 16290.323 | AC32: sonnig am NA | AD32: 6 | AE32: °C | AH32: =C32+E32+G32+I32+M32+Q32+Y32 -> 31385.5
A33: =SUM(A32+1) -> 26 | B33: So | C33: 12478 | D33: 6451.6129 | E33: 1599.2 | F33: 80.645161 | G33: 582.8 | H33: 80.645161 | I33: 0 | K33: =I33+J33 -> 0 | L33: 0 | M33: 2659.1 | O33: =M33+N33 -> 2659.1 | P33: 2022.5806 | Q33: 0 | R33: 0 | S33: =Q33+R33 -> 0 | T33: 3709.6774 | U33: 2374.4 | V33: 3945.1613 | W33: =SUM(C33+E33+G33+K33+O33+S33+U33) -> 19693.5 | X33: =SUM(D33+F33+H33+L33+P33+T33+V33) -> 16290.323 | Y33: 0 | AA33: =SUM(W33+Y33) -> 19693.5 | AB33: =SUM(X33+Z33) -> 16290.323 | AC33: sonnig | AD33: 5 | AE33: °C | AH33: =C33+E33+G33+I33+M33+Q33+Y33 -> 17319.1
A34: KW | B34: =SUM(B26+1) -> 4 | C34: =SUM(C27:C33) -> 55052.95 | D34: =SUM(D27:D33) -> 45161.29 | E34: =SUM(E27:E33) -> 2496.5 | F34: =SUM(F27:F33) -> 564.51613 | G34: =SUM(G27:G33) -> 1093.7 | H34: =SUM(H27:H33) -> 564.51613 | I34: =SUM(I27:I33) -> 0 | J34: =SUM(J27:J33) -> 0 | ... AB34: =SUM(AB27:AB33) -> 114032.26 | AC34: Ø Temp | AD34: =SUM(AD27:AD33)/7 -> 2.4285714 | AE34: °C
A35: =SUM(A33+1) -> 27 | B35: Mo | C35: 4108.8 | D35: 6451.6129 | E35: 0 | F35: 80.645161 | G35: 0 | H35: 80.645161 | I35: 0 | K35: =I35+J35 -> 0 | L35: 0 | M35: 0 | O35: =M35+N35 -> 0 | P35: 2022.5806 | Q35: 0 | R35: 0 | S35: =Q35+R35 -> 0 | T35: 3709.6774 | U35: 1572 | V35: 3945.1613 | W35: =SUM(C35+E35+G35+K35+O35+S35+U35) -> 5680.8 | X35: =SUM(D35+F35+H35+L35+P35+T35+V35) -> 16290.323 | Y35: 0 | AA35: =SUM(W35+Y35) -> 5680.8 | AB35: =SUM(X35+Z35) -> 16290.323 | AC35: regen | AD35: 5 | AE35: °C | AH35: =C35+E35+G35+I35+M35+Q35+Y35 -> 4108.8
A36: =SUM(A35+1) -> 28 | B36: Di. | C36: 6216.3 | D36: 6451.6129 | E36: 0 | F36: 80.645161 | G36: 9.5 | H36: 80.645161 | I36: 0 | K36: =I36+J36 -> 0 | L36: 0 | M36: 161 | O36: =M36+N36 -> 161 | P36: 2022.5806 | Q36: 142.4 | R36: 0 | S36: =Q36+R36 -> 142.4 | T36: 3709.6774 | U36: 1885.9 | V36: 3945.1613 | W36: =SUM(C36+E36+G36+K36+O36+S36+U36) -> 8415.1 | X36: =SUM(D36+F36+H36+L36+P36+T36+V36) -> 16290.323 | Y36: 0 | AA36: =SUM(W36+Y36) -> 8415.1 | AB36: =SUM(X36+Z36) -> 16290.323 | AC36: regen | AD36: 4 | AH36: =C36+E36+G36+I36+M36+Q36+Y36 -> 6529.2
A37: =SUM(A35+1) -> 28 | B37: Mi. | C37: 5782.9 | D37: 6451.6129 | E37: 22.7 | F37: 80.645161 | G37: 227.6 | H37: 80.645161 | I37: 0 | K37: =I37+J37 -> 0 | L37: 0 | M37: 120 | O37: =M37+N37 -> 120 | P37: 2022.5806 | Q37: 0 | R37: 0 | S37: =Q37+R37 -> 0 | T37: 3709.6774 | U37: 2354.49 | V37: 3945.1613 | W37: =SUM(C37+E37+G37+K37+O37+S37+U37) -> 8507.69 | X37: =SUM(D37+F37+H37+L37+P37+T37+V37) -> 16290.323 | Y37: 0 | AA37: =SUM(W37+Y37) -> 8507.69 | AB37: =SUM(X37+Z37) -> 16290.323 | AC37: sonnig NA | AD37: 5 | AH37: =C37+E37+G37+I37+M37+Q37+Y37 -> 6153.2
A38: 30 | B38: Do. | C38: 4639.65 | D38: 6451.6129 | E38: 0 | F38: 80.645161 | G38: 15 | H38: 80.645161 | I38: 0 | K38: =I38+J38 -> 0 | L38: 0 | M38: 0 | O38: =M38+N38 -> 0 | P38: 2022.5806 | Q38: 127.6 | R38: 1555 | S38: =Q38+R38 -> 1682.6 | T38: 3709.6774 | U38: 2008.42 | V38: 3945.1613 | W38: =SUM(C38+E38+G38+K38+O38+S38+U38) -> 8345.67 | X38: =SUM(D38+F38+H38+L38+P38+T38+V38) -> 16290.323 | Y38: 0 | AA38: =SUM(W38+Y38) -> 8345.67 | AB38: =SUM(X38+Z38) -> 16290.323 | AC38: regenschauer | AD38: 3 | AE38: °C | AH38: =C38+E38+G38+I38+M38+Q38+Y38 -> 4782.25
A39: 31 | B39: Fr. | C39: 9208.3 | D39: 6451.6129 | F39: 80.645161 | H39: 80.645161 | I39: 0 | K39: =I39+J39 -> 0 | L39: 0 | M39: 9851.5 | O39: =M39+N39 -> 9851.5 | P39: 2022.5806 | Q39: 0 | R39: 0 | S39: =Q39+R39 -> 0 | T39: 3709.6774 | U39: 2552.3 | V39: 3945.1613 | W39: =SUM(C39+E39+G39+K39+O39+S39+U39) -> 21612.1 | X39: =SUM(D39+F39+H39+L39+P39+T39+V39) -> 16290.323 | Y39: 0 | AA39: =SUM(W39+Y39) -> 21612.1 | AB39: =SUM(X39+Z39) -> 16290.323 | AC39: bewölkt | AD39: 3 | AE39: °C | AH39: =C39+E39+G39+I39+M39+Q39+Y39 -> 19059.8
A40: KW | B40: 5 | C40: =SUM(C35:C39) -> 29955.95 | D40: =SUM(D35:D39) -> 32258.065 | E40: =SUM(E35:E39) -> 22.7 | F40: =SUM(F35:F39) -> 403.22581 | G40: =SUM(G35:G39) -> 252.1 | H40: =SUM(H35:H39) -> 403.22581 | I40: =SUM(I35:I39) -> 0 | J40: =SUM(J35:J39) -> 0 | ... AB40: =SUM(AB35:AB39) -> 81451.613 | AC40: Ø Temp | AD40: =SUM(AD27:AD33)/7 -> 2.4285714 | AE40: °C
A41: Umsatz kumuliert | C41: =SUM(C10+C18+C26+C40+C34) -> 214399.3 | D41: =SUM(D10+D18+D26+D34+D40) -> 200000 | E41: =SUM(E10+E18+E26+E40+E34) -> 3128.6 | F41: =SUM(F10+F18+F26+F40+F34) -> 2500 | G41: =SUM(G10+G18+G26+G40+G34) -> 2540 | H41: =SUM(H10+H18+H26+H40+H34) -> 2500 | I41: =SUM(I10+I18+I26+I40+I34) -> 0 | J41: =SUM(J10+J18+J26+J40+J34) -> 0 | K41: =SUM(K10+K18+K26+K40+K34) -> 0 | L41: =SUM(L10+L18+L26+L40+L34) -> 0 | ... AB41: =SUM(AB10+AB18+AB26+AB40+AB34) -> 505000 | AC41: Umsatz kumuliert
...

Sheet 02_25
A1: Tagesumsätze | H1: 45689
C3: Restaurant | E3: Terrasse | G3: Lounge | I3: Pavillon | K3: Bankett | O3: Seminar | S3: Hotel | U3: TOTAL Gesamtbetrieb ohne Seebad | W3: Seebad | Y3: TOTAL Gesamtbetrieb mit Seebad | AA3: Info's | AF3: Gegenkontrolle Gastronovi
C4: IST | D4: Budget | E4: IST | F4: Budget | G4: IST | H4: Budget | I4: IST | J4: Budget | K4: IST/GN | L4: IST/ET | M4: TOTAL IST | N4: Budget | O4: IST/GN | P4: IST/ET | Q4: TOTAL IST | R4: Budget | S4: IST | T4: Budget | U4: IST | V4: Budget | W4: IST | X4: Budget | Y4: IST | Z4: Budget | AA4: Wetter | AB4: Temp. | AD4: Bemerkung
A5: 1 | B5: Sa | C5: 15286.3 | D5: 8571.4286 | E5: 0 | F5: 321.42857 | G5: 6 | H5: 178.57143 | I5: 0 | J5: 0 | K5: 4001 | M5: =K5+L5 -> 4001 | N5: 892.85714 | O5: 0 | P5: 0 | Q5: =SUM(O5:P5) -> 0 | R5: 2142.8571 | S5: 3620.4 | T5: 2714.2857 | U5: =C5+E5+G5+I5+M5+Q5+S5 -> 22913.7 | V5: =D5+F5+H5+J5+N5+R5+T5 -> 14821.429 | W5: 0 | Y5: =SUM(U5+W5) -> 22913.7 | Z5: =SUM(V5+X5) -> 14821.429 | AA5: bewölkt | AB5: 2 | AC5: °C | AF5: =+C5+E5+G5+K5+O5+W5 -> 19293.3
A6: =SUM(A5+1) -> 2 | B6: So | C6: 8277.1 | D6: 8571.4286 | F6: 321.42857 | H6: 178.57143 | I6: 0 | J6: 0 | K6: 12533.8 | M6: =K6+L6 -> 12533.8 | N6: 892.85714 | O6: 0 | P6: 0 | Q6: =SUM(O6:P6) -> 0 | R6: 2142.8571 | S6: 1652.8 | T6: 2714.2857 | U6: =C6+E6+G6+I6+M6+Q6+S6 -> 22463.7 | V6: =D6+F6+H6+J6+N6+R6+T6 -> 14821.429 | W6: 0 | Y6: =SUM(U6+W6) -> 22463.7 | Z6: =SUM(V6+X6) -> 14821.429 | AA6: bewölkt | AB6: 3 | AC6: °C | AF6: =+C6+E6+G6+K6+O6+W6 -> 20810.9
A7: KW | B7: 5 | C7: =SUM(C5:C6) -> 23563.4 | D7: =SUM(D5:D6) -> 17142.857 | E7: =SUM(E5:E6) -> 0 | F7: =SUM(F5:F6) -> 642.85714 | G7: =SUM(G5:G6) -> 6 | H7: =SUM(H5:H6) -> 357.14286 | I7: =SUM(I5:I6) -> 0 | J7: =SUM(J5:J6) -> 0 | ... Z7: =SUM(Z5:Z6) -> 29642.857 | AA7: Ø Temp | AB7: =SUM(AB5:AB6)/7 -> 0.71428571 | AC7: °C
A8: =SUM(A6+1) -> 3 | B8: Mo | C8: 3634.3 | D8: 8571.4286 | E8: 0 | F8: 321.42857 | G8: 0 | H8: 178.57143 | I8: 0 | J8: 0 | K8: 0 | M8: =K8+L8 -> 0 | N8: 892.85714 | O8: 106.6 | P8: 0 | Q8: =SUM(O8:P8) -> 106.6 | R8: 2142.8571 | S8: 2552.8 | T8: 2714.2857 | U8: =C8+E8+G8+I8+M8+Q8+S8 -> 6293.7 | V8: =D8+F8+H8+J8+N8+R8+T8 -> 14821.429 | W8: 0 | Y8: =SUM(U8+W8) -> 6293.7 | Z8: =SUM(V8+X8) -> 14821.429 | AA8: hochnebel | AB8: 3 | AC8: °C | AF8: =+C8+E8+G8+K8+O8+W8 -> 3740.9
A9: =SUM(A8+1) -> 4 | B9: Di | C9: 4572.2 | D9: 8571.4286 | E9: 0 | F9: 321.42857 | G9: 0 | H9: 178.57143 | I9: 0 | J9: 0 | K9: 1056 | M9: =K9+L9 -> 1056 | N9: 892.85714 | O9: 207 | P9: 2476 | Q9: =SUM(O9:P9) -> 2683 | R9: 2142.8571 | S9: 3235.6 | T9: 2714.2857 | U9: =C9+E9+G9+I9+M9+Q9+S9 -> 11546.8 | V9: =D9+F9+H9+J9+N9+R9+T9 -> 14821.429 | W9: 0 | Y9: =SUM(U9+W9) -> 11546.8 | Z9: =SUM(V9+X9) -> 14821.429 | AA9: sonnig am NA | AB9: 1 | AC9: °C | AF9: =+C9+E9+G9+K9+O9+W9 -> 5835.2
A10: =SUM(A9+1) -> 5 | B10: Mi | C10: 4537 | D10: 8571.4286 | E10: 0 | F10: 321.42857 | G10: 55 | H10: 178.57143 | I10: 0 | J10: 0 | K10: 0 | M10: =K10+L10 -> 0 | N10: 892.85714 | O10: 69 | P10: 1900 | Q10: =SUM(O10:P10) -> 1969 | R10: 2142.8571 | S10: 5029.55 | T10: 2714.2857 | U10: =C10+E10+G10+I10+M10+Q10+S10 -> 11590.55 | V10: =D10+F10+H10+J10+N10+R10+T10 -> 14821.429 | W10: 0 | Y10: =SUM(U10+W10) -> 11590.55 | Z10: =SUM(V10+X10) -> 14821.429 | AA10: bewölkt | AB10: -1 | AC10: °C | AF10: =+C10+E10+G10+K10+O10+W10 -> 4661
A11: =SUM(A10+1) -> 6 | B11: Do | C11: 5320.9 | D11: 8571.4286 | E11: 0 | F11: 321.42857 | G11: 0 | H11: 178.57143 | I11: 0 | J11: 0 | K11: 2593.3 | M11: =K11+L11 -> 2593.3 | N11: 892.85714 | O11: 941.6 | P11: 8250 | Q11: =SUM(O11:P11) -> 9191.6 | R11: 2142.8571 | S11: 4640.95 | T11: 2714.2857 | U11: =C11+E11+G11+I11+M11+Q11+S11 -> 21746.75 | V11: =D11+F11+H11+J11+N11+R11+T11 -> 14821.429 | W11: 0 | Y11: =SUM(U11+W11) -> 21746.75 | Z11: =SUM(V11+X11) -> 14821.429 | AA11: bewölkt | AB11: -1 | AC11: °C | AF11: =+C11+E11+G11+K11+O11+W11 -> 8855.8
A12: =SUM(A11+1) -> 7 | B12: Fr | C12: 8669.1 | D12: 8571.4286 | E12: 0 | F12: 321.42857 | G12: 19.8 | H12: 178.57143 | I12: 0 | J12: 0 | K12: 6790 | M12: =K12+L12 -> 6790 | N12: 892.85714 | O12: 556 | P12: 2324 | Q12: =SUM(O12:P12) -> 2880 | R12: 2142.8571 | S12: 2758.55 | T12: 2714.2857 | U12: =C12+E12+G12+I12+M12+Q12+S12 -> 21117.45 | V12: =D12+F12+H12+J12+N12+R12+T12 -> 14821.429 | W12: 0 | Y12: =SUM(U12+W12) -> 21117.45 | Z12: =SUM(V12+X12) -> 14821.429 | AA12: sonnig am NA | AB12: 1 | AC12: °C | AF12: =+C12+E12+G12+K12+O12+W12 -> 16034.9
A13: =SUM(A12+1) -> 8 | B13: Sa | C13: 11973 | D13: 8571.4286 | E13: 843 | F13: 321.42857 | G13: 181.9 | H13: 178.57143 | I13: 0 | J13: 0 | K13: 13072.4 | M13: =K13+L13 -> 13072.4 | N13: 892.85714 | O13: 0 | P13: 535 | Q13: =SUM(O13:P13) -> 535 | R13: 2142.8571 | S13: 5607.65 | T13: 2714.2857 | U13: =C13+E13+G13+I13+M13+Q13+S13 -> 32212.95 | V13: =D13+F13+H13+J13+N13+R13+T13 -> 14821.429 | W13: 0 | Y13: =SUM(U13+W13) -> 32212.95 | Z13: =SUM(V13+X13) -> 14821.429 | AA13: sonnig am NA | AB13: 5 | AC13: °C | AF13: =+C13+E13+G13+K13+O13+W13 -> 26070.3
A14: =SUM(A13+1) -> 9 | B14: So | C14: 10669.1 | D14: 8571.4286 | E14: 1862.4 | F14: 321.42857 | G14: 548.1 | H14: 178.57143 | I14: 0 | J14: 0 | K14: 0 | M14: =K14+L14 -> 0 | N14: 892.85714 | O14: 200 | P14: 2571 | Q14: =SUM(O14:P14) -> 2771 | R14: 2142.8571 | S14: 3177.43 | T14: 2714.2857 | U14: =C14+E14+G14+I14+M14+Q14+S14 -> 19028.03 | V14: =D14+F14+H14+J14+N14+R14+T14 -> 14821.429 | W14: 0 | Y14: =SUM(U14+W14) -> 19028.03 | Z14: =SUM(V14+X14) -> 14821.429 | AA14: hochnebel | AB14: 3 | AC14: °C | AF14: =+C14+E14+G14+K14+O14+W14 -> 13279.6
A15: KW | B15: =SUM(B7+1) -> 6 | C15: =SUM(C8:C14) -> 49375.6 | D15: =SUM(D8:D14) -> 60000 | E15: =SUM(E8:E14) -> 2705.4 | F15: =SUM(F8:F14) -> 2250 | G15: =SUM(G8:G14) -> 804.8 | H15: =SUM(H8:H14) -> 1250 | I15: =SUM(I8:I14) -> 0 | J15: =SUM(J8:J14) -> 0 | ... Z15: =SUM(Z8:Z14) -> 103750 | AA15: Ø Temp | AB15: =SUM(AB8:AB14)/7 -> 1.5714286 | AC15: °C
A16: =SUM(A14+1) -> 10 | B16: Mo | C16: 3735.5 | D16: 8571.4286 | E16: 0 | F16: 321.42857 | G16: 0 | H16: 178.57143 | I16: 0 | J16: 0 | K16: 0 | M16: =K16+L16 -> 0 | N16: 892.85714 | O16: 180 | P16: 725 | Q16: =SUM(O16:P16) -> 905 | R16: 2142.8571 | S16: 2520 | T16: 2714.2857 | U16: =C16+E16+G16+I16+M16+Q16+S16 -> 7160.5 | V16: =D16+F16+H16+J16+N16+R16+T16 -> 14821.429 | W16: 0 | Y16: =SUM(U16+W16) -> 7160.5 | Z16: =SUM(V16+X16) -> 14821.429 | AA16: bewölkt | AB16: 5 | AC16: °C | AF16: =+C16+E16+G16+K16+O16+W16 -> 3915.5
A17: =SUM(A16+1) -> 11 | B17: Di | C17: 5461.5 | D17: 8571.4286 | E17: 0 | F17: 321.42857 | G17: 0 | H17: 178.57143 | I17: 0 | J17: 0 | K17: 0 | M17: =K17+L17 -> 0 | N17: 892.85714 | O17: 416.2 | P17: 1804 | Q17: =SUM(O17:P17) -> 2220.2 | R17: 2142.8571 | S17: 4504.7 | T17: 2714.2857 | U17: =C17+E17+G17+I17+M17+Q17+S17 -> 12186.4 | V17: =D17+F17+H17+J17+N17+R17+T17 -> 14821.429 | W17: 0 | Y17: =SUM(U17+W17) -> 12186.4 | Z17: =SUM(V17+X17) -> 14821.429 | AA17: regen | AB17: 7 | AC17: °C | AF17: =+C17+E17+G17+K17+O17+W17 -> 5877.7
A18: =SUM(A17+1) -> 12 | B18: Mi | C18: 8047 | D18: 8571.4286 | E18: 0 | F18: 321.42857 | G18: 20.8 | H18: 178.57143 | I18: 0 | J18: 0 | K18: 0 | M18: =K18+L18 -> 0 | N18: 892.85714 | O18: 814.5 | P18: 2536.5 | Q18: =SUM(O18:P18) -> 3351 | R18: 2142.8571 | S18: 3730.47 | T18: 2714.2857 | U18: =C18+E18+G18+I18+M18+Q18+S18 -> 15149.27 | V18: =D18+F18+H18+J18+N18+R18+T18 -> 14821.429 | W18: 0 | Y18: =SUM(U18+W18) -> 15149.27 | Z18: =SUM(V18+X18) -> 14821.429 | AA18: regen | AB18: 7 | AC18: °C | AF18: =+C18+E18+G18+K18+O18+W18 -> 8882.3
A19: =SUM(A18+1) -> 13 | B19: Do | C19: 6676.6 | D19: 8571.4286 | E19: 0 | F19: 321.42857 | G19: 0 | H19: 178.57143 | I19: 0 | J19: 0 | K19: 550 | M19: =K19+L19 -> 550 | N19: 892.85714 | O19: 18 | P19: 861 | Q19: =SUM(O19:P19) -> 879 | R19: 2142.8571 | S19: 2256.3 | T19: 2714.2857 | U19: =C19+E19+G19+I19+M19+Q19+S19 -> 10361.9 | V19: =D19+F19+H19+J19+N19+R19+T19 -> 14821.429 | W19: 0 | Y19: =SUM(U19+W19) -> 10361.9 | Z19: =SUM(V19+X19) -> 14821.429 | AA19: nebel | AB19: 1 | AC19: °C | AF19: =+C19+E19+G19+K19+O19+W19 -> 7244.6
A20: =SUM(A19+1) -> 14 | B20: Fr | C20: 15846.7 | D20: 8571.4286 | E20: 0 | F20: 321.42857 | G20: 0 | H20: 178.57143 | I20: 0 | J20: 0 | K20: 6056.6 | M20: =K20+L20 -> 6056.6 | N20: 892.85714 | O20: 0 | P20: 0 | Q20: =SUM(O20:P20) -> 0 | R20: 2142.8571 | S20: 10627.17 | T20: 2714.2857 | U20: =C20+E20+G20+I20+M20+Q20+S20 -> 32530.47 | V20: =D20+F20+H20+J20+N20+R20+T20 -> 14821.429 | W20: 0 | Y20: =SUM(U20+W20) -> 32530.47 | Z20: =SUM(V20+X20) -> 14821.429 | AA20: schnee | AB20: -1 | AC20: °C | AD20: Valentinstag | AF20: =+C20+E20+G20+K20+O20+W20 -> 21903.3
A21: =SUM(A20+1) -> 15 | B21: Sa | C21: 14133.9 | D21: 8571.4286 | E21: 0 | F21: 321.42857 | G21: 15 | H21: 178.57143 | I21: 0 | J21: 0 | K21: 7291.25 | M21: =K21+L21 -> 7291.25 | N21: 892.85714 | O21: 0 | P21: 0 | Q21: =SUM(O21:P21) -> 0 | R21: 2142.8571 | S21: 6159.68 | T21: 2714.2857 | U21: =C21+E21+G21+I21+M21+Q21+S21 -> 27599.83 | V21: =D21+F21+H21+J21+N21+R21+T21 -> 14821.429 | W21: 0 | Y21: =SUM(U21+W21) -> 27599.83 | Z21: =SUM(V21+X21) -> 14821.429 | AA21: teils bewölkt | AB21: 2 | AC21: °C | AF21: =+C21+E21+G21+K21+O21+W21 -> 21440.15
A22: =SUM(A21+1) -> 16 | B22: So | C22: 13805.1 | D22: 8571.4286 | E22: 0 | F22: 321.42857 | G22: 0 | H22: 178.57143 | I22: 0 | J22: 0 | K22: 676.8 | M22: =K22+L22 -> 676.8 | N22: 892.85714 | O22: 0 | P22: 0 | Q22: =SUM(O22:P22) -> 0 | R22: 2142.8571 | S22: 2628.83 | T22: 2714.2857 | U22: =C22+E22+G22+I22+M22+Q22+S22 -> 17110.73 | V22: =D22+F22+H22+J22+N22+R22+T22 -> 14821.429 | W22: 0 | Y22: =SUM(U22+W22) -> 17110.73 | Z22: =SUM(V22+X22) -> 14821.429 | AA22: überwiegend bewölkt | AB22: 3 | AC22: °C | AF22: =+C22+E22+G22+K22+O22+W22 -> 14481.9
A23: KW | B23: =SUM(B15+1) -> 7 | C23: =SUM(C16:C22) -> 67706.3 | D23: =SUM(D16:D22) -> 60000 | E23: =SUM(E16:E22) -> 0 | F23: =SUM(F16:F22) -> 2250 | G23: =SUM(G16:G22) -> 35.8 | H23: =SUM(H16:H22) -> 1250 | I23: =SUM(I16:I22) -> 0 | J23: =SUM(J16:J22) -> 0 | ... Z23: =SUM(Z16:Z22) -> 103750 | AA23: Ø Temp | AB23: =SUM(AB16:AB22)/7 -> 3.4285714 | AC23: °C
A24: =SUM(A22+1) -> 17 | B24: Mo | C24: 5751.2 | D24: 8571.4286 | E24: 0 | F24: 321.42857 | G24: 0 | H24: 178.57143 | I24: 0 | J24: 0 | K24: 0 | M24: =K24+L24 -> 0 | N24: 892.85714 | O24: 6 | P24: 2172 | Q24: =SUM(O24:P24) -> 2178 | R24: 2142.8571 | S24: 1777.7 | T24: 2714.2857 | U24: =C24+E24+G24+I24+M24+Q24+S24 -> 9706.9 | V24: =D24+F24+H24+J24+N24+R24+T24 -> 14821.429 | W24: 0 | Y24: =SUM(U24+W24) -> 9706.9 | Z24: =SUM(V24+X24) -> 14821.429 | AA24: teils bewölkt | AB24: 4 | AC24: °C | AF24: =+C24+E24+G24+K24+O24+W24 -> 5757.2
A25: =SUM(A24+1) -> 18 | B25: Di | C25: 8241.1 | D25: 8571.4286 | E25: 0 | F25: 321.42857 | G25: 0 | H25: 178.57143 | I25: 0 | J25: 0 | K25: 836 | M25: =K25+L25 -> 836 | N25: 892.85714 | O25: 480.5 | P25: 1642 | Q25: =SUM(O25:P25) -> 2122.5 | R25: 2142.8571 | S25: 4381.7 | T25: 2714.2857 | U25: =C25+E25+G25+I25+M25+Q25+S25 -> 15581.3 | V25: =D25+F25+H25+J25+N25+R25+T25 -> 14821.429 | W25: 0 | Y25: =SUM(U25+W25) -> 15581.3 | Z25: =SUM(V25+X25) -> 14821.429 | AA25: bewölkt | AB25: 3 | AC25: °C | AF25: =+C25+E25+G25+K25+O25+W25 -> 9557.6
A26: =SUM(A25+1) -> 19 | B26: Mi | C26: 4999.9 | D26: 8571.4286 | E26: 0 | F26: 321.42857 | G26: 11 | H26: 178.57143 | I26: 0 | J26: 0 | K26: 0 | M26: =K26+L26 -> 0 | N26: 892.85714 | O26: 30 | P26: 2798 | Q26: =SUM(O26:P26) -> 2828 | R26: 2142.8571 | S26: 2167.95 | T26: 2714.2857 | U26: =C26+E26+G26+I26+M26+Q26+S26 -> 10006.85 | V26: =D26+F26+H26+J26+N26+R26+T26 -> 14821.429 | W26: 0 | Y26: =SUM(U26+W26) -> 10006.85 | Z26: =SUM(V26+X26) -> 14821.429 | AA26: bedeckt | AB26: 3 | AC26: °C | AF26: =+C26+E26+G26+K26+O26+W26 -> 5040.9
A27: =SUM(A26+1) -> 20 | B27: Do | C27: 4987.4 | D27: 8571.4286 | E27: 0 | F27: 321.42857 | G27: 44.5 | H27: 178.57143 | I27: 0 | J27: 0 | K27: 0 | M27: =K27+L27 -> 0 | N27: 892.85714 | O27: 723.9 | P27: 2807 | Q27: =SUM(O27:P27) -> 3530.9 | R27: 2142.8571 | S27: 1663.45 | T27: 2714.2857 | U27: =C27+E27+G27+I27+M27+Q27+S27 -> 10226.25 | V27: =D27+F27+H27+J27+N27+R27+T27 -> 14821.429 | W27: 0 | Y27: =SUM(U27+W27) -> 10226.25 | Z27: =SUM(V27+X27) -> 14821.429 | AA27: teilweise sonnig | AB27: 8 | AC27: °C | AF27: =+C27+E27+G27+K27+O27+W27 -> 5755.8
A28: =SUM(A27+1) -> 21 | B28: Fr | C28: 10549.2 | D28: 8571.4286 | E28: 225.5 | F28: 321.42857 | G28: 319.2 | H28: 178.57143 | I28: 0 | J28: 0 | K28: 1850 | M28: =K28+L28 -> 1850 | N28: 892.85714 | O28: 0 | P28: 0 | Q28: =SUM(O28:P28) -> 0 | R28: 2142.8571 | S28: 4065.95 | T28: 2714.2857 | U28: =C28+E28+G28+I28+M28+Q28+S28 -> 17009.85 | V28: =D28+F28+H28+J28+N28+R28+T28 -> 14821.429 | W28: 0 | Y28: =SUM(U28+W28) -> 17009.85 | Z28: =SUM(V28+X28) -> 14821.429 | AA28: sonnig | AB28: 11 | AC28: °C | AF28: =+C28+E28+G28+K28+O28+W28 -> 12943.9
A29: =SUM(A28+1) -> 22 | B29: Sa | C29: 12771.9 | D29: 8571.4286 | E29: 255.6 | F29: 321.42857 | G29: 423.6 | H29: 178.57143 | I29: 0 | J29: 0 | K29: 3765.5 | M29: =K29+L29 -> 3765.5 | N29: 892.85714 | O29: 488.8 | P29: 0 | Q29: =SUM(O29:P29) -> 488.8 | R29: 2142.8571 | S29: 5843.61 | T29: 2714.2857 | U29: =C29+E29+G29+I29+M29+Q29+S29 -> 23549.01 | V29: =D29+F29+H29+J29+N29+R29+T29 -> 14821.429 | W29: 0 | Y29: =SUM(U29+W29) -> 23549.01 | Z29: =SUM(V29+X29) -> 14821.429 | AA29: stark bewölkt | AB29: 13 | AC29: °C | AF29: =+C29+E29+G29+K29+O29+W29 -> 17705.4
A30: =SUM(A29+1) -> 23 | B30: So | C30: 11932.2 | D30: 8571.4286 | E30: 0 | F30: 321.42857 | G30: 49.5 | H30: 178.57143 | I30: 0 | J30: 0 | K30: 0 | M30: =K30+L30 -> 0 | N30: 892.85714 | O30: 0 | P30: 0 | Q30: =SUM(O30:P30) -> 0 | R30: 2142.8571 | S30: 2801.62 | T30: 2714.2857 | U30: =C30+E30+G30+I30+M30+Q30+S30 -> 14783.32 | V30: =D30+F30+H30+J30+N30+R30+T30 -> 14821.429 | W30: 0 | Y30: =SUM(U30+W30) -> 14783.32 | Z30: =SUM(V30+X30) -> 14821.429 | AA30: vereinzelte Regenschauer | AB30: 9 | AC30: °C | AF30: =+C30+E30+G30+K30+O30+W30 -> 11981.7
A31: KW | B31: =SUM(B23+1) -> 8 | C31: =SUM(C24:C30) -> 59232.9 | D31: =SUM(D24:D30) -> 60000 | E31: =SUM(E24:E30) -> 481.1 | F31: =SUM(F24:F30) -> 2250 | G31: =SUM(G24:G30) -> 847.8 | H31: =SUM(H24:H30) -> 1250 | I31: =SUM(I24:I30) -> 0 | J31: =SUM(J24:J30) -> 0 | ... Z31: =SUM(Z24:Z30) -> 103750 | AA31: Ø Temp | AB31: =SUM(AB24:AB30)/7 -> 7.2857143 | AC31: °C
A32: =SUM(A30+1) -> 24 | B32: Mo | C32: 7168.7 | D32: 8571.4286 | E32: 0 | F32: 321.42857 | G32: 0 | H32: 178.57143 | I32: 0 | J32: 0 | K32: 250 | M32: =K32+L32 -> 250 | N32: 892.85714 | O32: 0 | P32: 0 | Q32: =SUM(O32:P32) -> 0 | R32: 2142.8571 | S32: 3860.86 | T32: 2714.2857 | U32: =C32+E32+G32+I32+M32+Q32+S32 -> 11279.56 | V32: =D32+F32+H32+J32+N32+R32+T32 -> 14821.429 | W32: 0 | Y32: =SUM(U32+W32) -> 11279.56 | Z32: =SUM(V32+X32) -> 14821.429 | AA32: vereinzelte Regenschauer | AB32: 9 | AC32: °C | AF32: =+C32+E32+G32+K32+O32+W32 -> 7418.7
A33: =SUM(A32+1) -> 25 | B33: Di. | C33: 10861.3 | D33: 8571.4286 | E33: 0 | F33: 321.42857 | G33: 5.1 | H33: 178.57143 | I33: 0 | J33: 0 | K33: 1654.3 | M33: =K33+L33 -> 1654.3 | N33: 892.85714 | O33: 286.8 | P33: 4930.7 | Q33: =SUM(O33:P33) -> 5217.5 | R33: 2142.8571 | S33: 6096.45 | T33: 2714.2857 | U33: =C33+E33+G33+I33+M33+Q33+S33 -> 23834.65 | V33: =D33+F33+H33+J33+N33+R33+T33 -> 14821.429 | W33: 0 | Y33: =SUM(U33+W33) -> 23834.65 | Z33: =SUM(V33+X33) -> 14821.429 | AA33: Regenschauer | AB33: 8 | AC33: °C | AF33: =+C33+E33+G33+K33+O33+W33 -> 12807.5
A34: =SUM(A33+1) -> 26 | B34: Mi. | C34: 10205.4 | D34: 8571.4286 | E34: 0 | F34: 321.42857 | G34: 0 | H34: 178.57143 | I34: 0 | J34: 0 | K34: 0 | M34: =K34+L34 -> 0 | N34: 892.85714 | O34: 400.1 | P34: 2746 | Q34: =SUM(O34:P34) -> 3146.1 | R34: 2142.8571 | S34: 4970 | T34: 2714.2857 | U34: =C34+E34+G34+I34+M34+Q34+S34 -> 18321.5 | V34: =D34+F34+H34+J34+N34+R34+T34 -> 14821.429 | W34: 0 | Y34: =SUM(U34+W34) -> 18321.5 | Z34: =SUM(V34+X34) -> 14821.429 | AA34: bewölkt und regenschauer | AB34: 8 | AC34: °C | AF34: =+C34+E34+G34+K34+O34+W34 -> 10605.5
A35: =SUM(A34+1) -> 27 | B35: Do. | C35: 4512.8 | D35: 8571.4286 | E35: 0 | F35: 321.42857 | G35: 11.6 | H35: 178.57143 | I35: 0 | J35: 0 | K35: 2237.6 | M35: =K35+L35 -> 2237.6 | N35: 892.85714 | O35: 289.1 | P35: 1884 | Q35: =SUM(O35:P35) -> 2173.1 | R35: 2142.8571 | S35: 2444 | T35: 2714.2857 | U35: =C35+E35+G35+I35+M35+Q35+S35 -> 11379.1 | V35: =D35+F35+H35+J35+N35+R35+T35 -> 14821.429 | W35: 0 | Y35: =SUM(U35+W35) -> 11379.1 | Z35: =SUM(V35+X35) -> 14821.429 | AA35: Schneeschauer, sonnig | AB35: 4 | AC35: °C | AD35: Schmudo | AF35: =+C35+E35+G35+K35+O35+W35 -> 7051.1
A36: =SUM(A35+1) -> 28 | B36: Fr. | C36: 9524.3 | D36: 8571.4286 | E36: 0 | F36: 321.42857 | G36: 73.4 | H36: 178.57143 | I36: 0 | J36: 0 | K36: 0 | M36: =K36+L36 -> 0 | N36: 892.85714 | O36: 370.7 | P36: 3144 | Q36: =SUM(O36:P36) -> 3514.7 | R36: 2142.8571 | S36: 5087.15 | T36: 2714.2857 | U36: =C36+E36+G36+I36+M36+Q36+S36 -> 18199.55 | V36: =D36+F36+H36+J36+N36+R36+T36 -> 14821.429 | W36: 0 | Y36: =SUM(U36+W36) -> 18199.55 | Z36: =SUM(V36+X36) -> 14821.429 | AA36: bewölkt | AB36: 5 | AC36: °C | AF36: =+C36+E36+G36+K36+O36+W36 -> 9968.4
A37: KW | B37: =SUM(B31+1) -> 9 | C37: =SUM(C32:C36) -> 42272.5 | D37: =SUM(D32:D36) -> 42857.143 | E37: =SUM(E32:E36) -> 0 | F37: =SUM(F32:F36) -> 1607.1429 | G37: =SUM(G32:G36) -> 90.1 | H37: =SUM(H32:H36) -> 892.85714 | I37: =SUM(I32:I36) -> 0 | J37: 0 | K37: =SUM(K32:K36) -> 4141.9 | L37: =SUM(L32:L36) -> 0 | M37: =SUM(M32:M36) -> 4141.9 | N37: =SUM(N32:N36) -> 4464.2857 | O37: =SUM(O32:O36) -> 1346.7 | P37: =SUM(P32:P36) -> 12704.7 | Q37: =SUM(Q32:Q36) -> 14051.4 | R37: =SUM(R32:R36) -> 10714.286 | ... Z37: =SUM(Z32:Z36) -> 74107.143 | AA37: Ø Temp | AB37: =SUM(AB24:AB30)/7 -> 7.2857143 | AC37: °C
A38: Umsatz kumuliert | C38: =SUM(C7+C15+C23+C31+C37) -> 242150.7 | D38: =SUM(D7+D15+D23+D31+D37) -> 240000 | E38: =SUM(E7+E15+E23+E31+E37) -> 3186.5 | F38: =SUM(F7+F15+F23+F31+F37) -> 9000 | G38: =SUM(G7+G15+G23+G31+G37) -> 1784.5 | H38: =SUM(H7+H15+H23+H31+H37) -> 5000 | I38: =SUM(I7+I15+I23+I31+I37) -> 0 | J38: =SUM(J7+J15+J23+J31+J37) -> 0 | ... Z38: =SUM(Z7+Z15+Z23+Z31+Z37) -> 415000 | AA38: Umsatz kumuliert | AF38: =SUM(AF5:AF37) -> 318921.05
A39: Umsatz pro Tag | C39: =C38/28 -> 8648.2393 | D39: =D38/28 -> 8571.4286 | E39: =E38/28 -> 113.80357 | F39: =F38/28 -> 321.42857 | G39: =G38/28 -> 63.732143 | H39: =H38/28 -> 178.57143 | I39: =I38/28 -> 0 | J39: =J38/28 -> 0 | K39: =K38/28 -> 2329.0911 | N39: =N38/28 -> 892.85714 | O39: =O38/30 -> 219.49333 | R39: =R38/30 -> 2000 | S39: =S38/28 -> 3923.69 | T39: =T38/28 -> 2714.2857 | U39: =U38/28 -> 16960.377 | V39: =V38/28 -> 14821.429 | W39: =W38/28 -> 0 | X39: =X38/28 -> 0 | Y39: =Y38/28 -> 16960.377 | Z39: =Z38/28 -> 14821.429 | AA39: Budget pro Tag
A40: Diff. zu Budget | C40: =SUM(C38-D38) -> 2150.7 | E40: =SUM(E38-F38) -> -5813.5 | G40: =SUM(G38-H38) -> -3215.5 | I40: =SUM(I38-J38) -> 0 | K40: =SUM(K38-N38) -> 40214.55 | R40: =SUM(Q38-R38) -> -7309 | S40: =SUM(S38-T38) -> 33863.32 | U40: =SUM(U38-V38) -> 59890.57 | W40: =SUM(W38-X38) -> 0 | Y40: =SUM(Y38-Z38) -> 59890.57
A41: Index | C41: =SUM(100/D38*C38) -> 100.89613 | E41: =SUM(100/F38*E38) -> 35.405556 | G41: =SUM(100/H38*G38) -> 35.69 | I41: =SUM(100/J38*I38) -> #DIV/0! | K41: =SUM(100/N38*K38) -> 260.8582 | Q41: =SUM(100/R38*Q38) -> 87.818333 | S41: =SUM(100/T38*S38) -> 144.557 | U41: =SUM(100/V38*U38) -> 114.43146 | W41: =SUM(100/X38*W38) -> #DIV/0! | Y41: =SUM(100/Z38*Y38) -> 114.43146

Sheet 03_25
A1: Tagesumsätze | H1: 45717
C3: Restaurant | E3: Terrasse | G3: Lounge | I3: Pavillon | K3: Bankett | O3: Seminar | S3: Hotel | U3: TOTAL Gesamtbetrieb ohne Seebad | W3: Seebad | Y3: TOTAL Gesamtbetrieb mit Seebad | AA3: Info's | AF3: Gegenkontrolle Gastronovi
C4: IST | D4: Budget | E4: IST | F4: Budget | G4: IST | H4: Budget | I4: IST | J4: Budget | K4: IST/GN | L4: IST/ET | M4: TOTAL IST | N4: Budget | O4: IST/GN | P4: IST/ET | Q4: TOTAL IST | R4: Budget | S4: IST | T4: Budget | U4: IST | V4: Budget | W4: IST | X4: Budget | Y4: IST | Z4: Budget | AA4: Wetter | AB4: Temp. | AD4: Bemerkung
A5: 1 | B5: Sa | C5: 15765.3 | D5: 9516.129 | E5: 0 | F5: 483.87097 | G5: 0 | H5: 258.06452 | I5: 0 | K5: 200 | M5: =K5+L5 -> 200 | N5: 2670.9677 | O5: 0 | P5: 1095 | Q5: =SUM(O5:P5) -> 1095 | R5: 3225.8065 | S5: 2561.32 | T5: 4812.9032 | U5: =SUM(C5+E5+G5+I5+K5+Q5+S5) -> 19621.62 | V5: =SUM(D5+F5+H5+J5+N5+R5+T5) -> 20967.742 | W5: 0 | Y5: =SUM(U5+W5) -> 19621.62 | Z5: =SUM(V5+X5) -> 20967.742 | AA5: bewölkt | AB5: 4 | AC5: °C | AF5: =C5+E5+G5+K5+O5+W5 -> 15965.3
A6: =SUM(A5+1) -> 2 | B6: So | C6: 12145.4 | D6: 9516.129 | E6: 299.1 | F6: 483.87097 | G6: 308.7 | H6: 258.06452 | I6: 0 | K6: 0 | M6: =K6+L6 -> 0 | N6: 2670.9677 | O6: 0 | P6: 0 | Q6: =SUM(O6:P6) -> 0 | R6: 3225.8065 | S6: 1457.96 | T6: 4812.9032 | U6: =SUM(C6+E6+G6+I6+K6+Q6+S6) -> 14211.16 | V6: =SUM(D6+F6+H6+J6+N6+R6+T6) -> 20967.742 | W6: 0 | Y6: =SUM(U6+W6) -> 14211.16 | Z6: =SUM(V6+X6) -> 20967.742 | AA6: 0 | AB6: 5 | AC6: °C | AF6: =C6+E6+G6+K6+O6+W6 -> 12753.2
A7: KW | B7: 9 | C7: =SUM(C5:C6) -> 27910.7 | D7: =SUM(D5:D6) -> 19032.258 | E7: =SUM(E5:E6) -> 299.1 | F7: =SUM(F5:F6) -> 967.74194 | G7: =SUM(G5:G6) -> 308.7 | H7: =SUM(H5:H6) -> 516.12903 | I7: =SUM(I5:I6) -> 0 | J7: =SUM(J5:J6) -> 0 | ... Z7: =SUM(Z5:Z6) -> 41935.484 | AA7: Ø Temp | AB7: =SUM(AB5:AB6)/7 -> 1.2857143 | AC7: °C
A8: =SUM(A6+1) -> 3 | B8: Mo | C8: 7034.5 | D8: 9516.129 | E8: 1013.4 | F8: 483.87097 | G8: 531.7 | H8: 258.06452 | I8: 0 | K8: 0 | M8: =K8+L8 -> 0 | N8: 2670.9677 | O8: 1950.6 | P8: 755 | Q8: =SUM(O8:P8) -> 2705.6 | R8: 3225.8065 | S8: 3994.7 | T8: 4812.9032 | U8: =SUM(C8+E8+G8+I8+K8+Q8+S8) -> 15279.9 | V8: =SUM(D8+F8+H8+J8+N8+R8+T8) -> 20967.742 | W8: 0 | Y8: =SUM(U8+W8) -> 15279.9 | Z8: =SUM(V8+X8) -> 20967.742 | AA8: sonnig | AB8: 10 | AC8: °C | AD8: Güdismontag | AF8: =C8+E8+G8+K8+O8+W8 -> 10530.2
A9: =SUM(A8+1) -> 4 | B9: Di | C9: 9266.3 | D9: 9516.129 | E9: 1557.3 | F9: 483.87097 | G9: 448.1 | H9: 258.06452 | I9: 0 | K9: 0 | M9: =K9+L9 -> 0 | N9: 2670.9677 | O9: 2106.1 | P9: 5718.8 | Q9: =SUM(O9:P9) -> 7824.9 | R9: 3225.8065 | S9: 6085.45 | T9: 4812.9032 | U9: =SUM(C9+E9+G9+I9+K9+Q9+S9) -> 25182.05 | V9: =SUM(D9+F9+H9+J9+N9+R9+T9) -> 20967.742 | W9: 0 | Y9: =SUM(U9+W9) -> 25182.05 | Z9: =SUM(V9+X9) -> 20967.742 | AA9: sonnig | AB9: 11 | AC9: °C | AD9: Güdisdienstag | AF9: =C9+E9+G9+K9+O9+W9 -> 13377.8
A10: =SUM(A9+1) -> 5 | B10: Mi | C10: 10047.9 | D10: 9516.129 | E10: 2459.8 | F10: 483.87097 | G10: 549.1 | H10: 258.06452 | I10: 0 | K10: 1400 | M10: =K10+L10 -> 1400 | N10: 2670.9677 | O10: 1841.8 | P10: 4254.5 | Q10: =SUM(O10:P10) -> 6096.3 | R10: 3225.8065 | S10: 4171.7 | T10: 4812.9032 | U10: =SUM(C10+E10+G10+I10+K10+Q10+S10) -> 24724.8 | V10: =SUM(D10+F10+H10+J10+N10+R10+T10) -> 20967.742 | W10: 0 | Y10: =SUM(U10+W10) -> 24724.8 | Z10: =SUM(V10+X10) -> 20967.742 | AA10: sonnig | AB10: 13 | AC10: °C | AD10: Aschermittwoch | AF10: =C10+E10+G10+K10+O10+W10 -> 16298.6
A11: =SUM(A10+1) -> 6 | B11: Do | C11: 8079.1 | D11: 9516.129 | E11: 2717.2 | F11: 483.87097 | G11: 871.8 | H11: 258.06452 | I11: 0 | K11: 820 | M11: =K11+L11 -> 820 | N11: 2670.9677 | O11: 1529.8 | P11: 8220.5 | Q11: =SUM(O11:P11) -> 9750.3 | R11: 3225.8065 | S11: 3802.65 | T11: 4812.9032 | U11: =SUM(C11+E11+G11+I11+K11+Q11+S11) -> 26041.05 | V11: =SUM(D11+F11+H11+J11+N11+R11+T11) -> 20967.742 | W11: 0 | Y11: =SUM(U11+W11) -> 26041.05 | Z11: =SUM(V11+X11) -> 20967.742 | AA11: sonnig | AB11: 13 | AC11: °C | AF11: =C11+E11+G11+K11+O11+W11 -> 14017.9
A12: =SUM(A11+1) -> 7 | B12: Fr | C12: 14695 | D12: 9516.129 | E12: 4385.8 | F12: 483.87097 | G12: 632.3 | H12: 258.06452 | I12: 0 | K12: 908.6 | M12: =K12+L12 -> 908.6 | N12: 2670.9677 | O12: 383 | P12: 4692 | Q12: =SUM(O12:P12) -> 5075 | R12: 3225.8065 | S12: 5639.6 | T12: 4812.9032 | U12: =SUM(C12+E12+G12+I12+K12+Q12+S12) -> 31336.3 | V12: =SUM(D12+F12+H12+J12+N12+R12+T12) -> 20967.742 | W12: 0 | Y12: =SUM(U12+W12) -> 31336.3 | Z12: =SUM(V12+X12) -> 20967.742 | AA12: sonnig | AB12: 15 | AC12: °C | AF12: =C12+E12+G12+K12+O12+W12 -> 21004.7
A13: =SUM(A12+1) -> 8 | B13: Sa | C13: 15635.8 | D13: 9516.129 | E13: 10155.8 | F13: 483.87097 | G13: 1444.3 | H13: 258.06452 | I13: 0 | K13: 6563.8 | M13: =K13+L13 -> 6563.8 | N13: 2670.9677 | O13: 0 | P13: 1521 | Q13: =SUM(O13:P13) -> 1521 | R13: 3225.8065 | S13: 5520.29 | T13: 4812.9032 | U13: =SUM(C13+E13+G13+I13+K13+Q13+S13) -> 40840.99 | V13: =SUM(D13+F13+H13+J13+N13+R13+T13) -> 20967.742 | W13: 0 | Y13: =SUM(U13+W13) -> 40840.99 | Z13: =SUM(V13+X13) -> 20967.742 | AA13: sonnig | AB13: 16 | AC13: °C | AF13: =C13+E13+G13+K13+O13+W13 -> 33799.7
A14: =SUM(A13+1) -> 9 | B14: So | C14: 15005.6 | D14: 9516.129 | E14: 6343.7 | F14: 483.87097 | G14: 1110.1 | H14: 258.06452 | I14: 0 | K14: 3911.4 | M14: =K14+L14 -> 3911.4 | N14: 2670.9677 | O14: 0 | P14: 0 | Q14: =SUM(O14:P14) -> 0 | R14: 3225.8065 | S14: 3404.8 | T14: 4812.9032 | U14: =SUM(C14+E14+G14+I14+K14+Q14+S14) -> 29775.6 | V14: =SUM(D14+F14+H14+J14+N14+R14+T14) -> 20967.742 | W14: 0 | Y14: =SUM(U14+W14) -> 29775.6 | Z14: =SUM(V14+X14) -> 20967.742 | AA14: sonnig | AB14: 15 | AC14: °C | AF14: =C14+E14+G14+K14+O14+W14 -> 26370.8
A15: KW | B15: =SUM(B7+1) -> 10 | C15: =SUM(C8:C14) -> 79764.2 | D15: =SUM(D8:D14) -> 66612.903 | E15: =SUM(E8:E14) -> 28633 | F15: =SUM(F8:F14) -> 3387.0968 | G15: =SUM(G8:G14) -> 5587.4 | H15: =SUM(H8:H14) -> 1806.4516 | I15: =SUM(I8:I14) -> 0 | J15: =SUM(J8:J14) -> 0 | ... Z15: =SUM(Z8:Z14) -> 146774.19 | AA15: Ø Temp | AB15: =SUM(AB8:AB14)/7 -> 13.285714 | AC15: °C
A16: =SUM(A14+1) -> 10 | B16: Mo | C16: 5933.7 | D16: 9516.129 | E16: 71.7 | F16: 483.87097 | G16: 197.5 | H16: 258.06452 | I16: 0 | K16: 1362.8 | M16: =K16+L16 -> 1362.8 | N16: 2670.9677 | O16: 743.8 | P16: 2792 | Q16: =SUM(O16:P16) -> 3535.8 | R16: 3225.8065 | S16: 5883.8 | T16: 4812.9032 | U16: =SUM(C16+E16+G16+I16+K16+Q16+S16) -> 16985.3 | V16: =SUM(D16+F16+H16+J16+N16+R16+T16) -> 20967.742 | W16: 0 | Y16: =SUM(U16+W16) -> 16985.3 | Z16: =SUM(V16+X16) -> 20967.742 | AA16: bewölkt / teilweise Regen | AB16: 11 | AC16: °C | AF16: =C16+E16+G16+K16+O16+W16 -> 8309.5
A17: =SUM(A16+1) -> 11 | B17: Di | C17: 4132.7 | D17: 9516.129 | E17: 299.1 | F17: 483.87097 | G17: 159.9 | H17: 258.06452 | I17: 0 | K17: 0 | M17: =K17+L17 -> 0 | N17: 2670.9677 | O17: 788.6 | P17: 11353 | Q17: =SUM(O17:P17) -> 12141.6 | R17: 3225.8065 | S17: 7690.55 | T17: 4812.9032 | U17: =SUM(C17+E17+G17+I17+K17+Q17+S17) -> 24423.85 | V17: =SUM(D17+F17+H17+J17+N17+R17+T17) -> 20967.742 | W17: 0 | Y17: =SUM(U17+W17) -> 24423.85 | Z17: =SUM(V17+X17) -> 20967.742 | AA17: teilweise sonnig | AB17: 12 | AC17: °C | AF17: =C17+E17+G17+K17+O17+W17 -> 5380.3
A18: =SUM(A17+1) -> 12 | B18: Mi | C18: 5647.5 | D18: 9516.129 | E18: 0 | F18: 483.87097 | G18: 14.6 | H18: 258.06452 | I18: 0 | K18: 3884.5 | M18: =K18+L18 -> 3884.5 | N18: 2670.9677 | O18: 1011.6 | P18: 7139 | Q18: =SUM(O18:P18) -> 8150.6 | R18: 3225.8065 | S18: 3552.85 | T18: 4812.9032 | U18: =SUM(C18+E18+G18+I18+K18+Q18+S18) -> 21250.05 | V18: =SUM(D18+F18+H18+J18+N18+R18+T18) -> 20967.742 | W18: 0 | Y18: =SUM(U18+W18) -> 21250.05 | Z18: =SUM(V18+X18) -> 20967.742 | AA18: regen | AB18: 8 | AC18: °C | AF18: =C18+E18+G18+K18+O18+W18 -> 10558.2
A19: =SUM(A18+1) -> 13 | B19: Do | C19: 7114.3 | D19: 9516.129 | E19: 0 | F19: 483.87097 | G19: 0 | H19: 258.06452 | I19: 0 | K19: 165 | M19: =K19+L19 -> 165 | N19: 2670.9677 | O19: 256.9 | P19: 1467 | Q19: =SUM(O19:P19) -> 1723.9 | R19: 3225.8065 | S19: 4302.6 | T19: 4812.9032 | U19: =SUM(C19+E19+G19+I19+K19+Q19+S19) -> 13305.8 | V19: =SUM(D19+F19+H19+J19+N19+R19+T19) -> 20967.742 | W19: 0 | Y19: =SUM(U19+W19) -> 13305.8 | Z19: =SUM(V19+X19) -> 20967.742 | AA19: bewölkt | AB19: 4 | AC19: °C | AF19: =C19+E19+G19+K19+O19+W19 -> 7536.2
A20: =SUM(A19+1) -> 14 | B20: Fr | C20: 9456.3 | D20: 9516.129 | E20: 0 | F20: 483.87097 | G20: 0 | H20: 258.06452 | I20: 0 | K20: 7130.8 | M20: =K20+L20 -> 7130.8 | N20: 2670.9677 | O20: 105 | P20: 1823 | Q20: =SUM(O20:P20) -> 1928 | R20: 3225.8065 | S20: 8999.15 | T20: 4812.9032 | U20: =SUM(C20+E20+G20+I20+K20+Q20+S20) -> 27514.25 | V20: =SUM(D20+F20+H20+J20+N20+R20+T20) -> 20967.742 | W20: 0 | Y20: =SUM(U20+W20) -> 27514.25 | Z20: =SUM(V20+X20) -> 20967.742 | AA20: bewölkt | AB20: 3 | AC20: °C | AF20: =C20+E20+G20+K20+O20+W20 -> 16692.1
A21: =SUM(A20+1) -> 15 | B21: Sa | C21: 9893.4 | D21: 9516.129 | E21: 0 | F21: 483.87097 | G21: 5.1 | H21: 258.06452 | I21: 0 | K21: 6235.1 | M21: =K21+L21 -> 6235.1 | N21: 2670.9677 | O21: 0 | P21: 0 | Q21: =SUM(O21:P21) -> 0 | R21: 3225.8065 | S21: 5509.89 | T21: 4812.9032 | U21: =SUM(C21+E21+G21+I21+K21+Q21+S21) -> 21643.49 | V21: =SUM(D21+F21+H21+J21+N21+R21+T21) -> 20967.742 | W21: 0 | Y21: =SUM(U21+W21) -> 21643.49 | Z21: =SUM(V21+X21) -> 20967.742 | AA21: bewölkt | AB21: 2 | AC21: °C | AF21: =C21+E21+G21+K21+O21+W21 -> 16133.6
A22: =SUM(A21+1) -> 16 | B22: So | C22: 13303.8 | D22: 9516.129 | E22: 0 | F22: 483.87097 | G22: 0 | H22: 258.06452 | I22: 0 | K22: 10562.5 | M22: =K22+L22 -> 10562.5 | N22: 2670.9677 | O22: 254 | P22: 0 | Q22: =SUM(O22:P22) -> 254 | R22: 3225.8065 | S22: 1311.3 | T22: 4812.9032 | U22: =SUM(C22+E22+G22+I22+K22+Q22+S22) -> 25431.6 | V22: =SUM(D22+F22+H22+J22+N22+R22+T22) -> 20967.742 | W22: 0 | Y22: =SUM(U22+W22) -> 25431.6 | Z22: =SUM(V22+X22) -> 20967.742 | AA22: bewölkt / teilweise Regen | AB22: 3 | AC22: °C | AF22: =C22+E22+G22+K22+O22+W22 -> 24120.3
A23: KW | B23: =SUM(B15+1) -> 11 | C23: =SUM(C16:C22) -> 55481.7 | D23: =SUM(D16:D22) -> 66612.903 | E23: =SUM(E16:E22) -> 370.8 | F23: =SUM(F16:F22) -> 3387.0968 | G23: =SUM(G16:G22) -> 377.1 | H23: =SUM(H16:H22) -> 1806.4516 | I23: 0 | J23: =SUM(J16:J22) -> 0 | K23: =SUM(K16:K22) -> 29340.7 | L23: =SUM(L16:L22) -> 0 | M23: =SUM(M16:M22) -> 29340.7 | N23: =SUM(N16:N22) -> 18696.774 | O23: =SUM(O16:O22) -> 3159.9 | P23: =SUM(P16:P22) -> 24574 | Q23: =SUM(Q16:Q22) -> 27733.9 | ... Z23: =SUM(Z16:Z22) -> 146774.19 | AA23: Ø Temp | AB23: =SUM(AB16:AB22)/7 -> 6.1428571 | AC23: °C
A24: =SUM(A22+1) -> 17 | B24: Mo | C24: 5292.1 | D24: 9516.129 | E24: 28.6 | F24: 483.87097 | G24: 14.1 | H24: 258.06452 | I24: 0 | K24: 0 | M24: =K24+L24 -> 0 | N24: 2670.9677 | O24: 1098 | P24: 5279 | Q24: =SUM(O24:P24) -> 6377 | R24: 3225.8065 | S24: 6341.35 | T24: 4812.9032 | U24: =SUM(C24+E24+G24+I24+K24+Q24+S24) -> 18053.15 | V24: =SUM(D24+F24+H24+J24+N24+R24+T24) -> 20967.742 | W24: 0 | Y24: =SUM(U24+W24) -> 18053.15 | Z24: =SUM(V24+X24) -> 20967.742 | AA24: bewölkt | AB24: 3 | AC24: °C | AF24: =C24+E24+G24+K24+O24+W24 -> 6432.8
A25: =SUM(A24+1) -> 18 | B25: Di | C25: 4930.9 | D25: 9516.129 | E25: 771.8 | F25: 483.87097 | G25: 268.7 | H25: 258.06452 | I25: 0 | K25: 0 | M25: =K25+L25 -> 0 | N25: 2670.9677 | O25: 1868.9 | P25: 8832 | Q25: =SUM(O25:P25) -> 10700.9 | R25: 3225.8065 | S25: 6008.85 | T25: 4812.9032 | U25: =SUM(C25+E25+G25+I25+K25+Q25+S25) -> 22681.15 | V25: =SUM(D25+F25+H25+J25+N25+R25+T25) -> 20967.742 | W25: 0 | Y25: =SUM(U25+W25) -> 22681.15 | Z25: =SUM(V25+X25) -> 20967.742 | AA25: sonnig | AB25: 9 | AC25: °C | AF25: =C25+E25+G25+K25+O25+W25 -> 7840.3
A26: =SUM(A25+1) -> 19 | B26: Mi | C26: 6317.5 | D26: 9516.129 | E26: 2736.4 | F26: 483.87097 | G26: 723.2 | H26: 258.06452 | I26: 0 | K26: 1560 | M26: =K26+L26 -> 1560 | N26: 2670.9677 | O26: 88 | P26: 5902 | Q26: =SUM(O26:P26) -> 5990 | R26: 3225.8065 | S26: 3114.25 | T26: 4812.9032 | U26: =SUM(C26+E26+G26+I26+K26+Q26+S26) -> 20441.35 | V26: =SUM(D26+F26+H26+J26+N26+R26+T26) -> 20967.742 | W26: 0 | Y26: =SUM(U26+W26) -> 20441.35 | Z26: =SUM(V26+X26) -> 20967.742 | AA26: sonnig | AB26: 13 | AC26: °C | AF26: =C26+E26+G26+K26+O26+W26 -> 11425.1
A27: =SUM(A26+1) -> 20 | B27: Do | C27: 7879.1 | D27: 9516.129 | E27: 1694.5 | F27: 483.87097 | G27: 551.7 | H27: 258.06452 | I27: 0 | K27: 2806.9 | M27: =K27+L27 -> 2806.9 | N27: 2670.9677 | O27: 1164.4 | P27: 2448 | Q27: =SUM(O27:P27) -> 3612.4 | R27: 3225.8065 | S27: 2697.17 | T27: 4812.9032 | U27: =SUM(C27+E27+G27+I27+K27+Q27+S27) -> 19241.77 | V27: =SUM(D27+F27+H27+J27+N27+R27+T27) -> 20967.742 | W27: 0 | Y27: =SUM(U27+W27) -> 19241.77 | Z27: =SUM(V27+X27) -> 20967.742 | AA27: sonnig | AB27: 13 | AC27: °C | AF27: =C27+E27+G27+K27+O27+W27 -> 14096.6
A28: =SUM(A27+1) -> 21 | B28: Fr | C28: 9714.5 | D28: 9516.129 | E28: 559.1 | F28: 483.87097 | G28: 376.8 | H28: 258.06452 | I28: 0 | K28: 0 | M28: =K28+L28 -> 0 | N28: 2670.9677 | O28: 92.8 | P28: 450 | Q28: =SUM(O28:P28) -> 542.8 | R28: 3225.8065 | S28: 3578.98 | T28: 4812.9032 | U28: =SUM(C28+E28+G28+I28+K28+Q28+S28) -> 14772.18 | V28: =SUM(D28+F28+H28+J28+N28+R28+T28) -> 20967.742 | W28: 0 | Y28: =SUM(U28+W28) -> 14772.18 | Z28: =SUM(V28+X28) -> 20967.742 | AA28: bewölkt | AB28: 16 | AC28: °C | AF28: =C28+E28+G28+K28+O28+W28 -> 10743.2
A29: =SUM(A28+1) -> 22 | B29: Sa | C29: 14912.3 | D29: 9516.129 | E29: 5260.6 | F29: 483.87097 | G29: 1137.8 | H29: 258.06452 | I29: 0 | K29: 6285.7 | M29: =K29+L29 -> 6285.7 | N29: 2670.9677 | O29: 0 | P29: 0 | Q29: =SUM(O29:P29) -> 0 | R29: 3225.8065 | S29: 8129.6 | T29: 4812.9032 | U29: =SUM(C29+E29+G29+I29+K29+Q29+S29) -> 35726 | V29: =SUM(D29+F29+H29+J29+N29+R29+T29) -> 20967.742 | W29: 0 | Y29: =SUM(U29+W29) -> 35726 | Z29: =SUM(V29+X29) -> 20967.742 | AA29: sonnig | AB29: 17 | AC29: °C | AF29: =C29+E29+G29+K29+O29+W29 -> 27596.4
A30: =SUM(A29+1) -> 23 | B30: So | C30: 13138 | D30: 9516.129 | E30: 1462.7 | F30: 483.87097 | G30: 579.9 | H30: 258.06452 | I30: 0 | K30: 1720 | M30: =K30+L30 -> 1720 | N30: 2670.9677 | O30: 0 | P30: 0 | Q30: =SUM(O30:P30) -> 0 | R30: 3225.8065 | S30: 2563.11 | T30: 4812.9032 | U30: =SUM(C30+E30+G30+I30+K30+Q30+S30) -> 19463.71 | V30: =SUM(D30+F30+H30+J30+N30+R30+T30) -> 20967.742 | W30: 0 | Y30: =SUM(U30+W30) -> 19463.71 | Z30: =SUM(V30+X30) -> 20967.742 | AA30: bewölkt / sonnig | AB30: 15 | AC30: °C | AF30: =C30+E30+G30+K30+O30+W30 -> 16900.6
A31: KW | B31: =SUM(B23+1) -> 12 | C31: =SUM(C24:C30) -> 62184.4 | D31: =SUM(D24:D30) -> 66612.903 | E31: =SUM(E24:E30) -> 12513.7 | F31: =SUM(F24:F30) -> 3387.0968 | G31: =SUM(G24:G30) -> 3652.2 | H31: =SUM(H24:H30) -> 1806.4516 | I31: =SUM(I24:I30) -> 0 | J31: =SUM(J24:J30) -> 0 | ... Z31: =SUM(Z24:Z30) -> 146774.19 | AA31: Ø Temp | AB31: =SUM(AB24:AB30)/7 -> 12.285714 | AC31: °C
A32: =SUM(A30+1) -> 24 | B32: Mo | C32: 4868.1 | D32: 9516.129 | E32: 244.2 | F32: 483.87097 | G32: 93.3 | H32: 258.06452 | I32: 0 | K32: 652.1 | M32: =K32+L32 -> 652.1 | N32: 2670.9677 | O32: 1703.1 | P32: 610 | Q32: =SUM(O32:P32) -> 2313.1 | R32: 3225.8065 | S32: 3609.6 | T32: 4812.9032 | U32: =SUM(C32+E32+G32+I32+K32+Q32+S32) -> 11780.4 | V32: =SUM(D32+F32+H32+J32+N32+R32+T32) -> 20967.742 | W32: 0 | Y32: =SUM(U32+W32) -> 11780.4 | Z32: =SUM(V32+X32) -> 20967.742 | AA32: bewölkt / Regenschauer | AB32: 11 | AC32: °C | AF32: =C32+E32+G32+K32+O32+W32 -> 7560.8
A33: =SUM(A32+1) -> 25 | B33: Di | C33: 7446.3 | D33: 9516.129 | E33: 0 | F33: 483.87097 | G33: 29.9 | H33: 258.06452 | I33: 0 | K33: 2338 | M33: =K33+L33 -> 2338 | N33: 2670.9677 | O33: 1890.9 | P33: 5652 | Q33: =SUM(O33:P33) -> 7542.9 | R33: 3225.8065 | S33: 5646.86 | T33: 4812.9032 | U33: =SUM(C33+E33+G33+I33+K33+Q33+S33) -> 23003.96 | V33: =SUM(D33+F33+H33+J33+N33+R33+T33) -> 20967.742 | W33: 0 | Y33: =SUM(U33+W33) -> 23003.96 | Z33: =SUM(V33+X33) -> 20967.742 | AA33: regen | AB33: 5 | AC33: °C | AF33: =C33+E33+G33+K33+O33+W33 -> 11705.1
A34: =SUM(A33+1) -> 26 | B34: Mi | C34: 6297.2 | D34: 9516.129 | E34: 0 | F34: 483.87097 | G34: 100.5 | H34: 258.06452 | I34: 0 | K34: 0 | M34: =K34+L34 -> 0 | N34: 2670.9677 | O34: 2037.6 | P34: 8974.5 | Q34: =SUM(O34:P34) -> 11012.1 | R34: 3225.8065 | S34: 8591.59 | T34: 4812.9032 | U34: =SUM(C34+E34+G34+I34+K34+Q34+S34) -> 26001.39 | V34: =SUM(D34+F34+H34+J34+N34+R34+T34) -> 20967.742 | W34: 0 | Y34: =SUM(U34+W34) -> 26001.39 | Z34: =SUM(V34+X34) -> 20967.742 | AA34: bewölkt | AB34: 4 | AC34: °C | AF34: =C34+E34+G34+K34+O34+W34 -> 8435.3
A35: =SUM(A34+1) -> 27 | B35: Do | C35: 6439.3 | D35: 9516.129 | E35: 5.2 | F35: 483.87097 | G35: 22.4 | H35: 258.06452 | I35: 0 | K35: 1699.6 | M35: =K35+L35 -> 1699.6 | N35: 2670.9677 | O35: 601.1 | P35: 9284 | Q35: =SUM(O35:P35) -> 9885.1 | R35: 3225.8065 | S35: 5292.07 | T35: 4812.9032 | U35: =SUM(C35+E35+G35+I35+K35+Q35+S35) -> 23343.67 | V35: =SUM(D35+F35+H35+J35+N35+R35+T35) -> 20967.742 | W35: 0 | Y35: =SUM(U35+W35) -> 23343.67 | Z35: =SUM(V35+X35) -> 20967.742 | AA35: regen | AB35: 5 | AC35: °C | AF35: =C35+E35+G35+K35+O35+W35 -> 8767.6
A36: 28 | B36: Fr | C36: 10134 | D36: 9516.129 | E36: 0 | F36: 483.87097 | G36: 85.1 | H36: 258.06452 | I36: 0 | K36: 0 | M36: =K36+L36 -> 0 | N36: 2670.9677 | O36: 0 | P36: 0 | Q36: =SUM(O36:P36) -> 0 | R36: 3225.8065 | S36: 3573.08 | T36: 4812.9032 | U36: =SUM(C36+E36+G36+I36+K36+Q36+S36) -> 13792.18 | V36: =SUM(D36+F36+H36+J36+N36+R36+T36) -> 20967.742 | W36: 0 | Y36: =SUM(U36+W36) -> 13792.18 | Z36: =SUM(V36+X36) -> 20967.742 | AA36: teilweise Regen | AB36: 10 | AC36: °C | AF36: =C36+E36+G36+K36+O36+W36 -> 10219.1
A37: =SUM(A36+1) -> 29 | B37: Sa | C37: 15940.8 | D37: 9516.129 | E37: 0 | F37: 483.87097 | G37: 0 | H37: 258.06452 | I37: 0 | K37: 9860.7 | M37: =K37+L37 -> 9860.7 | N37: 2670.9677 | O37: 0 | P37: 125 | Q37: =SUM(O37:P37) -> 125 | R37: 3225.8065 | S37: 4681.77 | T37: 4812.9032 | U37: =SUM(C37+E37+G37+I37+K37+Q37+S37) -> 30608.27 | V37: =SUM(D37+F37+H37+J37+N37+R37+T37) -> 20967.742 | W37: 0 | Y37: =SUM(U37+W37) -> 30608.27 | Z37: =SUM(V37+X37) -> 20967.742 | AA37: Regen | AB37: 8 | AC37: °C | AF37: =C37+E37+G37+K37+O37+W37 -> 25801.5
A38: =SUM(A37+1) -> 30 | B38: So | C38: 19089.7 | D38: 9516.129 | E38: 2750.3 | F38: 483.87097 | G38: 911.9 | H38: 258.06452 | I38: 0 | K38: 3012.5 | M38: =K38+L38 -> 3012.5 | N38: 2670.9677 | O38: 0 | P38: 0 | Q38: =SUM(O38:P38) -> 0 | R38: 3225.8065 | S38: 1923.35 | T38: 4812.9032 | U38: =SUM(C38+E38+G38+I38+K38+Q38+S38) -> 27687.75 | V38: =SUM(D38+F38+H38+J38+N38+R38+T38) -> 20967.742 | W38: 0 | Y38: =SUM(U38+W38) -> 27687.75 | Z38: =SUM(V38+X38) -> 20967.742 | AA38: teilweise bewölkt | AB38: 13 | AC38: °C | AF38: =C38+E38+G38+K38+O38+W38 -> 25764.4
A39: KW | B39: =SUM(B31+1) -> 13 | C39: =SUM(C32:C38) -> 70215.4 | D39: =SUM(D32:D38) -> 66612.903 | E39: =SUM(E32:E38) -> 2999.7 | F39: =SUM(F32:F38) -> 3387.0968 | G39: =SUM(G32:G38) -> 1243.1 | H39: =SUM(H32:H38) -> 1806.4516 | I39: =SUM(I32:I38) -> 0 | J39: =SUM(J32:J38) -> 0 | ... Z39: =SUM(Z32:Z38) -> 146774.19 | AA39: Ø Temp | AB39: =SUM(AB32:AB36)/4 -> 8.75 | AC39: °C
A40: =A38+1 -> 31 | B40: Mo | C40: 6774.6 | D40: 9516.129 | E40: 87.3 | F40: 483.87097 | G40: 188.2 | H40: 258.06452 | I40: 0 | K40: 690 | M40: =K40+L40 -> 690 | N40: 2670.9677 | O40: 288.9 | P40: 2055 | Q40: 3243 | R40: 3225.8065 | S40: 2696.8 | T40: 4812.9032 | U40: =SUM(C40+E40+G40+I40+K40+Q40+S40) -> 13679.9 | V40: =SUM(D40+F40+H40+J40+N40+R40+T40) -> 20967.742 | W40: 0 | Y40: =SUM(U40+W40) -> 13679.9 | Z40: =SUM(V40+X40) -> 20967.742 | AA40: wechselhaft | AB40: 10 | AC40: °C | AF40: =C40+E40+G40+K40+O40+W40 -> 8029
