Workbook

Sheet 01_21
A1: Tagesumsätze | H1: 44197
C3: Restaurant | E3: Terrasse | G3: Lounge | I3: Pavillon | K3: Bankett | M3: Seminar | O3: Hotel | Q3: TOTAL Gesamtbetrieb ohne Seebad | S3: Seebad | U3: TOTAL Gesamtbetrieb mit Seebad | W3: Info's
C4: IST | D4: Budget | E4: IST | F4: Budget | G4: IST | H4: Budget | I4: IST | J4: Budget | K4: IST | L4: Budget | M4: IST | N4: Budget | O4: IST | P4: Budget | Q4: IST | R4: Budget | S4: IST | T4: Budget | U4: IST | V4: Budget | W4: Wetter | X4: Temp. | Z4: Bemerkung
A5: 1 | B5: Fr | C5: 1620.2 | D5: 2096.7742 | E5: 0 | F5: 29.03225 | G5: 0 | H5: 56.4516 | I5: 0 | J5: 0 | K5: 0 | L5: 306.4516 | M5: 0 | N5: 137.0967 | O5: 1808 | P5: 385.4838 | Q5: =SUM(C5+E5+G5+I5+K5+M5+O5) -> 3428.2 | R5: =SUM(D5+F5+H5+J5+L5+N5+P5) -> 3011.2901 | U5: =SUM(Q5+S5) -> 3428.2 | V5: =SUM(R5+T5) -> 3011.2901 | Y5: °C | Z5: Rest. geschlossen Corona
A6: =SUM(A5+1) -> 2 | B6: Sa | C6: 872.9 | D6: 2096.7742 | E6: 0 | F6: 29.03225 | G6: 0 | H6: 56.4516 | I6: 0 | J6: 0 | K6: 0 | L6: 306.4516 | M6: 0 | N6: 137.0967 | O6: 1522 | P6: 385.4838 | Q6: =SUM(C6+E6+G6+I6+K6+M6+O6) -> 2394.9 | R6: =SUM(D6+F6+H6+J6+L6+N6+P6) -> 3011.2901 | U6: =SUM(Q6+S6) -> 2394.9 | V6: =SUM(R6+T6) -> 3011.2901 | Y6: °C | Z6: Rest. geschlossen Corona
A7: =SUM(A6+1) -> 3 | B7: So | C7: 0 | D7: 2096.7742 | E7: 0 | F7: 29.03225 | G7: 0 | H7: 56.4516 | I7: 0 | J7: 0 | K7: 0 | L7: 306.4516 | M7: 0 | N7: 137.0967 | O7: 257.6 | P7: 385.4838 | Q7: =SUM(C7+E7+G7+I7+K7+M7+O7) -> 257.6 | R7: =SUM(D7+F7+H7+J7+L7+N7+P7) -> 3011.2901 | U7: =SUM(Q7+S7) -> 257.6 | V7: =SUM(R7+T7) -> 3011.2901 | Y7: °C | Z7: Rest. geschlossen Corona
A8: KW | B8: 1 | C8: =SUM(C5:C7) -> 2493.1 | D8: =SUM(D5:D7) -> 6290.3226 | E8: =SUM(E5:E7) -> 0 | F8: =SUM(F5:F7) -> 87.09675 | G8: =SUM(G5:G7) -> 0 | H8: =SUM(H5:H7) -> 169.3548 | I8: =SUM(I5:I7) -> 0 | J8: =SUM(J5:J7) -> 0 | ... V8: =SUM(V5:V7) -> 9033.8704 | W8: Ø Temp | X8: =SUM(X5:X7)/5 -> 0 | Y8: °C
A9: =SUM(A7+1) -> 4 | B9: Mo | C9: 636.2 | D9: 2096.7742 | E9: 0 | F9: 29.03225 | G9: 0 | H9: 56.4516 | I9: 0 | J9: 0 | K9: 0 | L9: 306.4516 | M9: 0 | N9: 137.0967 | O9: 1240.2 | P9: 385.4838 | Q9: =SUM(C9+E9+G9+I9+K9+M9+O9) -> 1876.4 | R9: =SUM(D9+F9+H9+J9+L9+N9+P9) -> 3011.2901 | U9: =SUM(Q9+S9) -> 1876.4 | V9: =SUM(R9+T9) -> 3011.2901 | Y9: °C | Z9: Rest. geschlossen Corona
A10: =SUM(A9+1) -> 5 | B10: Di | C10: 694.5 | D10: 2096.7742 | E10: 0 | F10: 29.03225 | G10: 0 | H10: 56.4516 | I10: 0 | J10: 0 | K10: 0 | L10: 306.4516 | M10: 0 | N10: 137.0967 | O10: 1246.7 | P10: 385.4838 | Q10: =SUM(C10+E10+G10+I10+K10+M10+O10) -> 1941.2 | R10: =SUM(D10+F10+H10+J10+L10+N10+P10) -> 3011.2901 | U10: =SUM(Q10+S10) -> 1941.2 | V10: =SUM(R10+T10) -> 3011.2901 | Y10: °C | Z10: Rest. geschlossen Corona
A11: =SUM(A10+1) -> 6 | B11: Mi | C11: 378.3 | D11: 2096.7742 | E11: 0 | F11: 29.03225 | G11: 0 | H11: 56.4516 | I11: 0 | J11: 0 | K11: 0 | L11: 306.4516 | M11: 0 | N11: 137.0967 | O11: 942.6 | P11: 385.4838 | Q11: =SUM(C11+E11+G11+I11+K11+M11+O11) -> 1320.9 | R11: =SUM(D11+F11+H11+J11+L11+N11+P11) -> 3011.2901 | U11: =SUM(Q11+S11) -> 1320.9 | V11: =SUM(R11+T11) -> 3011.2901 | Y11: °C | Z11: Rest. geschlossen Corona
A12: =SUM(A11+1) -> 7 | B12: Do | C12: 388.4 | D12: 2096.7742 | E12: 0 | F12: 29.03225 | G12: 0 | H12: 56.4516 | I12: 0 | J12: 0 | K12: 0 | L12: 306.4516 | M12: 1508.3 | N12: 137.0967 | O12: 2089.2 | P12: 385.4838 | Q12: =SUM(C12+E12+G12+I12+K12+M12+O12) -> 3985.9 | R12: =SUM(D12+F12+H12+J12+L12+N12+P12) -> 3011.2901 | U12: =SUM(Q12+S12) -> 3985.9 | V12: =SUM(R12+T12) -> 3011.2901 | Y12: °C | Z12: Rest. geschlossen Corona
A13: =SUM(A12+1) -> 8 | B13: Fr | C13: 1768.3 | D13: 2096.7742 | E13: 0 | F13: 29.03225 | G13: 0 | H13: 56.4516 | I13: 0 | J13: 0 | K13: 0 | L13: 306.4516 | M13: 464.6 | N13: 137.0967 | O13: 1632.6 | P13: 385.4838 | Q13: =SUM(C13+E13+G13+I13+K13+M13+O13) -> 3865.5 | R13: =SUM(D13+F13+H13+J13+L13+N13+P13) -> 3011.2901 | U13: =SUM(Q13+S13) -> 3865.5 | V13: =SUM(R13+T13) -> 3011.2901 | Y13: °C | Z13: Rest. geschlossen Corona
A14: =SUM(A13+1) -> 9 | B14: Sa | C14: 1673.1 | D14: 2096.7742 | E14: 0 | F14: 29.03225 | G14: 0 | H14: 56.4516 | I14: 0 | J14: 0 | K14: 0 | L14: 306.4516 | M14: 0 | N14: 137.0967 | O14: 2297.4 | P14: 385.4838 | Q14: =SUM(C14+E14+G14+I14+K14+M14+O14) -> 3970.5 | R14: =SUM(D14+F14+H14+J14+L14+N14+P14) -> 3011.2901 | U14: =SUM(Q14+S14) -> 3970.5 | V14: =SUM(R14+T14) -> 3011.2901 | Y14: °C | Z14: Rest. geschlossen Corona
A15: =SUM(A14+1) -> 10 | B15: So | C15: 0 | D15: 2096.7742 | E15: 0 | F15: 29.03225 | G15: 0 | H15: 56.4516 | I15: 0 | J15: 0 | K15: 0 | L15: 306.4516 | M15: 0 | N15: 137.0967 | O15: 144.3 | P15: 385.4838 | Q15: =SUM(C15+E15+G15+I15+K15+M15+O15) -> 144.3 | R15: =SUM(D15+F15+H15+J15+L15+N15+P15) -> 3011.2901 | U15: =SUM(Q15+S15) -> 144.3 | V15: =SUM(R15+T15) -> 3011.2901 | Y15: °C | Z15: Rest. geschlossen Corona
A16: KW | B16: =SUM(B8+1) -> 2 | C16: =SUM(C9:C15) -> 5538.8 | D16: =SUM(D9:D15) -> 14677.419 | E16: =SUM(E9:E15) -> 0 | F16: =SUM(F9:F15) -> 203.22575 | G16: =SUM(G9:G15) -> 0 | H16: =SUM(H9:H15) -> 395.1612 | I16: =SUM(I9:I15) -> 0 | J16: 0 | K16: =SUM(K9:K15) -> 0 | L16: =SUM(L9:L15) -> 2145.1612 | M16: =SUM(M9:M15) -> 1972.9 | N16: =SUM(N9:N15) -> 959.6769 | O16: =SUM(O9:O15) -> 9593 | P16: =SUM(P9:P15) -> 2698.3866 | Q16: =SUM(Q9:Q15) -> 17104.7 | R16: =SUM(R9:R15) -> 21079.031 | ... V16: =SUM(V9:V15) -> 21079.031 | W16: Ø Temp | X16: =SUM(X9:X15)/7 -> 0 | Y16: °C
A17: =SUM(A15+1) -> 11 | B17: Mo | C17: 184.1 | D17: 2096.7742 | E17: 0 | F17: 29.03225 | G17: 0 | H17: 56.4516 | I17: 0 | J17: 0 | K17: 0 | L17: 306.4516 | M17: 0 | N17: 137.0967 | O17: 333.6 | P17: 385.4838 | Q17: =SUM(C17+E17+G17+I17+K17+M17+O17) -> 517.7 | R17: =SUM(D17+F17+H17+J17+L17+N17+P17) -> 3011.2901 | U17: =SUM(Q17+S17) -> 517.7 | V17: =SUM(R17+T17) -> 3011.2901 | Y17: °C | Z17: Rest. geschlossen Corona
A18: =SUM(A17+1) -> 12 | B18: Di | C18: 248.7 | D18: 2096.7742 | E18: 0 | F18: 29.03225 | G18: 0 | H18: 56.4516 | I18: 0 | J18: 0 | K18: 0 | L18: 306.4516 | M18: 0 | N18: 137.0967 | O18: 1215.1 | P18: 385.4838 | Q18: =SUM(C18+E18+G18+I18+K18+M18+O18) -> 1463.8 | R18: =SUM(D18+F18+H18+J18+L18+N18+P18) -> 3011.2901 | U18: =SUM(Q18+S18) -> 1463.8 | V18: =SUM(R18+T18) -> 3011.2901 | Y18: °C | Z18: Rest. geschlossen Corona
A19: =SUM(A18+1) -> 13 | B19: Mi | C19: 824 | D19: 2096.7742 | E19: 0 | F19: 29.03225 | G19: 0 | H19: 56.4516 | I19: 0 | J19: 0 | K19: 0 | L19: 306.4516 | M19: 0 | N19: 137.0967 | O19: 1623.7 | P19: 385.4838 | Q19: =SUM(C19+E19+G19+I19+K19+M19+O19) -> 2447.7 | R19: =SUM(D19+F19+H19+J19+L19+N19+P19) -> 3011.2901 | U19: =SUM(Q19+S19) -> 2447.7 | V19: =SUM(R19+T19) -> 3011.2901 | Y19: °C | Z19: Rest. geschlossen Corona
A20: =SUM(A19+1) -> 14 | B20: Do | C20: 76.9 | D20: 2096.7742 | E20: 0 | F20: 29.03225 | G20: 0 | H20: 56.4516 | I20: 0 | J20: 0 | K20: 0 | L20: 306.4516 | M20: 0 | N20: 137.0967 | O20: 596 | P20: 385.4838 | Q20: =SUM(C20+E20+G20+I20+K20+M20+O20) -> 672.9 | R20: =SUM(D20+F20+H20+J20+L20+N20+P20) -> 3011.2901 | U20: =SUM(Q20+S20) -> 672.9 | V20: =SUM(R20+T20) -> 3011.2901 | Y20: °C | Z20: Rest. geschlossen Corona
A21: =SUM(A20+1) -> 15 | B21: Fr | C21: 243.9 | D21: 2096.7742 | E21: 0 | F21: 29.03225 | G21: 0 | H21: 56.4516 | I21: 0 | J21: 0 | K21: 0 | L21: 306.4516 | M21: 0 | N21: 137.0967 | O21: 890.1 | P21: 385.4838 | Q21: =SUM(C21+E21+G21+I21+K21+M21+O21) -> 1134 | R21: =SUM(D21+F21+H21+J21+L21+N21+P21) -> 3011.2901 | U21: =SUM(Q21+S21) -> 1134 | V21: =SUM(R21+T21) -> 3011.2901 | Y21: °C | Z21: Rest. geschlossen Corona
A22: =SUM(A21+1) -> 16 | B22: Sa | C22: 1049.3 | D22: 2096.7742 | E22: 0 | F22: 29.03225 | G22: 0 | H22: 56.4516 | I22: 0 | J22: 0 | K22: 0 | L22: 306.4516 | M22: 0 | N22: 137.0967 | O22: 1775.4 | P22: 385.4838 | Q22: =SUM(C22+E22+G22+I22+K22+M22+O22) -> 2824.7 | R22: =SUM(D22+F22+H22+J22+L22+N22+P22) -> 3011.2901 | U22: =SUM(Q22+S22) -> 2824.7 | V22: =SUM(R22+T22) -> 3011.2901 | Y22: °C | Z22: Rest. geschlossen Corona
A23: =SUM(A22+1) -> 17 | B23: So | C23: 114.7 | D23: 2096.7742 | E23: 0 | F23: 29.03225 | G23: 0 | H23: 56.4516 | I23: 0 | J23: 0 | K23: 0 | L23: 306.4516 | M23: 0 | N23: 137.0967 | O23: 643 | P23: 385.4838 | Q23: =SUM(C23+E23+G23+I23+K23+M23+O23) -> 757.7 | R23: =SUM(D23+F23+H23+J23+L23+N23+P23) -> 3011.2901 | U23: =SUM(Q23+S23) -> 757.7 | V23: =SUM(R23+T23) -> 3011.2901 | Y23: °C | Z23: Rest. geschlossen Corona
A24: KW | B24: =SUM(B16+1) -> 3 | C24: =SUM(C17:C23) -> 2741.6 | D24: =SUM(D17:D23) -> 14677.419 | E24: =SUM(E17:E23) -> 0 | F24: =SUM(F17:F23) -> 203.22575 | G24: =SUM(G17:G23) -> 0 | H24: =SUM(H17:H23) -> 395.1612 | I24: =SUM(I17:I23) -> 0 | J24: 0 | K24: =SUM(K17:K23) -> 0 | L24: =SUM(L17:L23) -> 2145.1612 | M24: =SUM(M17:M23) -> 0 | N24: =SUM(N17:N23) -> 959.6769 | O24: =SUM(O17:O23) -> 7076.9 | P24: =SUM(P17:P23) -> 2698.3866 | Q24: =SUM(Q17:Q23) -> 9818.5 | R24: =SUM(R17:R23) -> 21079.031 | ... V24: =SUM(V17:V23) -> 21079.031 | W24: Ø Temp | X24: =SUM(X17:X23)/7 -> 0 | Y24: °C
A25: =SUM(A23+1) -> 18 | B25: Mo | C25: 831.1 | D25: 2096.7742 | E25: 0 | F25: 29.03225 | G25: 0 | H25: 56.4516 | I25: 0 | J25: 0 | K25: 0 | L25: 306.4516 | M25: 0 | N25: 137.0967 | O25: 1126.4 | P25: 385.4838 | Q25: =SUM(C25+E25+G25+I25+K25+M25+O25) -> 1957.5 | R25: =SUM(D25+F25+H25+J25+L25+N25+P25) -> 3011.2901 | U25: =SUM(Q25+S25) -> 1957.5 | V25: =SUM(R25+T25) -> 3011.2901 | Y25: °C | Z25: Rest. geschlossen Corona
A26: =SUM(A25+1) -> 19 | B26: Di | C26: 464.1 | D26: 2096.7742 | E26: 0 | F26: 29.03225 | G26: 0 | H26: 56.4516 | I26: 0 | J26: 0 | K26: 0 | L26: 306.4516 | M26: 0 | N26: 137.0967 | O26: 1004.6 | P26: 385.4838 | Q26: =SUM(C26+E26+G26+I26+K26+M26+O26) -> 1468.7 | R26: =SUM(D26+F26+H26+J26+L26+N26+P26) -> 3011.2901 | U26: =SUM(Q26+S26) -> 1468.7 | V26: =SUM(R26+T26) -> 3011.2901 | Y26: °C | Z26: Rest. geschlossen Corona
A27: =SUM(A26+1) -> 20 | B27: Mi | C27: 85.7 | D27: 2096.7742 | E27: 0 | F27: 29.03225 | G27: 0 | H27: 56.4516 | I27: 0 | J27: 0 | K27: 0 | L27: 306.4516 | M27: 0 | N27: 137.0967 | O27: 974.6 | P27: 385.4838 | Q27: =SUM(C27+E27+G27+I27+K27+M27+O27) -> 1060.3 | R27: =SUM(D27+F27+H27+J27+L27+N27+P27) -> 3011.2901 | U27: =SUM(Q27+S27) -> 1060.3 | V27: =SUM(R27+T27) -> 3011.2901 | Y27: °C | Z27: Rest. geschlossen Corona
A28: =SUM(A27+1) -> 21 | B28: Do | C28: 123.2 | D28: 2096.7742 | E28: 0 | F28: 29.03225 | G28: 0 | H28: 56.4516 | I28: 0 | J28: 0 | K28: 0 | L28: 306.4516 | M28: 0 | N28: 137.0967 | O28: 257.6 | P28: 385.4838 | Q28: =SUM(C28+E28+G28+I28+K28+M28+O28) -> 380.8 | R28: =SUM(D28+F28+H28+J28+L28+N28+P28) -> 3011.2901 | U28: =SUM(Q28+S28) -> 380.8 | V28: =SUM(R28+T28) -> 3011.2901 | Y28: °C | Z28: Rest. geschlossen Corona
A29: =SUM(A28+1) -> 22 | B29: Fr | C29: 123.2 | D29: 2096.7742 | E29: 0 | F29: 29.03225 | G29: 0 | H29: 56.4516 | I29: 0 | J29: 0 | K29: 0 | L29: 306.4516 | M29: 0 | N29: 137.0967 | O29: 255.6 | P29: 385.4838 | Q29: =SUM(C29+E29+G29+I29+K29+M29+O29) -> 378.8 | R29: =SUM(D29+F29+H29+J29+L29+N29+P29) -> 3011.2901 | U29: =SUM(Q29+S29) -> 378.8 | V29: =SUM(R29+T29) -> 3011.2901 | Y29: °C | Z29: Rest. geschlossen Corona
A30: =SUM(A29+1) -> 23 | B30: Sa | C30: 2673.2 | D30: 2096.7742 | E30: 0 | F30: 29.03225 | G30: 0 | H30: 56.4516 | I30: 0 | J30: 0 | K30: 0 | L30: 306.4516 | M30: 0 | N30: 137.0967 | O30: 2930.4 | P30: 385.4838 | Q30: =SUM(C30+E30+G30+I30+K30+M30+O30) -> 5603.6 | R30: =SUM(D30+F30+H30+J30+L30+N30+P30) -> 3011.2901 | U30: =SUM(Q30+S30) -> 5603.6 | V30: =SUM(R30+T30) -> 3011.2901 | Y30: °C | Z30: Rest. geschlossen Corona
A31: =SUM(A30+1) -> 24 | B31: So | C31: -300 | D31: 2096.7742 | E31: 0 | F31: 29.03225 | G31: 0 | H31: 56.4516 | I31: 0 | J31: 0 | K31: 0 | L31: 306.4516 | M31: 0 | N31: 137.0967 | O31: 117 | P31: 385.4838 | Q31: =SUM(C31+E31+G31+I31+K31+M31+O31) -> -183 | R31: =SUM(D31+F31+H31+J31+L31+N31+P31) -> 3011.2901 | U31: =SUM(Q31+S31) -> -183 | V31: =SUM(R31+T31) -> 3011.2901 | Y31: °C | Z31: Rest. geschlossen Corona
A32: KW | B32: =SUM(B24+1) -> 4 | C32: =SUM(C25:C31) -> 4000.5 | D32: =SUM(D25:D31) -> 14677.419 | E32: =SUM(E25:E31) -> 0 | F32: =SUM(F25:F31) -> 203.22575 | G32: =SUM(G25:G31) -> 0 | H32: =SUM(H25:H31) -> 395.1612 | I32: =SUM(I25:I31) -> 0 | J32: =SUM(J25:J31) -> 0 | ... V32: =SUM(V25:V31) -> 21079.031 | W32: Ø Temp | X32: =SUM(X25:X31)/7 -> 0 | Y32: °C
A33: =SUM(A31+1) -> 25 | B33: Mo | C33: 641 | D33: 2096.7742 | E33: 0 | F33: 29.03225 | G33: 0 | H33: 56.4516 | I33: 0 | J33: 0 | K33: 0 | L33: 306.4516 | M33: 0 | N33: 137.0967 | O33: 319.4 | P33: 385.4838 | Q33: =SUM(C33+E33+G33+I33+K33+M33+O33) -> 960.4 | R33: =SUM(D33+F33+H33+J33+L33+N33+P33) -> 3011.2901 | U33: =SUM(Q33+S33) -> 960.4 | V33: =SUM(R33+T33) -> 3011.2901 | Y33: °C | Z33: Rest. geschlossen Corona
A34: =SUM(A33+1) -> 26 | B34: Di | C34: 200.3 | D34: 2096.7742 | E34: 0 | F34: 29.03225 | G34: 0 | H34: 56.4516 | I34: 0 | J34: 0 | K34: 0 | L34: 306.4516 | M34: 0 | N34: 137.0967 | O34: 235.6 | P34: 385.4838 | Q34: =SUM(C34+E34+G34+I34+K34+M34+O34) -> 435.9 | R34: =SUM(D34+F34+H34+J34+L34+N34+P34) -> 3011.2901 | U34: =SUM(Q34+S34) -> 435.9 | V34: =SUM(R34+T34) -> 3011.2901 | Y34: °C | Z34: Rest. geschlossen Corona
A35: =SUM(A34+1) -> 27 | B35: Mi | C35: 712.1 | D35: 2096.7742 | E35: 0 | F35: 29.03225 | G35: 0 | H35: 56.4516 | I35: 0 | J35: 0 | K35: 0 | L35: 306.4516 | M35: 0 | N35: 137.0967 | O35: 956.6 | P35: 385.4838 | Q35: =SUM(C35+E35+G35+I35+K35+M35+O35) -> 1668.7 | R35: =SUM(D35+F35+H35+J35+L35+N35+P35) -> 3011.2901 | U35: =SUM(Q35+S35) -> 1668.7 | V35: =SUM(R35+T35) -> 3011.2901 | Y35: °C | Z35: Rest. geschlossen Corona
A36: =SUM(A35+1) -> 28 | B36: Do | C36: 670 | D36: 2096.7742 | E36: 0 | F36: 29.03225 | G36: 0 | H36: 56.4516 | I36: 0 | J36: 0 | K36: 0 | L36: 306.4516 | M36: 0 | N36: 137.0967 | O36: 250.1 | P36: 385.4838 | Q36: =SUM(C36+E36+G36+I36+K36+M36+O36) -> 920.1 | R36: =SUM(D36+F36+H36+J36+L36+N36+P36) -> 3011.2901 | U36: =SUM(Q36+S36) -> 920.1 | V36: =SUM(R36+T36) -> 3011.2901 | Y36: °C | Z36: Rest. geschlossen Corona
A37: =SUM(A36+1) -> 29 | B37: Fr | C37: 774 | D37: 2096.7742 | E37: 0 | F37: 29.03225 | G37: 0 | H37: 56.4516 | I37: 0 | J37: 0 | K37: 0 | L37: 306.4516 | M37: 0 | N37: 137.0967 | O37: 1151.9 | P37: 385.4838 | Q37: =SUM(C37+E37+G37+I37+K37+M37+O37) -> 1925.9 | R37: =SUM(D37+F37+H37+J37+L37+N37+P37) -> 3011.2901 | U37: =SUM(Q37+S37) -> 1925.9 | V37: =SUM(R37+T37) -> 3011.2901 | Y37: °C | Z37: Rest. geschlossen Corona
A38: =SUM(A37+1) -> 30 | B38: Sa | C38: 1863.1 | D38: 2096.7742 | E38: 0 | F38: 29.03225 | G38: 0 | H38: 56.4516 | I38: 0 | J38: 0 | K38: 0 | L38: 306.4516 | M38: 0 | N38: 137.0967 | O38: 2771.6 | P38: 385.4838 | Q38: =SUM(C38+E38+G38+I38+K38+M38+O38) -> 4634.7 | R38: =SUM(D38+F38+H38+J38+L38+N38+P38) -> 3011.2901 | U38: =SUM(Q38+S38) -> 4634.7 | V38: =SUM(R38+T38) -> 3011.2901 | Y38: °C | Z38: Rest. geschlossen Corona
A39: =SUM(A38+1) -> 31 | B39: So | C39: -136.6 | D39: 2096.7742 | E39: 0 | F39: 29.03225 | G39: 0 | H39: 56.4516 | I39: 0 | J39: 0 | K39: 0 | L39: 306.4516 | M39: 0 | N39: 137.0967 | O39: 0 | P39: 385.4838 | Q39: =SUM(C39+E39+G39+I39+K39+M39+O39) -> -136.6 | R39: =SUM(D39+F39+H39+J39+L39+N39+P39) -> 3011.2901 | U39: =SUM(Q39+S39) -> -136.6 | V39: =SUM(R39+T39) -> 3011.2901 | Y39: °C | Z39: Rest. geschlossen Corona
A40: KW | B40: =SUM(B32+1) -> 5 | C40: =SUM(C33:C39) -> 4723.9 | D40: =SUM(D33:D39) -> 14677.419 | E40: =SUM(E33:E39) -> 0 | F40: =SUM(F33:F39) -> 203.22575 | G40: =SUM(G33:G39) -> 0 | H40: =SUM(H33:H39) -> 395.1612 | I40: =SUM(I33:I39) -> 0 | J40: 0 | K40: =SUM(K33:K39) -> 0 | L40: =SUM(L33:L39) -> 2145.1612 | M40: =SUM(M33:M39) -> 0 | N40: =SUM(N33:N39) -> 959.6769 | O40: =SUM(O33:O39) -> 5685.2 | P40: =SUM(P33:P39) -> 2698.3866 | Q40: =SUM(Q33:Q39) -> 10409.1 | R40: =SUM(R33:R39) -> 21079.031 | ... V40: =SUM(V33:V39) -> 21079.031 | W40: Ø Temp | X40: =SUM(X33:X39)/7 -> 0 | Y40: °C
A41: Umsatz kumuliert | C41: =SUM(C8+C16+C24+C32+C40) -> 19497.9 | D41: =SUM(D8+D16+D24+D32+D40) -> 65000 | E41: =SUM(E8+E16+E24+E32+E40) -> 0 | F41: =SUM(F8+F16+F24+F32+F40) -> 899.99975 | G41: =SUM(G8+G16+G24+G32+G40) -> 0 | H41: =SUM(H8+H16+H24+H32+H40) -> 1749.9996 | I41: =SUM(I8+I16+I24+I32+I40) -> 0 | J41: =SUM(J8+J16+J24+J32+J40) -> 0 | ... Q41: =SUM(Q8+Q16+Q24+Q32+Q40) -> 54079.7 | R41: =SUM(D41+F41+H41+J41+L41+N41+P41) -> 93349.994 | S41: =SUM(S8+S16+S24+S32+S40) -> 0 | T41: =SUM(T8+T16+T24+T32+T40) -> 0 | U41: =SUM(U8+U16+U24+U32+U40) -> 54079.7 | V41: =SUM(V8+V16+V24+V32+V40) -> 93349.994 | W41: Umsatz kumuliert
...

Sheet 02_21
A1: Tagesumsätze | H1: 44228
C3: Restaurant | E3: Terrasse | G3: Lounge | I3: Pavillon | K3: Bankett | M3: Seminar | O3: Hotel | Q3: TOTAL Gesamtbetrieb ohne Seebad | S3: Seebad | U3: TOTAL Gesamtbetrieb mit Seebad | W3: Info's
C4: IST | D4: Budget | E4: IST | F4: Budget | G4: IST | H4: Budget | I4: IST | J4: Budget | K4: IST | L4: Budget | M4: IST | N4: Budget | O4: IST | P4: Budget | Q4: IST | R4: Budget | S4: IST | T4: Budget | U4: IST | V4: Budget | W4: Wetter | X4: Temp. | Z4: Bemerkung
A5: 1 | B5: Mo | C5: 93.8 | D5: 1000 | E5: 0 | F5: 142.85714 | G5: 0 | H5: 142.85714 | I5: 0 | J5: 0 | K5: 0 | L5: 571.42857 | M5: 0 | N5: 571.42857 | O5: 273.6 | P5: 757.85714 | Q5: =SUM(C5+E5+G5+I5+K5+M5+O5) -> 367.4 | R5: =SUM(D5+F5+H5+J5+L5+N5+P5) -> 3186.4286 | S5: 0 | T5: 0 | U5: =SUM(Q5+S5) -> 367.4 | V5: =SUM(R5+T5) -> 3186.4286 | Y5: °C
A6: =SUM(A5+1) -> 2 | B6: Di | C6: 205.4 | D6: 1000 | E6: 0 | F6: 142.85714 | G6: 0 | H6: 142.85714 | I6: 0 | J6: 0 | K6: 0 | L6: 571.42857 | M6: 0 | N6: 571.42857 | O6: 235.6 | P6: 757.85714 | Q6: =SUM(C6+E6+G6+I6+K6+M6+O6) -> 441 | R6: =SUM(D6+F6+H6+J6+L6+N6+P6) -> 3186.4286 | S6: 0 | T6: 0 | U6: =SUM(Q6+S6) -> 441 | V6: =SUM(R6+T6) -> 3186.4286 | Y6: °C
A7: =SUM(A6+1) -> 3 | B7: Mi | C7: 0 | D7: 1000 | E7: 0 | F7: 142.85714 | G7: 0 | H7: 142.85714 | I7: 0 | J7: 0 | K7: 0 | L7: 571.42857 | M7: 0 | N7: 571.42857 | O7: 0 | P7: 757.85714 | Q7: =SUM(C7+E7+G7+I7+K7+M7+O7) -> 0 | R7: =SUM(D7+F7+H7+J7+L7+N7+P7) -> 3186.4286 | S7: 0 | T7: 0 | U7: =SUM(Q7+S7) -> 0 | V7: =SUM(R7+T7) -> 3186.4286 | Y7: °C
A8: =SUM(A7+1) -> 4 | B8: Do | C8: 1411 | D8: 1000 | E8: 0 | F8: 142.85714 | G8: 0 | H8: 142.85714 | I8: 0 | J8: 0 | K8: 0 | L8: 571.42857 | M8: 0 | N8: 571.42857 | O8: 1298 | P8: 757.85714 | Q8: =SUM(C8+E8+G8+I8+K8+M8+O8) -> 2709 | R8: =SUM(D8+F8+H8+J8+L8+N8+P8) -> 3186.4286 | S8: 0 | T8: 0 | U8: =SUM(Q8+S8) -> 2709 | V8: =SUM(R8+T8) -> 3186.4286 | Y8: °C
A9: =SUM(A8+1) -> 5 | B9: Fr | C9: 1680.9 | D9: 1000 | E9: 0 | F9: 142.85714 | G9: 0 | H9: 142.85714 | I9: 0 | J9: 0 | K9: 0 | L9: 571.42857 | M9: 1133.7 | N9: 571.42857 | O9: 1972.6 | P9: 757.85714 | Q9: =SUM(C9+E9+G9+I9+K9+M9+O9) -> 4787.2 | R9: =SUM(D9+F9+H9+J9+L9+N9+P9) -> 3186.4286 | S9: 0 | T9: 0 | U9: =SUM(Q9+S9) -> 4787.2 | V9: =SUM(R9+T9) -> 3186.4286 | Y9: °C
A10: =SUM(A9+1) -> 6 | B10: Sa | C10: 2955.6 | D10: 1000 | E10: 0 | F10: 142.85714 | G10: 0 | H10: 142.85714 | I10: 0 | J10: 0 | K10: 378.8 | L10: 571.42857 | M10: 19 | N10: 571.42857 | O10: 3673.8 | P10: 757.85714 | Q10: =SUM(C10+E10+G10+I10+K10+M10+O10) -> 7027.2 | R10: =SUM(D10+F10+H10+J10+L10+N10+P10) -> 3186.4286 | S10: 0 | T10: 0 | U10: =SUM(Q10+S10) -> 7027.2 | V10: =SUM(R10+T10) -> 3186.4286 | Y10: °C
A11: =SUM(A10+1) -> 7 | B11: So | C11: 30 | D11: 1000 | E11: 0 | F11: 142.85714 | G11: 0 | H11: 142.85714 | I11: 0 | J11: 0 | K11: 0 | L11: 571.42857 | M11: 150 | N11: 571.42857 | O11: 48.5 | P11: 757.85714 | Q11: =SUM(C11+E11+G11+I11+K11+M11+O11) -> 228.5 | R11: =SUM(D11+F11+H11+J11+L11+N11+P11) -> 3186.4286 | S11: 0 | T11: 0 | U11: =SUM(Q11+S11) -> 228.5 | V11: =SUM(R11+T11) -> 3186.4286 | Y11: °C
A12: KW | B12: 6 | C12: =SUM(C5:C11) -> 6376.7 | D12: =SUM(D5:D11) -> 7000 | E12: =SUM(E5:E11) -> 0 | F12: =SUM(F5:F11) -> 999.99998 | G12: =SUM(G5:G11) -> 0 | H12: =SUM(H5:H11) -> 999.99998 | I12: =SUM(I5:I11) -> 0 | J12: =SUM(J5:J11) -> 0 | ... V12: =SUM(V5:V11) -> 22305 | W12: Ø Temp | X12: =SUM(X5:X11)/7 -> 0 | Y12: °C | Z12: Hotel geschlossen
A13: =SUM(A11+1) -> 8 | B13: Mo | Q13: =SUM(C13+E13+G13+I13+K13+M13+O13) -> 0 | R13: =SUM(D13+F13+H13+J13+L13+N13+P13) -> 0 | U13: =SUM(Q13+S13) -> 0 | V13: =SUM(R13+T13) -> 0 | Y13: °C | Z13: Hotel geschlossen
A14: =SUM(A13+1) -> 9 | B14: Di | Q14: =SUM(C14+E14+G14+I14+K14+M14+O14) -> 0 | R14: =SUM(D14+F14+H14+J14+L14+N14+P14) -> 0 | U14: =SUM(Q14+S14) -> 0 | V14: =SUM(R14+T14) -> 0 | Y14: °C | Z14: Hotel geschlossen
A15: =SUM(A14+1) -> 10 | B15: Mi | Q15: =SUM(C15+E15+G15+I15+K15+M15+O15) -> 0 | R15: =SUM(D15+F15+H15+J15+L15+N15+P15) -> 0 | U15: =SUM(Q15+S15) -> 0 | V15: =SUM(R15+T15) -> 0 | Y15: °C | Z15: Hotel geschlossen
A16: =SUM(A15+1) -> 11 | B16: Do | Q16: =SUM(C16+E16+G16+I16+K16+M16+O16) -> 0 | R16: =SUM(D16+F16+H16+J16+L16+N16+P16) -> 0 | U16: =SUM(Q16+S16) -> 0 | V16: =SUM(R16+T16) -> 0 | Y16: °C | Z16: Hotel geschlossen
A17: =SUM(A16+1) -> 12 | B17: Fr | Q17: =SUM(C17+E17+G17+I17+K17+M17+O17) -> 0 | R17: =SUM(D17+F17+H17+J17+L17+N17+P17) -> 0 | U17: =SUM(Q17+S17) -> 0 | V17: =SUM(R17+T17) -> 0 | Y17: °C | Z17: Hotel geschlossen
A18: =SUM(A17+1) -> 13 | B18: Sa | Q18: =SUM(C18+E18+G18+I18+K18+M18+O18) -> 0 | R18: =SUM(D18+F18+H18+J18+L18+N18+P18) -> 0 | U18: =SUM(Q18+S18) -> 0 | V18: =SUM(R18+T18) -> 0 | Y18: °C | Z18: Hotel geschlossen
A19: =SUM(A18+1) -> 14 | B19: So | Q19: =SUM(C19+E19+G19+I19+K19+M19+O19) -> 0 | R19: =SUM(D19+F19+H19+J19+L19+N19+P19) -> 0 | U19: =SUM(Q19+S19) -> 0 | V19: =SUM(R19+T19) -> 0 | Y19: °C | Z19: Hotel geschlossen
A20: KW | B20: =SUM(B12+1) -> 7 | C20: =SUM(C13:C19) -> 0 | D20: =SUM(D13:D19) -> 0 | E20: =SUM(E13:E19) -> 0 | F20: =SUM(F13:F19) -> 0 | G20: =SUM(G13:G19) -> 0 | H20: =SUM(H13:H19) -> 0 | I20: =SUM(I13:I19) -> 0 | J20: =SUM(J13:J19) -> 0 | ... V20: =SUM(V13:V19) -> 0 | W20: Ø Temp | X20: =SUM(X13:X19)/7 -> 0 | Y20: °C | Z20: Hotel geschlossen
A21: =SUM(A19+1) -> 15 | B21: Mo | Q21: =SUM(C21+E21+G21+I21+K21+M21+O21) -> 0 | R21: =SUM(D21+F21+H21+J21+L21+N21+P21) -> 0 | U21: =SUM(Q21+S21) -> 0 | V21: =SUM(R21+T21) -> 0 | Y21: °C | Z21: Hotel geschlossen
A22: =SUM(A21+1) -> 16 | B22: Di | Q22: =SUM(C22+E22+G22+I22+K22+M22+O22) -> 0 | R22: =SUM(D22+F22+H22+J22+L22+N22+P22) -> 0 | U22: =SUM(Q22+S22) -> 0 | V22: =SUM(R22+T22) -> 0 | Y22: °C | Z22: Hotel geschlossen
A23: =SUM(A22+1) -> 17 | B23: Mi | Q23: =SUM(C23+E23+G23+I23+K23+M23+O23) -> 0 | R23: =SUM(D23+F23+H23+J23+L23+N23+P23) -> 0 | U23: =SUM(Q23+S23) -> 0 | V23: =SUM(R23+T23) -> 0 | Y23: °C | Z23: Hotel geschlossen
A24: =SUM(A23+1) -> 18 | B24: Do | Q24: =SUM(C24+E24+G24+I24+K24+M24+O24) -> 0 | R24: =SUM(D24+F24+H24+J24+L24+N24+P24) -> 0 | U24: =SUM(Q24+S24) -> 0 | V24: =SUM(R24+T24) -> 0 | Y24: °C | Z24: Hotel geschlossen
A25: =SUM(A24+1) -> 19 | B25: Fr | Q25: =SUM(C25+E25+G25+I25+K25+M25+O25) -> 0 | R25: =SUM(D25+F25+H25+J25+L25+N25+P25) -> 0 | U25: =SUM(Q25+S25) -> 0 | V25: =SUM(R25+T25) -> 0 | Y25: °C | Z25: Hotel geschlossen
A26: =SUM(A25+1) -> 20 | B26: Sa | Q26: =SUM(C26+E26+G26+I26+K26+M26+O26) -> 0 | R26: =SUM(D26+F26+H26+J26+L26+N26+P26) -> 0 | U26: =SUM(Q26+S26) -> 0 | V26: =SUM(R26+T26) -> 0 | Y26: °C | Z26: Hotel geschlossen
A27: =SUM(A26+1) -> 21 | B27: So | Q27: =SUM(C27+E27+G27+I27+K27+M27+O27) -> 0 | R27: =SUM(D27+F27+H27+J27+L27+N27+P27) -> 0 | U27: =SUM(Q27+S27) -> 0 | V27: =SUM(R27+T27) -> 0 | Y27: °C | Z27: Hotel geschlossen
A28: KW | B28: =SUM(B20+1) -> 8 | C28: =SUM(C21:C27) -> 0 | D28: =SUM(D21:D27) -> 0 | E28: =SUM(E21:E27) -> 0 | F28: =SUM(F21:F27) -> 0 | G28: =SUM(G21:G27) -> 0 | H28: =SUM(H21:H27) -> 0 | I28: =SUM(I21:I27) -> 0 | J28: =SUM(J21:J27) -> 0 | ... V28: =SUM(V21:V27) -> 0 | W28: Ø Temp | X28: =SUM(X21:X27)/7 -> 0 | Y28: °C | Z28: Hotel geschlossen
A29: =SUM(A27+1) -> 22 | B29: Mo | Q29: =SUM(C29+E29+G29+I29+K29+M29+O29) -> 0 | R29: =SUM(D29+F29+H29+J29+L29+N29+P29) -> 0 | U29: =SUM(Q29+S29) -> 0 | V29: =SUM(R29+T29) -> 0 | Y29: °C | Z29: Hotel geschlossen
A30: =SUM(A29+1) -> 23 | B30: Di | Q30: =SUM(C30+E30+G30+I30+K30+M30+O30) -> 0 | R30: =SUM(D30+F30+H30+J30+L30+N30+P30) -> 0 | U30: =SUM(Q30+S30) -> 0 | V30: =SUM(R30+T30) -> 0 | Y30: °C | Z30: Hotel geschlossen
A31: =SUM(A30+1) -> 24 | B31: Mi | Q31: =SUM(C31+E31+G31+I31+K31+M31+O31) -> 0 | R31: =SUM(D31+F31+H31+J31+L31+N31+P31) -> 0 | U31: =SUM(Q31+S31) -> 0 | V31: =SUM(R31+T31) -> 0 | Y31: °C | Z31: Hotel geschlossen
A32: =SUM(A31+1) -> 25 | B32: Do | Q32: =SUM(C32+E32+G32+I32+K32+M32+O32) -> 0 | R32: =SUM(D32+F32+H32+J32+L32+N32+P32) -> 0 | U32: =SUM(Q32+S32) -> 0 | V32: =SUM(R32+T32) -> 0 | Y32: °C | Z32: Hotel geschlossen
A33: =SUM(A32+1) -> 26 | B33: Fr | Q33: =SUM(C33+E33+G33+I33+K33+M33+O33) -> 0 | R33: =SUM(D33+F33+H33+J33+L33+N33+P33) -> 0 | U33: =SUM(Q33+S33) -> 0 | V33: =SUM(R33+T33) -> 0 | Y33: °C | Z33: Hotel geschlossen
A34: =SUM(A33+1) -> 27 | B34: Sa | Q34: =SUM(C34+E34+G34+I34+K34+M34+O34) -> 0 | R34: =SUM(D34+F34+H34+J34+L34+N34+P34) -> 0 | U34: =SUM(Q34+S34) -> 0 | V34: =SUM(R34+T34) -> 0 | Y34: °C | Z34: Hotel geschlossen
A35: =SUM(A34+1) -> 28 | B35: So | O35: -175.68 | Q35: =SUM(C35+E35+G35+I35+K35+M35+O35) -> -175.68 | R35: =SUM(D35+F35+H35+J35+L35+N35+P35) -> 0 | U35: =SUM(Q35+S35) -> -175.68 | V35: =SUM(R35+T35) -> 0 | Y35: °C | Z35: Hotel geschlossen
A36: KW | B36: =SUM(B28+1) -> 9 | C36: =SUM(C33:C35) -> 0 | D36: =SUM(D33:D35) -> 0 | E36: =SUM(E33:E35) -> 0 | F36: =SUM(F33:F35) -> 0 | G36: =SUM(G33:G35) -> 0 | H36: =SUM(H33:H35) -> 0 | I36: =SUM(I33:I35) -> 0 | J36: =SUM(J33:J35) -> 0 | ... V36: =SUM(V33:V35) -> 0 | W36: Ø Temp | X36: =SUM(X29:X35)/7 -> 0 | Y36: °C | Z36: Hotel geschlossen
A37: Umsatz kumuliert | C37: =SUM(C12+C20+C28+C36) -> 6376.7 | D37: =SUM(D12+D20+D28+D36) -> 7000 | E37: =SUM(E12+E20+E28+E36) -> 0 | F37: =SUM(F12+F20+F28+F36) -> 999.99998 | G37: =SUM(G12+G20+G28+G36) -> 0 | H37: =SUM(H12+H20+H28+H36) -> 999.99998 | I37: =SUM(I12+I20+I28+I36) -> 0 | J37: =SUM(J12+J20+J28+J36) -> 0 | ... V37: =SUM(V12+V20+V28+V36) -> 22305 | W37: Umsatz kumuliert
A38: Umsatz Forecast | C38: =IF(MONTH($H$1)<>MONTH(TODAY()),C37,SUM(C5:C11,C13:C19,C21:C27,C29:C35)/DAY(TODAY())*DAY(DATE(YEAR($H$1),MONTH($H$1)+1,1)-1)) -> 6376.7 | D38: =IF(MONTH($H$1)<>MONTH(TODAY()),D37,SUM(D5:D11,D13:D19,D21:D27,D29:D35)/DAY(TODAY())*DAY(DATE(YEAR($H$1),MONTH($H$1)+1,1)-1)) -> 7000 | E38: =IF(MONTH($H$1)<>MONTH(TODAY()),E37,SUM(E5:E11,E13:E19,E21:E27,E29:E35)/DAY(TODAY())*DAY(DATE(YEAR($H$1),MONTH($H$1)+1,1)-1)) -> 0 | F38: =IF(MONTH($H$1)<>MONTH(TODAY()),F37,SUM(F5:F11,F13:F19,F21:F27,F29:F35)/DAY(TODAY())*DAY(DATE(YEAR($H$1),MONTH($H$1)+1,1)-1)) -> 999.99998 | G38: =IF(MONTH($H$1)<>MONTH(TODAY()),G37,SUM(G5:G11,G13:G19,G21:G27,G29:G35)/DAY(TODAY())*DAY(DATE(YEAR($H$1),MONTH($H$1)+1,1)-1)) -> 0 | H38: =IF(MONTH($H$1)<>MONTH(TODAY()),H37,SUM(H5:H11,H13:H19,H21:H27,H29:H35)/DAY(TODAY())*DAY(DATE(YEAR($H$1),MONTH($H$1)+1,1)-1)) -> 999.99998 | I38: =IF(MONTH($H$1)<>MONTH(TODAY()),I37,SUM(I5:I11,I13:I19,I21:I27,I29:I35)/DAY(TODAY())*DAY(DATE(YEAR($H$1),MONTH($H$1)+1,1)-1)) -> 0 | J38: =IF(MONTH($H$1)<>MONTH(TODAY()),J37,SUM(J5:J11,J13:J19,J21:J27,J29:J35)/DAY(TODAY())*DAY(DATE(YEAR($H$1),MONTH($H$1)+1,1)-1)) -> 0 | ... V38: =IF(MONTH($H$1)<>MONTH(TODAY()),V37,SUM(V5:V11,V13:V19,V21:V27,V29:V35)/DAY(TODAY())*DAY(DATE(YEAR($H$1),MONTH($H$1)+1,1)-1)) -> 22305 | W38: Umsatz Forecast
A39: Umsatz pro Tag | C39: =C37/28 -> 227.73929 | D39: =D37/28 -> 250 | E39: =E37/28 -> 0 | F39: =F37/28 -> 35.714285 | G39: =G37/28 -> 0 | H39: =H37/28 -> 35.714285 | I39: =I37/28 -> 0 | J39: =J37/28 -> 0 | ... V39: =V37/28 -> 796.60714 | W39: Budget pro Tag
A40: Diff. zu Budget | C40: =SUM(C37-D37) -> -623.3 | E40: =SUM(E37-F37) -> -999.99998 | G40: =SUM(G37-H37) -> -999.99998 | I40: =SUM(I37-J37) -> 0 | K40: =SUM(K37-L37) -> -3621.2 | M40: =SUM(M37-N37) -> -2697.3 | O40: =SUM(O37-P37) -> 2021.42 | Q40: =SUM(Q37-R37) -> -6920.3799 | S40: =SUM(S37-T37) -> 0 | U40: =SUM(U37-V37) -> -6920.3799
A41: Index | C41: =SUM(100/D37*C37) -> 91.095714 | E41: =SUM(100/F37*E37) -> 0 | G41: =SUM(100/H37*G37) -> 0 | I41: =SUM(100/J37*I37) -> #DIV/0! | K41: =SUM(100/L37*K37) -> 9.47 | M41: =SUM(100/N37*M37) -> 32.5675 | O41: =SUM(100/P37*O37) -> 138.10405 | Q41: =SUM(100/R37*Q37) -> 68.973863 | S41: =SUM(100/T37*S37) -> #DIV/0! | U41: =SUM(100/V37*U37) -> 68.973863

Sheet 03_21
A1: Tagesumsätze | H1: 44256
C3: Restaurant | E3: Terrasse | G3: Lounge | I3: Pavillon | K3: Bankett | M3: Seminar | O3: Hotel | Q3: TOTAL Gesamtbetrieb ohne Seebad | S3: Seebad | U3: TOTAL Gesamtbetrieb mit Seebad | W3: Info's
C4: IST | D4: Budget | E4: IST | F4: Budget | G4: IST | H4: Budget | I4: IST | J4: Budget | K4: IST | L4: Budget | M4: IST | N4: Budget | O4: IST | P4: Budget | Q4: IST | R4: Budget | S4: IST | T4: Budget | U4: IST | V4: Budget | W4: Wetter | X4: Temp. | Z4: Bemerkung
A5: 1 | B5: Mo | D5: 4516.129 | F5: 1129.0322 | H5: 483.87096 | L5: 967.74194 | N5: 645.16129 | P5: 947.74194 | Q5: =SUM(C5+E5+G5+I5+K5+M5+O5) -> 0 | R5: =SUM(D5+F5+H5+J5+L5+N5+P5) -> 8689.6774 | U5: =SUM(Q5+S5) -> 0 | V5: =SUM(R5+T5) -> 8689.6774 | Y5: °C | Z5: Hotel geschlossen
A6: =SUM(A5+1) -> 2 | B6: Di | D6: 4516.129 | F6: 1129.0322 | H6: 483.87096 | L6: 967.74194 | N6: 645.16129 | P6: 947.74194 | Q6: =SUM(C6+E6+G6+I6+K6+M6+O6) -> 0 | R6: =SUM(D6+F6+H6+J6+L6+N6+P6) -> 8689.6774 | U6: =SUM(Q6+S6) -> 0 | V6: =SUM(R6+T6) -> 8689.6774 | Y6: °C | Z6: Hotel geschlossen
A7: =SUM(A6+1) -> 3 | B7: Mi | D7: 4516.129 | F7: 1129.0322 | H7: 483.87096 | L7: 967.74194 | N7: 645.16129 | P7: 947.74194 | Q7: =SUM(C7+E7+G7+I7+K7+M7+O7) -> 0 | R7: =SUM(D7+F7+H7+J7+L7+N7+P7) -> 8689.6774 | U7: =SUM(Q7+S7) -> 0 | V7: =SUM(R7+T7) -> 8689.6774 | Y7: °C | Z7: Hotel geschlossen
A8: =SUM(A7+1) -> 4 | B8: Do | D8: 4516.129 | F8: 1129.0322 | H8: 483.87096 | L8: 967.74194 | N8: 645.16129 | P8: 947.74194 | Q8: =SUM(C8+E8+G8+I8+K8+M8+O8) -> 0 | R8: =SUM(D8+F8+H8+J8+L8+N8+P8) -> 8689.6774 | U8: =SUM(Q8+S8) -> 0 | V8: =SUM(R8+T8) -> 8689.6774 | Y8: °C | Z8: Hotel geschlossen
A9: =SUM(A8+1) -> 5 | B9: Fr | C9: 1655.5 | D9: 4516.129 | F9: 1129.0322 | H9: 483.87096 | L9: 967.74194 | N9: 645.16129 | O9: 2262.8 | P9: 947.74194 | Q9: =SUM(C9+E9+G9+I9+K9+M9+O9) -> 3918.3 | R9: =SUM(D9+F9+H9+J9+L9+N9+P9) -> 8689.6774 | U9: =SUM(Q9+S9) -> 3918.3 | V9: =SUM(R9+T9) -> 8689.6774 | W9: bewölkt | X9: 5 | Y9: °C
A10: =SUM(A9+1) -> 6 | B10: Sa | C10: 3281.2 | D10: 4516.129 | F10: 1129.0322 | H10: 483.87096 | K10: 864.7 | L10: 967.74194 | N10: 645.16129 | O10: 3815.8 | P10: 947.74194 | Q10: =SUM(C10+E10+G10+I10+K10+M10+O10) -> 7961.7 | R10: =SUM(D10+F10+H10+J10+L10+N10+P10) -> 8689.6774 | U10: =SUM(Q10+S10) -> 7961.7 | V10: =SUM(R10+T10) -> 8689.6774 | W10: bewölkt | X10: 8 | Y10: °C
A11: =SUM(A10+1) -> 7 | B11: So | C11: -118 | D11: 4516.129 | F11: 1129.0322 | H11: 483.87096 | L11: 967.74194 | N11: 645.16129 | O11: 487.9 | P11: 947.74194 | Q11: =SUM(C11+E11+G11+I11+K11+M11+O11) -> 369.9 | R11: =SUM(D11+F11+H11+J11+L11+N11+P11) -> 8689.6774 | U11: =SUM(Q11+S11) -> 369.9 | V11: =SUM(R11+T11) -> 8689.6774 | W11: ziemlich sonnig | X11: 10 | Y11: °C
A12: KW | B12: 10 | C12: =SUM(C5:C11) -> 4818.7 | D12: =SUM(D5:D11) -> 31612.903 | E12: =SUM(E5:E11) -> 0 | F12: =SUM(F5:F11) -> 7903.2258 | G12: =SUM(G5:G11) -> 0 | H12: =SUM(H5:H11) -> 3387.0967 | I12: =SUM(I5:I11) -> 0 | J12: =SUM(J5:J11) -> 0 | ... V12: =SUM(V5:V11) -> 60827.742 | W12: Ø Temp | X12: =SUM(X5:X11)/7 -> 3.2857143 | Y12: °C
A13: =SUM(A11+1) -> 8 | B13: Mo | C13: 416.7 | D13: 4516.129 | F13: 1129.0322 | H13: 483.87096 | L13: 967.74194 | N13: 645.16129 | O13: 683 | P13: 947.74194 | Q13: =SUM(C13+E13+G13+I13+K13+M13+O13) -> 1099.7 | R13: =SUM(D13+F13+H13+J13+L13+N13+P13) -> 8689.6774 | U13: =SUM(Q13+S13) -> 1099.7 | V13: =SUM(R13+T13) -> 8689.6774 | W13: ziemlich sonnig | X13: 5 | Y13: °C
A14: =SUM(A13+1) -> 9 | B14: Di | C14: 1371 | D14: 4516.129 | F14: 1129.0322 | H14: 483.87096 | L14: 967.74194 | N14: 645.16129 | O14: 2208.8 | P14: 947.74194 | Q14: =SUM(C14+E14+G14+I14+K14+M14+O14) -> 3579.8 | R14: =SUM(D14+F14+H14+J14+L14+N14+P14) -> 8689.6774 | U14: =SUM(Q14+S14) -> 3579.8 | V14: =SUM(R14+T14) -> 8689.6774 | W14: bewölkt | X14: 6 | Y14: °C
A15: =SUM(A14+1) -> 10 | B15: Mi | C15: 1484 | D15: 4516.129 | F15: 1129.0322 | H15: 483.87096 | L15: 967.74194 | N15: 645.16129 | O15: 2123.2 | P15: 947.74194 | Q15: =SUM(C15+E15+G15+I15+K15+M15+O15) -> 3607.2 | R15: =SUM(D15+F15+H15+J15+L15+N15+P15) -> 8689.6774 | U15: =SUM(Q15+S15) -> 3607.2 | V15: =SUM(R15+T15) -> 8689.6774 | W15: sonnig | X15: 8 | Y15: °C
A16: =SUM(A15+1) -> 11 | B16: Do | C16: 502.1 | D16: 4516.129 | F16: 1129.0322 | H16: 483.87096 | L16: 967.74194 | N16: 645.16129 | O16: 985.4 | P16: 947.74194 | Q16: =SUM(C16+E16+G16+I16+K16+M16+O16) -> 1487.5 | R16: =SUM(D16+F16+H16+J16+L16+N16+P16) -> 8689.6774 | U16: =SUM(Q16+S16) -> 1487.5 | V16: =SUM(R16+T16) -> 8689.6774 | W16: bewölkt | X16: 5 | Y16: °C
A17: =SUM(A16+1) -> 12 | B17: Fr | C17: 2236.4 | D17: 4516.129 | F17: 1129.0322 | H17: 483.87096 | K17: 1529.5 | L17: 967.74194 | N17: 645.16129 | O17: 3286.4 | P17: 947.74194 | Q17: =SUM(C17+E17+G17+I17+K17+M17+O17) -> 7052.3 | R17: =SUM(D17+F17+H17+J17+L17+N17+P17) -> 8689.6774 | U17: =SUM(Q17+S17) -> 7052.3 | V17: =SUM(R17+T17) -> 8689.6774 | W17: sonnig | X17: 6 | Y17: °C
A18: =SUM(A17+1) -> 13 | B18: Sa | C18: 3418 | D18: 4516.129 | F18: 1129.0322 | H18: 483.87096 | K18: 303 | L18: 967.74194 | N18: 645.16129 | O18: 4408.9 | P18: 947.74194 | Q18: =SUM(C18+E18+G18+I18+K18+M18+O18) -> 8129.9 | R18: =SUM(D18+F18+H18+J18+L18+N18+P18) -> 8689.6774 | U18: =SUM(Q18+S18) -> 8129.9 | V18: =SUM(R18+T18) -> 8689.6774 | W18: sonnig | X18: 12 | Y18: °C
A19: =SUM(A18+1) -> 14 | B19: So | C19: 645.8 | D19: 4516.129 | F19: 1129.0322 | H19: 483.87096 | L19: 967.74194 | N19: 645.16129 | O19: 1190.4 | P19: 947.74194 | Q19: =SUM(C19+E19+G19+I19+K19+M19+O19) -> 1836.2 | R19: =SUM(D19+F19+H19+J19+L19+N19+P19) -> 8689.6774 | U19: =SUM(Q19+S19) -> 1836.2 | V19: =SUM(R19+T19) -> 8689.6774 | W19: Schneeschauer | X19: 5 | Y19: °C
A20: KW | B20: =SUM(B12+1) -> 11 | C20: =SUM(C13:C19) -> 10074 | D20: =SUM(D13:D19) -> 31612.903 | E20: =SUM(E13:E19) -> 0 | F20: =SUM(F13:F19) -> 7903.2258 | G20: =SUM(G13:G19) -> 0 | H20: =SUM(H13:H19) -> 3387.0967 | I20: =SUM(I13:I19) -> 0 | J20: =SUM(J13:J19) -> 0 | ... V20: =SUM(V13:V19) -> 60827.742 | W20: Ø Temp | X20: =SUM(X13:X19)/7 -> 6.7142857 | Y20: °C
A21: =SUM(A19+1) -> 15 | B21: Mo | C21: 707.4 | D21: 4516.129 | F21: 1129.0322 | H21: 483.87096 | K21: 48 | L21: 967.74194 | M21: 1995.8 | N21: 645.16129 | O21: 1791.8 | P21: 947.74194 | Q21: =SUM(C21+E21+G21+I21+K21+M21+O21) -> 4543 | R21: =SUM(D21+F21+H21+J21+L21+N21+P21) -> 8689.6774 | U21: =SUM(Q21+S21) -> 4543 | V21: =SUM(R21+T21) -> 8689.6774 | W21: Schneeschauer | X21: 5 | Y21: °C
A22: =SUM(A21+1) -> 16 | B22: Di | C22: 786.5 | D22: 4516.129 | E22: 0 | F22: 1129.0322 | G22: 0 | H22: 483.87096 | I22: 0 | K22: 0 | L22: 967.74194 | M22: 3140.6 | N22: 645.16129 | O22: 3612 | P22: 947.74194 | Q22: =SUM(C22+E22+G22+I22+K22+M22+O22) -> 7539.1 | R22: =SUM(D22+F22+H22+J22+L22+N22+P22) -> 8689.6774 | U22: =SUM(Q22+S22) -> 7539.1 | V22: =SUM(R22+T22) -> 8689.6774 | W22: Schneeschauer | X22: 5 | Y22: °C
A23: =SUM(A22+1) -> 17 | B23: Mi | C23: 644.2 | D23: 4516.129 | E23: 0 | F23: 1129.0322 | G23: 0 | H23: 483.87096 | I23: 0 | K23: 0 | L23: 967.74194 | M23: 1519.2 | N23: 645.16129 | O23: 1683.3 | P23: 947.74194 | Q23: =SUM(C23+E23+G23+I23+K23+M23+O23) -> 3846.7 | R23: =SUM(D23+F23+H23+J23+L23+N23+P23) -> 8689.6774 | U23: =SUM(Q23+S23) -> 3846.7 | V23: =SUM(R23+T23) -> 8689.6774 | W23: Schneeschauer | X23: 3 | Y23: °C
A24: =SUM(A23+1) -> 18 | B24: Do | C24: 117.1 | D24: 4516.129 | E24: 0 | F24: 1129.0322 | G24: 0 | H24: 483.87096 | I24: 0 | K24: 0 | L24: 967.74194 | M24: 0 | N24: 645.16129 | O24: 529.2 | P24: 947.74194 | Q24: =SUM(C24+E24+G24+I24+K24+M24+O24) -> 646.3 | R24: =SUM(D24+F24+H24+J24+L24+N24+P24) -> 8689.6774 | U24: =SUM(Q24+S24) -> 646.3 | V24: =SUM(R24+T24) -> 8689.6774 | W24: Schneeschauer | X24: 3 | Y24: °C
A25: =SUM(A24+1) -> 19 | B25: Fr | C25: 2053.7 | D25: 4516.129 | E25: 0 | F25: 1129.0322 | G25: 0 | H25: 483.87096 | I25: 0 | K25: 0 | L25: 967.74194 | M25: 0 | N25: 645.16129 | O25: 2768.2 | P25: 947.74194 | Q25: =SUM(C25+E25+G25+I25+K25+M25+O25) -> 4821.9 | R25: =SUM(D25+F25+H25+J25+L25+N25+P25) -> 8689.6774 | U25: =SUM(Q25+S25) -> 4821.9 | V25: =SUM(R25+T25) -> 8689.6774 | W25: sonnig | X25: 3 | Y25: °C
A26: =SUM(A25+1) -> 20 | B26: Sa | C26: 3643.7 | D26: 4516.129 | E26: 0 | F26: 1129.0322 | G26: 31.8 | H26: 483.87096 | I26: 0 | K26: 606.7 | L26: 967.74194 | M26: 0 | N26: 645.16129 | O26: 5595.8 | P26: 947.74194 | Q26: =SUM(C26+E26+G26+I26+K26+M26+O26) -> 9878 | R26: =SUM(D26+F26+H26+J26+L26+N26+P26) -> 8689.6774 | U26: =SUM(Q26+S26) -> 9878 | V26: =SUM(R26+T26) -> 8689.6774 | W26: sonnig | X26: 3 | Y26: °C
A27: =SUM(A26+1) -> 21 | B27: So | C27: 288.8 | D27: 4516.129 | E27: 0 | F27: 1129.0322 | G27: 0 | H27: 483.87096 | I27: 0 | K27: 0 | L27: 967.74194 | M27: 0 | N27: 645.16129 | O27: 1043.3 | P27: 947.74194 | Q27: =SUM(C27+E27+G27+I27+K27+M27+O27) -> 1332.1 | R27: =SUM(D27+F27+H27+J27+L27+N27+P27) -> 8689.6774 | U27: =SUM(Q27+S27) -> 1332.1 | V27: =SUM(R27+T27) -> 8689.6774 | W27: bewölkt | X27: 5 | Y27: °C
A28: KW | B28: =SUM(B20+1) -> 12 | C28: =SUM(C21:C27) -> 8241.4 | D28: =SUM(D21:D27) -> 31612.903 | E28: =SUM(E21:E27) -> 0 | F28: =SUM(F21:F27) -> 7903.2258 | G28: =SUM(G21:G27) -> 31.8 | H28: =SUM(H21:H27) -> 3387.0967 | I28: =SUM(I21:I27) -> 0 | J28: =SUM(J21:J27) -> 0 | ... V28: =SUM(V21:V27) -> 60827.742 | W28: Ø Temp | X28: =SUM(X21:X27)/7 -> 3.8571429 | Y28: °C
A29: =SUM(A27+1) -> 22 | B29: Mo | C29: 1266.7 | D29: 4516.129 | E29: 0 | F29: 1129.0322 | G29: 0 | H29: 483.87096 | I29: 0 | K29: 0 | L29: 967.74194 | M29: 2916.4 | N29: 645.16129 | O29: 1837.45 | P29: 947.74194 | Q29: =SUM(C29+E29+G29+I29+K29+M29+O29) -> 6020.55 | R29: =SUM(D29+F29+H29+J29+L29+N29+P29) -> 8689.6774 | U29: =SUM(Q29+S29) -> 6020.55 | V29: =SUM(R29+T29) -> 8689.6774 | W29: bewölkt | X29: 5 | Y29: °C
A30: =SUM(A29+1) -> 23 | B30: Di | C30: 1362.3 | D30: 4516.129 | E30: 22.7 | F30: 1129.0322 | G30: 0 | H30: 483.87096 | I30: 0 | K30: 0 | L30: 967.74194 | M30: 991.8 | N30: 645.16129 | O30: 2304.8 | P30: 947.74194 | Q30: =SUM(C30+E30+G30+I30+K30+M30+O30) -> 4681.6 | R30: =SUM(D30+F30+H30+J30+L30+N30+P30) -> 8689.6774 | U30: =SUM(Q30+S30) -> 4681.6 | V30: =SUM(R30+T30) -> 8689.6774 | W30: sonnig | X30: 10 | Y30: °C
A31: =SUM(A30+1) -> 24 | B31: Mi | C31: 508.5 | D31: 4516.129 | E31: 0 | F31: 1129.0322 | G31: 0 | H31: 483.87096 | I31: 0 | K31: 0 | L31: 967.74194 | M31: 13.5 | N31: 645.16129 | O31: 1268.4 | P31: 947.74194 | Q31: =SUM(C31+E31+G31+I31+K31+M31+O31) -> 1790.4 | R31: =SUM(D31+F31+H31+J31+L31+N31+P31) -> 8689.6774 | U31: =SUM(Q31+S31) -> 1790.4 | V31: =SUM(R31+T31) -> 8689.6774 | W31: sonnig | X31: 16 | Y31: °C
A32: =SUM(A31+1) -> 25 | B32: Do | C32: 1632.2 | D32: 4516.129 | E32: 0 | F32: 1129.0322 | G32: 0 | H32: 483.87096 | I32: 0 | K32: 23 | L32: 967.74194 | M32: 0 | N32: 645.16129 | O32: 2897.2 | P32: 947.74194 | Q32: =SUM(C32+E32+G32+I32+K32+M32+O32) -> 4552.4 | R32: =SUM(D32+F32+H32+J32+L32+N32+P32) -> 8689.6774 | U32: =SUM(Q32+S32) -> 4552.4 | V32: =SUM(R32+T32) -> 8689.6774 | W32: sonnig | X32: 16 | Y32: °C
A33: =SUM(A32+1) -> 26 | B33: Fr | C33: 2343.8 | D33: 4516.129 | E33: 15.2 | F33: 1129.0322 | G33: 21.6 | H33: 483.87096 | I33: 0 | K33: 2987.1 | L33: 967.74194 | M33: 42 | N33: 645.16129 | O33: 5112.2 | P33: 947.74194 | Q33: =SUM(C33+E33+G33+I33+K33+M33+O33) -> 10521.9 | R33: =SUM(D33+F33+H33+J33+L33+N33+P33) -> 8689.6774 | U33: =SUM(Q33+S33) -> 10521.9 | V33: =SUM(R33+T33) -> 8689.6774 | W33: sonnig | X33: 16 | Y33: °C
A34: =SUM(A33+1) -> 27 | B34: Sa | C34: 4511.2 | D34: 4516.129 | E34: 61.5 | F34: 1129.0322 | G34: 17 | H34: 483.87096 | I34: 0 | K34: 540.3 | L34: 967.74194 | M34: 0 | N34: 645.16129 | O34: 5519.2 | P34: 947.74194 | Q34: =SUM(C34+E34+G34+I34+K34+M34+O34) -> 10649.2 | R34: =SUM(D34+F34+H34+J34+L34+N34+P34) -> 8689.6774 | U34: =SUM(Q34+S34) -> 10649.2 | V34: =SUM(R34+T34) -> 8689.6774 | W34: wechselnd bewölkt | X34: 10 | Y34: °C
A35: =SUM(A34+1) -> 28 | B35: So | C35: 1932.6 | D35: 4516.129 | E35: 0 | F35: 1129.0322 | G35: 198.9 | H35: 483.87096 | I35: 0 | K35: 0 | L35: 967.74194 | M35: 0 | N35: 645.16129 | O35: 2595.8 | P35: 947.74194 | Q35: =SUM(C35+E35+G35+I35+K35+M35+O35) -> 4727.3 | R35: =SUM(D35+F35+H35+J35+L35+N35+P35) -> 8689.6774 | U35: =SUM(Q35+S35) -> 4727.3 | V35: =SUM(R35+T35) -> 8689.6774 | W35: sonnig | X35: 15 | Y35: °C
A36: KW | B36: =SUM(B28+1) -> 13 | C36: =SUM(C29:C35) -> 13557.3 | D36: =SUM(D29:D35) -> 31612.903 | E36: =SUM(E29:E35) -> 99.4 | F36: =SUM(F29:F35) -> 7903.2258 | G36: =SUM(G29:G35) -> 237.5 | H36: =SUM(H29:H35) -> 3387.0967 | I36: =SUM(I29:I35) -> 0 | J36: =SUM(J29:J35) -> 0 | ... V36: =SUM(V29:V35) -> 60827.742 | W36: Ø Temp | X36: =SUM(X29:X35)/7 -> 12.571429 | Y36: °C
A37: =SUM(A35+1) -> 29 | B37: Mo | C37: 1841.6 | D37: 4516.129 | E37: 27.1 | F37: 1129.0322 | G37: 27.9 | H37: 483.87096 | I37: 0 | K37: 0 | L37: 967.74194 | M37: 0 | N37: 645.16129 | O37: 3271.7 | P37: 947.74194 | Q37: =SUM(C37+E37+G37+I37+K37+M37+O37) -> 5168.3 | R37: =SUM(D37+F37+H37+J37+L37+N37+P37) -> 8689.6774 | U37: =SUM(Q37+S37) -> 5168.3 | V37: =SUM(R37+T37) -> 8689.6774 | W37: sonnig | X37: 16 | Y37: °C
A38: =SUM(A37+1) -> 30 | B38: Di | C38: 1556 | D38: 4516.129 | E38: 26.8 | F38: 1129.0322 | G38: 27.2 | H38: 483.87096 | I38: 0 | K38: 0 | L38: 967.74194 | M38: 0 | N38: 645.16129 | O38: 2588.5 | P38: 947.74194 | Q38: =SUM(C38+E38+G38+I38+K38+M38+O38) -> 4198.5 | R38: =SUM(D38+F38+H38+J38+L38+N38+P38) -> 8689.6774 | U38: =SUM(Q38+S38) -> 4198.5 | V38: =SUM(R38+T38) -> 8689.6774 | W38: sonnig | X38: 18 | Y38: °C
A39: =SUM(A38+1) -> 31 | B39: Mi | C39: 2210.1 | D39: 4516.129 | E39: 0 | F39: 1129.0322 | G39: 157.2 | H39: 483.87096 | I39: 0 | K39: 147.2 | L39: 967.74194 | M39: 0 | N39: 645.16129 | O39: 3747.8 | P39: 947.74194 | Q39: =SUM(C39+E39+G39+I39+K39+M39+O39) -> 6262.3 | R39: =SUM(D39+F39+H39+J39+L39+N39+P39) -> 8689.6774 | U39: =SUM(Q39+S39) -> 6262.3 | V39: =SUM(R39+T39) -> 8689.6774 | W39: sonnig | X39: 23 | Y39: °C
A40: KW | B40: =SUM(B36+1) -> 14 | C40: =SUM(C37:C39) -> 5607.7 | D40: =SUM(D37:D39) -> 13548.387 | E40: =SUM(E37:E39) -> 53.9 | F40: =SUM(F37:F39) -> 3387.0967 | G40: =SUM(G37:G39) -> 212.3 | H40: =SUM(H37:H39) -> 1451.6129 | I40: =SUM(I37:I39) -> 0 | J40: =SUM(J37:J39) -> 0 | ... U40: =SUM(U37:U39) -> 15629.1 | V40: =SUM(V33:V35) -> 26069.032 | W40: Ø Temp | X40: =SUM(X37:X39)/3 -> 19 | Y40: °C
A41: Umsatz kumuliert | C41: =SUM(C12+C20+C28+C36+C40) -> 42299.1 | D41: =SUM(D12+D20+D28+D36+D40) -> 140000 | E41: =SUM(E12+E20+E28+E36+E40) -> 153.3 | F41: =SUM(F12+F20+F28+F36+F40) -> 35000 | G41: =SUM(G12+G20+G28+G36+G40) -> 481.6 | H41: =SUM(H12+H20+H28+H36+H40) -> 15000 | I41: =SUM(I12+I20+I28+I40) -> 0 | J41: =SUM(J12+J20+J28+J40) -> 0 | K41: =SUM(K12+K20+K28+K36+K40) -> 7049.5 | L41: =SUM(L12+L20+L28+L36+L40) -> 30000 | M41: =SUM(M12+M20+M28+M36+M40) -> 10619.3 | N41: =SUM(N12+N20+N28+N36+N40) -> 20000 | O41: =SUM(O12+O20+O28+O36+O40) -> 69619.25 | P41: =SUM(P12+P20+P28+P36+P40) -> 29380 | Q41: =SUM(Q12+Q20+Q28+Q36+Q40) -> 130222.05 | R41: =SUM(R12+R20+R28+R36+R40) -> 269380 | ... V41: =SUM(V12+V20+V28+V36+V40) -> 269380 | W41: Umsatz kumuliert
...

Sheet 04_21
A1: Tagesumsätze | H1: 44287
C3: Restaurant | E3: Terrasse | G3: Lounge | I3: Pavillon | K3: Bankett | M3: Seminar | O3: Hotel | Q3: TOTAL Gesamtbetrieb ohne Seebad | S3: Seebad | U3: TOTAL Gesamtbetrieb mit Seebad | W3: Info's
C4: IST | D4: Budget | E4: IST | F4: Budget | G4: IST | H4: Budget | I4: IST | J4: Budget | K4: IST | L4: Budget | M4: IST | N4: Budget | O4: IST | P4: Budget | Q4: IST | R4: Budget | S4: IST | T4: Budget | U4: IST | V4: Budget | W4: Wetter | X4: Temp. | Z4: Bemerkung
A5: 1 | B5: Do | C5: 2514.6 | D5: 5000 | E5: 14 | F5: 2666.6667 | G5: 111.6 | H5: 833.33333 | I5: 0 | K5: 0 | L5: 2166.6667 | M5: 0 | N5: 1000 | O5: 4668.5 | P5: 1958.3333 | Q5: =SUM(C5+E5+G5+I5+K5+M5+O5) -> 7308.7 | R5: =SUM(D5+F5+H5+J5+L5+N5+P5) -> 13625 | S5: 0 | T5: 66.66666 | U5: =SUM(Q5+S5) -> 7308.7 | V5: =SUM(R5+T5) -> 13691.667 | W5: sonnig | X5: 22 | Y5: °C
A6: =SUM(A5+1) -> 2 | B6: Fr | C6: 3415 | D6: 5000 | E6: 15 | F6: 2666.6667 | G6: 329.9 | H6: 833.33333 | I6: 0 | K6: 982.3 | L6: 2166.6667 | M6: 0 | N6: 1000 | O6: 5809.8 | P6: 1958.3333 | Q6: =SUM(C6+E6+G6+I6+K6+M6+O6) -> 10552 | R6: =SUM(D6+F6+H6+J6+L6+N6+P6) -> 13625 | S6: 0 | T6: 66.66666 | U6: =SUM(Q6+S6) -> 10552 | V6: =SUM(R6+T6) -> 13691.667 | W6: sonnig | X6: 22 | Y6: °C | Z6: Karfreitag
A7: =SUM(A6+1) -> 3 | B7: Sa | C7: 4237.8 | D7: 5000 | E7: 0 | F7: 2666.6667 | G7: 26 | H7: 833.33333 | I7: 0 | K7: 820.7 | L7: 2166.6667 | M7: 0 | N7: 1000 | O7: 5888.6 | P7: 1958.3333 | Q7: =SUM(C7+E7+G7+I7+K7+M7+O7) -> 10973.1 | R7: =SUM(D7+F7+H7+J7+L7+N7+P7) -> 13625 | S7: 0 | T7: 66.66666 | U7: =SUM(Q7+S7) -> 10973.1 | V7: =SUM(R7+T7) -> 13691.667 | W7: bewölkt | X7: 10 | Y7: °C
A8: =SUM(A7+1) -> 4 | B8: So | C8: 2594.1 | D8: 5000 | E8: 0 | F8: 2666.6667 | G8: 303.4 | H8: 833.33333 | I8: 0 | K8: 552.8 | L8: 2166.6667 | M8: 0 | N8: 1000 | O8: 4898 | P8: 1958.3333 | Q8: =SUM(C8+E8+G8+I8+K8+M8+O8) -> 8348.3 | R8: =SUM(D8+F8+H8+J8+L8+N8+P8) -> 13625 | S8: 0 | T8: 66.66666 | U8: =SUM(Q8+S8) -> 8348.3 | V8: =SUM(R8+T8) -> 13691.667 | W8: sonnig | X8: 18 | Y8: °C | Z8: Ostern
A9: KW | B9: 14 | C9: =SUM(C5:C8) -> 12761.5 | D9: =SUM(D5:D8) -> 20000 | E9: =SUM(E5:E8) -> 29 | F9: =SUM(F5:F8) -> 10666.667 | G9: =SUM(G5:G8) -> 770.9 | H9: =SUM(H5:H8) -> 3333.3333 | I9: =SUM(I5:I8) -> 0 | J9: =SUM(J5:J8) -> 0 | ... V9: =SUM(V5:V8) -> 54766.667 | W9: Ø Temp | X9: =SUM(X5:X8)/4 -> 18 | Y9: °C
A10: =SUM(A8+1) -> 5 | B10: Mo | C10: 839.5 | D10: 5000 | E10: 0 | F10: 2666.6667 | G10: 0 | H10: 833.33333 | I10: 0 | K10: 21 | L10: 2166.6667 | M10: 0 | N10: 1000 | O10: 1330.5 | P10: 1958.3333 | Q10: =SUM(C10+E10+G10+I10+K10+M10+O10) -> 2191 | R10: =SUM(D10+F10+H10+J10+L10+N10+P10) -> 13625 | S10: 0 | T10: 66.66666 | U10: =SUM(Q10+S10) -> 2191 | V10: =SUM(R10+T10) -> 13691.667 | W10: Schneeschauer | X10: 2 | Y10: °C | Z10: Ostermontag
A11: =SUM(A10+1) -> 6 | B11: Di | C11: 1141 | D11: 5000 | E11: 0 | F11: 2666.6667 | G11: 0 | H11: 833.33333 | I11: 0 | K11: 0 | L11: 2166.6667 | M11: 0 | N11: 1000 | O11: 2662.4 | P11: 1958.3333 | Q11: =SUM(C11+E11+G11+I11+K11+M11+O11) -> 3803.4 | R11: =SUM(D11+F11+H11+J11+L11+N11+P11) -> 13625 | S11: 0 | T11: 66.66666 | U11: =SUM(Q11+S11) -> 3803.4 | V11: =SUM(R11+T11) -> 13691.667 | W11: Schneeschauer | X11: 1 | Y11: °C
A12: =SUM(A11+1) -> 7 | B12: Mi | C12: 2290.6 | D12: 5000 | E12: 0 | F12: 2666.6667 | G12: 0 | H12: 833.33333 | I12: 0 | K12: 862 | L12: 2166.6667 | M12: 0 | N12: 1000 | O12: 5101.8 | P12: 1958.3333 | Q12: =SUM(C12+E12+G12+I12+K12+M12+O12) -> 8254.4 | R12: =SUM(D12+F12+H12+J12+L12+N12+P12) -> 13625 | S12: 0 | T12: 66.66666 | U12: =SUM(Q12+S12) -> 8254.4 | V12: =SUM(R12+T12) -> 13691.667 | W12: Schneeschauer | X12: 1 | Y12: °C
A13: =SUM(A12+1) -> 8 | B13: Do | C13: 2349.8 | D13: 5000 | E13: 0 | F13: 2666.6667 | G13: 83.8 | H13: 833.33333 | I13: 0 | K13: 647.4 | L13: 2166.6667 | M13: 0 | N13: 1000 | O13: 4965.6 | P13: 1958.3333 | Q13: =SUM(C13+E13+G13+I13+K13+M13+O13) -> 8046.6 | R13: =SUM(D13+F13+H13+J13+L13+N13+P13) -> 13625 | S13: 0 | T13: 66.66666 | U13: =SUM(Q13+S13) -> 8046.6 | V13: =SUM(R13+T13) -> 13691.667 | W13: sonnig | X13: 9 | Y13: °C
A14: =SUM(A13+1) -> 9 | B14: Fr | C14: 2336.8 | D14: 5000 | E14: 0 | F14: 2666.6667 | G14: 0 | H14: 833.33333 | I14: 0 | K14: 374.4 | L14: 2166.6667 | M14: 1661.8 | N14: 1000 | O14: 4431.7 | P14: 1958.3333 | Q14: =SUM(C14+E14+G14+I14+K14+M14+O14) -> 8804.7 | R14: =SUM(D14+F14+H14+J14+L14+N14+P14) -> 13625 | S14: 0 | T14: 66.66666 | U14: =SUM(Q14+S14) -> 8804.7 | V14: =SUM(R14+T14) -> 13691.667 | W14: leicht bewölkt | X14: 10 | Y14: °C
A15: =SUM(A14+1) -> 10 | B15: Sa | C15: 4317.8 | D15: 5000 | E15: 184 | F15: 2666.6667 | G15: 127.1 | H15: 833.33333 | I15: 0 | K15: 616.2 | L15: 2166.6667 | M15: 441.9 | N15: 1000 | O15: 6164.7 | P15: 1958.3333 | Q15: =SUM(C15+E15+G15+I15+K15+M15+O15) -> 11851.7 | R15: =SUM(D15+F15+H15+J15+L15+N15+P15) -> 13625 | S15: 0 | T15: 66.66666 | U15: =SUM(Q15+S15) -> 11851.7 | V15: =SUM(R15+T15) -> 13691.667 | W15: bewölkt | X15: 8 | Y15: °C
A16: =SUM(A15+1) -> 11 | B16: So | C16: 1135.8 | D16: 5000 | E16: 0 | F16: 2666.6667 | G16: 0 | H16: 833.33333 | I16: 0 | K16: 0 | L16: 2166.6667 | M16: 0 | N16: 1000 | O16: 1420.5 | P16: 1958.3333 | Q16: =SUM(C16+E16+G16+I16+K16+M16+O16) -> 2556.3 | R16: =SUM(D16+F16+H16+J16+L16+N16+P16) -> 13625 | S16: 0 | T16: 66.66666 | U16: =SUM(Q16+S16) -> 2556.3 | V16: =SUM(R16+T16) -> 13691.667 | W16: sonnig | X16: 10 | Y16: °C
A17: KW | B17: =SUM(B9+1) -> 15 | C17: =SUM(C10:C16) -> 14411.3 | D17: =SUM(D10:D16) -> 35000 | E17: =SUM(E10:E16) -> 184 | F17: =SUM(F10:F16) -> 18666.667 | G17: =SUM(G10:G16) -> 210.9 | H17: =SUM(H10:H16) -> 5833.3333 | I17: =SUM(I10:I16) -> 0 | J17: =SUM(J10:J16) -> 0 | ... V17: =SUM(V10:V16) -> 95841.666 | W17: Ø Temp | X17: =SUM(X10:X16)/7 -> 5.8571429 | Y17: °C
A18: =SUM(A16+1) -> 12 | B18: Mo | C18: 968.8 | D18: 5000 | E18: 0 | F18: 2666.6667 | G18: 0 | H18: 833.33333 | I18: 0 | K18: 0 | L18: 2166.6667 | M18: 1271 | N18: 1000 | O18: 2121.3 | P18: 1958.3333 | Q18: =SUM(C18+E18+G18+I18+K18+M18+O18) -> 4361.1 | R18: =SUM(D18+F18+H18+J18+L18+N18+P18) -> 13625 | S18: 0 | T18: 66.66666 | U18: =SUM(Q18+S18) -> 4361.1 | V18: =SUM(R18+T18) -> 13691.667 | W18: leicht bewölkt | X18: 10 | Y18: °C
A19: =SUM(A18+1) -> 13 | B19: Di | C19: 1512.6 | D19: 5000 | E19: 0 | F19: 2666.6667 | G19: 0 | H19: 833.33333 | I19: 0 | K19: 0 | L19: 2166.6667 | M19: 5314.6 | N19: 1000 | O19: 2237.3 | P19: 1958.3333 | Q19: =SUM(C19+E19+G19+I19+K19+M19+O19) -> 9064.5 | R19: =SUM(D19+F19+H19+J19+L19+N19+P19) -> 13625 | S19: 0 | T19: 66.66666 | U19: =SUM(Q19+S19) -> 9064.5 | V19: =SUM(R19+T19) -> 13691.667 | W19: leicht bewölkt | X19: 10 | Y19: °C
A20: =SUM(A19+1) -> 14 | B20: Mi | C20: 2695.8 | D20: 5000 | E20: 0 | F20: 2666.6667 | G20: 0 | H20: 833.33333 | I20: 0 | K20: 382.3 | L20: 2166.6667 | M20: 900.9 | N20: 1000 | O20: 4611.2 | P20: 1958.3333 | Q20: =SUM(C20+E20+G20+I20+K20+M20+O20) -> 8590.2 | R20: =SUM(D20+F20+H20+J20+L20+N20+P20) -> 13625 | S20: 0 | T20: 66.66666 | U20: =SUM(Q20+S20) -> 8590.2 | V20: =SUM(R20+T20) -> 13691.667 | W20: leicht bewölkt | X20: 10 | Y20: °C
A21: =SUM(A20+1) -> 15 | B21: Do | C21: 2551.5 | D21: 5000 | E21: 0 | F21: 2666.6667 | G21: 0 | H21: 833.33333 | I21: 0 | K21: 0 | L21: 2166.6667 | M21: 0 | N21: 1000 | O21: 3836.8 | P21: 1958.3333 | Q21: =SUM(C21+E21+G21+I21+K21+M21+O21) -> 6388.3 | R21: =SUM(D21+F21+H21+J21+L21+N21+P21) -> 13625 | S21: 0 | T21: 66.66666 | U21: =SUM(Q21+S21) -> 6388.3 | V21: =SUM(R21+T21) -> 13691.667 | W21: leicht bewölkt | X21: 10 | Y21: °C
A22: =SUM(A21+1) -> 16 | B22: Fr | C22: 3818.7 | D22: 5000 | E22: 0 | F22: 2666.6667 | G22: 96.8 | H22: 833.33333 | I22: 0 | K22: 783.4 | L22: 2166.6667 | M22: 0 | N22: 1000 | O22: 6768 | P22: 1958.3333 | Q22: =SUM(C22+E22+G22+I22+K22+M22+O22) -> 11466.9 | R22: =SUM(D22+F22+H22+J22+L22+N22+P22) -> 13625 | S22: 0 | T22: 66.66666 | U22: =SUM(Q22+S22) -> 11466.9 | V22: =SUM(R22+T22) -> 13691.667 | W22: ziemlich sonnig | X22: 10 | Y22: °C
A23: =SUM(A22+1) -> 17 | B23: Sa | C23: 3990.1 | D23: 5000 | E23: 0 | F23: 2666.6667 | G23: 96 | H23: 833.33333 | I23: 0 | K23: 1856.8 | L23: 2166.6667 | M23: 0 | N23: 1000 | O23: 5666.4 | P23: 1958.3333 | Q23: =SUM(C23+E23+G23+I23+K23+M23+O23) -> 11609.3 | R23: =SUM(D23+F23+H23+J23+L23+N23+P23) -> 13625 | S23: 0 | T23: 66.66666 | U23: =SUM(Q23+S23) -> 11609.3 | V23: =SUM(R23+T23) -> 13691.667 | W23: ziemlich sonnig | X23: 10 | Y23: °C
A24: =SUM(A23+1) -> 18 | B24: So | C24: 425 | D24: 5000 | E24: 0 | F24: 2666.6667 | G24: 0 | H24: 833.33333 | I24: 0 | K24: 0 | L24: 2166.6667 | M24: 0 | N24: 1000 | O24: 943 | P24: 1958.3333 | Q24: =SUM(C24+E24+G24+I24+K24+M24+O24) -> 1368 | R24: =SUM(D24+F24+H24+J24+L24+N24+P24) -> 13625 | S24: 0 | T24: 66.66666 | U24: =SUM(Q24+S24) -> 1368 | V24: =SUM(R24+T24) -> 13691.667 | W24: ziemlich sonnig | X24: 12 | Y24: °C
A25: KW | B25: =SUM(B17+1) -> 16 | C25: =SUM(C18:C24) -> 15962.5 | D25: =SUM(D18:D24) -> 35000 | E25: =SUM(E18:E24) -> 0 | F25: =SUM(F18:F24) -> 18666.667 | G25: =SUM(G18:G24) -> 192.8 | H25: =SUM(H18:H24) -> 5833.3333 | I25: =SUM(I18:I24) -> 0 | J25: =SUM(J18:J24) -> 0 | ... V25: =SUM(V18:V24) -> 95841.666 | W25: Ø Temp | X25: =SUM(X18:X24)/7 -> 10.285714 | Y25: °C
A26: =SUM(A24+1) -> 19 | B26: Mo | C26: 1810.4 | D26: 5000 | E26: 1205.3 | F26: 2666.6667 | G26: 337.3 | H26: 833.33333 | I26: 0 | K26: 0 | L26: 2166.6667 | M26: 0 | N26: 1000 | O26: 2736.2 | P26: 1958.3333 | Q26: =SUM(C26+E26+G26+I26+K26+M26+O26) -> 6089.2 | R26: =SUM(D26+F26+H26+J26+L26+N26+P26) -> 13625 | S26: 0 | T26: 66.66666 | U26: =SUM(Q26+S26) -> 6089.2 | V26: =SUM(R26+T26) -> 13691.667 | W26: ziemlich sonnig | X26: 10 | Y26: °C
A27: =SUM(A26+1) -> 20 | B27: Di | C27: 1106.4 | D27: 5000 | E27: 4474.3 | F27: 2666.6667 | G27: 1301.7 | H27: 833.33333 | I27: 0 | K27: 0 | L27: 2166.6667 | M27: 1033.2 | N27: 1000 | O27: 3777 | P27: 1958.3333 | Q27: =SUM(C27+E27+G27+I27+K27+M27+O27) -> 11692.6 | R27: =SUM(D27+F27+H27+J27+L27+N27+P27) -> 13625 | S27: 0 | T27: 66.66666 | U27: =SUM(Q27+S27) -> 11692.6 | V27: =SUM(R27+T27) -> 13691.667 | W27: sonnig | X27: 14 | Y27: °C
A28: =SUM(A27+1) -> 21 | B28: Mi | C28: 1791.8 | D28: 5000 | E28: 3697.5 | F28: 2666.6667 | G28: 956.9 | H28: 833.33333 | I28: 0 | K28: 0 | L28: 2166.6667 | M28: 3225.8 | N28: 1000 | O28: 2302.1 | P28: 1958.3333 | Q28: =SUM(C28+E28+G28+I28+K28+M28+O28) -> 11974.1 | R28: =SUM(D28+F28+H28+J28+L28+N28+P28) -> 13625 | S28: 0 | T28: 66.66666 | U28: =SUM(Q28+S28) -> 11974.1 | V28: =SUM(R28+T28) -> 13691.667 | W28: sonnig | X28: 14 | Y28: °C
A29: =SUM(A28+1) -> 22 | B29: Do | C29: 2331.8 | D29: 5000 | E29: 4333.7 | F29: 2666.6667 | G29: 1052.7 | H29: 833.33333 | I29: 0 | K29: 0 | L29: 2166.6667 | M29: 4370.4 | N29: 1000 | O29: 3435.8 | P29: 1958.3333 | Q29: =SUM(C29+E29+G29+I29+K29+M29+O29) -> 15524.4 | R29: =SUM(D29+F29+H29+J29+L29+N29+P29) -> 13625 | S29: 0 | T29: 66.66666 | U29: =SUM(Q29+S29) -> 15524.4 | V29: =SUM(R29+T29) -> 13691.667 | W29: sonnig | X29: 16 | Y29: °C
A30: =SUM(A29+1) -> 23 | B30: Fr | C30: 2801.9 | D30: 5000 | E30: 10392.7 | F30: 2666.6667 | G30: 2161.8 | H30: 833.33333 | I30: 0 | K30: 0 | L30: 2166.6667 | M30: 1792.4 | N30: 1000 | O30: 6528.6 | P30: 1958.3333 | Q30: =SUM(C30+E30+G30+I30+K30+M30+O30) -> 23677.4 | R30: =SUM(D30+F30+H30+J30+L30+N30+P30) -> 13625 | S30: 0 | T30: 66.66666 | U30: =SUM(Q30+S30) -> 23677.4 | V30: =SUM(R30+T30) -> 13691.667 | W30: sonnig | X30: 18 | Y30: °C
A31: =SUM(A30+1) -> 24 | B31: Sa | C31: 2982.8 | D31: 5000 | E31: 14734.1 | F31: 2666.6667 | G31: 2534.5 | H31: 833.33333 | I31: 0 | K31: 688.2 | L31: 2166.6667 | M31: 0 | N31: 1000 | O31: 6181.9 | P31: 1958.3333 | Q31: =SUM(C31+E31+G31+I31+K31+M31+O31) -> 27121.5 | R31: =SUM(D31+F31+H31+J31+L31+N31+P31) -> 13625 | S31: 0 | T31: 66.66666 | U31: =SUM(Q31+S31) -> 27121.5 | V31: =SUM(R31+T31) -> 13691.667 | W31: sonnig | X31: 19 | Y31: °C
A32: =SUM(A31+1) -> 25 | B32: So | C32: 1697.5 | D32: 5000 | E32: 15650.6 | F32: 2666.6667 | G32: 2539.8 | H32: 833.33333 | I32: 0 | K32: 0 | L32: 2166.6667 | M32: 0 | N32: 1000 | O32: 3577.3 | P32: 1958.3333 | Q32: =SUM(C32+E32+G32+I32+K32+M32+O32) -> 23465.2 | R32: =SUM(D32+F32+H32+J32+L32+N32+P32) -> 13625 | S32: 0 | T32: 66.66666 | U32: =SUM(Q32+S32) -> 23465.2 | V32: =SUM(R32+T32) -> 13691.667 | W32: sonnig | X32: 19 | Y32: °C
A33: KW | B33: =SUM(B25+1) -> 17 | C33: =SUM(C26:C32) -> 14522.6 | D33: =SUM(D26:D32) -> 35000 | E33: =SUM(E26:E32) -> 54488.2 | F33: =SUM(F26:F32) -> 18666.667 | G33: =SUM(G26:G32) -> 10884.7 | H33: =SUM(H26:H32) -> 5833.3333 | I33: =SUM(I26:I32) -> 0 | J33: =SUM(J26:J32) -> 0 | ... V33: =SUM(V26:V32) -> 95841.666 | W33: Ø Temp | X33: =SUM(X26:X32)/7 -> 15.714286 | Y33: °C
A34: =SUM(A32+1) -> 26 | B34: Mo | C34: 1859.3 | D34: 5000 | E34: 4711.7 | F34: 2666.6667 | G34: 279.1 | H34: 833.33333 | I34: 0 | K34: 0 | L34: 2166.6667 | M34: 0 | N34: 1000 | O34: 3051.7 | P34: 1958.3333 | Q34: =SUM(C34+E34+G34+I34+K34+M34+O34) -> 9901.8 | R34: =SUM(D34+F34+H34+J34+L34+N34+P34) -> 13625 | S34: 0 | T34: 66.66666 | U34: =SUM(Q34+S34) -> 9901.8 | V34: =SUM(R34+T34) -> 13691.667 | W34: leicht bewölkt | X34: 16 | Y34: °C
A35: =SUM(A34+1) -> 27 | B35: Di | C35: 2104.8 | D35: 5000 | E35: 7550.9 | F35: 2666.6667 | G35: 306.7 | H35: 833.33333 | I35: 0 | K35: 0 | L35: 2166.6667 | M35: 61 | N35: 1000 | O35: 2484.5 | P35: 1958.3333 | Q35: =SUM(C35+E35+G35+I35+K35+M35+O35) -> 12507.9 | R35: =SUM(D35+F35+H35+J35+L35+N35+P35) -> 13625 | S35: 0 | T35: 66.66666 | U35: =SUM(Q35+S35) -> 12507.9 | V35: =SUM(R35+T35) -> 13691.667 | W35: sonnig | X35: 16 | Y35: °C
A36: =SUM(A35+1) -> 28 | B36: Mi | C36: 1100.4 | D36: 5000 | E36: 3493 | F36: 2666.6667 | G36: 344.5 | H36: 833.33333 | I36: 0 | K36: 0 | L36: 2166.6667 | M36: 0 | N36: 1000 | O36: 2049.6 | P36: 1958.3333 | Q36: =SUM(C36+E36+G36+I36+K36+M36+O36) -> 6987.5 | R36: =SUM(D36+F36+H36+J36+L36+N36+P36) -> 13625 | S36: 0 | T36: 66.66666 | U36: =SUM(Q36+S36) -> 6987.5 | V36: =SUM(R36+T36) -> 13691.667 | W36: ziemlich sonnig | X36: 20 | Y36: °C
A37: =SUM(A36+1) -> 29 | B37: Do | C37: 1848.4 | D37: 5000 | E37: 1240.9 | F37: 2666.6667 | G37: 44.2 | H37: 833.33333 | I37: 0 | K37: 0 | L37: 2166.6667 | M37: 0 | N37: 1000 | O37: 3197.2 | P37: 1958.3333 | Q37: =SUM(C37+E37+G37+I37+K37+M37+O37) -> 6330.7 | R37: =SUM(D37+F37+H37+J37+L37+N37+P37) -> 13625 | S37: 0 | T37: 66.66666 | U37: =SUM(Q37+S37) -> 6330.7 | V37: =SUM(R37+T37) -> 13691.667 | W37: Regenschauer | X37: 14 | Y37: °C
A38: =SUM(A37+1) -> 30 | B38: Fr | C38: 2724.7 | D38: 5000 | E38: 728.8 | F38: 2666.6667 | G38: 4.6 | H38: 833.33333 | I38: 0 | K38: 2237.7 | L38: 2166.6667 | M38: 0 | N38: 1000 | O38: 6260.9 | P38: 1958.3333 | Q38: =SUM(C38+E38+G38+I38+K38+M38+O38) -> 11956.7 | R38: =SUM(D38+F38+H38+J38+L38+N38+P38) -> 13625 | S38: 0 | T38: 66.66666 | U38: =SUM(Q38+S38) -> 11956.7 | V38: =SUM(R38+T38) -> 13691.667 | W38: bewölkt | X38: 14 | Y38: °C
A39: KW | B39: =SUM(B33+1) -> 18 | C39: =SUM(C34:C38) -> 9637.6 | D39: =SUM(D34:D38) -> 25000 | E39: =SUM(E34:E38) -> 17725.3 | F39: =SUM(F34:F38) -> 13333.333 | G39: =SUM(G34:G38) -> 979.1 | H39: =SUM(H34:H38) -> 4166.6667 | I39: =SUM(I34:I38) -> 0 | J39: =SUM(J34:J38) -> 0 | ... V39: =SUM(V34:V38) -> 68458.333 | W39: Ø Temp | X39: =SUM(X34:X38)/5 -> 16 | Y39: °C
A40: Umsatz kumuliert | C40: =SUM(C9+C17+C25+C33+C39) -> 67295.5 | D40: =SUM(D9+D17+D25+D33+D39) -> 150000 | E40: =SUM(E9+E17+E25+E33+E39) -> 72426.5 | F40: =SUM(F9+F17+F25+F33+F39) -> 80000 | G40: =SUM(G9+G17+G25+G33+G39) -> 13038.4 | H40: =SUM(H9+H17+H25+H33+H39) -> 25000 | I40: =SUM(I9+I17+I25+I33+I39) -> 0 | J40: =SUM(J9+J17+J25+J33+J39) -> 0 | ... V40: =SUM(V9+V17+V25+V33+V39) -> 410750 | W40: Umsatz kumuliert
